2015-04-01 16:40:41,824 INFO org.apache.hadoop.yarn.server.resourcemanager.ResourceManager: STARTUP_MSG: 
/************************************************************
STARTUP_MSG: Starting ResourceManager
STARTUP_MSG:   host = a11p2/127.0.1.1
STARTUP_MSG:   args = []
STARTUP_MSG:   version = 2.5.2
STARTUP_MSG:   build = https://git-wip-us.apache.org/repos/asf/hadoop.git -r cc72e9b000545b86b75a61f4835eb86d57bfafc0; compiled by 'jenkins' on 2014-11-14T23:45Z
STARTUP_MSG:   java = 1.7.0_75
************************************************************/
2015-04-01 16:40:41,831 INFO org.apache.hadoop.yarn.server.resourcemanager.ResourceManager: registered UNIX signal handlers for [TERM, HUP, INT]
2015-04-01 16:40:41,999 INFO org.apache.hadoop.conf.Configuration: found resource core-site.xml at file:/home/m1/echallier/fac/m2/PPD/TP4/hadoop-2.5.2/etc/hadoop/core-site.xml
2015-04-01 16:40:42,083 WARN org.apache.hadoop.util.NativeCodeLoader: Unable to load native-hadoop library for your platform... using builtin-java classes where applicable
2015-04-01 16:40:42,084 INFO org.apache.hadoop.security.Groups: clearing userToGroupsMap cache
2015-04-01 16:40:42,089 INFO org.apache.hadoop.conf.Configuration: found resource yarn-site.xml at file:/home/m1/echallier/fac/m2/PPD/TP4/hadoop-2.5.2/etc/hadoop/yarn-site.xml
2015-04-01 16:40:42,137 INFO org.apache.hadoop.yarn.event.AsyncDispatcher: Registering class org.apache.hadoop.yarn.server.resourcemanager.RMFatalEventType for class org.apache.hadoop.yarn.server.resourcemanager.ResourceManager$RMFatalEventDispatcher
2015-04-01 16:40:42,212 INFO org.apache.hadoop.yarn.server.resourcemanager.security.NMTokenSecretManagerInRM: NMTokenKeyRollingInterval: 86400000ms and NMTokenKeyActivationDelay: 900000ms
2015-04-01 16:40:42,215 INFO org.apache.hadoop.yarn.server.resourcemanager.security.RMContainerTokenSecretManager: ContainerTokenKeyRollingInterval: 86400000ms and ContainerTokenKeyActivationDelay: 900000ms
2015-04-01 16:40:42,218 INFO org.apache.hadoop.yarn.server.resourcemanager.security.AMRMTokenSecretManager: Rolling master-key for amrm-tokens
2015-04-01 16:40:42,236 INFO org.apache.hadoop.yarn.event.AsyncDispatcher: Registering class org.apache.hadoop.yarn.server.resourcemanager.recovery.RMStateStoreEventType for class org.apache.hadoop.yarn.server.resourcemanager.recovery.RMStateStore$ForwardingEventHandler
2015-04-01 16:40:42,384 INFO org.apache.hadoop.yarn.event.AsyncDispatcher: Registering class org.apache.hadoop.yarn.server.resourcemanager.NodesListManagerEventType for class org.apache.hadoop.yarn.server.resourcemanager.NodesListManager
2015-04-01 16:40:42,384 INFO org.apache.hadoop.yarn.server.resourcemanager.ResourceManager: Using Scheduler: org.apache.hadoop.yarn.server.resourcemanager.scheduler.capacity.CapacityScheduler
2015-04-01 16:40:42,412 INFO org.apache.hadoop.yarn.event.AsyncDispatcher: Registering class org.apache.hadoop.yarn.server.resourcemanager.scheduler.event.SchedulerEventType for class org.apache.hadoop.yarn.server.resourcemanager.ResourceManager$SchedulerEventDispatcher
2015-04-01 16:40:42,412 INFO org.apache.hadoop.yarn.event.AsyncDispatcher: Registering class org.apache.hadoop.yarn.server.resourcemanager.rmapp.RMAppEventType for class org.apache.hadoop.yarn.server.resourcemanager.ResourceManager$ApplicationEventDispatcher
2015-04-01 16:40:42,413 INFO org.apache.hadoop.yarn.event.AsyncDispatcher: Registering class org.apache.hadoop.yarn.server.resourcemanager.rmapp.attempt.RMAppAttemptEventType for class org.apache.hadoop.yarn.server.resourcemanager.ResourceManager$ApplicationAttemptEventDispatcher
2015-04-01 16:40:42,414 INFO org.apache.hadoop.yarn.event.AsyncDispatcher: Registering class org.apache.hadoop.yarn.server.resourcemanager.rmnode.RMNodeEventType for class org.apache.hadoop.yarn.server.resourcemanager.ResourceManager$NodeEventDispatcher
2015-04-01 16:40:42,474 INFO org.apache.hadoop.metrics2.impl.MetricsConfig: loaded properties from hadoop-metrics2.properties
2015-04-01 16:40:42,528 INFO org.apache.hadoop.metrics2.impl.MetricsSystemImpl: Scheduled snapshot period at 10 second(s).
2015-04-01 16:40:42,528 INFO org.apache.hadoop.metrics2.impl.MetricsSystemImpl: ResourceManager metrics system started
2015-04-01 16:40:42,568 INFO org.apache.hadoop.yarn.event.AsyncDispatcher: Registering class org.apache.hadoop.yarn.server.resourcemanager.RMAppManagerEventType for class org.apache.hadoop.yarn.server.resourcemanager.RMAppManager
2015-04-01 16:40:42,572 INFO org.apache.hadoop.yarn.event.AsyncDispatcher: Registering class org.apache.hadoop.yarn.server.resourcemanager.amlauncher.AMLauncherEventType for class org.apache.hadoop.yarn.server.resourcemanager.amlauncher.ApplicationMasterLauncher
2015-04-01 16:40:42,574 INFO org.apache.hadoop.yarn.server.resourcemanager.RMNMInfo: Registered RMNMInfo MBean
2015-04-01 16:40:42,575 INFO org.apache.hadoop.yarn.event.AsyncDispatcher: Registering class org.apache.hadoop.yarn.server.resourcemanager.ahs.WritingHistoryEventType for class org.apache.hadoop.yarn.server.resourcemanager.ahs.RMApplicationHistoryWriter$ForwardingEventHandler
2015-04-01 16:40:42,575 INFO org.apache.hadoop.yarn.event.AsyncDispatcher: Registering class org.apache.hadoop.yarn.server.resourcemanager.ahs.WritingHistoryEventType for class org.apache.hadoop.yarn.server.resourcemanager.ahs.RMApplicationHistoryWriter$ForwardingEventHandler
2015-04-01 16:40:42,575 INFO org.apache.hadoop.yarn.event.AsyncDispatcher: Registering class org.apache.hadoop.yarn.server.resourcemanager.ahs.WritingHistoryEventType for class org.apache.hadoop.yarn.server.resourcemanager.ahs.RMApplicationHistoryWriter$ForwardingEventHandler
2015-04-01 16:40:42,575 INFO org.apache.hadoop.yarn.event.AsyncDispatcher: Registering class org.apache.hadoop.yarn.server.resourcemanager.ahs.WritingHistoryEventType for class org.apache.hadoop.yarn.server.resourcemanager.ahs.RMApplicationHistoryWriter$ForwardingEventHandler
2015-04-01 16:40:42,575 INFO org.apache.hadoop.yarn.event.AsyncDispatcher: Registering class org.apache.hadoop.yarn.server.resourcemanager.ahs.WritingHistoryEventType for class org.apache.hadoop.yarn.server.resourcemanager.ahs.RMApplicationHistoryWriter$ForwardingEventHandler
2015-04-01 16:40:42,575 INFO org.apache.hadoop.yarn.event.AsyncDispatcher: Registering class org.apache.hadoop.yarn.server.resourcemanager.ahs.WritingHistoryEventType for class org.apache.hadoop.yarn.server.resourcemanager.ahs.RMApplicationHistoryWriter$ForwardingEventHandler
2015-04-01 16:40:42,576 INFO org.apache.hadoop.yarn.event.AsyncDispatcher: Registering class org.apache.hadoop.yarn.server.resourcemanager.ahs.WritingHistoryEventType for class org.apache.hadoop.yarn.server.resourcemanager.ahs.RMApplicationHistoryWriter$ForwardingEventHandler
2015-04-01 16:40:42,576 INFO org.apache.hadoop.yarn.event.AsyncDispatcher: Registering class org.apache.hadoop.yarn.server.resourcemanager.ahs.WritingHistoryEventType for class org.apache.hadoop.yarn.server.resourcemanager.ahs.RMApplicationHistoryWriter$ForwardingEventHandler
2015-04-01 16:40:42,576 INFO org.apache.hadoop.yarn.event.AsyncDispatcher: Registering class org.apache.hadoop.yarn.server.resourcemanager.ahs.WritingHistoryEventType for class org.apache.hadoop.yarn.server.resourcemanager.ahs.RMApplicationHistoryWriter$ForwardingEventHandler
2015-04-01 16:40:42,576 INFO org.apache.hadoop.yarn.event.AsyncDispatcher: Registering class org.apache.hadoop.yarn.server.resourcemanager.ahs.WritingHistoryEventType for class org.apache.hadoop.yarn.server.resourcemanager.ahs.RMApplicationHistoryWriter$ForwardingEventHandler
2015-04-01 16:40:42,576 INFO org.apache.hadoop.util.HostsFileReader: Refreshing hosts (include/exclude) list
2015-04-01 16:40:42,583 INFO org.apache.hadoop.conf.Configuration: found resource capacity-scheduler.xml at file:/home/m1/echallier/fac/m2/PPD/TP4/hadoop-2.5.2/etc/hadoop/capacity-scheduler.xml
2015-04-01 16:40:42,630 INFO org.apache.hadoop.yarn.server.resourcemanager.scheduler.capacity.ParentQueue: root, capacity=1.0, asboluteCapacity=1.0, maxCapacity=1.0, asboluteMaxCapacity=1.0, state=RUNNING, acls=ADMINISTER_QUEUE:*SUBMIT_APPLICATIONS:*
2015-04-01 16:40:42,631 INFO org.apache.hadoop.yarn.server.resourcemanager.scheduler.capacity.ParentQueue: Initialized parent-queue root name=root, fullname=root
2015-04-01 16:40:42,638 INFO org.apache.hadoop.yarn.server.resourcemanager.scheduler.capacity.LeafQueue: Initializing default
capacity = 1.0 [= (float) configuredCapacity / 100 ]
asboluteCapacity = 1.0 [= parentAbsoluteCapacity * capacity ]
maxCapacity = 1.0 [= configuredMaxCapacity ]
absoluteMaxCapacity = 1.0 [= 1.0 maximumCapacity undefined, (parentAbsoluteMaxCapacity * maximumCapacity) / 100 otherwise ]
userLimit = 100 [= configuredUserLimit ]
userLimitFactor = 1.0 [= configuredUserLimitFactor ]
maxApplications = 10000 [= configuredMaximumSystemApplicationsPerQueue or (int)(configuredMaximumSystemApplications * absoluteCapacity)]
maxApplicationsPerUser = 10000 [= (int)(maxApplications * (userLimit / 100.0f) * userLimitFactor) ]
maxActiveApplications = 1 [= max((int)ceil((clusterResourceMemory / minimumAllocation) * maxAMResourcePerQueuePercent * absoluteMaxCapacity),1) ]
maxActiveAppsUsingAbsCap = 1 [= max((int)ceil((clusterResourceMemory / minimumAllocation) *maxAMResourcePercent * absoluteCapacity),1) ]
maxActiveApplicationsPerUser = 1 [= max((int)(maxActiveApplications * (userLimit / 100.0f) * userLimitFactor),1) ]
usedCapacity = 0.0 [= usedResourcesMemory / (clusterResourceMemory * absoluteCapacity)]
absoluteUsedCapacity = 0.0 [= usedResourcesMemory / clusterResourceMemory]
maxAMResourcePerQueuePercent = 0.1 [= configuredMaximumAMResourcePercent ]
minimumAllocationFactor = 0.875 [= (float)(maximumAllocationMemory - minimumAllocationMemory) / maximumAllocationMemory ]
numContainers = 0 [= currentNumContainers ]
state = RUNNING [= configuredState ]
acls = ADMINISTER_QUEUE:*SUBMIT_APPLICATIONS:* [= configuredAcls ]
nodeLocalityDelay = 40

2015-04-01 16:40:42,638 INFO org.apache.hadoop.yarn.server.resourcemanager.scheduler.capacity.CapacityScheduler: Initialized queue: default: capacity=1.0, absoluteCapacity=1.0, usedResources=<memory:0, vCores:0>, usedCapacity=0.0, absoluteUsedCapacity=0.0, numApps=0, numContainers=0
2015-04-01 16:40:42,638 INFO org.apache.hadoop.yarn.server.resourcemanager.scheduler.capacity.CapacityScheduler: Initialized queue: root: numChildQueue= 1, capacity=1.0, absoluteCapacity=1.0, usedResources=<memory:0, vCores:0>usedCapacity=0.0, numApps=0, numContainers=0
2015-04-01 16:40:42,638 INFO org.apache.hadoop.yarn.server.resourcemanager.scheduler.capacity.CapacityScheduler: Initialized root queue root: numChildQueue= 1, capacity=1.0, absoluteCapacity=1.0, usedResources=<memory:0, vCores:0>usedCapacity=0.0, numApps=0, numContainers=0
2015-04-01 16:40:42,638 INFO org.apache.hadoop.yarn.server.resourcemanager.scheduler.capacity.CapacityScheduler: Initialized CapacityScheduler with calculator=class org.apache.hadoop.yarn.util.resource.DefaultResourceCalculator, minimumAllocation=<<memory:1024, vCores:1>>, maximumAllocation=<<memory:8192, vCores:32>>, asynchronousScheduling=false, asyncScheduleInterval=5ms
2015-04-01 16:40:42,643 INFO org.apache.hadoop.yarn.server.resourcemanager.ResourceManager: Transitioning to active state
2015-04-01 16:40:42,648 INFO org.apache.hadoop.yarn.server.resourcemanager.security.AMRMTokenSecretManager: Rolling master-key for amrm-tokens
2015-04-01 16:40:42,648 INFO org.apache.hadoop.yarn.server.resourcemanager.security.RMContainerTokenSecretManager: Rolling master-key for container-tokens
2015-04-01 16:40:42,651 INFO org.apache.hadoop.yarn.server.resourcemanager.security.NMTokenSecretManagerInRM: Rolling master-key for nm-tokens
2015-04-01 16:40:42,651 INFO org.apache.hadoop.security.token.delegation.AbstractDelegationTokenSecretManager: Updating the current master key for generating delegation tokens
2015-04-01 16:40:42,651 INFO org.apache.hadoop.yarn.server.resourcemanager.security.RMDelegationTokenSecretManager: storing master key with keyID 1
2015-04-01 16:40:42,652 INFO org.apache.hadoop.security.token.delegation.AbstractDelegationTokenSecretManager: Starting expired delegation token remover thread, tokenRemoverScanInterval=60 min(s)
2015-04-01 16:40:42,652 INFO org.apache.hadoop.security.token.delegation.AbstractDelegationTokenSecretManager: Updating the current master key for generating delegation tokens
2015-04-01 16:40:42,652 INFO org.apache.hadoop.yarn.server.resourcemanager.security.RMDelegationTokenSecretManager: storing master key with keyID 2
2015-04-01 16:40:42,678 INFO org.apache.hadoop.ipc.CallQueueManager: Using callQueue class java.util.concurrent.LinkedBlockingQueue
2015-04-01 16:40:42,689 INFO org.apache.hadoop.ipc.Server: Starting Socket Reader #1 for port 8031
2015-04-01 16:40:42,704 INFO org.apache.hadoop.yarn.factories.impl.pb.RpcServerFactoryPBImpl: Adding protocol org.apache.hadoop.yarn.server.api.ResourceTrackerPB to the server
2015-04-01 16:40:42,704 INFO org.apache.hadoop.ipc.Server: IPC Server Responder: starting
2015-04-01 16:40:42,705 INFO org.apache.hadoop.ipc.Server: IPC Server listener on 8031: starting
2015-04-01 16:40:42,733 INFO org.apache.hadoop.ipc.CallQueueManager: Using callQueue class java.util.concurrent.LinkedBlockingQueue
2015-04-01 16:40:42,741 INFO org.apache.hadoop.ipc.Server: Starting Socket Reader #1 for port 8030
2015-04-01 16:40:42,779 INFO org.apache.hadoop.yarn.factories.impl.pb.RpcServerFactoryPBImpl: Adding protocol org.apache.hadoop.yarn.api.ApplicationMasterProtocolPB to the server
2015-04-01 16:40:42,779 INFO org.apache.hadoop.ipc.Server: IPC Server Responder: starting
2015-04-01 16:40:42,779 INFO org.apache.hadoop.ipc.Server: IPC Server listener on 8030: starting
2015-04-01 16:40:42,816 INFO org.apache.hadoop.ipc.CallQueueManager: Using callQueue class java.util.concurrent.LinkedBlockingQueue
2015-04-01 16:40:42,817 INFO org.apache.hadoop.ipc.Server: Starting Socket Reader #1 for port 8032
2015-04-01 16:40:42,819 INFO org.apache.hadoop.yarn.factories.impl.pb.RpcServerFactoryPBImpl: Adding protocol org.apache.hadoop.yarn.api.ApplicationClientProtocolPB to the server
2015-04-01 16:40:42,821 INFO org.apache.hadoop.ipc.Server: IPC Server Responder: starting
2015-04-01 16:40:42,821 INFO org.apache.hadoop.ipc.Server: IPC Server listener on 8032: starting
2015-04-01 16:40:42,825 INFO org.apache.hadoop.yarn.server.resourcemanager.ResourceManager: Transitioned to active state
2015-04-01 16:40:42,885 INFO org.mortbay.log: Logging to org.slf4j.impl.Log4jLoggerAdapter(org.mortbay.log) via org.mortbay.log.Slf4jLog
2015-04-01 16:40:42,888 INFO org.apache.hadoop.http.HttpRequestLog: Http request log for http.requests.resourcemanager is not defined
2015-04-01 16:40:42,897 INFO org.apache.hadoop.http.HttpServer2: Added global filter 'safety' (class=org.apache.hadoop.http.HttpServer2$QuotingInputFilter)
2015-04-01 16:40:42,903 INFO org.apache.hadoop.http.HttpServer2: Added filter YARNAuthenticationFilter (class=org.apache.hadoop.yarn.server.security.http.RMAuthenticationFilter) to context cluster
2015-04-01 16:40:42,904 INFO org.apache.hadoop.http.HttpServer2: Added filter YARNAuthenticationFilter (class=org.apache.hadoop.yarn.server.security.http.RMAuthenticationFilter) to context logs
2015-04-01 16:40:42,904 INFO org.apache.hadoop.http.HttpServer2: Added filter YARNAuthenticationFilter (class=org.apache.hadoop.yarn.server.security.http.RMAuthenticationFilter) to context static
2015-04-01 16:40:42,904 INFO org.apache.hadoop.http.HttpServer2: Added filter static_user_filter (class=org.apache.hadoop.http.lib.StaticUserWebFilter$StaticUserFilter) to context cluster
2015-04-01 16:40:42,904 INFO org.apache.hadoop.http.HttpServer2: Added filter static_user_filter (class=org.apache.hadoop.http.lib.StaticUserWebFilter$StaticUserFilter) to context logs
2015-04-01 16:40:42,904 INFO org.apache.hadoop.http.HttpServer2: Added filter static_user_filter (class=org.apache.hadoop.http.lib.StaticUserWebFilter$StaticUserFilter) to context static
2015-04-01 16:40:42,907 INFO org.apache.hadoop.http.HttpServer2: adding path spec: /cluster/*
2015-04-01 16:40:42,907 INFO org.apache.hadoop.http.HttpServer2: adding path spec: /ws/*
2015-04-01 16:40:42,920 INFO org.apache.hadoop.http.HttpServer2: Jetty bound to port 8088
2015-04-01 16:40:42,920 INFO org.mortbay.log: jetty-6.1.26
2015-04-01 16:40:42,940 INFO org.mortbay.log: Extract jar:file:/home/m1/echallier/fac/m2/PPD/TP4/hadoop-2.5.2/share/hadoop/yarn/hadoop-yarn-common-2.5.2.jar!/webapps/cluster to /tmp/Jetty_0_0_0_0_8088_cluster____u0rgz3/webapp
2015-04-01 16:40:43,177 WARN org.apache.hadoop.security.authentication.server.AuthenticationFilter: 'signature.secret' configuration not set, using a random value as secret
2015-04-01 16:40:43,202 WARN org.apache.hadoop.security.authentication.server.AuthenticationFilter: 'signature.secret' configuration not set, using a random value as secret
2015-04-01 16:40:43,202 WARN org.apache.hadoop.security.authentication.server.AuthenticationFilter: 'signature.secret' configuration not set, using a random value as secret
2015-04-01 16:40:43,206 INFO org.mortbay.log: Started HttpServer2$SelectChannelConnectorWithSafeStartup@0.0.0.0:8088
2015-04-01 16:40:43,206 INFO org.apache.hadoop.yarn.webapp.WebApps: Web app /cluster started at 8088
2015-04-01 16:40:43,578 INFO org.apache.hadoop.yarn.webapp.WebApps: Registered webapp guice modules
2015-04-01 16:40:43,597 INFO org.apache.hadoop.ipc.CallQueueManager: Using callQueue class java.util.concurrent.LinkedBlockingQueue
2015-04-01 16:40:43,598 INFO org.apache.hadoop.ipc.Server: Starting Socket Reader #1 for port 8033
2015-04-01 16:40:43,606 INFO org.apache.hadoop.yarn.factories.impl.pb.RpcServerFactoryPBImpl: Adding protocol org.apache.hadoop.yarn.server.api.ResourceManagerAdministrationProtocolPB to the server
2015-04-01 16:40:43,606 INFO org.apache.hadoop.ipc.Server: IPC Server Responder: starting
2015-04-01 16:40:43,606 INFO org.apache.hadoop.ipc.Server: IPC Server listener on 8033: starting
2015-04-01 16:40:45,374 INFO org.apache.hadoop.yarn.util.RackResolver: Resolved a11p2.fil.univ-lille1.fr. to /default-rack
2015-04-01 16:40:45,380 INFO org.apache.hadoop.yarn.server.resourcemanager.ResourceTrackerService: NodeManager from node a11p2.fil.univ-lille1.fr.(cmPort: 55305 httpPort: 8042) registered with capability: <memory:8192, vCores:8>, assigned nodeId a11p2.fil.univ-lille1.fr.:55305
2015-04-01 16:40:45,381 INFO org.apache.hadoop.yarn.server.resourcemanager.rmnode.RMNodeImpl: a11p2.fil.univ-lille1.fr.:55305 Node Transitioned from NEW to RUNNING
2015-04-01 16:40:45,383 INFO org.apache.hadoop.yarn.server.resourcemanager.scheduler.capacity.CapacityScheduler: Added node a11p2.fil.univ-lille1.fr.:55305 clusterResource: <memory:8192, vCores:8>
2015-04-01 16:42:01,637 INFO org.apache.hadoop.yarn.server.resourcemanager.ClientRMService: Allocated new applicationId: 1
2015-04-01 16:42:02,741 INFO org.apache.hadoop.yarn.server.resourcemanager.ClientRMService: Application with id 1 submitted by user echallier
2015-04-01 16:42:02,741 INFO org.apache.hadoop.yarn.server.resourcemanager.rmapp.RMAppImpl: Storing application with id application_1427899242644_0001
2015-04-01 16:42:02,742 INFO org.apache.hadoop.yarn.server.resourcemanager.RMAuditLogger: USER=echallier	IP=127.0.0.1	OPERATION=Submit Application Request	TARGET=ClientRMService	RESULT=SUCCESS	APPID=application_1427899242644_0001
2015-04-01 16:42:02,743 INFO org.apache.hadoop.yarn.server.resourcemanager.rmapp.RMAppImpl: application_1427899242644_0001 State change from NEW to NEW_SAVING
2015-04-01 16:42:02,751 INFO org.apache.hadoop.yarn.server.resourcemanager.recovery.RMStateStore: Storing info for app: application_1427899242644_0001
2015-04-01 16:42:02,752 INFO org.apache.hadoop.yarn.server.resourcemanager.rmapp.RMAppImpl: application_1427899242644_0001 State change from NEW_SAVING to SUBMITTED
2015-04-01 16:42:02,753 INFO org.apache.hadoop.yarn.server.resourcemanager.scheduler.capacity.ParentQueue: Application added - appId: application_1427899242644_0001 user: echallier leaf-queue of parent: root #applications: 1
2015-04-01 16:42:02,754 INFO org.apache.hadoop.yarn.server.resourcemanager.scheduler.capacity.CapacityScheduler: Accepted application application_1427899242644_0001 from user: echallier, in queue: default
2015-04-01 16:42:02,760 INFO org.apache.hadoop.yarn.server.resourcemanager.rmapp.RMAppImpl: application_1427899242644_0001 State change from SUBMITTED to ACCEPTED
2015-04-01 16:42:02,761 INFO org.apache.hadoop.yarn.server.resourcemanager.ApplicationMasterService: Registering app attempt : appattempt_1427899242644_0001_000001
2015-04-01 16:42:02,777 INFO org.apache.hadoop.yarn.server.resourcemanager.rmapp.attempt.RMAppAttemptImpl: appattempt_1427899242644_0001_000001 State change from NEW to SUBMITTED
2015-04-01 16:42:02,787 INFO org.apache.hadoop.yarn.server.resourcemanager.scheduler.capacity.LeafQueue: Application application_1427899242644_0001 from user: echallier activated in queue: default
2015-04-01 16:42:02,787 INFO org.apache.hadoop.yarn.server.resourcemanager.scheduler.capacity.LeafQueue: Application added - appId: application_1427899242644_0001 user: org.apache.hadoop.yarn.server.resourcemanager.scheduler.capacity.LeafQueue$User@14703c3, leaf-queue: default #user-pending-applications: 0 #user-active-applications: 1 #queue-pending-applications: 0 #queue-active-applications: 1
2015-04-01 16:42:02,787 INFO org.apache.hadoop.yarn.server.resourcemanager.scheduler.capacity.CapacityScheduler: Added Application Attempt appattempt_1427899242644_0001_000001 to scheduler from user echallier in queue default
2015-04-01 16:42:02,788 INFO org.apache.hadoop.yarn.server.resourcemanager.rmapp.attempt.RMAppAttemptImpl: appattempt_1427899242644_0001_000001 State change from SUBMITTED to SCHEDULED
2015-04-01 16:42:03,593 INFO org.apache.hadoop.yarn.server.resourcemanager.rmcontainer.RMContainerImpl: container_1427899242644_0001_01_000001 Container Transitioned from NEW to ALLOCATED
2015-04-01 16:42:03,593 INFO org.apache.hadoop.yarn.server.resourcemanager.RMAuditLogger: USER=echallier	OPERATION=AM Allocated Container	TARGET=SchedulerApp	RESULT=SUCCESS	APPID=application_1427899242644_0001	CONTAINERID=container_1427899242644_0001_01_000001
2015-04-01 16:42:03,594 INFO org.apache.hadoop.yarn.server.resourcemanager.scheduler.SchedulerNode: Assigned container container_1427899242644_0001_01_000001 of capacity <memory:2048, vCores:1> on host a11p2.fil.univ-lille1.fr.:55305, which has 1 containers, <memory:2048, vCores:1> used and <memory:6144, vCores:7> available after allocation
2015-04-01 16:42:03,594 INFO org.apache.hadoop.yarn.server.resourcemanager.scheduler.capacity.LeafQueue: assignedContainer application attempt=appattempt_1427899242644_0001_000001 container=Container: [ContainerId: container_1427899242644_0001_01_000001, NodeId: a11p2.fil.univ-lille1.fr.:55305, NodeHttpAddress: a11p2.fil.univ-lille1.fr.:8042, Resource: <memory:2048, vCores:1>, Priority: 0, Token: null, ] queue=default: capacity=1.0, absoluteCapacity=1.0, usedResources=<memory:0, vCores:0>, usedCapacity=0.0, absoluteUsedCapacity=0.0, numApps=1, numContainers=0 clusterResource=<memory:8192, vCores:8>
2015-04-01 16:42:03,594 INFO org.apache.hadoop.yarn.server.resourcemanager.scheduler.capacity.ParentQueue: Re-sorting assigned queue: root.default stats: default: capacity=1.0, absoluteCapacity=1.0, usedResources=<memory:2048, vCores:1>, usedCapacity=0.25, absoluteUsedCapacity=0.25, numApps=1, numContainers=1
2015-04-01 16:42:03,595 INFO org.apache.hadoop.yarn.server.resourcemanager.scheduler.capacity.ParentQueue: assignedContainer queue=root usedCapacity=0.25 absoluteUsedCapacity=0.25 used=<memory:2048, vCores:1> cluster=<memory:8192, vCores:8>
2015-04-01 16:42:03,598 INFO org.apache.hadoop.yarn.server.resourcemanager.security.NMTokenSecretManagerInRM: Sending NMToken for nodeId : a11p2.fil.univ-lille1.fr.:55305 for container : container_1427899242644_0001_01_000001
2015-04-01 16:42:03,604 INFO org.apache.hadoop.yarn.server.resourcemanager.rmcontainer.RMContainerImpl: container_1427899242644_0001_01_000001 Container Transitioned from ALLOCATED to ACQUIRED
2015-04-01 16:42:03,604 INFO org.apache.hadoop.yarn.server.resourcemanager.security.NMTokenSecretManagerInRM: Clear node set for appattempt_1427899242644_0001_000001
2015-04-01 16:42:03,608 INFO org.apache.hadoop.yarn.server.resourcemanager.rmapp.attempt.RMAppAttemptImpl: Storing attempt: AppId: application_1427899242644_0001 AttemptId: appattempt_1427899242644_0001_000001 MasterContainer: Container: [ContainerId: container_1427899242644_0001_01_000001, NodeId: a11p2.fil.univ-lille1.fr.:55305, NodeHttpAddress: a11p2.fil.univ-lille1.fr.:8042, Resource: <memory:2048, vCores:1>, Priority: 0, Token: Token { kind: ContainerToken, service: 127.0.1.1:55305 }, ]
2015-04-01 16:42:03,613 INFO org.apache.hadoop.yarn.server.resourcemanager.rmapp.attempt.RMAppAttemptImpl: appattempt_1427899242644_0001_000001 State change from SCHEDULED to ALLOCATED_SAVING
2015-04-01 16:42:03,626 INFO org.apache.hadoop.yarn.server.resourcemanager.rmapp.attempt.RMAppAttemptImpl: appattempt_1427899242644_0001_000001 State change from ALLOCATED_SAVING to ALLOCATED
2015-04-01 16:42:03,630 INFO org.apache.hadoop.yarn.server.resourcemanager.amlauncher.AMLauncher: Launching masterappattempt_1427899242644_0001_000001
2015-04-01 16:42:03,667 INFO org.apache.hadoop.yarn.server.resourcemanager.amlauncher.AMLauncher: Setting up container Container: [ContainerId: container_1427899242644_0001_01_000001, NodeId: a11p2.fil.univ-lille1.fr.:55305, NodeHttpAddress: a11p2.fil.univ-lille1.fr.:8042, Resource: <memory:2048, vCores:1>, Priority: 0, Token: Token { kind: ContainerToken, service: 127.0.1.1:55305 }, ] for AM appattempt_1427899242644_0001_000001
2015-04-01 16:42:03,667 INFO org.apache.hadoop.yarn.server.resourcemanager.amlauncher.AMLauncher: Command to launch container container_1427899242644_0001_01_000001 : $JAVA_HOME/bin/java -Dlog4j.configuration=container-log4j.properties -Dyarn.app.container.log.dir=<LOG_DIR> -Dyarn.app.container.log.filesize=0 -Dhadoop.root.logger=INFO,CLA  -Xmx1024m org.apache.hadoop.mapreduce.v2.app.MRAppMaster 1><LOG_DIR>/stdout 2><LOG_DIR>/stderr 
2015-04-01 16:42:03,930 INFO org.apache.hadoop.yarn.server.resourcemanager.amlauncher.AMLauncher: Done launching container Container: [ContainerId: container_1427899242644_0001_01_000001, NodeId: a11p2.fil.univ-lille1.fr.:55305, NodeHttpAddress: a11p2.fil.univ-lille1.fr.:8042, Resource: <memory:2048, vCores:1>, Priority: 0, Token: Token { kind: ContainerToken, service: 127.0.1.1:55305 }, ] for AM appattempt_1427899242644_0001_000001
2015-04-01 16:42:03,930 INFO org.apache.hadoop.yarn.server.resourcemanager.rmapp.attempt.RMAppAttemptImpl: appattempt_1427899242644_0001_000001 State change from ALLOCATED to LAUNCHED
2015-04-01 16:42:04,576 INFO org.apache.hadoop.yarn.server.resourcemanager.rmcontainer.RMContainerImpl: container_1427899242644_0001_01_000001 Container Transitioned from ACQUIRED to RUNNING
2015-04-01 16:42:07,530 INFO SecurityLogger.org.apache.hadoop.ipc.Server: Auth successful for appattempt_1427899242644_0001_000001 (auth:SIMPLE)
2015-04-01 16:42:07,535 INFO org.apache.hadoop.yarn.server.resourcemanager.ApplicationMasterService: AM registration appattempt_1427899242644_0001_000001
2015-04-01 16:42:07,535 INFO org.apache.hadoop.yarn.server.resourcemanager.RMAuditLogger: USER=echallier	IP=127.0.0.1	OPERATION=Register App Master	TARGET=ApplicationMasterService	RESULT=SUCCESS	APPID=application_1427899242644_0001	APPATTEMPTID=appattempt_1427899242644_0001_000001
2015-04-01 16:42:07,536 INFO org.apache.hadoop.yarn.server.resourcemanager.rmapp.attempt.RMAppAttemptImpl: appattempt_1427899242644_0001_000001 State change from LAUNCHED to RUNNING
2015-04-01 16:42:07,536 INFO org.apache.hadoop.yarn.server.resourcemanager.rmapp.RMAppImpl: application_1427899242644_0001 State change from ACCEPTED to RUNNING
2015-04-01 16:42:09,583 INFO org.apache.hadoop.yarn.server.resourcemanager.rmcontainer.RMContainerImpl: container_1427899242644_0001_01_000002 Container Transitioned from NEW to ALLOCATED
2015-04-01 16:42:09,584 INFO org.apache.hadoop.yarn.server.resourcemanager.RMAuditLogger: USER=echallier	OPERATION=AM Allocated Container	TARGET=SchedulerApp	RESULT=SUCCESS	APPID=application_1427899242644_0001	CONTAINERID=container_1427899242644_0001_01_000002
2015-04-01 16:42:09,584 INFO org.apache.hadoop.yarn.server.resourcemanager.scheduler.SchedulerNode: Assigned container container_1427899242644_0001_01_000002 of capacity <memory:1024, vCores:1> on host a11p2.fil.univ-lille1.fr.:55305, which has 2 containers, <memory:3072, vCores:2> used and <memory:5120, vCores:6> available after allocation
2015-04-01 16:42:09,584 INFO org.apache.hadoop.yarn.server.resourcemanager.scheduler.capacity.LeafQueue: assignedContainer application attempt=appattempt_1427899242644_0001_000001 container=Container: [ContainerId: container_1427899242644_0001_01_000002, NodeId: a11p2.fil.univ-lille1.fr.:55305, NodeHttpAddress: a11p2.fil.univ-lille1.fr.:8042, Resource: <memory:1024, vCores:1>, Priority: 20, Token: null, ] queue=default: capacity=1.0, absoluteCapacity=1.0, usedResources=<memory:2048, vCores:1>, usedCapacity=0.25, absoluteUsedCapacity=0.25, numApps=1, numContainers=1 clusterResource=<memory:8192, vCores:8>
2015-04-01 16:42:09,585 INFO org.apache.hadoop.yarn.server.resourcemanager.scheduler.capacity.ParentQueue: Re-sorting assigned queue: root.default stats: default: capacity=1.0, absoluteCapacity=1.0, usedResources=<memory:3072, vCores:2>, usedCapacity=0.375, absoluteUsedCapacity=0.375, numApps=1, numContainers=2
2015-04-01 16:42:09,585 INFO org.apache.hadoop.yarn.server.resourcemanager.scheduler.capacity.ParentQueue: assignedContainer queue=root usedCapacity=0.375 absoluteUsedCapacity=0.375 used=<memory:3072, vCores:2> cluster=<memory:8192, vCores:8>
2015-04-01 16:42:09,613 INFO org.apache.hadoop.yarn.server.resourcemanager.security.NMTokenSecretManagerInRM: Sending NMToken for nodeId : a11p2.fil.univ-lille1.fr.:55305 for container : container_1427899242644_0001_01_000002
2015-04-01 16:42:09,614 INFO org.apache.hadoop.yarn.server.resourcemanager.rmcontainer.RMContainerImpl: container_1427899242644_0001_01_000002 Container Transitioned from ALLOCATED to ACQUIRED
2015-04-01 16:42:10,584 INFO org.apache.hadoop.yarn.server.resourcemanager.rmcontainer.RMContainerImpl: container_1427899242644_0001_01_000002 Container Transitioned from ACQUIRED to RUNNING
2015-04-01 16:42:10,632 INFO org.apache.hadoop.yarn.server.resourcemanager.scheduler.AppSchedulingInfo: checking for deactivate... 
2015-04-01 16:42:12,978 INFO org.apache.hadoop.yarn.server.resourcemanager.rmcontainer.RMContainerImpl: container_1427899242644_0001_01_000002 Container Transitioned from RUNNING to COMPLETED
2015-04-01 16:42:12,978 INFO org.apache.hadoop.yarn.server.resourcemanager.scheduler.common.fica.FiCaSchedulerApp: Completed container: container_1427899242644_0001_01_000002 in state: COMPLETED event:FINISHED
2015-04-01 16:42:12,978 INFO org.apache.hadoop.yarn.server.resourcemanager.RMAuditLogger: USER=echallier	OPERATION=AM Released Container	TARGET=SchedulerApp	RESULT=SUCCESS	APPID=application_1427899242644_0001	CONTAINERID=container_1427899242644_0001_01_000002
2015-04-01 16:42:12,979 INFO org.apache.hadoop.yarn.server.resourcemanager.scheduler.SchedulerNode: Released container container_1427899242644_0001_01_000002 of capacity <memory:1024, vCores:1> on host a11p2.fil.univ-lille1.fr.:55305, which currently has 1 containers, <memory:2048, vCores:1> used and <memory:6144, vCores:7> available, release resources=true
2015-04-01 16:42:12,979 INFO org.apache.hadoop.yarn.server.resourcemanager.scheduler.capacity.LeafQueue: default used=<memory:2048, vCores:1> numContainers=1 user=echallier user-resources=<memory:2048, vCores:1>
2015-04-01 16:42:12,979 INFO org.apache.hadoop.yarn.server.resourcemanager.scheduler.capacity.LeafQueue: completedContainer container=Container: [ContainerId: container_1427899242644_0001_01_000002, NodeId: a11p2.fil.univ-lille1.fr.:55305, NodeHttpAddress: a11p2.fil.univ-lille1.fr.:8042, Resource: <memory:1024, vCores:1>, Priority: 20, Token: Token { kind: ContainerToken, service: 127.0.1.1:55305 }, ] queue=default: capacity=1.0, absoluteCapacity=1.0, usedResources=<memory:2048, vCores:1>, usedCapacity=0.25, absoluteUsedCapacity=0.25, numApps=1, numContainers=1 cluster=<memory:8192, vCores:8>
2015-04-01 16:42:12,979 INFO org.apache.hadoop.yarn.server.resourcemanager.scheduler.capacity.ParentQueue: completedContainer queue=root usedCapacity=0.25 absoluteUsedCapacity=0.25 used=<memory:2048, vCores:1> cluster=<memory:8192, vCores:8>
2015-04-01 16:42:12,979 INFO org.apache.hadoop.yarn.server.resourcemanager.scheduler.capacity.ParentQueue: Re-sorting completed queue: root.default stats: default: capacity=1.0, absoluteCapacity=1.0, usedResources=<memory:2048, vCores:1>, usedCapacity=0.25, absoluteUsedCapacity=0.25, numApps=1, numContainers=1
2015-04-01 16:42:12,980 INFO org.apache.hadoop.yarn.server.resourcemanager.scheduler.capacity.CapacityScheduler: Application attempt appattempt_1427899242644_0001_000001 released container container_1427899242644_0001_01_000002 on node: host: a11p2.fil.univ-lille1.fr.:55305 #containers=1 available=6144 used=2048 with event: FINISHED
2015-04-01 16:42:13,980 INFO org.apache.hadoop.yarn.server.resourcemanager.rmcontainer.RMContainerImpl: container_1427899242644_0001_01_000003 Container Transitioned from NEW to ALLOCATED
2015-04-01 16:42:13,980 INFO org.apache.hadoop.yarn.server.resourcemanager.RMAuditLogger: USER=echallier	OPERATION=AM Allocated Container	TARGET=SchedulerApp	RESULT=SUCCESS	APPID=application_1427899242644_0001	CONTAINERID=container_1427899242644_0001_01_000003
2015-04-01 16:42:13,980 INFO org.apache.hadoop.yarn.server.resourcemanager.scheduler.SchedulerNode: Assigned container container_1427899242644_0001_01_000003 of capacity <memory:1024, vCores:1> on host a11p2.fil.univ-lille1.fr.:55305, which has 2 containers, <memory:3072, vCores:2> used and <memory:5120, vCores:6> available after allocation
2015-04-01 16:42:13,981 INFO org.apache.hadoop.yarn.server.resourcemanager.scheduler.capacity.LeafQueue: assignedContainer application attempt=appattempt_1427899242644_0001_000001 container=Container: [ContainerId: container_1427899242644_0001_01_000003, NodeId: a11p2.fil.univ-lille1.fr.:55305, NodeHttpAddress: a11p2.fil.univ-lille1.fr.:8042, Resource: <memory:1024, vCores:1>, Priority: 10, Token: null, ] queue=default: capacity=1.0, absoluteCapacity=1.0, usedResources=<memory:2048, vCores:1>, usedCapacity=0.25, absoluteUsedCapacity=0.25, numApps=1, numContainers=1 clusterResource=<memory:8192, vCores:8>
2015-04-01 16:42:13,981 INFO org.apache.hadoop.yarn.server.resourcemanager.scheduler.capacity.ParentQueue: Re-sorting assigned queue: root.default stats: default: capacity=1.0, absoluteCapacity=1.0, usedResources=<memory:3072, vCores:2>, usedCapacity=0.375, absoluteUsedCapacity=0.375, numApps=1, numContainers=2
2015-04-01 16:42:13,981 INFO org.apache.hadoop.yarn.server.resourcemanager.scheduler.capacity.ParentQueue: assignedContainer queue=root usedCapacity=0.375 absoluteUsedCapacity=0.375 used=<memory:3072, vCores:2> cluster=<memory:8192, vCores:8>
2015-04-01 16:42:14,652 INFO org.apache.hadoop.yarn.server.resourcemanager.rmcontainer.RMContainerImpl: container_1427899242644_0001_01_000003 Container Transitioned from ALLOCATED to ACQUIRED
2015-04-01 16:42:14,982 INFO org.apache.hadoop.yarn.server.resourcemanager.rmcontainer.RMContainerImpl: container_1427899242644_0001_01_000003 Container Transitioned from ACQUIRED to RUNNING
2015-04-01 16:42:15,655 INFO org.apache.hadoop.yarn.server.resourcemanager.scheduler.AppSchedulingInfo: checking for deactivate... 
2015-04-01 16:42:17,441 INFO org.apache.hadoop.yarn.server.resourcemanager.rmapp.attempt.RMAppAttemptImpl: Updating application attempt appattempt_1427899242644_0001_000001 with final state: FINISHING, and exit status: -1000
2015-04-01 16:42:17,442 INFO org.apache.hadoop.yarn.server.resourcemanager.rmapp.attempt.RMAppAttemptImpl: appattempt_1427899242644_0001_000001 State change from RUNNING to FINAL_SAVING
2015-04-01 16:42:17,442 INFO org.apache.hadoop.yarn.server.resourcemanager.rmapp.RMAppImpl: Updating application application_1427899242644_0001 with final state: FINISHING
2015-04-01 16:42:17,442 INFO org.apache.hadoop.yarn.server.resourcemanager.rmapp.RMAppImpl: application_1427899242644_0001 State change from RUNNING to FINAL_SAVING
2015-04-01 16:42:17,443 INFO org.apache.hadoop.yarn.server.resourcemanager.recovery.RMStateStore: Updating info for app: application_1427899242644_0001
2015-04-01 16:42:17,443 INFO org.apache.hadoop.yarn.server.resourcemanager.rmapp.attempt.RMAppAttemptImpl: appattempt_1427899242644_0001_000001 State change from FINAL_SAVING to FINISHING
2015-04-01 16:42:17,443 INFO org.apache.hadoop.yarn.server.resourcemanager.rmapp.RMAppImpl: application_1427899242644_0001 State change from FINAL_SAVING to FINISHING
2015-04-01 16:42:18,015 INFO org.apache.hadoop.yarn.server.resourcemanager.rmcontainer.RMContainerImpl: container_1427899242644_0001_01_000003 Container Transitioned from RUNNING to COMPLETED
2015-04-01 16:42:18,015 INFO org.apache.hadoop.yarn.server.resourcemanager.scheduler.common.fica.FiCaSchedulerApp: Completed container: container_1427899242644_0001_01_000003 in state: COMPLETED event:FINISHED
2015-04-01 16:42:18,015 INFO org.apache.hadoop.yarn.server.resourcemanager.RMAuditLogger: USER=echallier	OPERATION=AM Released Container	TARGET=SchedulerApp	RESULT=SUCCESS	APPID=application_1427899242644_0001	CONTAINERID=container_1427899242644_0001_01_000003
2015-04-01 16:42:18,015 INFO org.apache.hadoop.yarn.server.resourcemanager.scheduler.SchedulerNode: Released container container_1427899242644_0001_01_000003 of capacity <memory:1024, vCores:1> on host a11p2.fil.univ-lille1.fr.:55305, which currently has 1 containers, <memory:2048, vCores:1> used and <memory:6144, vCores:7> available, release resources=true
2015-04-01 16:42:18,015 INFO org.apache.hadoop.yarn.server.resourcemanager.scheduler.capacity.LeafQueue: default used=<memory:2048, vCores:1> numContainers=1 user=echallier user-resources=<memory:2048, vCores:1>
2015-04-01 16:42:18,016 INFO org.apache.hadoop.yarn.server.resourcemanager.scheduler.capacity.LeafQueue: completedContainer container=Container: [ContainerId: container_1427899242644_0001_01_000003, NodeId: a11p2.fil.univ-lille1.fr.:55305, NodeHttpAddress: a11p2.fil.univ-lille1.fr.:8042, Resource: <memory:1024, vCores:1>, Priority: 10, Token: Token { kind: ContainerToken, service: 127.0.1.1:55305 }, ] queue=default: capacity=1.0, absoluteCapacity=1.0, usedResources=<memory:2048, vCores:1>, usedCapacity=0.25, absoluteUsedCapacity=0.25, numApps=1, numContainers=1 cluster=<memory:8192, vCores:8>
2015-04-01 16:42:18,016 INFO org.apache.hadoop.yarn.server.resourcemanager.scheduler.capacity.ParentQueue: completedContainer queue=root usedCapacity=0.25 absoluteUsedCapacity=0.25 used=<memory:2048, vCores:1> cluster=<memory:8192, vCores:8>
2015-04-01 16:42:18,016 INFO org.apache.hadoop.yarn.server.resourcemanager.scheduler.capacity.ParentQueue: Re-sorting completed queue: root.default stats: default: capacity=1.0, absoluteCapacity=1.0, usedResources=<memory:2048, vCores:1>, usedCapacity=0.25, absoluteUsedCapacity=0.25, numApps=1, numContainers=1
2015-04-01 16:42:18,016 INFO org.apache.hadoop.yarn.server.resourcemanager.scheduler.capacity.CapacityScheduler: Application attempt appattempt_1427899242644_0001_000001 released container container_1427899242644_0001_01_000003 on node: host: a11p2.fil.univ-lille1.fr.:55305 #containers=1 available=6144 used=2048 with event: FINISHED
2015-04-01 16:42:24,026 INFO org.apache.hadoop.yarn.server.resourcemanager.rmcontainer.RMContainerImpl: container_1427899242644_0001_01_000001 Container Transitioned from RUNNING to COMPLETED
2015-04-01 16:42:24,026 INFO org.apache.hadoop.yarn.server.resourcemanager.ApplicationMasterService: Unregistering app attempt : appattempt_1427899242644_0001_000001
2015-04-01 16:42:24,027 INFO org.apache.hadoop.yarn.server.resourcemanager.scheduler.common.fica.FiCaSchedulerApp: Completed container: container_1427899242644_0001_01_000001 in state: COMPLETED event:FINISHED
2015-04-01 16:42:24,027 INFO org.apache.hadoop.yarn.server.resourcemanager.RMAuditLogger: USER=echallier	OPERATION=AM Released Container	TARGET=SchedulerApp	RESULT=SUCCESS	APPID=application_1427899242644_0001	CONTAINERID=container_1427899242644_0001_01_000001
2015-04-01 16:42:24,027 INFO org.apache.hadoop.yarn.server.resourcemanager.scheduler.SchedulerNode: Released container container_1427899242644_0001_01_000001 of capacity <memory:2048, vCores:1> on host a11p2.fil.univ-lille1.fr.:55305, which currently has 0 containers, <memory:0, vCores:0> used and <memory:8192, vCores:8> available, release resources=true
2015-04-01 16:42:24,027 INFO org.apache.hadoop.yarn.server.resourcemanager.scheduler.capacity.LeafQueue: default used=<memory:0, vCores:0> numContainers=0 user=echallier user-resources=<memory:0, vCores:0>
2015-04-01 16:42:24,027 INFO org.apache.hadoop.yarn.server.resourcemanager.scheduler.capacity.LeafQueue: completedContainer container=Container: [ContainerId: container_1427899242644_0001_01_000001, NodeId: a11p2.fil.univ-lille1.fr.:55305, NodeHttpAddress: a11p2.fil.univ-lille1.fr.:8042, Resource: <memory:2048, vCores:1>, Priority: 0, Token: Token { kind: ContainerToken, service: 127.0.1.1:55305 }, ] queue=default: capacity=1.0, absoluteCapacity=1.0, usedResources=<memory:0, vCores:0>, usedCapacity=0.0, absoluteUsedCapacity=0.0, numApps=1, numContainers=0 cluster=<memory:8192, vCores:8>
2015-04-01 16:42:24,028 INFO org.apache.hadoop.yarn.server.resourcemanager.scheduler.capacity.ParentQueue: completedContainer queue=root usedCapacity=0.0 absoluteUsedCapacity=0.0 used=<memory:0, vCores:0> cluster=<memory:8192, vCores:8>
2015-04-01 16:42:24,028 INFO org.apache.hadoop.yarn.server.resourcemanager.scheduler.capacity.ParentQueue: Re-sorting completed queue: root.default stats: default: capacity=1.0, absoluteCapacity=1.0, usedResources=<memory:0, vCores:0>, usedCapacity=0.0, absoluteUsedCapacity=0.0, numApps=1, numContainers=0
2015-04-01 16:42:24,028 INFO org.apache.hadoop.yarn.server.resourcemanager.scheduler.capacity.CapacityScheduler: Application attempt appattempt_1427899242644_0001_000001 released container container_1427899242644_0001_01_000001 on node: host: a11p2.fil.univ-lille1.fr.:55305 #containers=0 available=8192 used=0 with event: FINISHED
2015-04-01 16:42:24,028 INFO org.apache.hadoop.yarn.server.resourcemanager.rmapp.attempt.RMAppAttemptImpl: appattempt_1427899242644_0001_000001 State change from FINISHING to FINISHED
2015-04-01 16:42:24,031 INFO org.apache.hadoop.yarn.server.resourcemanager.rmapp.RMAppImpl: application_1427899242644_0001 State change from FINISHING to FINISHED
2015-04-01 16:42:24,031 INFO org.apache.hadoop.yarn.server.resourcemanager.scheduler.capacity.CapacityScheduler: Application Attempt appattempt_1427899242644_0001_000001 is done. finalState=FINISHED
2015-04-01 16:42:24,031 INFO org.apache.hadoop.yarn.server.resourcemanager.scheduler.AppSchedulingInfo: Application application_1427899242644_0001 requests cleared
2015-04-01 16:42:24,031 INFO org.apache.hadoop.yarn.server.resourcemanager.scheduler.capacity.LeafQueue: Application removed - appId: application_1427899242644_0001 user: echallier queue: default #user-pending-applications: 0 #user-active-applications: 0 #queue-pending-applications: 0 #queue-active-applications: 0
2015-04-01 16:42:24,032 INFO org.apache.hadoop.yarn.server.resourcemanager.scheduler.capacity.ParentQueue: Application removed - appId: application_1427899242644_0001 user: echallier leaf-queue of parent: root #applications: 0
2015-04-01 16:42:24,032 INFO org.apache.hadoop.yarn.server.resourcemanager.amlauncher.AMLauncher: Cleaning master appattempt_1427899242644_0001_000001
2015-04-01 16:42:24,032 INFO org.apache.hadoop.yarn.server.resourcemanager.RMAuditLogger: USER=echallier	OPERATION=Application Finished - Succeeded	TARGET=RMAppManager	RESULT=SUCCESS	APPID=application_1427899242644_0001
2015-04-01 16:42:24,034 INFO org.apache.hadoop.yarn.server.resourcemanager.RMAppManager$ApplicationSummary: appId=application_1427899242644_0001,name=anagrames,user=echallier,queue=default,state=FINISHED,trackingUrl=http://a11p2.fil.univ-lille1.fr.:8088/proxy/application_1427899242644_0001/jobhistory/job/job_1427899242644_0001,appMasterHost=a11p2,startTime=1427899322740,finishTime=1427899337442,finalStatus=SUCCEEDED
2015-04-01 16:45:08,920 INFO org.apache.hadoop.yarn.server.resourcemanager.ClientRMService: Allocated new applicationId: 2
2015-04-01 16:45:09,781 INFO org.apache.hadoop.yarn.server.resourcemanager.ClientRMService: Application with id 2 submitted by user echallier
2015-04-01 16:45:09,781 INFO org.apache.hadoop.yarn.server.resourcemanager.rmapp.RMAppImpl: Storing application with id application_1427899242644_0002
2015-04-01 16:45:09,781 INFO org.apache.hadoop.yarn.server.resourcemanager.RMAuditLogger: USER=echallier	IP=127.0.0.1	OPERATION=Submit Application Request	TARGET=ClientRMService	RESULT=SUCCESS	APPID=application_1427899242644_0002
2015-04-01 16:45:09,781 INFO org.apache.hadoop.yarn.server.resourcemanager.rmapp.RMAppImpl: application_1427899242644_0002 State change from NEW to NEW_SAVING
2015-04-01 16:45:09,781 INFO org.apache.hadoop.yarn.server.resourcemanager.recovery.RMStateStore: Storing info for app: application_1427899242644_0002
2015-04-01 16:45:09,781 INFO org.apache.hadoop.yarn.server.resourcemanager.rmapp.RMAppImpl: application_1427899242644_0002 State change from NEW_SAVING to SUBMITTED
2015-04-01 16:45:09,782 INFO org.apache.hadoop.yarn.server.resourcemanager.scheduler.capacity.ParentQueue: Application added - appId: application_1427899242644_0002 user: echallier leaf-queue of parent: root #applications: 1
2015-04-01 16:45:09,782 INFO org.apache.hadoop.yarn.server.resourcemanager.scheduler.capacity.CapacityScheduler: Accepted application application_1427899242644_0002 from user: echallier, in queue: default
2015-04-01 16:45:09,782 INFO org.apache.hadoop.yarn.server.resourcemanager.rmapp.RMAppImpl: application_1427899242644_0002 State change from SUBMITTED to ACCEPTED
2015-04-01 16:45:09,783 INFO org.apache.hadoop.yarn.server.resourcemanager.ApplicationMasterService: Registering app attempt : appattempt_1427899242644_0002_000001
2015-04-01 16:45:09,783 INFO org.apache.hadoop.yarn.server.resourcemanager.rmapp.attempt.RMAppAttemptImpl: appattempt_1427899242644_0002_000001 State change from NEW to SUBMITTED
2015-04-01 16:45:09,783 INFO org.apache.hadoop.yarn.server.resourcemanager.scheduler.capacity.LeafQueue: Application application_1427899242644_0002 from user: echallier activated in queue: default
2015-04-01 16:45:09,783 INFO org.apache.hadoop.yarn.server.resourcemanager.scheduler.capacity.LeafQueue: Application added - appId: application_1427899242644_0002 user: org.apache.hadoop.yarn.server.resourcemanager.scheduler.capacity.LeafQueue$User@38e3d8, leaf-queue: default #user-pending-applications: 0 #user-active-applications: 1 #queue-pending-applications: 0 #queue-active-applications: 1
2015-04-01 16:45:09,783 INFO org.apache.hadoop.yarn.server.resourcemanager.scheduler.capacity.CapacityScheduler: Added Application Attempt appattempt_1427899242644_0002_000001 to scheduler from user echallier in queue default
2015-04-01 16:45:09,783 INFO org.apache.hadoop.yarn.server.resourcemanager.rmapp.attempt.RMAppAttemptImpl: appattempt_1427899242644_0002_000001 State change from SUBMITTED to SCHEDULED
2015-04-01 16:45:10,300 INFO org.apache.hadoop.yarn.server.resourcemanager.rmcontainer.RMContainerImpl: container_1427899242644_0002_01_000001 Container Transitioned from NEW to ALLOCATED
2015-04-01 16:45:10,300 INFO org.apache.hadoop.yarn.server.resourcemanager.RMAuditLogger: USER=echallier	OPERATION=AM Allocated Container	TARGET=SchedulerApp	RESULT=SUCCESS	APPID=application_1427899242644_0002	CONTAINERID=container_1427899242644_0002_01_000001
2015-04-01 16:45:10,300 INFO org.apache.hadoop.yarn.server.resourcemanager.scheduler.SchedulerNode: Assigned container container_1427899242644_0002_01_000001 of capacity <memory:2048, vCores:1> on host a11p2.fil.univ-lille1.fr.:55305, which has 1 containers, <memory:2048, vCores:1> used and <memory:6144, vCores:7> available after allocation
2015-04-01 16:45:10,300 INFO org.apache.hadoop.yarn.server.resourcemanager.scheduler.capacity.LeafQueue: assignedContainer application attempt=appattempt_1427899242644_0002_000001 container=Container: [ContainerId: container_1427899242644_0002_01_000001, NodeId: a11p2.fil.univ-lille1.fr.:55305, NodeHttpAddress: a11p2.fil.univ-lille1.fr.:8042, Resource: <memory:2048, vCores:1>, Priority: 0, Token: null, ] queue=default: capacity=1.0, absoluteCapacity=1.0, usedResources=<memory:0, vCores:0>, usedCapacity=0.0, absoluteUsedCapacity=0.0, numApps=1, numContainers=0 clusterResource=<memory:8192, vCores:8>
2015-04-01 16:45:10,300 INFO org.apache.hadoop.yarn.server.resourcemanager.scheduler.capacity.ParentQueue: Re-sorting assigned queue: root.default stats: default: capacity=1.0, absoluteCapacity=1.0, usedResources=<memory:2048, vCores:1>, usedCapacity=0.25, absoluteUsedCapacity=0.25, numApps=1, numContainers=1
2015-04-01 16:45:10,301 INFO org.apache.hadoop.yarn.server.resourcemanager.scheduler.capacity.ParentQueue: assignedContainer queue=root usedCapacity=0.25 absoluteUsedCapacity=0.25 used=<memory:2048, vCores:1> cluster=<memory:8192, vCores:8>
2015-04-01 16:45:10,301 INFO org.apache.hadoop.yarn.server.resourcemanager.security.NMTokenSecretManagerInRM: Sending NMToken for nodeId : a11p2.fil.univ-lille1.fr.:55305 for container : container_1427899242644_0002_01_000001
2015-04-01 16:45:10,302 INFO org.apache.hadoop.yarn.server.resourcemanager.rmcontainer.RMContainerImpl: container_1427899242644_0002_01_000001 Container Transitioned from ALLOCATED to ACQUIRED
2015-04-01 16:45:10,302 INFO org.apache.hadoop.yarn.server.resourcemanager.security.NMTokenSecretManagerInRM: Clear node set for appattempt_1427899242644_0002_000001
2015-04-01 16:45:10,302 INFO org.apache.hadoop.yarn.server.resourcemanager.rmapp.attempt.RMAppAttemptImpl: Storing attempt: AppId: application_1427899242644_0002 AttemptId: appattempt_1427899242644_0002_000001 MasterContainer: Container: [ContainerId: container_1427899242644_0002_01_000001, NodeId: a11p2.fil.univ-lille1.fr.:55305, NodeHttpAddress: a11p2.fil.univ-lille1.fr.:8042, Resource: <memory:2048, vCores:1>, Priority: 0, Token: Token { kind: ContainerToken, service: 127.0.1.1:55305 }, ]
2015-04-01 16:45:10,302 INFO org.apache.hadoop.yarn.server.resourcemanager.rmapp.attempt.RMAppAttemptImpl: appattempt_1427899242644_0002_000001 State change from SCHEDULED to ALLOCATED_SAVING
2015-04-01 16:45:10,302 INFO org.apache.hadoop.yarn.server.resourcemanager.rmapp.attempt.RMAppAttemptImpl: appattempt_1427899242644_0002_000001 State change from ALLOCATED_SAVING to ALLOCATED
2015-04-01 16:45:10,303 INFO org.apache.hadoop.yarn.server.resourcemanager.amlauncher.AMLauncher: Launching masterappattempt_1427899242644_0002_000001
2015-04-01 16:45:10,304 INFO org.apache.hadoop.yarn.server.resourcemanager.amlauncher.AMLauncher: Setting up container Container: [ContainerId: container_1427899242644_0002_01_000001, NodeId: a11p2.fil.univ-lille1.fr.:55305, NodeHttpAddress: a11p2.fil.univ-lille1.fr.:8042, Resource: <memory:2048, vCores:1>, Priority: 0, Token: Token { kind: ContainerToken, service: 127.0.1.1:55305 }, ] for AM appattempt_1427899242644_0002_000001
2015-04-01 16:45:10,304 INFO org.apache.hadoop.yarn.server.resourcemanager.amlauncher.AMLauncher: Command to launch container container_1427899242644_0002_01_000001 : $JAVA_HOME/bin/java -Dlog4j.configuration=container-log4j.properties -Dyarn.app.container.log.dir=<LOG_DIR> -Dyarn.app.container.log.filesize=0 -Dhadoop.root.logger=INFO,CLA  -Xmx1024m org.apache.hadoop.mapreduce.v2.app.MRAppMaster 1><LOG_DIR>/stdout 2><LOG_DIR>/stderr 
2015-04-01 16:45:10,316 INFO org.apache.hadoop.yarn.server.resourcemanager.amlauncher.AMLauncher: Done launching container Container: [ContainerId: container_1427899242644_0002_01_000001, NodeId: a11p2.fil.univ-lille1.fr.:55305, NodeHttpAddress: a11p2.fil.univ-lille1.fr.:8042, Resource: <memory:2048, vCores:1>, Priority: 0, Token: Token { kind: ContainerToken, service: 127.0.1.1:55305 }, ] for AM appattempt_1427899242644_0002_000001
2015-04-01 16:45:10,316 INFO org.apache.hadoop.yarn.server.resourcemanager.rmapp.attempt.RMAppAttemptImpl: appattempt_1427899242644_0002_000001 State change from ALLOCATED to LAUNCHED
2015-04-01 16:45:11,301 INFO org.apache.hadoop.yarn.server.resourcemanager.rmcontainer.RMContainerImpl: container_1427899242644_0002_01_000001 Container Transitioned from ACQUIRED to RUNNING
2015-04-01 16:45:13,320 INFO SecurityLogger.org.apache.hadoop.ipc.Server: Auth successful for appattempt_1427899242644_0002_000001 (auth:SIMPLE)
2015-04-01 16:45:13,322 INFO org.apache.hadoop.yarn.server.resourcemanager.ApplicationMasterService: AM registration appattempt_1427899242644_0002_000001
2015-04-01 16:45:13,322 INFO org.apache.hadoop.yarn.server.resourcemanager.RMAuditLogger: USER=echallier	IP=127.0.0.1	OPERATION=Register App Master	TARGET=ApplicationMasterService	RESULT=SUCCESS	APPID=application_1427899242644_0002	APPATTEMPTID=appattempt_1427899242644_0002_000001
2015-04-01 16:45:13,323 INFO org.apache.hadoop.yarn.server.resourcemanager.rmapp.attempt.RMAppAttemptImpl: appattempt_1427899242644_0002_000001 State change from LAUNCHED to RUNNING
2015-04-01 16:45:13,323 INFO org.apache.hadoop.yarn.server.resourcemanager.rmapp.RMAppImpl: application_1427899242644_0002 State change from ACCEPTED to RUNNING
2015-04-01 16:45:15,308 INFO org.apache.hadoop.yarn.server.resourcemanager.rmcontainer.RMContainerImpl: container_1427899242644_0002_01_000002 Container Transitioned from NEW to ALLOCATED
2015-04-01 16:45:15,308 INFO org.apache.hadoop.yarn.server.resourcemanager.RMAuditLogger: USER=echallier	OPERATION=AM Allocated Container	TARGET=SchedulerApp	RESULT=SUCCESS	APPID=application_1427899242644_0002	CONTAINERID=container_1427899242644_0002_01_000002
2015-04-01 16:45:15,308 INFO org.apache.hadoop.yarn.server.resourcemanager.scheduler.SchedulerNode: Assigned container container_1427899242644_0002_01_000002 of capacity <memory:1024, vCores:1> on host a11p2.fil.univ-lille1.fr.:55305, which has 2 containers, <memory:3072, vCores:2> used and <memory:5120, vCores:6> available after allocation
2015-04-01 16:45:15,309 INFO org.apache.hadoop.yarn.server.resourcemanager.scheduler.capacity.LeafQueue: assignedContainer application attempt=appattempt_1427899242644_0002_000001 container=Container: [ContainerId: container_1427899242644_0002_01_000002, NodeId: a11p2.fil.univ-lille1.fr.:55305, NodeHttpAddress: a11p2.fil.univ-lille1.fr.:8042, Resource: <memory:1024, vCores:1>, Priority: 20, Token: null, ] queue=default: capacity=1.0, absoluteCapacity=1.0, usedResources=<memory:2048, vCores:1>, usedCapacity=0.25, absoluteUsedCapacity=0.25, numApps=1, numContainers=1 clusterResource=<memory:8192, vCores:8>
2015-04-01 16:45:15,309 INFO org.apache.hadoop.yarn.server.resourcemanager.scheduler.capacity.ParentQueue: Re-sorting assigned queue: root.default stats: default: capacity=1.0, absoluteCapacity=1.0, usedResources=<memory:3072, vCores:2>, usedCapacity=0.375, absoluteUsedCapacity=0.375, numApps=1, numContainers=2
2015-04-01 16:45:15,309 INFO org.apache.hadoop.yarn.server.resourcemanager.scheduler.capacity.ParentQueue: assignedContainer queue=root usedCapacity=0.375 absoluteUsedCapacity=0.375 used=<memory:3072, vCores:2> cluster=<memory:8192, vCores:8>
2015-04-01 16:45:15,378 INFO org.apache.hadoop.yarn.server.resourcemanager.security.NMTokenSecretManagerInRM: Sending NMToken for nodeId : a11p2.fil.univ-lille1.fr.:55305 for container : container_1427899242644_0002_01_000002
2015-04-01 16:45:15,379 INFO org.apache.hadoop.yarn.server.resourcemanager.rmcontainer.RMContainerImpl: container_1427899242644_0002_01_000002 Container Transitioned from ALLOCATED to ACQUIRED
2015-04-01 16:45:16,313 INFO org.apache.hadoop.yarn.server.resourcemanager.rmcontainer.RMContainerImpl: container_1427899242644_0002_01_000002 Container Transitioned from ACQUIRED to RUNNING
2015-04-01 16:45:16,394 INFO org.apache.hadoop.yarn.server.resourcemanager.scheduler.AppSchedulingInfo: checking for deactivate... 
2015-04-01 16:45:18,609 INFO org.apache.hadoop.yarn.server.resourcemanager.rmcontainer.RMContainerImpl: container_1427899242644_0002_01_000002 Container Transitioned from RUNNING to COMPLETED
2015-04-01 16:45:18,610 INFO org.apache.hadoop.yarn.server.resourcemanager.scheduler.common.fica.FiCaSchedulerApp: Completed container: container_1427899242644_0002_01_000002 in state: COMPLETED event:FINISHED
2015-04-01 16:45:18,610 INFO org.apache.hadoop.yarn.server.resourcemanager.RMAuditLogger: USER=echallier	OPERATION=AM Released Container	TARGET=SchedulerApp	RESULT=SUCCESS	APPID=application_1427899242644_0002	CONTAINERID=container_1427899242644_0002_01_000002
2015-04-01 16:45:18,610 INFO org.apache.hadoop.yarn.server.resourcemanager.scheduler.SchedulerNode: Released container container_1427899242644_0002_01_000002 of capacity <memory:1024, vCores:1> on host a11p2.fil.univ-lille1.fr.:55305, which currently has 1 containers, <memory:2048, vCores:1> used and <memory:6144, vCores:7> available, release resources=true
2015-04-01 16:45:18,610 INFO org.apache.hadoop.yarn.server.resourcemanager.scheduler.capacity.LeafQueue: default used=<memory:2048, vCores:1> numContainers=1 user=echallier user-resources=<memory:2048, vCores:1>
2015-04-01 16:45:18,610 INFO org.apache.hadoop.yarn.server.resourcemanager.scheduler.capacity.LeafQueue: completedContainer container=Container: [ContainerId: container_1427899242644_0002_01_000002, NodeId: a11p2.fil.univ-lille1.fr.:55305, NodeHttpAddress: a11p2.fil.univ-lille1.fr.:8042, Resource: <memory:1024, vCores:1>, Priority: 20, Token: Token { kind: ContainerToken, service: 127.0.1.1:55305 }, ] queue=default: capacity=1.0, absoluteCapacity=1.0, usedResources=<memory:2048, vCores:1>, usedCapacity=0.25, absoluteUsedCapacity=0.25, numApps=1, numContainers=1 cluster=<memory:8192, vCores:8>
2015-04-01 16:45:18,610 INFO org.apache.hadoop.yarn.server.resourcemanager.scheduler.capacity.ParentQueue: completedContainer queue=root usedCapacity=0.25 absoluteUsedCapacity=0.25 used=<memory:2048, vCores:1> cluster=<memory:8192, vCores:8>
2015-04-01 16:45:18,611 INFO org.apache.hadoop.yarn.server.resourcemanager.scheduler.capacity.ParentQueue: Re-sorting completed queue: root.default stats: default: capacity=1.0, absoluteCapacity=1.0, usedResources=<memory:2048, vCores:1>, usedCapacity=0.25, absoluteUsedCapacity=0.25, numApps=1, numContainers=1
2015-04-01 16:45:18,611 INFO org.apache.hadoop.yarn.server.resourcemanager.scheduler.capacity.CapacityScheduler: Application attempt appattempt_1427899242644_0002_000001 released container container_1427899242644_0002_01_000002 on node: host: a11p2.fil.univ-lille1.fr.:55305 #containers=1 available=6144 used=2048 with event: FINISHED
2015-04-01 16:45:19,612 INFO org.apache.hadoop.yarn.server.resourcemanager.rmcontainer.RMContainerImpl: container_1427899242644_0002_01_000003 Container Transitioned from NEW to ALLOCATED
2015-04-01 16:45:19,612 INFO org.apache.hadoop.yarn.server.resourcemanager.RMAuditLogger: USER=echallier	OPERATION=AM Allocated Container	TARGET=SchedulerApp	RESULT=SUCCESS	APPID=application_1427899242644_0002	CONTAINERID=container_1427899242644_0002_01_000003
2015-04-01 16:45:19,612 INFO org.apache.hadoop.yarn.server.resourcemanager.scheduler.SchedulerNode: Assigned container container_1427899242644_0002_01_000003 of capacity <memory:1024, vCores:1> on host a11p2.fil.univ-lille1.fr.:55305, which has 2 containers, <memory:3072, vCores:2> used and <memory:5120, vCores:6> available after allocation
2015-04-01 16:45:19,612 INFO org.apache.hadoop.yarn.server.resourcemanager.scheduler.capacity.LeafQueue: assignedContainer application attempt=appattempt_1427899242644_0002_000001 container=Container: [ContainerId: container_1427899242644_0002_01_000003, NodeId: a11p2.fil.univ-lille1.fr.:55305, NodeHttpAddress: a11p2.fil.univ-lille1.fr.:8042, Resource: <memory:1024, vCores:1>, Priority: 10, Token: null, ] queue=default: capacity=1.0, absoluteCapacity=1.0, usedResources=<memory:2048, vCores:1>, usedCapacity=0.25, absoluteUsedCapacity=0.25, numApps=1, numContainers=1 clusterResource=<memory:8192, vCores:8>
2015-04-01 16:45:19,612 INFO org.apache.hadoop.yarn.server.resourcemanager.scheduler.capacity.ParentQueue: Re-sorting assigned queue: root.default stats: default: capacity=1.0, absoluteCapacity=1.0, usedResources=<memory:3072, vCores:2>, usedCapacity=0.375, absoluteUsedCapacity=0.375, numApps=1, numContainers=2
2015-04-01 16:45:19,612 INFO org.apache.hadoop.yarn.server.resourcemanager.scheduler.capacity.ParentQueue: assignedContainer queue=root usedCapacity=0.375 absoluteUsedCapacity=0.375 used=<memory:3072, vCores:2> cluster=<memory:8192, vCores:8>
2015-04-01 16:45:20,410 INFO org.apache.hadoop.yarn.server.resourcemanager.rmcontainer.RMContainerImpl: container_1427899242644_0002_01_000003 Container Transitioned from ALLOCATED to ACQUIRED
2015-04-01 16:45:20,613 INFO org.apache.hadoop.yarn.server.resourcemanager.rmcontainer.RMContainerImpl: container_1427899242644_0002_01_000003 Container Transitioned from ACQUIRED to RUNNING
2015-04-01 16:45:21,414 INFO org.apache.hadoop.yarn.server.resourcemanager.scheduler.AppSchedulingInfo: checking for deactivate... 
2015-04-01 16:45:23,577 INFO org.apache.hadoop.yarn.server.resourcemanager.rmapp.attempt.RMAppAttemptImpl: Updating application attempt appattempt_1427899242644_0002_000001 with final state: FINISHING, and exit status: -1000
2015-04-01 16:45:23,577 INFO org.apache.hadoop.yarn.server.resourcemanager.rmapp.attempt.RMAppAttemptImpl: appattempt_1427899242644_0002_000001 State change from RUNNING to FINAL_SAVING
2015-04-01 16:45:23,577 INFO org.apache.hadoop.yarn.server.resourcemanager.rmapp.RMAppImpl: Updating application application_1427899242644_0002 with final state: FINISHING
2015-04-01 16:45:23,577 INFO org.apache.hadoop.yarn.server.resourcemanager.rmapp.RMAppImpl: application_1427899242644_0002 State change from RUNNING to FINAL_SAVING
2015-04-01 16:45:23,577 INFO org.apache.hadoop.yarn.server.resourcemanager.recovery.RMStateStore: Updating info for app: application_1427899242644_0002
2015-04-01 16:45:23,578 INFO org.apache.hadoop.yarn.server.resourcemanager.rmapp.attempt.RMAppAttemptImpl: appattempt_1427899242644_0002_000001 State change from FINAL_SAVING to FINISHING
2015-04-01 16:45:23,578 INFO org.apache.hadoop.yarn.server.resourcemanager.rmapp.RMAppImpl: application_1427899242644_0002 State change from FINAL_SAVING to FINISHING
2015-04-01 16:45:23,747 INFO org.apache.hadoop.yarn.server.resourcemanager.rmcontainer.RMContainerImpl: container_1427899242644_0002_01_000003 Container Transitioned from RUNNING to COMPLETED
2015-04-01 16:45:23,748 INFO org.apache.hadoop.yarn.server.resourcemanager.scheduler.common.fica.FiCaSchedulerApp: Completed container: container_1427899242644_0002_01_000003 in state: COMPLETED event:FINISHED
2015-04-01 16:45:23,748 INFO org.apache.hadoop.yarn.server.resourcemanager.RMAuditLogger: USER=echallier	OPERATION=AM Released Container	TARGET=SchedulerApp	RESULT=SUCCESS	APPID=application_1427899242644_0002	CONTAINERID=container_1427899242644_0002_01_000003
2015-04-01 16:45:23,748 INFO org.apache.hadoop.yarn.server.resourcemanager.scheduler.SchedulerNode: Released container container_1427899242644_0002_01_000003 of capacity <memory:1024, vCores:1> on host a11p2.fil.univ-lille1.fr.:55305, which currently has 1 containers, <memory:2048, vCores:1> used and <memory:6144, vCores:7> available, release resources=true
2015-04-01 16:45:23,748 INFO org.apache.hadoop.yarn.server.resourcemanager.scheduler.capacity.LeafQueue: default used=<memory:2048, vCores:1> numContainers=1 user=echallier user-resources=<memory:2048, vCores:1>
2015-04-01 16:45:23,748 INFO org.apache.hadoop.yarn.server.resourcemanager.scheduler.capacity.LeafQueue: completedContainer container=Container: [ContainerId: container_1427899242644_0002_01_000003, NodeId: a11p2.fil.univ-lille1.fr.:55305, NodeHttpAddress: a11p2.fil.univ-lille1.fr.:8042, Resource: <memory:1024, vCores:1>, Priority: 10, Token: Token { kind: ContainerToken, service: 127.0.1.1:55305 }, ] queue=default: capacity=1.0, absoluteCapacity=1.0, usedResources=<memory:2048, vCores:1>, usedCapacity=0.25, absoluteUsedCapacity=0.25, numApps=1, numContainers=1 cluster=<memory:8192, vCores:8>
2015-04-01 16:45:23,748 INFO org.apache.hadoop.yarn.server.resourcemanager.scheduler.capacity.ParentQueue: completedContainer queue=root usedCapacity=0.25 absoluteUsedCapacity=0.25 used=<memory:2048, vCores:1> cluster=<memory:8192, vCores:8>
2015-04-01 16:45:23,748 INFO org.apache.hadoop.yarn.server.resourcemanager.scheduler.capacity.ParentQueue: Re-sorting completed queue: root.default stats: default: capacity=1.0, absoluteCapacity=1.0, usedResources=<memory:2048, vCores:1>, usedCapacity=0.25, absoluteUsedCapacity=0.25, numApps=1, numContainers=1
2015-04-01 16:45:23,749 INFO org.apache.hadoop.yarn.server.resourcemanager.scheduler.capacity.CapacityScheduler: Application attempt appattempt_1427899242644_0002_000001 released container container_1427899242644_0002_01_000003 on node: host: a11p2.fil.univ-lille1.fr.:55305 #containers=1 available=6144 used=2048 with event: FINISHED
2015-04-01 16:45:30,760 INFO org.apache.hadoop.yarn.server.resourcemanager.rmcontainer.RMContainerImpl: container_1427899242644_0002_01_000001 Container Transitioned from RUNNING to COMPLETED
2015-04-01 16:45:30,761 INFO org.apache.hadoop.yarn.server.resourcemanager.ApplicationMasterService: Unregistering app attempt : appattempt_1427899242644_0002_000001
2015-04-01 16:45:30,761 INFO org.apache.hadoop.yarn.server.resourcemanager.scheduler.common.fica.FiCaSchedulerApp: Completed container: container_1427899242644_0002_01_000001 in state: COMPLETED event:FINISHED
2015-04-01 16:45:30,762 INFO org.apache.hadoop.yarn.server.resourcemanager.rmapp.attempt.RMAppAttemptImpl: appattempt_1427899242644_0002_000001 State change from FINISHING to FINISHED
2015-04-01 16:45:30,762 INFO org.apache.hadoop.yarn.server.resourcemanager.RMAuditLogger: USER=echallier	OPERATION=AM Released Container	TARGET=SchedulerApp	RESULT=SUCCESS	APPID=application_1427899242644_0002	CONTAINERID=container_1427899242644_0002_01_000001
2015-04-01 16:45:30,762 INFO org.apache.hadoop.yarn.server.resourcemanager.rmapp.RMAppImpl: application_1427899242644_0002 State change from FINISHING to FINISHED
2015-04-01 16:45:30,762 INFO org.apache.hadoop.yarn.server.resourcemanager.scheduler.SchedulerNode: Released container container_1427899242644_0002_01_000001 of capacity <memory:2048, vCores:1> on host a11p2.fil.univ-lille1.fr.:55305, which currently has 0 containers, <memory:0, vCores:0> used and <memory:8192, vCores:8> available, release resources=true
2015-04-01 16:45:30,762 INFO org.apache.hadoop.yarn.server.resourcemanager.scheduler.capacity.LeafQueue: default used=<memory:0, vCores:0> numContainers=0 user=echallier user-resources=<memory:0, vCores:0>
2015-04-01 16:45:30,762 INFO org.apache.hadoop.yarn.server.resourcemanager.RMAuditLogger: USER=echallier	OPERATION=Application Finished - Succeeded	TARGET=RMAppManager	RESULT=SUCCESS	APPID=application_1427899242644_0002
2015-04-01 16:45:30,762 INFO org.apache.hadoop.yarn.server.resourcemanager.scheduler.capacity.LeafQueue: completedContainer container=Container: [ContainerId: container_1427899242644_0002_01_000001, NodeId: a11p2.fil.univ-lille1.fr.:55305, NodeHttpAddress: a11p2.fil.univ-lille1.fr.:8042, Resource: <memory:2048, vCores:1>, Priority: 0, Token: Token { kind: ContainerToken, service: 127.0.1.1:55305 }, ] queue=default: capacity=1.0, absoluteCapacity=1.0, usedResources=<memory:0, vCores:0>, usedCapacity=0.0, absoluteUsedCapacity=0.0, numApps=1, numContainers=0 cluster=<memory:8192, vCores:8>
2015-04-01 16:45:30,762 INFO org.apache.hadoop.yarn.server.resourcemanager.scheduler.capacity.ParentQueue: completedContainer queue=root usedCapacity=0.0 absoluteUsedCapacity=0.0 used=<memory:0, vCores:0> cluster=<memory:8192, vCores:8>
2015-04-01 16:45:30,762 INFO org.apache.hadoop.yarn.server.resourcemanager.scheduler.capacity.ParentQueue: Re-sorting completed queue: root.default stats: default: capacity=1.0, absoluteCapacity=1.0, usedResources=<memory:0, vCores:0>, usedCapacity=0.0, absoluteUsedCapacity=0.0, numApps=1, numContainers=0
2015-04-01 16:45:30,762 INFO org.apache.hadoop.yarn.server.resourcemanager.amlauncher.AMLauncher: Cleaning master appattempt_1427899242644_0002_000001
2015-04-01 16:45:30,763 INFO org.apache.hadoop.yarn.server.resourcemanager.RMAppManager$ApplicationSummary: appId=application_1427899242644_0002,name=anagrames,user=echallier,queue=default,state=FINISHED,trackingUrl=http://a11p2.fil.univ-lille1.fr.:8088/proxy/application_1427899242644_0002/jobhistory/job/job_1427899242644_0002,appMasterHost=a11p2,startTime=1427899509780,finishTime=1427899523577,finalStatus=SUCCEEDED
2015-04-01 16:45:30,762 INFO org.apache.hadoop.yarn.server.resourcemanager.scheduler.capacity.CapacityScheduler: Application attempt appattempt_1427899242644_0002_000001 released container container_1427899242644_0002_01_000001 on node: host: a11p2.fil.univ-lille1.fr.:55305 #containers=0 available=8192 used=0 with event: FINISHED
2015-04-01 16:45:30,763 INFO org.apache.hadoop.yarn.server.resourcemanager.scheduler.capacity.CapacityScheduler: Application Attempt appattempt_1427899242644_0002_000001 is done. finalState=FINISHED
2015-04-01 16:45:30,763 INFO org.apache.hadoop.yarn.server.resourcemanager.scheduler.AppSchedulingInfo: Application application_1427899242644_0002 requests cleared
2015-04-01 16:45:30,763 INFO org.apache.hadoop.yarn.server.resourcemanager.scheduler.capacity.LeafQueue: Application removed - appId: application_1427899242644_0002 user: echallier queue: default #user-pending-applications: 0 #user-active-applications: 0 #queue-pending-applications: 0 #queue-active-applications: 0
2015-04-01 16:45:30,763 INFO org.apache.hadoop.yarn.server.resourcemanager.scheduler.capacity.ParentQueue: Application removed - appId: application_1427899242644_0002 user: echallier leaf-queue of parent: root #applications: 0
2015-04-01 16:49:56,176 INFO org.apache.hadoop.yarn.server.resourcemanager.ClientRMService: Allocated new applicationId: 3
2015-04-01 16:49:56,935 INFO org.apache.hadoop.yarn.server.resourcemanager.ClientRMService: Application with id 3 submitted by user echallier
2015-04-01 16:49:56,935 INFO org.apache.hadoop.yarn.server.resourcemanager.rmapp.RMAppImpl: Storing application with id application_1427899242644_0003
2015-04-01 16:49:56,935 INFO org.apache.hadoop.yarn.server.resourcemanager.RMAuditLogger: USER=echallier	IP=127.0.0.1	OPERATION=Submit Application Request	TARGET=ClientRMService	RESULT=SUCCESS	APPID=application_1427899242644_0003
2015-04-01 16:49:56,935 INFO org.apache.hadoop.yarn.server.resourcemanager.rmapp.RMAppImpl: application_1427899242644_0003 State change from NEW to NEW_SAVING
2015-04-01 16:49:56,936 INFO org.apache.hadoop.yarn.server.resourcemanager.recovery.RMStateStore: Storing info for app: application_1427899242644_0003
2015-04-01 16:49:56,936 INFO org.apache.hadoop.yarn.server.resourcemanager.rmapp.RMAppImpl: application_1427899242644_0003 State change from NEW_SAVING to SUBMITTED
2015-04-01 16:49:56,936 INFO org.apache.hadoop.yarn.server.resourcemanager.scheduler.capacity.ParentQueue: Application added - appId: application_1427899242644_0003 user: echallier leaf-queue of parent: root #applications: 1
2015-04-01 16:49:56,936 INFO org.apache.hadoop.yarn.server.resourcemanager.scheduler.capacity.CapacityScheduler: Accepted application application_1427899242644_0003 from user: echallier, in queue: default
2015-04-01 16:49:56,937 INFO org.apache.hadoop.yarn.server.resourcemanager.rmapp.RMAppImpl: application_1427899242644_0003 State change from SUBMITTED to ACCEPTED
2015-04-01 16:49:56,937 INFO org.apache.hadoop.yarn.server.resourcemanager.ApplicationMasterService: Registering app attempt : appattempt_1427899242644_0003_000001
2015-04-01 16:49:56,937 INFO org.apache.hadoop.yarn.server.resourcemanager.rmapp.attempt.RMAppAttemptImpl: appattempt_1427899242644_0003_000001 State change from NEW to SUBMITTED
2015-04-01 16:49:56,937 INFO org.apache.hadoop.yarn.server.resourcemanager.scheduler.capacity.LeafQueue: Application application_1427899242644_0003 from user: echallier activated in queue: default
2015-04-01 16:49:56,937 INFO org.apache.hadoop.yarn.server.resourcemanager.scheduler.capacity.LeafQueue: Application added - appId: application_1427899242644_0003 user: org.apache.hadoop.yarn.server.resourcemanager.scheduler.capacity.LeafQueue$User@aaacc0, leaf-queue: default #user-pending-applications: 0 #user-active-applications: 1 #queue-pending-applications: 0 #queue-active-applications: 1
2015-04-01 16:49:56,937 INFO org.apache.hadoop.yarn.server.resourcemanager.scheduler.capacity.CapacityScheduler: Added Application Attempt appattempt_1427899242644_0003_000001 to scheduler from user echallier in queue default
2015-04-01 16:49:56,937 INFO org.apache.hadoop.yarn.server.resourcemanager.rmapp.attempt.RMAppAttemptImpl: appattempt_1427899242644_0003_000001 State change from SUBMITTED to SCHEDULED
2015-04-01 16:49:57,180 INFO org.apache.hadoop.yarn.server.resourcemanager.rmcontainer.RMContainerImpl: container_1427899242644_0003_01_000001 Container Transitioned from NEW to ALLOCATED
2015-04-01 16:49:57,180 INFO org.apache.hadoop.yarn.server.resourcemanager.RMAuditLogger: USER=echallier	OPERATION=AM Allocated Container	TARGET=SchedulerApp	RESULT=SUCCESS	APPID=application_1427899242644_0003	CONTAINERID=container_1427899242644_0003_01_000001
2015-04-01 16:49:57,180 INFO org.apache.hadoop.yarn.server.resourcemanager.scheduler.SchedulerNode: Assigned container container_1427899242644_0003_01_000001 of capacity <memory:2048, vCores:1> on host a11p2.fil.univ-lille1.fr.:55305, which has 1 containers, <memory:2048, vCores:1> used and <memory:6144, vCores:7> available after allocation
2015-04-01 16:49:57,181 INFO org.apache.hadoop.yarn.server.resourcemanager.scheduler.capacity.LeafQueue: assignedContainer application attempt=appattempt_1427899242644_0003_000001 container=Container: [ContainerId: container_1427899242644_0003_01_000001, NodeId: a11p2.fil.univ-lille1.fr.:55305, NodeHttpAddress: a11p2.fil.univ-lille1.fr.:8042, Resource: <memory:2048, vCores:1>, Priority: 0, Token: null, ] queue=default: capacity=1.0, absoluteCapacity=1.0, usedResources=<memory:0, vCores:0>, usedCapacity=0.0, absoluteUsedCapacity=0.0, numApps=1, numContainers=0 clusterResource=<memory:8192, vCores:8>
2015-04-01 16:49:57,181 INFO org.apache.hadoop.yarn.server.resourcemanager.scheduler.capacity.ParentQueue: Re-sorting assigned queue: root.default stats: default: capacity=1.0, absoluteCapacity=1.0, usedResources=<memory:2048, vCores:1>, usedCapacity=0.25, absoluteUsedCapacity=0.25, numApps=1, numContainers=1
2015-04-01 16:49:57,181 INFO org.apache.hadoop.yarn.server.resourcemanager.scheduler.capacity.ParentQueue: assignedContainer queue=root usedCapacity=0.25 absoluteUsedCapacity=0.25 used=<memory:2048, vCores:1> cluster=<memory:8192, vCores:8>
2015-04-01 16:49:57,181 INFO org.apache.hadoop.yarn.server.resourcemanager.security.NMTokenSecretManagerInRM: Sending NMToken for nodeId : a11p2.fil.univ-lille1.fr.:55305 for container : container_1427899242644_0003_01_000001
2015-04-01 16:49:57,182 INFO org.apache.hadoop.yarn.server.resourcemanager.rmcontainer.RMContainerImpl: container_1427899242644_0003_01_000001 Container Transitioned from ALLOCATED to ACQUIRED
2015-04-01 16:49:57,182 INFO org.apache.hadoop.yarn.server.resourcemanager.security.NMTokenSecretManagerInRM: Clear node set for appattempt_1427899242644_0003_000001
2015-04-01 16:49:57,183 INFO org.apache.hadoop.yarn.server.resourcemanager.rmapp.attempt.RMAppAttemptImpl: Storing attempt: AppId: application_1427899242644_0003 AttemptId: appattempt_1427899242644_0003_000001 MasterContainer: Container: [ContainerId: container_1427899242644_0003_01_000001, NodeId: a11p2.fil.univ-lille1.fr.:55305, NodeHttpAddress: a11p2.fil.univ-lille1.fr.:8042, Resource: <memory:2048, vCores:1>, Priority: 0, Token: Token { kind: ContainerToken, service: 127.0.1.1:55305 }, ]
2015-04-01 16:49:57,183 INFO org.apache.hadoop.yarn.server.resourcemanager.rmapp.attempt.RMAppAttemptImpl: appattempt_1427899242644_0003_000001 State change from SCHEDULED to ALLOCATED_SAVING
2015-04-01 16:49:57,183 INFO org.apache.hadoop.yarn.server.resourcemanager.rmapp.attempt.RMAppAttemptImpl: appattempt_1427899242644_0003_000001 State change from ALLOCATED_SAVING to ALLOCATED
2015-04-01 16:49:57,183 INFO org.apache.hadoop.yarn.server.resourcemanager.amlauncher.AMLauncher: Launching masterappattempt_1427899242644_0003_000001
2015-04-01 16:49:57,185 INFO org.apache.hadoop.yarn.server.resourcemanager.amlauncher.AMLauncher: Setting up container Container: [ContainerId: container_1427899242644_0003_01_000001, NodeId: a11p2.fil.univ-lille1.fr.:55305, NodeHttpAddress: a11p2.fil.univ-lille1.fr.:8042, Resource: <memory:2048, vCores:1>, Priority: 0, Token: Token { kind: ContainerToken, service: 127.0.1.1:55305 }, ] for AM appattempt_1427899242644_0003_000001
2015-04-01 16:49:57,185 INFO org.apache.hadoop.yarn.server.resourcemanager.amlauncher.AMLauncher: Command to launch container container_1427899242644_0003_01_000001 : $JAVA_HOME/bin/java -Dlog4j.configuration=container-log4j.properties -Dyarn.app.container.log.dir=<LOG_DIR> -Dyarn.app.container.log.filesize=0 -Dhadoop.root.logger=INFO,CLA  -Xmx1024m org.apache.hadoop.mapreduce.v2.app.MRAppMaster 1><LOG_DIR>/stdout 2><LOG_DIR>/stderr 
2015-04-01 16:49:57,196 INFO org.apache.hadoop.yarn.server.resourcemanager.amlauncher.AMLauncher: Done launching container Container: [ContainerId: container_1427899242644_0003_01_000001, NodeId: a11p2.fil.univ-lille1.fr.:55305, NodeHttpAddress: a11p2.fil.univ-lille1.fr.:8042, Resource: <memory:2048, vCores:1>, Priority: 0, Token: Token { kind: ContainerToken, service: 127.0.1.1:55305 }, ] for AM appattempt_1427899242644_0003_000001
2015-04-01 16:49:57,196 INFO org.apache.hadoop.yarn.server.resourcemanager.rmapp.attempt.RMAppAttemptImpl: appattempt_1427899242644_0003_000001 State change from ALLOCATED to LAUNCHED
2015-04-01 16:49:58,181 INFO org.apache.hadoop.yarn.server.resourcemanager.rmcontainer.RMContainerImpl: container_1427899242644_0003_01_000001 Container Transitioned from ACQUIRED to RUNNING
2015-04-01 16:50:00,148 INFO SecurityLogger.org.apache.hadoop.ipc.Server: Auth successful for appattempt_1427899242644_0003_000001 (auth:SIMPLE)
2015-04-01 16:50:00,149 INFO org.apache.hadoop.yarn.server.resourcemanager.ApplicationMasterService: AM registration appattempt_1427899242644_0003_000001
2015-04-01 16:50:00,149 INFO org.apache.hadoop.yarn.server.resourcemanager.RMAuditLogger: USER=echallier	IP=127.0.0.1	OPERATION=Register App Master	TARGET=ApplicationMasterService	RESULT=SUCCESS	APPID=application_1427899242644_0003	APPATTEMPTID=appattempt_1427899242644_0003_000001
2015-04-01 16:50:00,150 INFO org.apache.hadoop.yarn.server.resourcemanager.rmapp.attempt.RMAppAttemptImpl: appattempt_1427899242644_0003_000001 State change from LAUNCHED to RUNNING
2015-04-01 16:50:00,150 INFO org.apache.hadoop.yarn.server.resourcemanager.rmapp.RMAppImpl: application_1427899242644_0003 State change from ACCEPTED to RUNNING
2015-04-01 16:50:01,185 INFO org.apache.hadoop.yarn.server.resourcemanager.rmcontainer.RMContainerImpl: container_1427899242644_0003_01_000002 Container Transitioned from NEW to ALLOCATED
2015-04-01 16:50:01,186 INFO org.apache.hadoop.yarn.server.resourcemanager.RMAuditLogger: USER=echallier	OPERATION=AM Allocated Container	TARGET=SchedulerApp	RESULT=SUCCESS	APPID=application_1427899242644_0003	CONTAINERID=container_1427899242644_0003_01_000002
2015-04-01 16:50:01,186 INFO org.apache.hadoop.yarn.server.resourcemanager.scheduler.SchedulerNode: Assigned container container_1427899242644_0003_01_000002 of capacity <memory:1024, vCores:1> on host a11p2.fil.univ-lille1.fr.:55305, which has 2 containers, <memory:3072, vCores:2> used and <memory:5120, vCores:6> available after allocation
2015-04-01 16:50:01,186 INFO org.apache.hadoop.yarn.server.resourcemanager.scheduler.capacity.LeafQueue: assignedContainer application attempt=appattempt_1427899242644_0003_000001 container=Container: [ContainerId: container_1427899242644_0003_01_000002, NodeId: a11p2.fil.univ-lille1.fr.:55305, NodeHttpAddress: a11p2.fil.univ-lille1.fr.:8042, Resource: <memory:1024, vCores:1>, Priority: 20, Token: null, ] queue=default: capacity=1.0, absoluteCapacity=1.0, usedResources=<memory:2048, vCores:1>, usedCapacity=0.25, absoluteUsedCapacity=0.25, numApps=1, numContainers=1 clusterResource=<memory:8192, vCores:8>
2015-04-01 16:50:01,186 INFO org.apache.hadoop.yarn.server.resourcemanager.scheduler.capacity.ParentQueue: Re-sorting assigned queue: root.default stats: default: capacity=1.0, absoluteCapacity=1.0, usedResources=<memory:3072, vCores:2>, usedCapacity=0.375, absoluteUsedCapacity=0.375, numApps=1, numContainers=2
2015-04-01 16:50:01,186 INFO org.apache.hadoop.yarn.server.resourcemanager.scheduler.capacity.ParentQueue: assignedContainer queue=root usedCapacity=0.375 absoluteUsedCapacity=0.375 used=<memory:3072, vCores:2> cluster=<memory:8192, vCores:8>
2015-04-01 16:50:02,208 INFO org.apache.hadoop.yarn.server.resourcemanager.security.NMTokenSecretManagerInRM: Sending NMToken for nodeId : a11p2.fil.univ-lille1.fr.:55305 for container : container_1427899242644_0003_01_000002
2015-04-01 16:50:02,209 INFO org.apache.hadoop.yarn.server.resourcemanager.rmcontainer.RMContainerImpl: container_1427899242644_0003_01_000002 Container Transitioned from ALLOCATED to ACQUIRED
2015-04-01 16:50:03,188 INFO org.apache.hadoop.yarn.server.resourcemanager.rmcontainer.RMContainerImpl: container_1427899242644_0003_01_000002 Container Transitioned from ACQUIRED to RUNNING
2015-04-01 16:50:03,224 INFO org.apache.hadoop.yarn.server.resourcemanager.scheduler.AppSchedulingInfo: checking for deactivate... 
2015-04-01 16:50:05,480 INFO org.apache.hadoop.yarn.server.resourcemanager.rmcontainer.RMContainerImpl: container_1427899242644_0003_01_000002 Container Transitioned from RUNNING to COMPLETED
2015-04-01 16:50:05,481 INFO org.apache.hadoop.yarn.server.resourcemanager.scheduler.common.fica.FiCaSchedulerApp: Completed container: container_1427899242644_0003_01_000002 in state: COMPLETED event:FINISHED
2015-04-01 16:50:05,481 INFO org.apache.hadoop.yarn.server.resourcemanager.RMAuditLogger: USER=echallier	OPERATION=AM Released Container	TARGET=SchedulerApp	RESULT=SUCCESS	APPID=application_1427899242644_0003	CONTAINERID=container_1427899242644_0003_01_000002
2015-04-01 16:50:05,481 INFO org.apache.hadoop.yarn.server.resourcemanager.scheduler.SchedulerNode: Released container container_1427899242644_0003_01_000002 of capacity <memory:1024, vCores:1> on host a11p2.fil.univ-lille1.fr.:55305, which currently has 1 containers, <memory:2048, vCores:1> used and <memory:6144, vCores:7> available, release resources=true
2015-04-01 16:50:05,481 INFO org.apache.hadoop.yarn.server.resourcemanager.scheduler.capacity.LeafQueue: default used=<memory:2048, vCores:1> numContainers=1 user=echallier user-resources=<memory:2048, vCores:1>
2015-04-01 16:50:05,481 INFO org.apache.hadoop.yarn.server.resourcemanager.scheduler.capacity.LeafQueue: completedContainer container=Container: [ContainerId: container_1427899242644_0003_01_000002, NodeId: a11p2.fil.univ-lille1.fr.:55305, NodeHttpAddress: a11p2.fil.univ-lille1.fr.:8042, Resource: <memory:1024, vCores:1>, Priority: 20, Token: Token { kind: ContainerToken, service: 127.0.1.1:55305 }, ] queue=default: capacity=1.0, absoluteCapacity=1.0, usedResources=<memory:2048, vCores:1>, usedCapacity=0.25, absoluteUsedCapacity=0.25, numApps=1, numContainers=1 cluster=<memory:8192, vCores:8>
2015-04-01 16:50:05,481 INFO org.apache.hadoop.yarn.server.resourcemanager.scheduler.capacity.ParentQueue: completedContainer queue=root usedCapacity=0.25 absoluteUsedCapacity=0.25 used=<memory:2048, vCores:1> cluster=<memory:8192, vCores:8>
2015-04-01 16:50:05,482 INFO org.apache.hadoop.yarn.server.resourcemanager.scheduler.capacity.ParentQueue: Re-sorting completed queue: root.default stats: default: capacity=1.0, absoluteCapacity=1.0, usedResources=<memory:2048, vCores:1>, usedCapacity=0.25, absoluteUsedCapacity=0.25, numApps=1, numContainers=1
2015-04-01 16:50:05,482 INFO org.apache.hadoop.yarn.server.resourcemanager.scheduler.capacity.CapacityScheduler: Application attempt appattempt_1427899242644_0003_000001 released container container_1427899242644_0003_01_000002 on node: host: a11p2.fil.univ-lille1.fr.:55305 #containers=1 available=6144 used=2048 with event: FINISHED
2015-04-01 16:50:06,483 INFO org.apache.hadoop.yarn.server.resourcemanager.rmcontainer.RMContainerImpl: container_1427899242644_0003_01_000003 Container Transitioned from NEW to ALLOCATED
2015-04-01 16:50:06,483 INFO org.apache.hadoop.yarn.server.resourcemanager.RMAuditLogger: USER=echallier	OPERATION=AM Allocated Container	TARGET=SchedulerApp	RESULT=SUCCESS	APPID=application_1427899242644_0003	CONTAINERID=container_1427899242644_0003_01_000003
2015-04-01 16:50:06,483 INFO org.apache.hadoop.yarn.server.resourcemanager.scheduler.SchedulerNode: Assigned container container_1427899242644_0003_01_000003 of capacity <memory:1024, vCores:1> on host a11p2.fil.univ-lille1.fr.:55305, which has 2 containers, <memory:3072, vCores:2> used and <memory:5120, vCores:6> available after allocation
2015-04-01 16:50:06,483 INFO org.apache.hadoop.yarn.server.resourcemanager.scheduler.capacity.LeafQueue: assignedContainer application attempt=appattempt_1427899242644_0003_000001 container=Container: [ContainerId: container_1427899242644_0003_01_000003, NodeId: a11p2.fil.univ-lille1.fr.:55305, NodeHttpAddress: a11p2.fil.univ-lille1.fr.:8042, Resource: <memory:1024, vCores:1>, Priority: 10, Token: null, ] queue=default: capacity=1.0, absoluteCapacity=1.0, usedResources=<memory:2048, vCores:1>, usedCapacity=0.25, absoluteUsedCapacity=0.25, numApps=1, numContainers=1 clusterResource=<memory:8192, vCores:8>
2015-04-01 16:50:06,483 INFO org.apache.hadoop.yarn.server.resourcemanager.scheduler.capacity.ParentQueue: Re-sorting assigned queue: root.default stats: default: capacity=1.0, absoluteCapacity=1.0, usedResources=<memory:3072, vCores:2>, usedCapacity=0.375, absoluteUsedCapacity=0.375, numApps=1, numContainers=2
2015-04-01 16:50:06,483 INFO org.apache.hadoop.yarn.server.resourcemanager.scheduler.capacity.ParentQueue: assignedContainer queue=root usedCapacity=0.375 absoluteUsedCapacity=0.375 used=<memory:3072, vCores:2> cluster=<memory:8192, vCores:8>
2015-04-01 16:50:07,240 INFO org.apache.hadoop.yarn.server.resourcemanager.rmcontainer.RMContainerImpl: container_1427899242644_0003_01_000003 Container Transitioned from ALLOCATED to ACQUIRED
2015-04-01 16:50:07,484 INFO org.apache.hadoop.yarn.server.resourcemanager.rmcontainer.RMContainerImpl: container_1427899242644_0003_01_000003 Container Transitioned from ACQUIRED to RUNNING
2015-04-01 16:50:08,244 INFO org.apache.hadoop.yarn.server.resourcemanager.scheduler.AppSchedulingInfo: checking for deactivate... 
2015-04-01 16:50:09,995 INFO org.apache.hadoop.yarn.server.resourcemanager.rmapp.attempt.RMAppAttemptImpl: Updating application attempt appattempt_1427899242644_0003_000001 with final state: FINISHING, and exit status: -1000
2015-04-01 16:50:09,995 INFO org.apache.hadoop.yarn.server.resourcemanager.rmapp.attempt.RMAppAttemptImpl: appattempt_1427899242644_0003_000001 State change from RUNNING to FINAL_SAVING
2015-04-01 16:50:09,995 INFO org.apache.hadoop.yarn.server.resourcemanager.rmapp.RMAppImpl: Updating application application_1427899242644_0003 with final state: FINISHING
2015-04-01 16:50:09,995 INFO org.apache.hadoop.yarn.server.resourcemanager.rmapp.RMAppImpl: application_1427899242644_0003 State change from RUNNING to FINAL_SAVING
2015-04-01 16:50:09,995 INFO org.apache.hadoop.yarn.server.resourcemanager.recovery.RMStateStore: Updating info for app: application_1427899242644_0003
2015-04-01 16:50:09,996 INFO org.apache.hadoop.yarn.server.resourcemanager.rmapp.attempt.RMAppAttemptImpl: appattempt_1427899242644_0003_000001 State change from FINAL_SAVING to FINISHING
2015-04-01 16:50:09,996 INFO org.apache.hadoop.yarn.server.resourcemanager.rmapp.RMAppImpl: application_1427899242644_0003 State change from FINAL_SAVING to FINISHING
2015-04-01 16:50:10,551 INFO org.apache.hadoop.yarn.server.resourcemanager.rmcontainer.RMContainerImpl: container_1427899242644_0003_01_000003 Container Transitioned from RUNNING to COMPLETED
2015-04-01 16:50:10,551 INFO org.apache.hadoop.yarn.server.resourcemanager.scheduler.common.fica.FiCaSchedulerApp: Completed container: container_1427899242644_0003_01_000003 in state: COMPLETED event:FINISHED
2015-04-01 16:50:10,551 INFO org.apache.hadoop.yarn.server.resourcemanager.RMAuditLogger: USER=echallier	OPERATION=AM Released Container	TARGET=SchedulerApp	RESULT=SUCCESS	APPID=application_1427899242644_0003	CONTAINERID=container_1427899242644_0003_01_000003
2015-04-01 16:50:10,551 INFO org.apache.hadoop.yarn.server.resourcemanager.scheduler.SchedulerNode: Released container container_1427899242644_0003_01_000003 of capacity <memory:1024, vCores:1> on host a11p2.fil.univ-lille1.fr.:55305, which currently has 1 containers, <memory:2048, vCores:1> used and <memory:6144, vCores:7> available, release resources=true
2015-04-01 16:50:10,551 INFO org.apache.hadoop.yarn.server.resourcemanager.scheduler.capacity.LeafQueue: default used=<memory:2048, vCores:1> numContainers=1 user=echallier user-resources=<memory:2048, vCores:1>
2015-04-01 16:50:10,552 INFO org.apache.hadoop.yarn.server.resourcemanager.scheduler.capacity.LeafQueue: completedContainer container=Container: [ContainerId: container_1427899242644_0003_01_000003, NodeId: a11p2.fil.univ-lille1.fr.:55305, NodeHttpAddress: a11p2.fil.univ-lille1.fr.:8042, Resource: <memory:1024, vCores:1>, Priority: 10, Token: Token { kind: ContainerToken, service: 127.0.1.1:55305 }, ] queue=default: capacity=1.0, absoluteCapacity=1.0, usedResources=<memory:2048, vCores:1>, usedCapacity=0.25, absoluteUsedCapacity=0.25, numApps=1, numContainers=1 cluster=<memory:8192, vCores:8>
2015-04-01 16:50:10,552 INFO org.apache.hadoop.yarn.server.resourcemanager.scheduler.capacity.ParentQueue: completedContainer queue=root usedCapacity=0.25 absoluteUsedCapacity=0.25 used=<memory:2048, vCores:1> cluster=<memory:8192, vCores:8>
2015-04-01 16:50:10,552 INFO org.apache.hadoop.yarn.server.resourcemanager.scheduler.capacity.ParentQueue: Re-sorting completed queue: root.default stats: default: capacity=1.0, absoluteCapacity=1.0, usedResources=<memory:2048, vCores:1>, usedCapacity=0.25, absoluteUsedCapacity=0.25, numApps=1, numContainers=1
2015-04-01 16:50:10,552 INFO org.apache.hadoop.yarn.server.resourcemanager.scheduler.capacity.CapacityScheduler: Application attempt appattempt_1427899242644_0003_000001 released container container_1427899242644_0003_01_000003 on node: host: a11p2.fil.univ-lille1.fr.:55305 #containers=1 available=6144 used=2048 with event: FINISHED
2015-04-01 16:50:16,561 INFO org.apache.hadoop.yarn.server.resourcemanager.rmcontainer.RMContainerImpl: container_1427899242644_0003_01_000001 Container Transitioned from RUNNING to COMPLETED
2015-04-01 16:50:16,561 INFO org.apache.hadoop.yarn.server.resourcemanager.ApplicationMasterService: Unregistering app attempt : appattempt_1427899242644_0003_000001
2015-04-01 16:50:16,561 INFO org.apache.hadoop.yarn.server.resourcemanager.scheduler.common.fica.FiCaSchedulerApp: Completed container: container_1427899242644_0003_01_000001 in state: COMPLETED event:FINISHED
2015-04-01 16:50:16,562 INFO org.apache.hadoop.yarn.server.resourcemanager.rmapp.attempt.RMAppAttemptImpl: appattempt_1427899242644_0003_000001 State change from FINISHING to FINISHED
2015-04-01 16:50:16,562 INFO org.apache.hadoop.yarn.server.resourcemanager.RMAuditLogger: USER=echallier	OPERATION=AM Released Container	TARGET=SchedulerApp	RESULT=SUCCESS	APPID=application_1427899242644_0003	CONTAINERID=container_1427899242644_0003_01_000001
2015-04-01 16:50:16,562 INFO org.apache.hadoop.yarn.server.resourcemanager.rmapp.RMAppImpl: application_1427899242644_0003 State change from FINISHING to FINISHED
2015-04-01 16:50:16,562 INFO org.apache.hadoop.yarn.server.resourcemanager.scheduler.SchedulerNode: Released container container_1427899242644_0003_01_000001 of capacity <memory:2048, vCores:1> on host a11p2.fil.univ-lille1.fr.:55305, which currently has 0 containers, <memory:0, vCores:0> used and <memory:8192, vCores:8> available, release resources=true
2015-04-01 16:50:16,562 INFO org.apache.hadoop.yarn.server.resourcemanager.scheduler.capacity.LeafQueue: default used=<memory:0, vCores:0> numContainers=0 user=echallier user-resources=<memory:0, vCores:0>
2015-04-01 16:50:16,562 INFO org.apache.hadoop.yarn.server.resourcemanager.RMAuditLogger: USER=echallier	OPERATION=Application Finished - Succeeded	TARGET=RMAppManager	RESULT=SUCCESS	APPID=application_1427899242644_0003
2015-04-01 16:50:16,562 INFO org.apache.hadoop.yarn.server.resourcemanager.scheduler.capacity.LeafQueue: completedContainer container=Container: [ContainerId: container_1427899242644_0003_01_000001, NodeId: a11p2.fil.univ-lille1.fr.:55305, NodeHttpAddress: a11p2.fil.univ-lille1.fr.:8042, Resource: <memory:2048, vCores:1>, Priority: 0, Token: Token { kind: ContainerToken, service: 127.0.1.1:55305 }, ] queue=default: capacity=1.0, absoluteCapacity=1.0, usedResources=<memory:0, vCores:0>, usedCapacity=0.0, absoluteUsedCapacity=0.0, numApps=1, numContainers=0 cluster=<memory:8192, vCores:8>
2015-04-01 16:50:16,562 INFO org.apache.hadoop.yarn.server.resourcemanager.scheduler.capacity.ParentQueue: completedContainer queue=root usedCapacity=0.0 absoluteUsedCapacity=0.0 used=<memory:0, vCores:0> cluster=<memory:8192, vCores:8>
2015-04-01 16:50:16,562 INFO org.apache.hadoop.yarn.server.resourcemanager.scheduler.capacity.ParentQueue: Re-sorting completed queue: root.default stats: default: capacity=1.0, absoluteCapacity=1.0, usedResources=<memory:0, vCores:0>, usedCapacity=0.0, absoluteUsedCapacity=0.0, numApps=1, numContainers=0
2015-04-01 16:50:16,563 INFO org.apache.hadoop.yarn.server.resourcemanager.amlauncher.AMLauncher: Cleaning master appattempt_1427899242644_0003_000001
2015-04-01 16:50:16,563 INFO org.apache.hadoop.yarn.server.resourcemanager.scheduler.capacity.CapacityScheduler: Application attempt appattempt_1427899242644_0003_000001 released container container_1427899242644_0003_01_000001 on node: host: a11p2.fil.univ-lille1.fr.:55305 #containers=0 available=8192 used=0 with event: FINISHED
2015-04-01 16:50:16,563 INFO org.apache.hadoop.yarn.server.resourcemanager.RMAppManager$ApplicationSummary: appId=application_1427899242644_0003,name=anagrames,user=echallier,queue=default,state=FINISHED,trackingUrl=http://a11p2.fil.univ-lille1.fr.:8088/proxy/application_1427899242644_0003/jobhistory/job/job_1427899242644_0003,appMasterHost=a11p2,startTime=1427899796935,finishTime=1427899809995,finalStatus=SUCCEEDED
2015-04-01 16:50:16,563 INFO org.apache.hadoop.yarn.server.resourcemanager.scheduler.capacity.CapacityScheduler: Application Attempt appattempt_1427899242644_0003_000001 is done. finalState=FINISHED
2015-04-01 16:50:16,563 INFO org.apache.hadoop.yarn.server.resourcemanager.scheduler.AppSchedulingInfo: Application application_1427899242644_0003 requests cleared
2015-04-01 16:50:16,563 INFO org.apache.hadoop.yarn.server.resourcemanager.scheduler.capacity.LeafQueue: Application removed - appId: application_1427899242644_0003 user: echallier queue: default #user-pending-applications: 0 #user-active-applications: 0 #queue-pending-applications: 0 #queue-active-applications: 0
2015-04-01 16:50:16,563 INFO org.apache.hadoop.yarn.server.resourcemanager.scheduler.capacity.ParentQueue: Application removed - appId: application_1427899242644_0003 user: echallier leaf-queue of parent: root #applications: 0
2015-04-01 16:52:50,435 INFO org.apache.hadoop.yarn.server.resourcemanager.ClientRMService: Allocated new applicationId: 4
2015-04-01 16:52:51,301 INFO org.apache.hadoop.yarn.server.resourcemanager.ClientRMService: Application with id 4 submitted by user echallier
2015-04-01 16:52:51,301 INFO org.apache.hadoop.yarn.server.resourcemanager.rmapp.RMAppImpl: Storing application with id application_1427899242644_0004
2015-04-01 16:52:51,301 INFO org.apache.hadoop.yarn.server.resourcemanager.RMAuditLogger: USER=echallier	IP=127.0.0.1	OPERATION=Submit Application Request	TARGET=ClientRMService	RESULT=SUCCESS	APPID=application_1427899242644_0004
2015-04-01 16:52:51,301 INFO org.apache.hadoop.yarn.server.resourcemanager.rmapp.RMAppImpl: application_1427899242644_0004 State change from NEW to NEW_SAVING
2015-04-01 16:52:51,301 INFO org.apache.hadoop.yarn.server.resourcemanager.recovery.RMStateStore: Storing info for app: application_1427899242644_0004
2015-04-01 16:52:51,301 INFO org.apache.hadoop.yarn.server.resourcemanager.rmapp.RMAppImpl: application_1427899242644_0004 State change from NEW_SAVING to SUBMITTED
2015-04-01 16:52:51,301 INFO org.apache.hadoop.yarn.server.resourcemanager.scheduler.capacity.ParentQueue: Application added - appId: application_1427899242644_0004 user: echallier leaf-queue of parent: root #applications: 1
2015-04-01 16:52:51,301 INFO org.apache.hadoop.yarn.server.resourcemanager.scheduler.capacity.CapacityScheduler: Accepted application application_1427899242644_0004 from user: echallier, in queue: default
2015-04-01 16:52:51,302 INFO org.apache.hadoop.yarn.server.resourcemanager.rmapp.RMAppImpl: application_1427899242644_0004 State change from SUBMITTED to ACCEPTED
2015-04-01 16:52:51,302 INFO org.apache.hadoop.yarn.server.resourcemanager.ApplicationMasterService: Registering app attempt : appattempt_1427899242644_0004_000001
2015-04-01 16:52:51,302 INFO org.apache.hadoop.yarn.server.resourcemanager.rmapp.attempt.RMAppAttemptImpl: appattempt_1427899242644_0004_000001 State change from NEW to SUBMITTED
2015-04-01 16:52:51,302 INFO org.apache.hadoop.yarn.server.resourcemanager.scheduler.capacity.LeafQueue: Application application_1427899242644_0004 from user: echallier activated in queue: default
2015-04-01 16:52:51,302 INFO org.apache.hadoop.yarn.server.resourcemanager.scheduler.capacity.LeafQueue: Application added - appId: application_1427899242644_0004 user: org.apache.hadoop.yarn.server.resourcemanager.scheduler.capacity.LeafQueue$User@185a0b9, leaf-queue: default #user-pending-applications: 0 #user-active-applications: 1 #queue-pending-applications: 0 #queue-active-applications: 1
2015-04-01 16:52:51,302 INFO org.apache.hadoop.yarn.server.resourcemanager.scheduler.capacity.CapacityScheduler: Added Application Attempt appattempt_1427899242644_0004_000001 to scheduler from user echallier in queue default
2015-04-01 16:52:51,302 INFO org.apache.hadoop.yarn.server.resourcemanager.rmapp.attempt.RMAppAttemptImpl: appattempt_1427899242644_0004_000001 State change from SUBMITTED to SCHEDULED
2015-04-01 16:52:51,806 INFO org.apache.hadoop.yarn.server.resourcemanager.rmcontainer.RMContainerImpl: container_1427899242644_0004_01_000001 Container Transitioned from NEW to ALLOCATED
2015-04-01 16:52:51,806 INFO org.apache.hadoop.yarn.server.resourcemanager.RMAuditLogger: USER=echallier	OPERATION=AM Allocated Container	TARGET=SchedulerApp	RESULT=SUCCESS	APPID=application_1427899242644_0004	CONTAINERID=container_1427899242644_0004_01_000001
2015-04-01 16:52:51,806 INFO org.apache.hadoop.yarn.server.resourcemanager.scheduler.SchedulerNode: Assigned container container_1427899242644_0004_01_000001 of capacity <memory:2048, vCores:1> on host a11p2.fil.univ-lille1.fr.:55305, which has 1 containers, <memory:2048, vCores:1> used and <memory:6144, vCores:7> available after allocation
2015-04-01 16:52:51,807 INFO org.apache.hadoop.yarn.server.resourcemanager.scheduler.capacity.LeafQueue: assignedContainer application attempt=appattempt_1427899242644_0004_000001 container=Container: [ContainerId: container_1427899242644_0004_01_000001, NodeId: a11p2.fil.univ-lille1.fr.:55305, NodeHttpAddress: a11p2.fil.univ-lille1.fr.:8042, Resource: <memory:2048, vCores:1>, Priority: 0, Token: null, ] queue=default: capacity=1.0, absoluteCapacity=1.0, usedResources=<memory:0, vCores:0>, usedCapacity=0.0, absoluteUsedCapacity=0.0, numApps=1, numContainers=0 clusterResource=<memory:8192, vCores:8>
2015-04-01 16:52:51,807 INFO org.apache.hadoop.yarn.server.resourcemanager.scheduler.capacity.ParentQueue: Re-sorting assigned queue: root.default stats: default: capacity=1.0, absoluteCapacity=1.0, usedResources=<memory:2048, vCores:1>, usedCapacity=0.25, absoluteUsedCapacity=0.25, numApps=1, numContainers=1
2015-04-01 16:52:51,807 INFO org.apache.hadoop.yarn.server.resourcemanager.scheduler.capacity.ParentQueue: assignedContainer queue=root usedCapacity=0.25 absoluteUsedCapacity=0.25 used=<memory:2048, vCores:1> cluster=<memory:8192, vCores:8>
2015-04-01 16:52:51,807 INFO org.apache.hadoop.yarn.server.resourcemanager.security.NMTokenSecretManagerInRM: Sending NMToken for nodeId : a11p2.fil.univ-lille1.fr.:55305 for container : container_1427899242644_0004_01_000001
2015-04-01 16:52:51,808 INFO org.apache.hadoop.yarn.server.resourcemanager.rmcontainer.RMContainerImpl: container_1427899242644_0004_01_000001 Container Transitioned from ALLOCATED to ACQUIRED
2015-04-01 16:52:51,808 INFO org.apache.hadoop.yarn.server.resourcemanager.security.NMTokenSecretManagerInRM: Clear node set for appattempt_1427899242644_0004_000001
2015-04-01 16:52:51,808 INFO org.apache.hadoop.yarn.server.resourcemanager.rmapp.attempt.RMAppAttemptImpl: Storing attempt: AppId: application_1427899242644_0004 AttemptId: appattempt_1427899242644_0004_000001 MasterContainer: Container: [ContainerId: container_1427899242644_0004_01_000001, NodeId: a11p2.fil.univ-lille1.fr.:55305, NodeHttpAddress: a11p2.fil.univ-lille1.fr.:8042, Resource: <memory:2048, vCores:1>, Priority: 0, Token: Token { kind: ContainerToken, service: 127.0.1.1:55305 }, ]
2015-04-01 16:52:51,808 INFO org.apache.hadoop.yarn.server.resourcemanager.rmapp.attempt.RMAppAttemptImpl: appattempt_1427899242644_0004_000001 State change from SCHEDULED to ALLOCATED_SAVING
2015-04-01 16:52:51,809 INFO org.apache.hadoop.yarn.server.resourcemanager.rmapp.attempt.RMAppAttemptImpl: appattempt_1427899242644_0004_000001 State change from ALLOCATED_SAVING to ALLOCATED
2015-04-01 16:52:51,809 INFO org.apache.hadoop.yarn.server.resourcemanager.amlauncher.AMLauncher: Launching masterappattempt_1427899242644_0004_000001
2015-04-01 16:52:51,811 INFO org.apache.hadoop.yarn.server.resourcemanager.amlauncher.AMLauncher: Setting up container Container: [ContainerId: container_1427899242644_0004_01_000001, NodeId: a11p2.fil.univ-lille1.fr.:55305, NodeHttpAddress: a11p2.fil.univ-lille1.fr.:8042, Resource: <memory:2048, vCores:1>, Priority: 0, Token: Token { kind: ContainerToken, service: 127.0.1.1:55305 }, ] for AM appattempt_1427899242644_0004_000001
2015-04-01 16:52:51,811 INFO org.apache.hadoop.yarn.server.resourcemanager.amlauncher.AMLauncher: Command to launch container container_1427899242644_0004_01_000001 : $JAVA_HOME/bin/java -Dlog4j.configuration=container-log4j.properties -Dyarn.app.container.log.dir=<LOG_DIR> -Dyarn.app.container.log.filesize=0 -Dhadoop.root.logger=INFO,CLA  -Xmx1024m org.apache.hadoop.mapreduce.v2.app.MRAppMaster 1><LOG_DIR>/stdout 2><LOG_DIR>/stderr 
2015-04-01 16:52:51,822 INFO org.apache.hadoop.yarn.server.resourcemanager.amlauncher.AMLauncher: Done launching container Container: [ContainerId: container_1427899242644_0004_01_000001, NodeId: a11p2.fil.univ-lille1.fr.:55305, NodeHttpAddress: a11p2.fil.univ-lille1.fr.:8042, Resource: <memory:2048, vCores:1>, Priority: 0, Token: Token { kind: ContainerToken, service: 127.0.1.1:55305 }, ] for AM appattempt_1427899242644_0004_000001
2015-04-01 16:52:51,823 INFO org.apache.hadoop.yarn.server.resourcemanager.rmapp.attempt.RMAppAttemptImpl: appattempt_1427899242644_0004_000001 State change from ALLOCATED to LAUNCHED
2015-04-01 16:52:52,807 INFO org.apache.hadoop.yarn.server.resourcemanager.rmcontainer.RMContainerImpl: container_1427899242644_0004_01_000001 Container Transitioned from ACQUIRED to RUNNING
2015-04-01 16:52:54,816 INFO SecurityLogger.org.apache.hadoop.ipc.Server: Auth successful for appattempt_1427899242644_0004_000001 (auth:SIMPLE)
2015-04-01 16:52:54,818 INFO org.apache.hadoop.yarn.server.resourcemanager.ApplicationMasterService: AM registration appattempt_1427899242644_0004_000001
2015-04-01 16:52:54,818 INFO org.apache.hadoop.yarn.server.resourcemanager.RMAuditLogger: USER=echallier	IP=127.0.0.1	OPERATION=Register App Master	TARGET=ApplicationMasterService	RESULT=SUCCESS	APPID=application_1427899242644_0004	APPATTEMPTID=appattempt_1427899242644_0004_000001
2015-04-01 16:52:54,818 INFO org.apache.hadoop.yarn.server.resourcemanager.rmapp.attempt.RMAppAttemptImpl: appattempt_1427899242644_0004_000001 State change from LAUNCHED to RUNNING
2015-04-01 16:52:54,819 INFO org.apache.hadoop.yarn.server.resourcemanager.rmapp.RMAppImpl: application_1427899242644_0004 State change from ACCEPTED to RUNNING
2015-04-01 16:52:56,813 INFO org.apache.hadoop.yarn.server.resourcemanager.rmcontainer.RMContainerImpl: container_1427899242644_0004_01_000002 Container Transitioned from NEW to ALLOCATED
2015-04-01 16:52:56,814 INFO org.apache.hadoop.yarn.server.resourcemanager.RMAuditLogger: USER=echallier	OPERATION=AM Allocated Container	TARGET=SchedulerApp	RESULT=SUCCESS	APPID=application_1427899242644_0004	CONTAINERID=container_1427899242644_0004_01_000002
2015-04-01 16:52:56,814 INFO org.apache.hadoop.yarn.server.resourcemanager.scheduler.SchedulerNode: Assigned container container_1427899242644_0004_01_000002 of capacity <memory:1024, vCores:1> on host a11p2.fil.univ-lille1.fr.:55305, which has 2 containers, <memory:3072, vCores:2> used and <memory:5120, vCores:6> available after allocation
2015-04-01 16:52:56,814 INFO org.apache.hadoop.yarn.server.resourcemanager.scheduler.capacity.LeafQueue: assignedContainer application attempt=appattempt_1427899242644_0004_000001 container=Container: [ContainerId: container_1427899242644_0004_01_000002, NodeId: a11p2.fil.univ-lille1.fr.:55305, NodeHttpAddress: a11p2.fil.univ-lille1.fr.:8042, Resource: <memory:1024, vCores:1>, Priority: 20, Token: null, ] queue=default: capacity=1.0, absoluteCapacity=1.0, usedResources=<memory:2048, vCores:1>, usedCapacity=0.25, absoluteUsedCapacity=0.25, numApps=1, numContainers=1 clusterResource=<memory:8192, vCores:8>
2015-04-01 16:52:56,814 INFO org.apache.hadoop.yarn.server.resourcemanager.scheduler.capacity.ParentQueue: Re-sorting assigned queue: root.default stats: default: capacity=1.0, absoluteCapacity=1.0, usedResources=<memory:3072, vCores:2>, usedCapacity=0.375, absoluteUsedCapacity=0.375, numApps=1, numContainers=2
2015-04-01 16:52:56,814 INFO org.apache.hadoop.yarn.server.resourcemanager.scheduler.capacity.ParentQueue: assignedContainer queue=root usedCapacity=0.375 absoluteUsedCapacity=0.375 used=<memory:3072, vCores:2> cluster=<memory:8192, vCores:8>
2015-04-01 16:52:56,874 INFO org.apache.hadoop.yarn.server.resourcemanager.security.NMTokenSecretManagerInRM: Sending NMToken for nodeId : a11p2.fil.univ-lille1.fr.:55305 for container : container_1427899242644_0004_01_000002
2015-04-01 16:52:56,875 INFO org.apache.hadoop.yarn.server.resourcemanager.rmcontainer.RMContainerImpl: container_1427899242644_0004_01_000002 Container Transitioned from ALLOCATED to ACQUIRED
2015-04-01 16:52:57,814 INFO org.apache.hadoop.yarn.server.resourcemanager.rmcontainer.RMContainerImpl: container_1427899242644_0004_01_000002 Container Transitioned from ACQUIRED to RUNNING
2015-04-01 16:52:57,891 INFO org.apache.hadoop.yarn.server.resourcemanager.scheduler.AppSchedulingInfo: checking for deactivate... 
2015-04-01 16:53:00,213 INFO org.apache.hadoop.yarn.server.resourcemanager.rmcontainer.RMContainerImpl: container_1427899242644_0004_01_000002 Container Transitioned from RUNNING to COMPLETED
2015-04-01 16:53:00,213 INFO org.apache.hadoop.yarn.server.resourcemanager.scheduler.common.fica.FiCaSchedulerApp: Completed container: container_1427899242644_0004_01_000002 in state: COMPLETED event:FINISHED
2015-04-01 16:53:00,213 INFO org.apache.hadoop.yarn.server.resourcemanager.RMAuditLogger: USER=echallier	OPERATION=AM Released Container	TARGET=SchedulerApp	RESULT=SUCCESS	APPID=application_1427899242644_0004	CONTAINERID=container_1427899242644_0004_01_000002
2015-04-01 16:53:00,214 INFO org.apache.hadoop.yarn.server.resourcemanager.scheduler.SchedulerNode: Released container container_1427899242644_0004_01_000002 of capacity <memory:1024, vCores:1> on host a11p2.fil.univ-lille1.fr.:55305, which currently has 1 containers, <memory:2048, vCores:1> used and <memory:6144, vCores:7> available, release resources=true
2015-04-01 16:53:00,214 INFO org.apache.hadoop.yarn.server.resourcemanager.scheduler.capacity.LeafQueue: default used=<memory:2048, vCores:1> numContainers=1 user=echallier user-resources=<memory:2048, vCores:1>
2015-04-01 16:53:00,214 INFO org.apache.hadoop.yarn.server.resourcemanager.scheduler.capacity.LeafQueue: completedContainer container=Container: [ContainerId: container_1427899242644_0004_01_000002, NodeId: a11p2.fil.univ-lille1.fr.:55305, NodeHttpAddress: a11p2.fil.univ-lille1.fr.:8042, Resource: <memory:1024, vCores:1>, Priority: 20, Token: Token { kind: ContainerToken, service: 127.0.1.1:55305 }, ] queue=default: capacity=1.0, absoluteCapacity=1.0, usedResources=<memory:2048, vCores:1>, usedCapacity=0.25, absoluteUsedCapacity=0.25, numApps=1, numContainers=1 cluster=<memory:8192, vCores:8>
2015-04-01 16:53:00,214 INFO org.apache.hadoop.yarn.server.resourcemanager.scheduler.capacity.ParentQueue: completedContainer queue=root usedCapacity=0.25 absoluteUsedCapacity=0.25 used=<memory:2048, vCores:1> cluster=<memory:8192, vCores:8>
2015-04-01 16:53:00,214 INFO org.apache.hadoop.yarn.server.resourcemanager.scheduler.capacity.ParentQueue: Re-sorting completed queue: root.default stats: default: capacity=1.0, absoluteCapacity=1.0, usedResources=<memory:2048, vCores:1>, usedCapacity=0.25, absoluteUsedCapacity=0.25, numApps=1, numContainers=1
2015-04-01 16:53:00,214 INFO org.apache.hadoop.yarn.server.resourcemanager.scheduler.capacity.CapacityScheduler: Application attempt appattempt_1427899242644_0004_000001 released container container_1427899242644_0004_01_000002 on node: host: a11p2.fil.univ-lille1.fr.:55305 #containers=1 available=6144 used=2048 with event: FINISHED
2015-04-01 16:53:01,215 INFO org.apache.hadoop.yarn.server.resourcemanager.rmcontainer.RMContainerImpl: container_1427899242644_0004_01_000003 Container Transitioned from NEW to ALLOCATED
2015-04-01 16:53:01,215 INFO org.apache.hadoop.yarn.server.resourcemanager.RMAuditLogger: USER=echallier	OPERATION=AM Allocated Container	TARGET=SchedulerApp	RESULT=SUCCESS	APPID=application_1427899242644_0004	CONTAINERID=container_1427899242644_0004_01_000003
2015-04-01 16:53:01,216 INFO org.apache.hadoop.yarn.server.resourcemanager.scheduler.SchedulerNode: Assigned container container_1427899242644_0004_01_000003 of capacity <memory:1024, vCores:1> on host a11p2.fil.univ-lille1.fr.:55305, which has 2 containers, <memory:3072, vCores:2> used and <memory:5120, vCores:6> available after allocation
2015-04-01 16:53:01,216 INFO org.apache.hadoop.yarn.server.resourcemanager.scheduler.capacity.LeafQueue: assignedContainer application attempt=appattempt_1427899242644_0004_000001 container=Container: [ContainerId: container_1427899242644_0004_01_000003, NodeId: a11p2.fil.univ-lille1.fr.:55305, NodeHttpAddress: a11p2.fil.univ-lille1.fr.:8042, Resource: <memory:1024, vCores:1>, Priority: 10, Token: null, ] queue=default: capacity=1.0, absoluteCapacity=1.0, usedResources=<memory:2048, vCores:1>, usedCapacity=0.25, absoluteUsedCapacity=0.25, numApps=1, numContainers=1 clusterResource=<memory:8192, vCores:8>
2015-04-01 16:53:01,216 INFO org.apache.hadoop.yarn.server.resourcemanager.scheduler.capacity.ParentQueue: Re-sorting assigned queue: root.default stats: default: capacity=1.0, absoluteCapacity=1.0, usedResources=<memory:3072, vCores:2>, usedCapacity=0.375, absoluteUsedCapacity=0.375, numApps=1, numContainers=2
2015-04-01 16:53:01,216 INFO org.apache.hadoop.yarn.server.resourcemanager.scheduler.capacity.ParentQueue: assignedContainer queue=root usedCapacity=0.375 absoluteUsedCapacity=0.375 used=<memory:3072, vCores:2> cluster=<memory:8192, vCores:8>
2015-04-01 16:53:01,907 INFO org.apache.hadoop.yarn.server.resourcemanager.rmcontainer.RMContainerImpl: container_1427899242644_0004_01_000003 Container Transitioned from ALLOCATED to ACQUIRED
2015-04-01 16:53:02,217 INFO org.apache.hadoop.yarn.server.resourcemanager.rmcontainer.RMContainerImpl: container_1427899242644_0004_01_000003 Container Transitioned from ACQUIRED to RUNNING
2015-04-01 16:53:02,911 INFO org.apache.hadoop.yarn.server.resourcemanager.scheduler.AppSchedulingInfo: checking for deactivate... 
2015-04-01 16:53:04,994 INFO org.apache.hadoop.yarn.server.resourcemanager.rmapp.attempt.RMAppAttemptImpl: Updating application attempt appattempt_1427899242644_0004_000001 with final state: FINISHING, and exit status: -1000
2015-04-01 16:53:04,995 INFO org.apache.hadoop.yarn.server.resourcemanager.rmapp.attempt.RMAppAttemptImpl: appattempt_1427899242644_0004_000001 State change from RUNNING to FINAL_SAVING
2015-04-01 16:53:04,995 INFO org.apache.hadoop.yarn.server.resourcemanager.rmapp.RMAppImpl: Updating application application_1427899242644_0004 with final state: FINISHING
2015-04-01 16:53:04,995 INFO org.apache.hadoop.yarn.server.resourcemanager.rmapp.RMAppImpl: application_1427899242644_0004 State change from RUNNING to FINAL_SAVING
2015-04-01 16:53:04,995 INFO org.apache.hadoop.yarn.server.resourcemanager.recovery.RMStateStore: Updating info for app: application_1427899242644_0004
2015-04-01 16:53:04,995 INFO org.apache.hadoop.yarn.server.resourcemanager.rmapp.attempt.RMAppAttemptImpl: appattempt_1427899242644_0004_000001 State change from FINAL_SAVING to FINISHING
2015-04-01 16:53:04,995 INFO org.apache.hadoop.yarn.server.resourcemanager.rmapp.RMAppImpl: application_1427899242644_0004 State change from FINAL_SAVING to FINISHING
2015-04-01 16:53:05,616 INFO org.apache.hadoop.yarn.server.resourcemanager.rmcontainer.RMContainerImpl: container_1427899242644_0004_01_000003 Container Transitioned from RUNNING to COMPLETED
2015-04-01 16:53:05,616 INFO org.apache.hadoop.yarn.server.resourcemanager.scheduler.common.fica.FiCaSchedulerApp: Completed container: container_1427899242644_0004_01_000003 in state: COMPLETED event:FINISHED
2015-04-01 16:53:05,616 INFO org.apache.hadoop.yarn.server.resourcemanager.RMAuditLogger: USER=echallier	OPERATION=AM Released Container	TARGET=SchedulerApp	RESULT=SUCCESS	APPID=application_1427899242644_0004	CONTAINERID=container_1427899242644_0004_01_000003
2015-04-01 16:53:05,616 INFO org.apache.hadoop.yarn.server.resourcemanager.scheduler.SchedulerNode: Released container container_1427899242644_0004_01_000003 of capacity <memory:1024, vCores:1> on host a11p2.fil.univ-lille1.fr.:55305, which currently has 1 containers, <memory:2048, vCores:1> used and <memory:6144, vCores:7> available, release resources=true
2015-04-01 16:53:05,616 INFO org.apache.hadoop.yarn.server.resourcemanager.scheduler.capacity.LeafQueue: default used=<memory:2048, vCores:1> numContainers=1 user=echallier user-resources=<memory:2048, vCores:1>
2015-04-01 16:53:05,617 INFO org.apache.hadoop.yarn.server.resourcemanager.scheduler.capacity.LeafQueue: completedContainer container=Container: [ContainerId: container_1427899242644_0004_01_000003, NodeId: a11p2.fil.univ-lille1.fr.:55305, NodeHttpAddress: a11p2.fil.univ-lille1.fr.:8042, Resource: <memory:1024, vCores:1>, Priority: 10, Token: Token { kind: ContainerToken, service: 127.0.1.1:55305 }, ] queue=default: capacity=1.0, absoluteCapacity=1.0, usedResources=<memory:2048, vCores:1>, usedCapacity=0.25, absoluteUsedCapacity=0.25, numApps=1, numContainers=1 cluster=<memory:8192, vCores:8>
2015-04-01 16:53:05,617 INFO org.apache.hadoop.yarn.server.resourcemanager.scheduler.capacity.ParentQueue: completedContainer queue=root usedCapacity=0.25 absoluteUsedCapacity=0.25 used=<memory:2048, vCores:1> cluster=<memory:8192, vCores:8>
2015-04-01 16:53:05,617 INFO org.apache.hadoop.yarn.server.resourcemanager.scheduler.capacity.ParentQueue: Re-sorting completed queue: root.default stats: default: capacity=1.0, absoluteCapacity=1.0, usedResources=<memory:2048, vCores:1>, usedCapacity=0.25, absoluteUsedCapacity=0.25, numApps=1, numContainers=1
2015-04-01 16:53:05,617 INFO org.apache.hadoop.yarn.server.resourcemanager.scheduler.capacity.CapacityScheduler: Application attempt appattempt_1427899242644_0004_000001 released container container_1427899242644_0004_01_000003 on node: host: a11p2.fil.univ-lille1.fr.:55305 #containers=1 available=6144 used=2048 with event: FINISHED
2015-04-01 16:53:11,626 INFO org.apache.hadoop.yarn.server.resourcemanager.rmcontainer.RMContainerImpl: container_1427899242644_0004_01_000001 Container Transitioned from RUNNING to COMPLETED
2015-04-01 16:53:11,626 INFO org.apache.hadoop.yarn.server.resourcemanager.ApplicationMasterService: Unregistering app attempt : appattempt_1427899242644_0004_000001
2015-04-01 16:53:11,627 INFO org.apache.hadoop.yarn.server.resourcemanager.scheduler.common.fica.FiCaSchedulerApp: Completed container: container_1427899242644_0004_01_000001 in state: COMPLETED event:FINISHED
2015-04-01 16:53:11,628 INFO org.apache.hadoop.yarn.server.resourcemanager.rmapp.attempt.RMAppAttemptImpl: appattempt_1427899242644_0004_000001 State change from FINISHING to FINISHED
2015-04-01 16:53:11,628 INFO org.apache.hadoop.yarn.server.resourcemanager.RMAuditLogger: USER=echallier	OPERATION=AM Released Container	TARGET=SchedulerApp	RESULT=SUCCESS	APPID=application_1427899242644_0004	CONTAINERID=container_1427899242644_0004_01_000001
2015-04-01 16:53:11,628 INFO org.apache.hadoop.yarn.server.resourcemanager.rmapp.RMAppImpl: application_1427899242644_0004 State change from FINISHING to FINISHED
2015-04-01 16:53:11,628 INFO org.apache.hadoop.yarn.server.resourcemanager.scheduler.SchedulerNode: Released container container_1427899242644_0004_01_000001 of capacity <memory:2048, vCores:1> on host a11p2.fil.univ-lille1.fr.:55305, which currently has 0 containers, <memory:0, vCores:0> used and <memory:8192, vCores:8> available, release resources=true
2015-04-01 16:53:11,628 INFO org.apache.hadoop.yarn.server.resourcemanager.scheduler.capacity.LeafQueue: default used=<memory:0, vCores:0> numContainers=0 user=echallier user-resources=<memory:0, vCores:0>
2015-04-01 16:53:11,628 INFO org.apache.hadoop.yarn.server.resourcemanager.RMAuditLogger: USER=echallier	OPERATION=Application Finished - Succeeded	TARGET=RMAppManager	RESULT=SUCCESS	APPID=application_1427899242644_0004
2015-04-01 16:53:11,628 INFO org.apache.hadoop.yarn.server.resourcemanager.scheduler.capacity.LeafQueue: completedContainer container=Container: [ContainerId: container_1427899242644_0004_01_000001, NodeId: a11p2.fil.univ-lille1.fr.:55305, NodeHttpAddress: a11p2.fil.univ-lille1.fr.:8042, Resource: <memory:2048, vCores:1>, Priority: 0, Token: Token { kind: ContainerToken, service: 127.0.1.1:55305 }, ] queue=default: capacity=1.0, absoluteCapacity=1.0, usedResources=<memory:0, vCores:0>, usedCapacity=0.0, absoluteUsedCapacity=0.0, numApps=1, numContainers=0 cluster=<memory:8192, vCores:8>
2015-04-01 16:53:11,628 INFO org.apache.hadoop.yarn.server.resourcemanager.scheduler.capacity.ParentQueue: completedContainer queue=root usedCapacity=0.0 absoluteUsedCapacity=0.0 used=<memory:0, vCores:0> cluster=<memory:8192, vCores:8>
2015-04-01 16:53:11,628 INFO org.apache.hadoop.yarn.server.resourcemanager.scheduler.capacity.ParentQueue: Re-sorting completed queue: root.default stats: default: capacity=1.0, absoluteCapacity=1.0, usedResources=<memory:0, vCores:0>, usedCapacity=0.0, absoluteUsedCapacity=0.0, numApps=1, numContainers=0
2015-04-01 16:53:11,628 INFO org.apache.hadoop.yarn.server.resourcemanager.scheduler.capacity.CapacityScheduler: Application attempt appattempt_1427899242644_0004_000001 released container container_1427899242644_0004_01_000001 on node: host: a11p2.fil.univ-lille1.fr.:55305 #containers=0 available=8192 used=0 with event: FINISHED
2015-04-01 16:53:11,628 INFO org.apache.hadoop.yarn.server.resourcemanager.amlauncher.AMLauncher: Cleaning master appattempt_1427899242644_0004_000001
2015-04-01 16:53:11,629 INFO org.apache.hadoop.yarn.server.resourcemanager.RMAppManager$ApplicationSummary: appId=application_1427899242644_0004,name=anagrames,user=echallier,queue=default,state=FINISHED,trackingUrl=http://a11p2.fil.univ-lille1.fr.:8088/proxy/application_1427899242644_0004/jobhistory/job/job_1427899242644_0004,appMasterHost=a11p2,startTime=1427899971301,finishTime=1427899984995,finalStatus=SUCCEEDED
2015-04-01 16:53:11,629 INFO org.apache.hadoop.yarn.server.resourcemanager.scheduler.capacity.CapacityScheduler: Application Attempt appattempt_1427899242644_0004_000001 is done. finalState=FINISHED
2015-04-01 16:53:11,630 INFO org.apache.hadoop.yarn.server.resourcemanager.scheduler.AppSchedulingInfo: Application application_1427899242644_0004 requests cleared
2015-04-01 16:53:11,630 INFO org.apache.hadoop.yarn.server.resourcemanager.scheduler.capacity.LeafQueue: Application removed - appId: application_1427899242644_0004 user: echallier queue: default #user-pending-applications: 0 #user-active-applications: 0 #queue-pending-applications: 0 #queue-active-applications: 0
2015-04-01 16:53:11,630 INFO org.apache.hadoop.yarn.server.resourcemanager.scheduler.capacity.ParentQueue: Application removed - appId: application_1427899242644_0004 user: echallier leaf-queue of parent: root #applications: 0
2015-04-01 16:55:18,834 INFO org.apache.hadoop.yarn.server.resourcemanager.ClientRMService: Allocated new applicationId: 5
2015-04-01 16:55:19,596 INFO org.apache.hadoop.yarn.server.resourcemanager.ClientRMService: Application with id 5 submitted by user echallier
2015-04-01 16:55:19,596 INFO org.apache.hadoop.yarn.server.resourcemanager.rmapp.RMAppImpl: Storing application with id application_1427899242644_0005
2015-04-01 16:55:19,596 INFO org.apache.hadoop.yarn.server.resourcemanager.RMAuditLogger: USER=echallier	IP=127.0.0.1	OPERATION=Submit Application Request	TARGET=ClientRMService	RESULT=SUCCESS	APPID=application_1427899242644_0005
2015-04-01 16:55:19,596 INFO org.apache.hadoop.yarn.server.resourcemanager.rmapp.RMAppImpl: application_1427899242644_0005 State change from NEW to NEW_SAVING
2015-04-01 16:55:19,596 INFO org.apache.hadoop.yarn.server.resourcemanager.recovery.RMStateStore: Storing info for app: application_1427899242644_0005
2015-04-01 16:55:19,596 INFO org.apache.hadoop.yarn.server.resourcemanager.rmapp.RMAppImpl: application_1427899242644_0005 State change from NEW_SAVING to SUBMITTED
2015-04-01 16:55:19,596 INFO org.apache.hadoop.yarn.server.resourcemanager.scheduler.capacity.ParentQueue: Application added - appId: application_1427899242644_0005 user: echallier leaf-queue of parent: root #applications: 1
2015-04-01 16:55:19,596 INFO org.apache.hadoop.yarn.server.resourcemanager.scheduler.capacity.CapacityScheduler: Accepted application application_1427899242644_0005 from user: echallier, in queue: default
2015-04-01 16:55:19,597 INFO org.apache.hadoop.yarn.server.resourcemanager.rmapp.RMAppImpl: application_1427899242644_0005 State change from SUBMITTED to ACCEPTED
2015-04-01 16:55:19,597 INFO org.apache.hadoop.yarn.server.resourcemanager.ApplicationMasterService: Registering app attempt : appattempt_1427899242644_0005_000001
2015-04-01 16:55:19,597 INFO org.apache.hadoop.yarn.server.resourcemanager.rmapp.attempt.RMAppAttemptImpl: appattempt_1427899242644_0005_000001 State change from NEW to SUBMITTED
2015-04-01 16:55:19,597 INFO org.apache.hadoop.yarn.server.resourcemanager.scheduler.capacity.LeafQueue: Application application_1427899242644_0005 from user: echallier activated in queue: default
2015-04-01 16:55:19,597 INFO org.apache.hadoop.yarn.server.resourcemanager.scheduler.capacity.LeafQueue: Application added - appId: application_1427899242644_0005 user: org.apache.hadoop.yarn.server.resourcemanager.scheduler.capacity.LeafQueue$User@13ab58, leaf-queue: default #user-pending-applications: 0 #user-active-applications: 1 #queue-pending-applications: 0 #queue-active-applications: 1
2015-04-01 16:55:19,597 INFO org.apache.hadoop.yarn.server.resourcemanager.scheduler.capacity.CapacityScheduler: Added Application Attempt appattempt_1427899242644_0005_000001 to scheduler from user echallier in queue default
2015-04-01 16:55:19,597 INFO org.apache.hadoop.yarn.server.resourcemanager.rmapp.attempt.RMAppAttemptImpl: appattempt_1427899242644_0005_000001 State change from SUBMITTED to SCHEDULED
2015-04-01 16:55:19,830 INFO org.apache.hadoop.yarn.server.resourcemanager.rmcontainer.RMContainerImpl: container_1427899242644_0005_01_000001 Container Transitioned from NEW to ALLOCATED
2015-04-01 16:55:19,830 INFO org.apache.hadoop.yarn.server.resourcemanager.RMAuditLogger: USER=echallier	OPERATION=AM Allocated Container	TARGET=SchedulerApp	RESULT=SUCCESS	APPID=application_1427899242644_0005	CONTAINERID=container_1427899242644_0005_01_000001
2015-04-01 16:55:19,830 INFO org.apache.hadoop.yarn.server.resourcemanager.scheduler.SchedulerNode: Assigned container container_1427899242644_0005_01_000001 of capacity <memory:2048, vCores:1> on host a11p2.fil.univ-lille1.fr.:55305, which has 1 containers, <memory:2048, vCores:1> used and <memory:6144, vCores:7> available after allocation
2015-04-01 16:55:19,830 INFO org.apache.hadoop.yarn.server.resourcemanager.scheduler.capacity.LeafQueue: assignedContainer application attempt=appattempt_1427899242644_0005_000001 container=Container: [ContainerId: container_1427899242644_0005_01_000001, NodeId: a11p2.fil.univ-lille1.fr.:55305, NodeHttpAddress: a11p2.fil.univ-lille1.fr.:8042, Resource: <memory:2048, vCores:1>, Priority: 0, Token: null, ] queue=default: capacity=1.0, absoluteCapacity=1.0, usedResources=<memory:0, vCores:0>, usedCapacity=0.0, absoluteUsedCapacity=0.0, numApps=1, numContainers=0 clusterResource=<memory:8192, vCores:8>
2015-04-01 16:55:19,830 INFO org.apache.hadoop.yarn.server.resourcemanager.scheduler.capacity.ParentQueue: Re-sorting assigned queue: root.default stats: default: capacity=1.0, absoluteCapacity=1.0, usedResources=<memory:2048, vCores:1>, usedCapacity=0.25, absoluteUsedCapacity=0.25, numApps=1, numContainers=1
2015-04-01 16:55:19,831 INFO org.apache.hadoop.yarn.server.resourcemanager.scheduler.capacity.ParentQueue: assignedContainer queue=root usedCapacity=0.25 absoluteUsedCapacity=0.25 used=<memory:2048, vCores:1> cluster=<memory:8192, vCores:8>
2015-04-01 16:55:19,831 INFO org.apache.hadoop.yarn.server.resourcemanager.security.NMTokenSecretManagerInRM: Sending NMToken for nodeId : a11p2.fil.univ-lille1.fr.:55305 for container : container_1427899242644_0005_01_000001
2015-04-01 16:55:19,832 INFO org.apache.hadoop.yarn.server.resourcemanager.rmcontainer.RMContainerImpl: container_1427899242644_0005_01_000001 Container Transitioned from ALLOCATED to ACQUIRED
2015-04-01 16:55:19,832 INFO org.apache.hadoop.yarn.server.resourcemanager.security.NMTokenSecretManagerInRM: Clear node set for appattempt_1427899242644_0005_000001
2015-04-01 16:55:19,832 INFO org.apache.hadoop.yarn.server.resourcemanager.rmapp.attempt.RMAppAttemptImpl: Storing attempt: AppId: application_1427899242644_0005 AttemptId: appattempt_1427899242644_0005_000001 MasterContainer: Container: [ContainerId: container_1427899242644_0005_01_000001, NodeId: a11p2.fil.univ-lille1.fr.:55305, NodeHttpAddress: a11p2.fil.univ-lille1.fr.:8042, Resource: <memory:2048, vCores:1>, Priority: 0, Token: Token { kind: ContainerToken, service: 127.0.1.1:55305 }, ]
2015-04-01 16:55:19,832 INFO org.apache.hadoop.yarn.server.resourcemanager.rmapp.attempt.RMAppAttemptImpl: appattempt_1427899242644_0005_000001 State change from SCHEDULED to ALLOCATED_SAVING
2015-04-01 16:55:19,832 INFO org.apache.hadoop.yarn.server.resourcemanager.rmapp.attempt.RMAppAttemptImpl: appattempt_1427899242644_0005_000001 State change from ALLOCATED_SAVING to ALLOCATED
2015-04-01 16:55:19,833 INFO org.apache.hadoop.yarn.server.resourcemanager.amlauncher.AMLauncher: Launching masterappattempt_1427899242644_0005_000001
2015-04-01 16:55:19,834 INFO org.apache.hadoop.yarn.server.resourcemanager.amlauncher.AMLauncher: Setting up container Container: [ContainerId: container_1427899242644_0005_01_000001, NodeId: a11p2.fil.univ-lille1.fr.:55305, NodeHttpAddress: a11p2.fil.univ-lille1.fr.:8042, Resource: <memory:2048, vCores:1>, Priority: 0, Token: Token { kind: ContainerToken, service: 127.0.1.1:55305 }, ] for AM appattempt_1427899242644_0005_000001
2015-04-01 16:55:19,834 INFO org.apache.hadoop.yarn.server.resourcemanager.amlauncher.AMLauncher: Command to launch container container_1427899242644_0005_01_000001 : $JAVA_HOME/bin/java -Dlog4j.configuration=container-log4j.properties -Dyarn.app.container.log.dir=<LOG_DIR> -Dyarn.app.container.log.filesize=0 -Dhadoop.root.logger=INFO,CLA  -Xmx1024m org.apache.hadoop.mapreduce.v2.app.MRAppMaster 1><LOG_DIR>/stdout 2><LOG_DIR>/stderr 
2015-04-01 16:55:19,846 INFO org.apache.hadoop.yarn.server.resourcemanager.amlauncher.AMLauncher: Done launching container Container: [ContainerId: container_1427899242644_0005_01_000001, NodeId: a11p2.fil.univ-lille1.fr.:55305, NodeHttpAddress: a11p2.fil.univ-lille1.fr.:8042, Resource: <memory:2048, vCores:1>, Priority: 0, Token: Token { kind: ContainerToken, service: 127.0.1.1:55305 }, ] for AM appattempt_1427899242644_0005_000001
2015-04-01 16:55:19,847 INFO org.apache.hadoop.yarn.server.resourcemanager.rmapp.attempt.RMAppAttemptImpl: appattempt_1427899242644_0005_000001 State change from ALLOCATED to LAUNCHED
2015-04-01 16:55:20,831 INFO org.apache.hadoop.yarn.server.resourcemanager.rmcontainer.RMContainerImpl: container_1427899242644_0005_01_000001 Container Transitioned from ACQUIRED to RUNNING
2015-04-01 16:55:22,782 INFO SecurityLogger.org.apache.hadoop.ipc.Server: Auth successful for appattempt_1427899242644_0005_000001 (auth:SIMPLE)
2015-04-01 16:55:22,784 INFO org.apache.hadoop.yarn.server.resourcemanager.ApplicationMasterService: AM registration appattempt_1427899242644_0005_000001
2015-04-01 16:55:22,784 INFO org.apache.hadoop.yarn.server.resourcemanager.RMAuditLogger: USER=echallier	IP=127.0.0.1	OPERATION=Register App Master	TARGET=ApplicationMasterService	RESULT=SUCCESS	APPID=application_1427899242644_0005	APPATTEMPTID=appattempt_1427899242644_0005_000001
2015-04-01 16:55:22,785 INFO org.apache.hadoop.yarn.server.resourcemanager.rmapp.attempt.RMAppAttemptImpl: appattempt_1427899242644_0005_000001 State change from LAUNCHED to RUNNING
2015-04-01 16:55:22,785 INFO org.apache.hadoop.yarn.server.resourcemanager.rmapp.RMAppImpl: application_1427899242644_0005 State change from ACCEPTED to RUNNING
2015-04-01 16:55:23,835 INFO org.apache.hadoop.yarn.server.resourcemanager.rmcontainer.RMContainerImpl: container_1427899242644_0005_01_000002 Container Transitioned from NEW to ALLOCATED
2015-04-01 16:55:23,835 INFO org.apache.hadoop.yarn.server.resourcemanager.RMAuditLogger: USER=echallier	OPERATION=AM Allocated Container	TARGET=SchedulerApp	RESULT=SUCCESS	APPID=application_1427899242644_0005	CONTAINERID=container_1427899242644_0005_01_000002
2015-04-01 16:55:23,835 INFO org.apache.hadoop.yarn.server.resourcemanager.scheduler.SchedulerNode: Assigned container container_1427899242644_0005_01_000002 of capacity <memory:1024, vCores:1> on host a11p2.fil.univ-lille1.fr.:55305, which has 2 containers, <memory:3072, vCores:2> used and <memory:5120, vCores:6> available after allocation
2015-04-01 16:55:23,835 INFO org.apache.hadoop.yarn.server.resourcemanager.scheduler.capacity.LeafQueue: assignedContainer application attempt=appattempt_1427899242644_0005_000001 container=Container: [ContainerId: container_1427899242644_0005_01_000002, NodeId: a11p2.fil.univ-lille1.fr.:55305, NodeHttpAddress: a11p2.fil.univ-lille1.fr.:8042, Resource: <memory:1024, vCores:1>, Priority: 20, Token: null, ] queue=default: capacity=1.0, absoluteCapacity=1.0, usedResources=<memory:2048, vCores:1>, usedCapacity=0.25, absoluteUsedCapacity=0.25, numApps=1, numContainers=1 clusterResource=<memory:8192, vCores:8>
2015-04-01 16:55:23,835 INFO org.apache.hadoop.yarn.server.resourcemanager.scheduler.capacity.ParentQueue: Re-sorting assigned queue: root.default stats: default: capacity=1.0, absoluteCapacity=1.0, usedResources=<memory:3072, vCores:2>, usedCapacity=0.375, absoluteUsedCapacity=0.375, numApps=1, numContainers=2
2015-04-01 16:55:23,836 INFO org.apache.hadoop.yarn.server.resourcemanager.scheduler.capacity.ParentQueue: assignedContainer queue=root usedCapacity=0.375 absoluteUsedCapacity=0.375 used=<memory:3072, vCores:2> cluster=<memory:8192, vCores:8>
2015-04-01 16:55:24,840 INFO org.apache.hadoop.yarn.server.resourcemanager.security.NMTokenSecretManagerInRM: Sending NMToken for nodeId : a11p2.fil.univ-lille1.fr.:55305 for container : container_1427899242644_0005_01_000002
2015-04-01 16:55:24,841 INFO org.apache.hadoop.yarn.server.resourcemanager.rmcontainer.RMContainerImpl: container_1427899242644_0005_01_000002 Container Transitioned from ALLOCATED to ACQUIRED
2015-04-01 16:55:25,838 INFO org.apache.hadoop.yarn.server.resourcemanager.rmcontainer.RMContainerImpl: container_1427899242644_0005_01_000002 Container Transitioned from ACQUIRED to RUNNING
2015-04-01 16:55:25,856 INFO org.apache.hadoop.yarn.server.resourcemanager.scheduler.AppSchedulingInfo: checking for deactivate... 
2015-04-01 16:55:28,189 INFO org.apache.hadoop.yarn.server.resourcemanager.rmcontainer.RMContainerImpl: container_1427899242644_0005_01_000002 Container Transitioned from RUNNING to COMPLETED
2015-04-01 16:55:28,190 INFO org.apache.hadoop.yarn.server.resourcemanager.scheduler.common.fica.FiCaSchedulerApp: Completed container: container_1427899242644_0005_01_000002 in state: COMPLETED event:FINISHED
2015-04-01 16:55:28,190 INFO org.apache.hadoop.yarn.server.resourcemanager.RMAuditLogger: USER=echallier	OPERATION=AM Released Container	TARGET=SchedulerApp	RESULT=SUCCESS	APPID=application_1427899242644_0005	CONTAINERID=container_1427899242644_0005_01_000002
2015-04-01 16:55:28,190 INFO org.apache.hadoop.yarn.server.resourcemanager.scheduler.SchedulerNode: Released container container_1427899242644_0005_01_000002 of capacity <memory:1024, vCores:1> on host a11p2.fil.univ-lille1.fr.:55305, which currently has 1 containers, <memory:2048, vCores:1> used and <memory:6144, vCores:7> available, release resources=true
2015-04-01 16:55:28,190 INFO org.apache.hadoop.yarn.server.resourcemanager.scheduler.capacity.LeafQueue: default used=<memory:2048, vCores:1> numContainers=1 user=echallier user-resources=<memory:2048, vCores:1>
2015-04-01 16:55:28,190 INFO org.apache.hadoop.yarn.server.resourcemanager.scheduler.capacity.LeafQueue: completedContainer container=Container: [ContainerId: container_1427899242644_0005_01_000002, NodeId: a11p2.fil.univ-lille1.fr.:55305, NodeHttpAddress: a11p2.fil.univ-lille1.fr.:8042, Resource: <memory:1024, vCores:1>, Priority: 20, Token: Token { kind: ContainerToken, service: 127.0.1.1:55305 }, ] queue=default: capacity=1.0, absoluteCapacity=1.0, usedResources=<memory:2048, vCores:1>, usedCapacity=0.25, absoluteUsedCapacity=0.25, numApps=1, numContainers=1 cluster=<memory:8192, vCores:8>
2015-04-01 16:55:28,190 INFO org.apache.hadoop.yarn.server.resourcemanager.scheduler.capacity.ParentQueue: completedContainer queue=root usedCapacity=0.25 absoluteUsedCapacity=0.25 used=<memory:2048, vCores:1> cluster=<memory:8192, vCores:8>
2015-04-01 16:55:28,190 INFO org.apache.hadoop.yarn.server.resourcemanager.scheduler.capacity.ParentQueue: Re-sorting completed queue: root.default stats: default: capacity=1.0, absoluteCapacity=1.0, usedResources=<memory:2048, vCores:1>, usedCapacity=0.25, absoluteUsedCapacity=0.25, numApps=1, numContainers=1
2015-04-01 16:55:28,191 INFO org.apache.hadoop.yarn.server.resourcemanager.scheduler.capacity.CapacityScheduler: Application attempt appattempt_1427899242644_0005_000001 released container container_1427899242644_0005_01_000002 on node: host: a11p2.fil.univ-lille1.fr.:55305 #containers=1 available=6144 used=2048 with event: FINISHED
2015-04-01 16:55:29,192 INFO org.apache.hadoop.yarn.server.resourcemanager.rmcontainer.RMContainerImpl: container_1427899242644_0005_01_000003 Container Transitioned from NEW to ALLOCATED
2015-04-01 16:55:29,192 INFO org.apache.hadoop.yarn.server.resourcemanager.RMAuditLogger: USER=echallier	OPERATION=AM Allocated Container	TARGET=SchedulerApp	RESULT=SUCCESS	APPID=application_1427899242644_0005	CONTAINERID=container_1427899242644_0005_01_000003
2015-04-01 16:55:29,192 INFO org.apache.hadoop.yarn.server.resourcemanager.scheduler.SchedulerNode: Assigned container container_1427899242644_0005_01_000003 of capacity <memory:1024, vCores:1> on host a11p2.fil.univ-lille1.fr.:55305, which has 2 containers, <memory:3072, vCores:2> used and <memory:5120, vCores:6> available after allocation
2015-04-01 16:55:29,192 INFO org.apache.hadoop.yarn.server.resourcemanager.scheduler.capacity.LeafQueue: assignedContainer application attempt=appattempt_1427899242644_0005_000001 container=Container: [ContainerId: container_1427899242644_0005_01_000003, NodeId: a11p2.fil.univ-lille1.fr.:55305, NodeHttpAddress: a11p2.fil.univ-lille1.fr.:8042, Resource: <memory:1024, vCores:1>, Priority: 10, Token: null, ] queue=default: capacity=1.0, absoluteCapacity=1.0, usedResources=<memory:2048, vCores:1>, usedCapacity=0.25, absoluteUsedCapacity=0.25, numApps=1, numContainers=1 clusterResource=<memory:8192, vCores:8>
2015-04-01 16:55:29,192 INFO org.apache.hadoop.yarn.server.resourcemanager.scheduler.capacity.ParentQueue: Re-sorting assigned queue: root.default stats: default: capacity=1.0, absoluteCapacity=1.0, usedResources=<memory:3072, vCores:2>, usedCapacity=0.375, absoluteUsedCapacity=0.375, numApps=1, numContainers=2
2015-04-01 16:55:29,192 INFO org.apache.hadoop.yarn.server.resourcemanager.scheduler.capacity.ParentQueue: assignedContainer queue=root usedCapacity=0.375 absoluteUsedCapacity=0.375 used=<memory:3072, vCores:2> cluster=<memory:8192, vCores:8>
2015-04-01 16:55:29,873 INFO org.apache.hadoop.yarn.server.resourcemanager.rmcontainer.RMContainerImpl: container_1427899242644_0005_01_000003 Container Transitioned from ALLOCATED to ACQUIRED
2015-04-01 16:55:30,193 INFO org.apache.hadoop.yarn.server.resourcemanager.rmcontainer.RMContainerImpl: container_1427899242644_0005_01_000003 Container Transitioned from ACQUIRED to RUNNING
2015-04-01 16:55:30,876 INFO org.apache.hadoop.yarn.server.resourcemanager.scheduler.AppSchedulingInfo: checking for deactivate... 
2015-04-01 16:55:32,699 INFO org.apache.hadoop.yarn.server.resourcemanager.rmapp.attempt.RMAppAttemptImpl: Updating application attempt appattempt_1427899242644_0005_000001 with final state: FINISHING, and exit status: -1000
2015-04-01 16:55:32,700 INFO org.apache.hadoop.yarn.server.resourcemanager.rmapp.attempt.RMAppAttemptImpl: appattempt_1427899242644_0005_000001 State change from RUNNING to FINAL_SAVING
2015-04-01 16:55:32,700 INFO org.apache.hadoop.yarn.server.resourcemanager.rmapp.RMAppImpl: Updating application application_1427899242644_0005 with final state: FINISHING
2015-04-01 16:55:32,700 INFO org.apache.hadoop.yarn.server.resourcemanager.rmapp.RMAppImpl: application_1427899242644_0005 State change from RUNNING to FINAL_SAVING
2015-04-01 16:55:32,700 INFO org.apache.hadoop.yarn.server.resourcemanager.recovery.RMStateStore: Updating info for app: application_1427899242644_0005
2015-04-01 16:55:32,700 INFO org.apache.hadoop.yarn.server.resourcemanager.rmapp.attempt.RMAppAttemptImpl: appattempt_1427899242644_0005_000001 State change from FINAL_SAVING to FINISHING
2015-04-01 16:55:32,701 INFO org.apache.hadoop.yarn.server.resourcemanager.rmapp.RMAppImpl: application_1427899242644_0005 State change from FINAL_SAVING to FINISHING
2015-04-01 16:55:33,301 INFO org.apache.hadoop.yarn.server.resourcemanager.rmcontainer.RMContainerImpl: container_1427899242644_0005_01_000003 Container Transitioned from RUNNING to COMPLETED
2015-04-01 16:55:33,301 INFO org.apache.hadoop.yarn.server.resourcemanager.scheduler.common.fica.FiCaSchedulerApp: Completed container: container_1427899242644_0005_01_000003 in state: COMPLETED event:FINISHED
2015-04-01 16:55:33,301 INFO org.apache.hadoop.yarn.server.resourcemanager.RMAuditLogger: USER=echallier	OPERATION=AM Released Container	TARGET=SchedulerApp	RESULT=SUCCESS	APPID=application_1427899242644_0005	CONTAINERID=container_1427899242644_0005_01_000003
2015-04-01 16:55:33,301 INFO org.apache.hadoop.yarn.server.resourcemanager.scheduler.SchedulerNode: Released container container_1427899242644_0005_01_000003 of capacity <memory:1024, vCores:1> on host a11p2.fil.univ-lille1.fr.:55305, which currently has 1 containers, <memory:2048, vCores:1> used and <memory:6144, vCores:7> available, release resources=true
2015-04-01 16:55:33,301 INFO org.apache.hadoop.yarn.server.resourcemanager.scheduler.capacity.LeafQueue: default used=<memory:2048, vCores:1> numContainers=1 user=echallier user-resources=<memory:2048, vCores:1>
2015-04-01 16:55:33,302 INFO org.apache.hadoop.yarn.server.resourcemanager.scheduler.capacity.LeafQueue: completedContainer container=Container: [ContainerId: container_1427899242644_0005_01_000003, NodeId: a11p2.fil.univ-lille1.fr.:55305, NodeHttpAddress: a11p2.fil.univ-lille1.fr.:8042, Resource: <memory:1024, vCores:1>, Priority: 10, Token: Token { kind: ContainerToken, service: 127.0.1.1:55305 }, ] queue=default: capacity=1.0, absoluteCapacity=1.0, usedResources=<memory:2048, vCores:1>, usedCapacity=0.25, absoluteUsedCapacity=0.25, numApps=1, numContainers=1 cluster=<memory:8192, vCores:8>
2015-04-01 16:55:33,302 INFO org.apache.hadoop.yarn.server.resourcemanager.scheduler.capacity.ParentQueue: completedContainer queue=root usedCapacity=0.25 absoluteUsedCapacity=0.25 used=<memory:2048, vCores:1> cluster=<memory:8192, vCores:8>
2015-04-01 16:55:33,302 INFO org.apache.hadoop.yarn.server.resourcemanager.scheduler.capacity.ParentQueue: Re-sorting completed queue: root.default stats: default: capacity=1.0, absoluteCapacity=1.0, usedResources=<memory:2048, vCores:1>, usedCapacity=0.25, absoluteUsedCapacity=0.25, numApps=1, numContainers=1
2015-04-01 16:55:33,302 INFO org.apache.hadoop.yarn.server.resourcemanager.scheduler.capacity.CapacityScheduler: Application attempt appattempt_1427899242644_0005_000001 released container container_1427899242644_0005_01_000003 on node: host: a11p2.fil.univ-lille1.fr.:55305 #containers=1 available=6144 used=2048 with event: FINISHED
2015-04-01 16:55:39,310 INFO org.apache.hadoop.yarn.server.resourcemanager.rmcontainer.RMContainerImpl: container_1427899242644_0005_01_000001 Container Transitioned from RUNNING to COMPLETED
2015-04-01 16:55:39,311 INFO org.apache.hadoop.yarn.server.resourcemanager.ApplicationMasterService: Unregistering app attempt : appattempt_1427899242644_0005_000001
2015-04-01 16:55:39,311 INFO org.apache.hadoop.yarn.server.resourcemanager.scheduler.common.fica.FiCaSchedulerApp: Completed container: container_1427899242644_0005_01_000001 in state: COMPLETED event:FINISHED
2015-04-01 16:55:39,311 INFO org.apache.hadoop.yarn.server.resourcemanager.rmapp.attempt.RMAppAttemptImpl: appattempt_1427899242644_0005_000001 State change from FINISHING to FINISHED
2015-04-01 16:55:39,311 INFO org.apache.hadoop.yarn.server.resourcemanager.RMAuditLogger: USER=echallier	OPERATION=AM Released Container	TARGET=SchedulerApp	RESULT=SUCCESS	APPID=application_1427899242644_0005	CONTAINERID=container_1427899242644_0005_01_000001
2015-04-01 16:55:39,311 INFO org.apache.hadoop.yarn.server.resourcemanager.rmapp.RMAppImpl: application_1427899242644_0005 State change from FINISHING to FINISHED
2015-04-01 16:55:39,312 INFO org.apache.hadoop.yarn.server.resourcemanager.scheduler.SchedulerNode: Released container container_1427899242644_0005_01_000001 of capacity <memory:2048, vCores:1> on host a11p2.fil.univ-lille1.fr.:55305, which currently has 0 containers, <memory:0, vCores:0> used and <memory:8192, vCores:8> available, release resources=true
2015-04-01 16:55:39,312 INFO org.apache.hadoop.yarn.server.resourcemanager.scheduler.capacity.LeafQueue: default used=<memory:0, vCores:0> numContainers=0 user=echallier user-resources=<memory:0, vCores:0>
2015-04-01 16:55:39,312 INFO org.apache.hadoop.yarn.server.resourcemanager.RMAuditLogger: USER=echallier	OPERATION=Application Finished - Succeeded	TARGET=RMAppManager	RESULT=SUCCESS	APPID=application_1427899242644_0005
2015-04-01 16:55:39,312 INFO org.apache.hadoop.yarn.server.resourcemanager.scheduler.capacity.LeafQueue: completedContainer container=Container: [ContainerId: container_1427899242644_0005_01_000001, NodeId: a11p2.fil.univ-lille1.fr.:55305, NodeHttpAddress: a11p2.fil.univ-lille1.fr.:8042, Resource: <memory:2048, vCores:1>, Priority: 0, Token: Token { kind: ContainerToken, service: 127.0.1.1:55305 }, ] queue=default: capacity=1.0, absoluteCapacity=1.0, usedResources=<memory:0, vCores:0>, usedCapacity=0.0, absoluteUsedCapacity=0.0, numApps=1, numContainers=0 cluster=<memory:8192, vCores:8>
2015-04-01 16:55:39,312 INFO org.apache.hadoop.yarn.server.resourcemanager.scheduler.capacity.ParentQueue: completedContainer queue=root usedCapacity=0.0 absoluteUsedCapacity=0.0 used=<memory:0, vCores:0> cluster=<memory:8192, vCores:8>
2015-04-01 16:55:39,312 INFO org.apache.hadoop.yarn.server.resourcemanager.scheduler.capacity.ParentQueue: Re-sorting completed queue: root.default stats: default: capacity=1.0, absoluteCapacity=1.0, usedResources=<memory:0, vCores:0>, usedCapacity=0.0, absoluteUsedCapacity=0.0, numApps=1, numContainers=0
2015-04-01 16:55:39,312 INFO org.apache.hadoop.yarn.server.resourcemanager.amlauncher.AMLauncher: Cleaning master appattempt_1427899242644_0005_000001
2015-04-01 16:55:39,312 INFO org.apache.hadoop.yarn.server.resourcemanager.scheduler.capacity.CapacityScheduler: Application attempt appattempt_1427899242644_0005_000001 released container container_1427899242644_0005_01_000001 on node: host: a11p2.fil.univ-lille1.fr.:55305 #containers=0 available=8192 used=0 with event: FINISHED
2015-04-01 16:55:39,312 INFO org.apache.hadoop.yarn.server.resourcemanager.RMAppManager$ApplicationSummary: appId=application_1427899242644_0005,name=anagrames,user=echallier,queue=default,state=FINISHED,trackingUrl=http://a11p2.fil.univ-lille1.fr.:8088/proxy/application_1427899242644_0005/jobhistory/job/job_1427899242644_0005,appMasterHost=a11p2,startTime=1427900119596,finishTime=1427900132700,finalStatus=SUCCEEDED
2015-04-01 16:55:39,312 INFO org.apache.hadoop.yarn.server.resourcemanager.scheduler.capacity.CapacityScheduler: Application Attempt appattempt_1427899242644_0005_000001 is done. finalState=FINISHED
2015-04-01 16:55:39,312 INFO org.apache.hadoop.yarn.server.resourcemanager.scheduler.AppSchedulingInfo: Application application_1427899242644_0005 requests cleared
2015-04-01 16:55:39,312 INFO org.apache.hadoop.yarn.server.resourcemanager.scheduler.capacity.LeafQueue: Application removed - appId: application_1427899242644_0005 user: echallier queue: default #user-pending-applications: 0 #user-active-applications: 0 #queue-pending-applications: 0 #queue-active-applications: 0
2015-04-01 16:55:39,312 INFO org.apache.hadoop.yarn.server.resourcemanager.scheduler.capacity.ParentQueue: Application removed - appId: application_1427899242644_0005 user: echallier leaf-queue of parent: root #applications: 0
2015-04-01 17:18:22,360 INFO org.apache.hadoop.yarn.server.resourcemanager.ClientRMService: Allocated new applicationId: 6
2015-04-01 17:18:23,204 INFO org.apache.hadoop.yarn.server.resourcemanager.ClientRMService: Application with id 6 submitted by user echallier
2015-04-01 17:18:23,204 INFO org.apache.hadoop.yarn.server.resourcemanager.rmapp.RMAppImpl: Storing application with id application_1427899242644_0006
2015-04-01 17:18:23,204 INFO org.apache.hadoop.yarn.server.resourcemanager.RMAuditLogger: USER=echallier	IP=127.0.0.1	OPERATION=Submit Application Request	TARGET=ClientRMService	RESULT=SUCCESS	APPID=application_1427899242644_0006
2015-04-01 17:18:23,204 INFO org.apache.hadoop.yarn.server.resourcemanager.rmapp.RMAppImpl: application_1427899242644_0006 State change from NEW to NEW_SAVING
2015-04-01 17:18:23,204 INFO org.apache.hadoop.yarn.server.resourcemanager.recovery.RMStateStore: Storing info for app: application_1427899242644_0006
2015-04-01 17:18:23,204 INFO org.apache.hadoop.yarn.server.resourcemanager.rmapp.RMAppImpl: application_1427899242644_0006 State change from NEW_SAVING to SUBMITTED
2015-04-01 17:18:23,205 INFO org.apache.hadoop.yarn.server.resourcemanager.scheduler.capacity.ParentQueue: Application added - appId: application_1427899242644_0006 user: echallier leaf-queue of parent: root #applications: 1
2015-04-01 17:18:23,205 INFO org.apache.hadoop.yarn.server.resourcemanager.scheduler.capacity.CapacityScheduler: Accepted application application_1427899242644_0006 from user: echallier, in queue: default
2015-04-01 17:18:23,205 INFO org.apache.hadoop.yarn.server.resourcemanager.rmapp.RMAppImpl: application_1427899242644_0006 State change from SUBMITTED to ACCEPTED
2015-04-01 17:18:23,205 INFO org.apache.hadoop.yarn.server.resourcemanager.ApplicationMasterService: Registering app attempt : appattempt_1427899242644_0006_000001
2015-04-01 17:18:23,206 INFO org.apache.hadoop.yarn.server.resourcemanager.rmapp.attempt.RMAppAttemptImpl: appattempt_1427899242644_0006_000001 State change from NEW to SUBMITTED
2015-04-01 17:18:23,206 INFO org.apache.hadoop.yarn.server.resourcemanager.scheduler.capacity.LeafQueue: Application application_1427899242644_0006 from user: echallier activated in queue: default
2015-04-01 17:18:23,206 INFO org.apache.hadoop.yarn.server.resourcemanager.scheduler.capacity.LeafQueue: Application added - appId: application_1427899242644_0006 user: org.apache.hadoop.yarn.server.resourcemanager.scheduler.capacity.LeafQueue$User@ab4a2, leaf-queue: default #user-pending-applications: 0 #user-active-applications: 1 #queue-pending-applications: 0 #queue-active-applications: 1
2015-04-01 17:18:23,206 INFO org.apache.hadoop.yarn.server.resourcemanager.scheduler.capacity.CapacityScheduler: Added Application Attempt appattempt_1427899242644_0006_000001 to scheduler from user echallier in queue default
2015-04-01 17:18:23,206 INFO org.apache.hadoop.yarn.server.resourcemanager.rmapp.attempt.RMAppAttemptImpl: appattempt_1427899242644_0006_000001 State change from SUBMITTED to SCHEDULED
2015-04-01 17:18:23,423 INFO org.apache.hadoop.yarn.server.resourcemanager.rmcontainer.RMContainerImpl: container_1427899242644_0006_01_000001 Container Transitioned from NEW to ALLOCATED
2015-04-01 17:18:23,423 INFO org.apache.hadoop.yarn.server.resourcemanager.RMAuditLogger: USER=echallier	OPERATION=AM Allocated Container	TARGET=SchedulerApp	RESULT=SUCCESS	APPID=application_1427899242644_0006	CONTAINERID=container_1427899242644_0006_01_000001
2015-04-01 17:18:23,423 INFO org.apache.hadoop.yarn.server.resourcemanager.scheduler.SchedulerNode: Assigned container container_1427899242644_0006_01_000001 of capacity <memory:2048, vCores:1> on host a11p2.fil.univ-lille1.fr.:55305, which has 1 containers, <memory:2048, vCores:1> used and <memory:6144, vCores:7> available after allocation
2015-04-01 17:18:23,424 INFO org.apache.hadoop.yarn.server.resourcemanager.scheduler.capacity.LeafQueue: assignedContainer application attempt=appattempt_1427899242644_0006_000001 container=Container: [ContainerId: container_1427899242644_0006_01_000001, NodeId: a11p2.fil.univ-lille1.fr.:55305, NodeHttpAddress: a11p2.fil.univ-lille1.fr.:8042, Resource: <memory:2048, vCores:1>, Priority: 0, Token: null, ] queue=default: capacity=1.0, absoluteCapacity=1.0, usedResources=<memory:0, vCores:0>, usedCapacity=0.0, absoluteUsedCapacity=0.0, numApps=1, numContainers=0 clusterResource=<memory:8192, vCores:8>
2015-04-01 17:18:23,424 INFO org.apache.hadoop.yarn.server.resourcemanager.scheduler.capacity.ParentQueue: Re-sorting assigned queue: root.default stats: default: capacity=1.0, absoluteCapacity=1.0, usedResources=<memory:2048, vCores:1>, usedCapacity=0.25, absoluteUsedCapacity=0.25, numApps=1, numContainers=1
2015-04-01 17:18:23,424 INFO org.apache.hadoop.yarn.server.resourcemanager.scheduler.capacity.ParentQueue: assignedContainer queue=root usedCapacity=0.25 absoluteUsedCapacity=0.25 used=<memory:2048, vCores:1> cluster=<memory:8192, vCores:8>
2015-04-01 17:18:23,424 INFO org.apache.hadoop.yarn.server.resourcemanager.security.NMTokenSecretManagerInRM: Sending NMToken for nodeId : a11p2.fil.univ-lille1.fr.:55305 for container : container_1427899242644_0006_01_000001
2015-04-01 17:18:23,425 INFO org.apache.hadoop.yarn.server.resourcemanager.rmcontainer.RMContainerImpl: container_1427899242644_0006_01_000001 Container Transitioned from ALLOCATED to ACQUIRED
2015-04-01 17:18:23,425 INFO org.apache.hadoop.yarn.server.resourcemanager.security.NMTokenSecretManagerInRM: Clear node set for appattempt_1427899242644_0006_000001
2015-04-01 17:18:23,425 INFO org.apache.hadoop.yarn.server.resourcemanager.rmapp.attempt.RMAppAttemptImpl: Storing attempt: AppId: application_1427899242644_0006 AttemptId: appattempt_1427899242644_0006_000001 MasterContainer: Container: [ContainerId: container_1427899242644_0006_01_000001, NodeId: a11p2.fil.univ-lille1.fr.:55305, NodeHttpAddress: a11p2.fil.univ-lille1.fr.:8042, Resource: <memory:2048, vCores:1>, Priority: 0, Token: Token { kind: ContainerToken, service: 127.0.1.1:55305 }, ]
2015-04-01 17:18:23,425 INFO org.apache.hadoop.yarn.server.resourcemanager.rmapp.attempt.RMAppAttemptImpl: appattempt_1427899242644_0006_000001 State change from SCHEDULED to ALLOCATED_SAVING
2015-04-01 17:18:23,425 INFO org.apache.hadoop.yarn.server.resourcemanager.rmapp.attempt.RMAppAttemptImpl: appattempt_1427899242644_0006_000001 State change from ALLOCATED_SAVING to ALLOCATED
2015-04-01 17:18:23,425 INFO org.apache.hadoop.yarn.server.resourcemanager.amlauncher.AMLauncher: Launching masterappattempt_1427899242644_0006_000001
2015-04-01 17:18:23,426 INFO org.apache.hadoop.yarn.server.resourcemanager.amlauncher.AMLauncher: Setting up container Container: [ContainerId: container_1427899242644_0006_01_000001, NodeId: a11p2.fil.univ-lille1.fr.:55305, NodeHttpAddress: a11p2.fil.univ-lille1.fr.:8042, Resource: <memory:2048, vCores:1>, Priority: 0, Token: Token { kind: ContainerToken, service: 127.0.1.1:55305 }, ] for AM appattempt_1427899242644_0006_000001
2015-04-01 17:18:23,426 INFO org.apache.hadoop.yarn.server.resourcemanager.amlauncher.AMLauncher: Command to launch container container_1427899242644_0006_01_000001 : $JAVA_HOME/bin/java -Dlog4j.configuration=container-log4j.properties -Dyarn.app.container.log.dir=<LOG_DIR> -Dyarn.app.container.log.filesize=0 -Dhadoop.root.logger=INFO,CLA  -Xmx1024m org.apache.hadoop.mapreduce.v2.app.MRAppMaster 1><LOG_DIR>/stdout 2><LOG_DIR>/stderr 
2015-04-01 17:18:23,435 INFO org.apache.hadoop.yarn.server.resourcemanager.amlauncher.AMLauncher: Done launching container Container: [ContainerId: container_1427899242644_0006_01_000001, NodeId: a11p2.fil.univ-lille1.fr.:55305, NodeHttpAddress: a11p2.fil.univ-lille1.fr.:8042, Resource: <memory:2048, vCores:1>, Priority: 0, Token: Token { kind: ContainerToken, service: 127.0.1.1:55305 }, ] for AM appattempt_1427899242644_0006_000001
2015-04-01 17:18:23,435 INFO org.apache.hadoop.yarn.server.resourcemanager.rmapp.attempt.RMAppAttemptImpl: appattempt_1427899242644_0006_000001 State change from ALLOCATED to LAUNCHED
2015-04-01 17:18:24,424 INFO org.apache.hadoop.yarn.server.resourcemanager.rmcontainer.RMContainerImpl: container_1427899242644_0006_01_000001 Container Transitioned from ACQUIRED to RUNNING
2015-04-01 17:18:26,307 INFO SecurityLogger.org.apache.hadoop.ipc.Server: Auth successful for appattempt_1427899242644_0006_000001 (auth:SIMPLE)
2015-04-01 17:18:26,309 INFO org.apache.hadoop.yarn.server.resourcemanager.ApplicationMasterService: AM registration appattempt_1427899242644_0006_000001
2015-04-01 17:18:26,309 INFO org.apache.hadoop.yarn.server.resourcemanager.RMAuditLogger: USER=echallier	IP=127.0.0.1	OPERATION=Register App Master	TARGET=ApplicationMasterService	RESULT=SUCCESS	APPID=application_1427899242644_0006	APPATTEMPTID=appattempt_1427899242644_0006_000001
2015-04-01 17:18:26,309 INFO org.apache.hadoop.yarn.server.resourcemanager.rmapp.attempt.RMAppAttemptImpl: appattempt_1427899242644_0006_000001 State change from LAUNCHED to RUNNING
2015-04-01 17:18:26,309 INFO org.apache.hadoop.yarn.server.resourcemanager.rmapp.RMAppImpl: application_1427899242644_0006 State change from ACCEPTED to RUNNING
2015-04-01 17:18:27,427 INFO org.apache.hadoop.yarn.server.resourcemanager.rmcontainer.RMContainerImpl: container_1427899242644_0006_01_000002 Container Transitioned from NEW to ALLOCATED
2015-04-01 17:18:27,427 INFO org.apache.hadoop.yarn.server.resourcemanager.RMAuditLogger: USER=echallier	OPERATION=AM Allocated Container	TARGET=SchedulerApp	RESULT=SUCCESS	APPID=application_1427899242644_0006	CONTAINERID=container_1427899242644_0006_01_000002
2015-04-01 17:18:27,427 INFO org.apache.hadoop.yarn.server.resourcemanager.scheduler.SchedulerNode: Assigned container container_1427899242644_0006_01_000002 of capacity <memory:1024, vCores:1> on host a11p2.fil.univ-lille1.fr.:55305, which has 2 containers, <memory:3072, vCores:2> used and <memory:5120, vCores:6> available after allocation
2015-04-01 17:18:27,427 INFO org.apache.hadoop.yarn.server.resourcemanager.scheduler.capacity.LeafQueue: assignedContainer application attempt=appattempt_1427899242644_0006_000001 container=Container: [ContainerId: container_1427899242644_0006_01_000002, NodeId: a11p2.fil.univ-lille1.fr.:55305, NodeHttpAddress: a11p2.fil.univ-lille1.fr.:8042, Resource: <memory:1024, vCores:1>, Priority: 20, Token: null, ] queue=default: capacity=1.0, absoluteCapacity=1.0, usedResources=<memory:2048, vCores:1>, usedCapacity=0.25, absoluteUsedCapacity=0.25, numApps=1, numContainers=1 clusterResource=<memory:8192, vCores:8>
2015-04-01 17:18:27,427 INFO org.apache.hadoop.yarn.server.resourcemanager.scheduler.capacity.ParentQueue: Re-sorting assigned queue: root.default stats: default: capacity=1.0, absoluteCapacity=1.0, usedResources=<memory:3072, vCores:2>, usedCapacity=0.375, absoluteUsedCapacity=0.375, numApps=1, numContainers=2
2015-04-01 17:18:27,427 INFO org.apache.hadoop.yarn.server.resourcemanager.scheduler.capacity.ParentQueue: assignedContainer queue=root usedCapacity=0.375 absoluteUsedCapacity=0.375 used=<memory:3072, vCores:2> cluster=<memory:8192, vCores:8>
2015-04-01 17:18:28,347 INFO org.apache.hadoop.yarn.server.resourcemanager.security.NMTokenSecretManagerInRM: Sending NMToken for nodeId : a11p2.fil.univ-lille1.fr.:55305 for container : container_1427899242644_0006_01_000002
2015-04-01 17:18:28,348 INFO org.apache.hadoop.yarn.server.resourcemanager.rmcontainer.RMContainerImpl: container_1427899242644_0006_01_000002 Container Transitioned from ALLOCATED to ACQUIRED
2015-04-01 17:18:29,363 INFO org.apache.hadoop.yarn.server.resourcemanager.scheduler.AppSchedulingInfo: checking for deactivate... 
2015-04-01 17:18:29,429 INFO org.apache.hadoop.yarn.server.resourcemanager.rmcontainer.RMContainerImpl: container_1427899242644_0006_01_000002 Container Transitioned from ACQUIRED to RUNNING
2015-04-01 17:18:31,861 INFO org.apache.hadoop.yarn.server.resourcemanager.rmcontainer.RMContainerImpl: container_1427899242644_0006_01_000002 Container Transitioned from RUNNING to COMPLETED
2015-04-01 17:18:31,861 INFO org.apache.hadoop.yarn.server.resourcemanager.scheduler.common.fica.FiCaSchedulerApp: Completed container: container_1427899242644_0006_01_000002 in state: COMPLETED event:FINISHED
2015-04-01 17:18:31,861 INFO org.apache.hadoop.yarn.server.resourcemanager.RMAuditLogger: USER=echallier	OPERATION=AM Released Container	TARGET=SchedulerApp	RESULT=SUCCESS	APPID=application_1427899242644_0006	CONTAINERID=container_1427899242644_0006_01_000002
2015-04-01 17:18:31,861 INFO org.apache.hadoop.yarn.server.resourcemanager.scheduler.SchedulerNode: Released container container_1427899242644_0006_01_000002 of capacity <memory:1024, vCores:1> on host a11p2.fil.univ-lille1.fr.:55305, which currently has 1 containers, <memory:2048, vCores:1> used and <memory:6144, vCores:7> available, release resources=true
2015-04-01 17:18:31,861 INFO org.apache.hadoop.yarn.server.resourcemanager.scheduler.capacity.LeafQueue: default used=<memory:2048, vCores:1> numContainers=1 user=echallier user-resources=<memory:2048, vCores:1>
2015-04-01 17:18:31,861 INFO org.apache.hadoop.yarn.server.resourcemanager.scheduler.capacity.LeafQueue: completedContainer container=Container: [ContainerId: container_1427899242644_0006_01_000002, NodeId: a11p2.fil.univ-lille1.fr.:55305, NodeHttpAddress: a11p2.fil.univ-lille1.fr.:8042, Resource: <memory:1024, vCores:1>, Priority: 20, Token: Token { kind: ContainerToken, service: 127.0.1.1:55305 }, ] queue=default: capacity=1.0, absoluteCapacity=1.0, usedResources=<memory:2048, vCores:1>, usedCapacity=0.25, absoluteUsedCapacity=0.25, numApps=1, numContainers=1 cluster=<memory:8192, vCores:8>
2015-04-01 17:18:31,862 INFO org.apache.hadoop.yarn.server.resourcemanager.scheduler.capacity.ParentQueue: completedContainer queue=root usedCapacity=0.25 absoluteUsedCapacity=0.25 used=<memory:2048, vCores:1> cluster=<memory:8192, vCores:8>
2015-04-01 17:18:31,862 INFO org.apache.hadoop.yarn.server.resourcemanager.scheduler.capacity.ParentQueue: Re-sorting completed queue: root.default stats: default: capacity=1.0, absoluteCapacity=1.0, usedResources=<memory:2048, vCores:1>, usedCapacity=0.25, absoluteUsedCapacity=0.25, numApps=1, numContainers=1
2015-04-01 17:18:31,862 INFO org.apache.hadoop.yarn.server.resourcemanager.scheduler.capacity.CapacityScheduler: Application attempt appattempt_1427899242644_0006_000001 released container container_1427899242644_0006_01_000002 on node: host: a11p2.fil.univ-lille1.fr.:55305 #containers=1 available=6144 used=2048 with event: FINISHED
2015-04-01 17:18:32,863 INFO org.apache.hadoop.yarn.server.resourcemanager.rmcontainer.RMContainerImpl: container_1427899242644_0006_01_000003 Container Transitioned from NEW to ALLOCATED
2015-04-01 17:18:32,863 INFO org.apache.hadoop.yarn.server.resourcemanager.RMAuditLogger: USER=echallier	OPERATION=AM Allocated Container	TARGET=SchedulerApp	RESULT=SUCCESS	APPID=application_1427899242644_0006	CONTAINERID=container_1427899242644_0006_01_000003
2015-04-01 17:18:32,863 INFO org.apache.hadoop.yarn.server.resourcemanager.scheduler.SchedulerNode: Assigned container container_1427899242644_0006_01_000003 of capacity <memory:1024, vCores:1> on host a11p2.fil.univ-lille1.fr.:55305, which has 2 containers, <memory:3072, vCores:2> used and <memory:5120, vCores:6> available after allocation
2015-04-01 17:18:32,863 INFO org.apache.hadoop.yarn.server.resourcemanager.scheduler.capacity.LeafQueue: assignedContainer application attempt=appattempt_1427899242644_0006_000001 container=Container: [ContainerId: container_1427899242644_0006_01_000003, NodeId: a11p2.fil.univ-lille1.fr.:55305, NodeHttpAddress: a11p2.fil.univ-lille1.fr.:8042, Resource: <memory:1024, vCores:1>, Priority: 10, Token: null, ] queue=default: capacity=1.0, absoluteCapacity=1.0, usedResources=<memory:2048, vCores:1>, usedCapacity=0.25, absoluteUsedCapacity=0.25, numApps=1, numContainers=1 clusterResource=<memory:8192, vCores:8>
2015-04-01 17:18:32,863 INFO org.apache.hadoop.yarn.server.resourcemanager.scheduler.capacity.ParentQueue: Re-sorting assigned queue: root.default stats: default: capacity=1.0, absoluteCapacity=1.0, usedResources=<memory:3072, vCores:2>, usedCapacity=0.375, absoluteUsedCapacity=0.375, numApps=1, numContainers=2
2015-04-01 17:18:32,863 INFO org.apache.hadoop.yarn.server.resourcemanager.scheduler.capacity.ParentQueue: assignedContainer queue=root usedCapacity=0.375 absoluteUsedCapacity=0.375 used=<memory:3072, vCores:2> cluster=<memory:8192, vCores:8>
2015-04-01 17:18:33,379 INFO org.apache.hadoop.yarn.server.resourcemanager.rmcontainer.RMContainerImpl: container_1427899242644_0006_01_000003 Container Transitioned from ALLOCATED to ACQUIRED
2015-04-01 17:18:33,864 INFO org.apache.hadoop.yarn.server.resourcemanager.rmcontainer.RMContainerImpl: container_1427899242644_0006_01_000003 Container Transitioned from ACQUIRED to RUNNING
2015-04-01 17:18:34,382 INFO org.apache.hadoop.yarn.server.resourcemanager.scheduler.AppSchedulingInfo: checking for deactivate... 
2015-04-01 17:18:36,424 INFO org.apache.hadoop.yarn.server.resourcemanager.rmapp.attempt.RMAppAttemptImpl: Updating application attempt appattempt_1427899242644_0006_000001 with final state: FINISHING, and exit status: -1000
2015-04-01 17:18:36,424 INFO org.apache.hadoop.yarn.server.resourcemanager.rmapp.attempt.RMAppAttemptImpl: appattempt_1427899242644_0006_000001 State change from RUNNING to FINAL_SAVING
2015-04-01 17:18:36,424 INFO org.apache.hadoop.yarn.server.resourcemanager.rmapp.RMAppImpl: Updating application application_1427899242644_0006 with final state: FINISHING
2015-04-01 17:18:36,424 INFO org.apache.hadoop.yarn.server.resourcemanager.rmapp.RMAppImpl: application_1427899242644_0006 State change from RUNNING to FINAL_SAVING
2015-04-01 17:18:36,424 INFO org.apache.hadoop.yarn.server.resourcemanager.recovery.RMStateStore: Updating info for app: application_1427899242644_0006
2015-04-01 17:18:36,425 INFO org.apache.hadoop.yarn.server.resourcemanager.rmapp.attempt.RMAppAttemptImpl: appattempt_1427899242644_0006_000001 State change from FINAL_SAVING to FINISHING
2015-04-01 17:18:36,425 INFO org.apache.hadoop.yarn.server.resourcemanager.rmapp.RMAppImpl: application_1427899242644_0006 State change from FINAL_SAVING to FINISHING
2015-04-01 17:18:37,045 INFO org.apache.hadoop.yarn.server.resourcemanager.rmcontainer.RMContainerImpl: container_1427899242644_0006_01_000003 Container Transitioned from RUNNING to COMPLETED
2015-04-01 17:18:37,045 INFO org.apache.hadoop.yarn.server.resourcemanager.scheduler.common.fica.FiCaSchedulerApp: Completed container: container_1427899242644_0006_01_000003 in state: COMPLETED event:FINISHED
2015-04-01 17:18:37,045 INFO org.apache.hadoop.yarn.server.resourcemanager.RMAuditLogger: USER=echallier	OPERATION=AM Released Container	TARGET=SchedulerApp	RESULT=SUCCESS	APPID=application_1427899242644_0006	CONTAINERID=container_1427899242644_0006_01_000003
2015-04-01 17:18:37,045 INFO org.apache.hadoop.yarn.server.resourcemanager.scheduler.SchedulerNode: Released container container_1427899242644_0006_01_000003 of capacity <memory:1024, vCores:1> on host a11p2.fil.univ-lille1.fr.:55305, which currently has 1 containers, <memory:2048, vCores:1> used and <memory:6144, vCores:7> available, release resources=true
2015-04-01 17:18:37,045 INFO org.apache.hadoop.yarn.server.resourcemanager.scheduler.capacity.LeafQueue: default used=<memory:2048, vCores:1> numContainers=1 user=echallier user-resources=<memory:2048, vCores:1>
2015-04-01 17:18:37,046 INFO org.apache.hadoop.yarn.server.resourcemanager.scheduler.capacity.LeafQueue: completedContainer container=Container: [ContainerId: container_1427899242644_0006_01_000003, NodeId: a11p2.fil.univ-lille1.fr.:55305, NodeHttpAddress: a11p2.fil.univ-lille1.fr.:8042, Resource: <memory:1024, vCores:1>, Priority: 10, Token: Token { kind: ContainerToken, service: 127.0.1.1:55305 }, ] queue=default: capacity=1.0, absoluteCapacity=1.0, usedResources=<memory:2048, vCores:1>, usedCapacity=0.25, absoluteUsedCapacity=0.25, numApps=1, numContainers=1 cluster=<memory:8192, vCores:8>
2015-04-01 17:18:37,046 INFO org.apache.hadoop.yarn.server.resourcemanager.scheduler.capacity.ParentQueue: completedContainer queue=root usedCapacity=0.25 absoluteUsedCapacity=0.25 used=<memory:2048, vCores:1> cluster=<memory:8192, vCores:8>
2015-04-01 17:18:37,046 INFO org.apache.hadoop.yarn.server.resourcemanager.scheduler.capacity.ParentQueue: Re-sorting completed queue: root.default stats: default: capacity=1.0, absoluteCapacity=1.0, usedResources=<memory:2048, vCores:1>, usedCapacity=0.25, absoluteUsedCapacity=0.25, numApps=1, numContainers=1
2015-04-01 17:18:37,046 INFO org.apache.hadoop.yarn.server.resourcemanager.scheduler.capacity.CapacityScheduler: Application attempt appattempt_1427899242644_0006_000001 released container container_1427899242644_0006_01_000003 on node: host: a11p2.fil.univ-lille1.fr.:55305 #containers=1 available=6144 used=2048 with event: FINISHED
2015-04-01 17:18:43,055 INFO org.apache.hadoop.yarn.server.resourcemanager.rmcontainer.RMContainerImpl: container_1427899242644_0006_01_000001 Container Transitioned from RUNNING to COMPLETED
2015-04-01 17:18:43,055 INFO org.apache.hadoop.yarn.server.resourcemanager.ApplicationMasterService: Unregistering app attempt : appattempt_1427899242644_0006_000001
2015-04-01 17:18:43,055 INFO org.apache.hadoop.yarn.server.resourcemanager.scheduler.common.fica.FiCaSchedulerApp: Completed container: container_1427899242644_0006_01_000001 in state: COMPLETED event:FINISHED
2015-04-01 17:18:43,055 INFO org.apache.hadoop.yarn.server.resourcemanager.rmapp.attempt.RMAppAttemptImpl: appattempt_1427899242644_0006_000001 State change from FINISHING to FINISHED
2015-04-01 17:18:43,056 INFO org.apache.hadoop.yarn.server.resourcemanager.RMAuditLogger: USER=echallier	OPERATION=AM Released Container	TARGET=SchedulerApp	RESULT=SUCCESS	APPID=application_1427899242644_0006	CONTAINERID=container_1427899242644_0006_01_000001
2015-04-01 17:18:43,056 INFO org.apache.hadoop.yarn.server.resourcemanager.rmapp.RMAppImpl: application_1427899242644_0006 State change from FINISHING to FINISHED
2015-04-01 17:18:43,056 INFO org.apache.hadoop.yarn.server.resourcemanager.scheduler.SchedulerNode: Released container container_1427899242644_0006_01_000001 of capacity <memory:2048, vCores:1> on host a11p2.fil.univ-lille1.fr.:55305, which currently has 0 containers, <memory:0, vCores:0> used and <memory:8192, vCores:8> available, release resources=true
2015-04-01 17:18:43,056 INFO org.apache.hadoop.yarn.server.resourcemanager.scheduler.capacity.LeafQueue: default used=<memory:0, vCores:0> numContainers=0 user=echallier user-resources=<memory:0, vCores:0>
2015-04-01 17:18:43,056 INFO org.apache.hadoop.yarn.server.resourcemanager.RMAuditLogger: USER=echallier	OPERATION=Application Finished - Succeeded	TARGET=RMAppManager	RESULT=SUCCESS	APPID=application_1427899242644_0006
2015-04-01 17:18:43,056 INFO org.apache.hadoop.yarn.server.resourcemanager.amlauncher.AMLauncher: Cleaning master appattempt_1427899242644_0006_000001
2015-04-01 17:18:43,056 INFO org.apache.hadoop.yarn.server.resourcemanager.scheduler.capacity.LeafQueue: completedContainer container=Container: [ContainerId: container_1427899242644_0006_01_000001, NodeId: a11p2.fil.univ-lille1.fr.:55305, NodeHttpAddress: a11p2.fil.univ-lille1.fr.:8042, Resource: <memory:2048, vCores:1>, Priority: 0, Token: Token { kind: ContainerToken, service: 127.0.1.1:55305 }, ] queue=default: capacity=1.0, absoluteCapacity=1.0, usedResources=<memory:0, vCores:0>, usedCapacity=0.0, absoluteUsedCapacity=0.0, numApps=1, numContainers=0 cluster=<memory:8192, vCores:8>
2015-04-01 17:18:43,056 INFO org.apache.hadoop.yarn.server.resourcemanager.scheduler.capacity.ParentQueue: completedContainer queue=root usedCapacity=0.0 absoluteUsedCapacity=0.0 used=<memory:0, vCores:0> cluster=<memory:8192, vCores:8>
2015-04-01 17:18:43,056 INFO org.apache.hadoop.yarn.server.resourcemanager.scheduler.capacity.ParentQueue: Re-sorting completed queue: root.default stats: default: capacity=1.0, absoluteCapacity=1.0, usedResources=<memory:0, vCores:0>, usedCapacity=0.0, absoluteUsedCapacity=0.0, numApps=1, numContainers=0
2015-04-01 17:18:43,056 INFO org.apache.hadoop.yarn.server.resourcemanager.scheduler.capacity.CapacityScheduler: Application attempt appattempt_1427899242644_0006_000001 released container container_1427899242644_0006_01_000001 on node: host: a11p2.fil.univ-lille1.fr.:55305 #containers=0 available=8192 used=0 with event: FINISHED
2015-04-01 17:18:43,056 INFO org.apache.hadoop.yarn.server.resourcemanager.RMAppManager$ApplicationSummary: appId=application_1427899242644_0006,name=GPS,user=echallier,queue=default,state=FINISHED,trackingUrl=http://a11p2.fil.univ-lille1.fr.:8088/proxy/application_1427899242644_0006/jobhistory/job/job_1427899242644_0006,appMasterHost=a11p2,startTime=1427901503204,finishTime=1427901516424,finalStatus=SUCCEEDED
2015-04-01 17:18:43,057 INFO org.apache.hadoop.yarn.server.resourcemanager.scheduler.capacity.CapacityScheduler: Application Attempt appattempt_1427899242644_0006_000001 is done. finalState=FINISHED
2015-04-01 17:18:43,057 INFO org.apache.hadoop.yarn.server.resourcemanager.scheduler.AppSchedulingInfo: Application application_1427899242644_0006 requests cleared
2015-04-01 17:18:43,057 INFO org.apache.hadoop.yarn.server.resourcemanager.scheduler.capacity.LeafQueue: Application removed - appId: application_1427899242644_0006 user: echallier queue: default #user-pending-applications: 0 #user-active-applications: 0 #queue-pending-applications: 0 #queue-active-applications: 0
2015-04-01 17:18:43,057 INFO org.apache.hadoop.yarn.server.resourcemanager.scheduler.capacity.ParentQueue: Application removed - appId: application_1427899242644_0006 user: echallier leaf-queue of parent: root #applications: 0
2015-04-01 17:20:40,058 INFO org.apache.hadoop.yarn.server.resourcemanager.ClientRMService: Allocated new applicationId: 7
2015-04-01 17:20:40,832 INFO org.apache.hadoop.yarn.server.resourcemanager.ClientRMService: Application with id 7 submitted by user echallier
2015-04-01 17:20:40,832 INFO org.apache.hadoop.yarn.server.resourcemanager.RMAuditLogger: USER=echallier	IP=127.0.0.1	OPERATION=Submit Application Request	TARGET=ClientRMService	RESULT=SUCCESS	APPID=application_1427899242644_0007
2015-04-01 17:20:40,832 INFO org.apache.hadoop.yarn.server.resourcemanager.rmapp.RMAppImpl: Storing application with id application_1427899242644_0007
2015-04-01 17:20:40,833 INFO org.apache.hadoop.yarn.server.resourcemanager.recovery.RMStateStore: Storing info for app: application_1427899242644_0007
2015-04-01 17:20:40,832 INFO org.apache.hadoop.yarn.server.resourcemanager.rmapp.RMAppImpl: application_1427899242644_0007 State change from NEW to NEW_SAVING
2015-04-01 17:20:40,833 INFO org.apache.hadoop.yarn.server.resourcemanager.rmapp.RMAppImpl: application_1427899242644_0007 State change from NEW_SAVING to SUBMITTED
2015-04-01 17:20:40,833 INFO org.apache.hadoop.yarn.server.resourcemanager.scheduler.capacity.ParentQueue: Application added - appId: application_1427899242644_0007 user: echallier leaf-queue of parent: root #applications: 1
2015-04-01 17:20:40,833 INFO org.apache.hadoop.yarn.server.resourcemanager.scheduler.capacity.CapacityScheduler: Accepted application application_1427899242644_0007 from user: echallier, in queue: default
2015-04-01 17:20:40,834 INFO org.apache.hadoop.yarn.server.resourcemanager.rmapp.RMAppImpl: application_1427899242644_0007 State change from SUBMITTED to ACCEPTED
2015-04-01 17:20:40,834 INFO org.apache.hadoop.yarn.server.resourcemanager.ApplicationMasterService: Registering app attempt : appattempt_1427899242644_0007_000001
2015-04-01 17:20:40,834 INFO org.apache.hadoop.yarn.server.resourcemanager.rmapp.attempt.RMAppAttemptImpl: appattempt_1427899242644_0007_000001 State change from NEW to SUBMITTED
2015-04-01 17:20:40,834 INFO org.apache.hadoop.yarn.server.resourcemanager.scheduler.capacity.LeafQueue: Application application_1427899242644_0007 from user: echallier activated in queue: default
2015-04-01 17:20:40,834 INFO org.apache.hadoop.yarn.server.resourcemanager.scheduler.capacity.LeafQueue: Application added - appId: application_1427899242644_0007 user: org.apache.hadoop.yarn.server.resourcemanager.scheduler.capacity.LeafQueue$User@e84b77, leaf-queue: default #user-pending-applications: 0 #user-active-applications: 1 #queue-pending-applications: 0 #queue-active-applications: 1
2015-04-01 17:20:40,834 INFO org.apache.hadoop.yarn.server.resourcemanager.scheduler.capacity.CapacityScheduler: Added Application Attempt appattempt_1427899242644_0007_000001 to scheduler from user echallier in queue default
2015-04-01 17:20:40,834 INFO org.apache.hadoop.yarn.server.resourcemanager.rmapp.attempt.RMAppAttemptImpl: appattempt_1427899242644_0007_000001 State change from SUBMITTED to SCHEDULED
2015-04-01 17:20:41,224 INFO org.apache.hadoop.yarn.server.resourcemanager.rmcontainer.RMContainerImpl: container_1427899242644_0007_01_000001 Container Transitioned from NEW to ALLOCATED
2015-04-01 17:20:41,224 INFO org.apache.hadoop.yarn.server.resourcemanager.RMAuditLogger: USER=echallier	OPERATION=AM Allocated Container	TARGET=SchedulerApp	RESULT=SUCCESS	APPID=application_1427899242644_0007	CONTAINERID=container_1427899242644_0007_01_000001
2015-04-01 17:20:41,224 INFO org.apache.hadoop.yarn.server.resourcemanager.scheduler.SchedulerNode: Assigned container container_1427899242644_0007_01_000001 of capacity <memory:2048, vCores:1> on host a11p2.fil.univ-lille1.fr.:55305, which has 1 containers, <memory:2048, vCores:1> used and <memory:6144, vCores:7> available after allocation
2015-04-01 17:20:41,225 INFO org.apache.hadoop.yarn.server.resourcemanager.scheduler.capacity.LeafQueue: assignedContainer application attempt=appattempt_1427899242644_0007_000001 container=Container: [ContainerId: container_1427899242644_0007_01_000001, NodeId: a11p2.fil.univ-lille1.fr.:55305, NodeHttpAddress: a11p2.fil.univ-lille1.fr.:8042, Resource: <memory:2048, vCores:1>, Priority: 0, Token: null, ] queue=default: capacity=1.0, absoluteCapacity=1.0, usedResources=<memory:0, vCores:0>, usedCapacity=0.0, absoluteUsedCapacity=0.0, numApps=1, numContainers=0 clusterResource=<memory:8192, vCores:8>
2015-04-01 17:20:41,225 INFO org.apache.hadoop.yarn.server.resourcemanager.scheduler.capacity.ParentQueue: Re-sorting assigned queue: root.default stats: default: capacity=1.0, absoluteCapacity=1.0, usedResources=<memory:2048, vCores:1>, usedCapacity=0.25, absoluteUsedCapacity=0.25, numApps=1, numContainers=1
2015-04-01 17:20:41,225 INFO org.apache.hadoop.yarn.server.resourcemanager.scheduler.capacity.ParentQueue: assignedContainer queue=root usedCapacity=0.25 absoluteUsedCapacity=0.25 used=<memory:2048, vCores:1> cluster=<memory:8192, vCores:8>
2015-04-01 17:20:41,225 INFO org.apache.hadoop.yarn.server.resourcemanager.security.NMTokenSecretManagerInRM: Sending NMToken for nodeId : a11p2.fil.univ-lille1.fr.:55305 for container : container_1427899242644_0007_01_000001
2015-04-01 17:20:41,226 INFO org.apache.hadoop.yarn.server.resourcemanager.rmcontainer.RMContainerImpl: container_1427899242644_0007_01_000001 Container Transitioned from ALLOCATED to ACQUIRED
2015-04-01 17:20:41,226 INFO org.apache.hadoop.yarn.server.resourcemanager.security.NMTokenSecretManagerInRM: Clear node set for appattempt_1427899242644_0007_000001
2015-04-01 17:20:41,226 INFO org.apache.hadoop.yarn.server.resourcemanager.rmapp.attempt.RMAppAttemptImpl: Storing attempt: AppId: application_1427899242644_0007 AttemptId: appattempt_1427899242644_0007_000001 MasterContainer: Container: [ContainerId: container_1427899242644_0007_01_000001, NodeId: a11p2.fil.univ-lille1.fr.:55305, NodeHttpAddress: a11p2.fil.univ-lille1.fr.:8042, Resource: <memory:2048, vCores:1>, Priority: 0, Token: Token { kind: ContainerToken, service: 127.0.1.1:55305 }, ]
2015-04-01 17:20:41,226 INFO org.apache.hadoop.yarn.server.resourcemanager.rmapp.attempt.RMAppAttemptImpl: appattempt_1427899242644_0007_000001 State change from SCHEDULED to ALLOCATED_SAVING
2015-04-01 17:20:41,226 INFO org.apache.hadoop.yarn.server.resourcemanager.rmapp.attempt.RMAppAttemptImpl: appattempt_1427899242644_0007_000001 State change from ALLOCATED_SAVING to ALLOCATED
2015-04-01 17:20:41,226 INFO org.apache.hadoop.yarn.server.resourcemanager.amlauncher.AMLauncher: Launching masterappattempt_1427899242644_0007_000001
2015-04-01 17:20:41,228 INFO org.apache.hadoop.yarn.server.resourcemanager.amlauncher.AMLauncher: Setting up container Container: [ContainerId: container_1427899242644_0007_01_000001, NodeId: a11p2.fil.univ-lille1.fr.:55305, NodeHttpAddress: a11p2.fil.univ-lille1.fr.:8042, Resource: <memory:2048, vCores:1>, Priority: 0, Token: Token { kind: ContainerToken, service: 127.0.1.1:55305 }, ] for AM appattempt_1427899242644_0007_000001
2015-04-01 17:20:41,228 INFO org.apache.hadoop.yarn.server.resourcemanager.amlauncher.AMLauncher: Command to launch container container_1427899242644_0007_01_000001 : $JAVA_HOME/bin/java -Dlog4j.configuration=container-log4j.properties -Dyarn.app.container.log.dir=<LOG_DIR> -Dyarn.app.container.log.filesize=0 -Dhadoop.root.logger=INFO,CLA  -Xmx1024m org.apache.hadoop.mapreduce.v2.app.MRAppMaster 1><LOG_DIR>/stdout 2><LOG_DIR>/stderr 
2015-04-01 17:20:41,238 INFO org.apache.hadoop.yarn.server.resourcemanager.amlauncher.AMLauncher: Done launching container Container: [ContainerId: container_1427899242644_0007_01_000001, NodeId: a11p2.fil.univ-lille1.fr.:55305, NodeHttpAddress: a11p2.fil.univ-lille1.fr.:8042, Resource: <memory:2048, vCores:1>, Priority: 0, Token: Token { kind: ContainerToken, service: 127.0.1.1:55305 }, ] for AM appattempt_1427899242644_0007_000001
2015-04-01 17:20:41,239 INFO org.apache.hadoop.yarn.server.resourcemanager.rmapp.attempt.RMAppAttemptImpl: appattempt_1427899242644_0007_000001 State change from ALLOCATED to LAUNCHED
2015-04-01 17:20:42,225 INFO org.apache.hadoop.yarn.server.resourcemanager.rmcontainer.RMContainerImpl: container_1427899242644_0007_01_000001 Container Transitioned from ACQUIRED to RUNNING
2015-04-01 17:20:44,186 INFO SecurityLogger.org.apache.hadoop.ipc.Server: Auth successful for appattempt_1427899242644_0007_000001 (auth:SIMPLE)
2015-04-01 17:20:44,187 INFO org.apache.hadoop.yarn.server.resourcemanager.ApplicationMasterService: AM registration appattempt_1427899242644_0007_000001
2015-04-01 17:20:44,188 INFO org.apache.hadoop.yarn.server.resourcemanager.RMAuditLogger: USER=echallier	IP=127.0.0.1	OPERATION=Register App Master	TARGET=ApplicationMasterService	RESULT=SUCCESS	APPID=application_1427899242644_0007	APPATTEMPTID=appattempt_1427899242644_0007_000001
2015-04-01 17:20:44,188 INFO org.apache.hadoop.yarn.server.resourcemanager.rmapp.attempt.RMAppAttemptImpl: appattempt_1427899242644_0007_000001 State change from LAUNCHED to RUNNING
2015-04-01 17:20:44,188 INFO org.apache.hadoop.yarn.server.resourcemanager.rmapp.RMAppImpl: application_1427899242644_0007 State change from ACCEPTED to RUNNING
2015-04-01 17:20:45,229 INFO org.apache.hadoop.yarn.server.resourcemanager.rmcontainer.RMContainerImpl: container_1427899242644_0007_01_000002 Container Transitioned from NEW to ALLOCATED
2015-04-01 17:20:45,229 INFO org.apache.hadoop.yarn.server.resourcemanager.RMAuditLogger: USER=echallier	OPERATION=AM Allocated Container	TARGET=SchedulerApp	RESULT=SUCCESS	APPID=application_1427899242644_0007	CONTAINERID=container_1427899242644_0007_01_000002
2015-04-01 17:20:45,229 INFO org.apache.hadoop.yarn.server.resourcemanager.scheduler.SchedulerNode: Assigned container container_1427899242644_0007_01_000002 of capacity <memory:1024, vCores:1> on host a11p2.fil.univ-lille1.fr.:55305, which has 2 containers, <memory:3072, vCores:2> used and <memory:5120, vCores:6> available after allocation
2015-04-01 17:20:45,229 INFO org.apache.hadoop.yarn.server.resourcemanager.scheduler.capacity.LeafQueue: assignedContainer application attempt=appattempt_1427899242644_0007_000001 container=Container: [ContainerId: container_1427899242644_0007_01_000002, NodeId: a11p2.fil.univ-lille1.fr.:55305, NodeHttpAddress: a11p2.fil.univ-lille1.fr.:8042, Resource: <memory:1024, vCores:1>, Priority: 20, Token: null, ] queue=default: capacity=1.0, absoluteCapacity=1.0, usedResources=<memory:2048, vCores:1>, usedCapacity=0.25, absoluteUsedCapacity=0.25, numApps=1, numContainers=1 clusterResource=<memory:8192, vCores:8>
2015-04-01 17:20:45,229 INFO org.apache.hadoop.yarn.server.resourcemanager.scheduler.capacity.ParentQueue: Re-sorting assigned queue: root.default stats: default: capacity=1.0, absoluteCapacity=1.0, usedResources=<memory:3072, vCores:2>, usedCapacity=0.375, absoluteUsedCapacity=0.375, numApps=1, numContainers=2
2015-04-01 17:20:45,229 INFO org.apache.hadoop.yarn.server.resourcemanager.scheduler.capacity.ParentQueue: assignedContainer queue=root usedCapacity=0.375 absoluteUsedCapacity=0.375 used=<memory:3072, vCores:2> cluster=<memory:8192, vCores:8>
2015-04-01 17:20:46,244 INFO org.apache.hadoop.yarn.server.resourcemanager.security.NMTokenSecretManagerInRM: Sending NMToken for nodeId : a11p2.fil.univ-lille1.fr.:55305 for container : container_1427899242644_0007_01_000002
2015-04-01 17:20:46,245 INFO org.apache.hadoop.yarn.server.resourcemanager.rmcontainer.RMContainerImpl: container_1427899242644_0007_01_000002 Container Transitioned from ALLOCATED to ACQUIRED
2015-04-01 17:20:47,231 INFO org.apache.hadoop.yarn.server.resourcemanager.rmcontainer.RMContainerImpl: container_1427899242644_0007_01_000002 Container Transitioned from ACQUIRED to RUNNING
2015-04-01 17:20:47,260 INFO org.apache.hadoop.yarn.server.resourcemanager.scheduler.AppSchedulingInfo: checking for deactivate... 
2015-04-01 17:20:49,930 INFO org.apache.hadoop.yarn.server.resourcemanager.rmcontainer.RMContainerImpl: container_1427899242644_0007_01_000002 Container Transitioned from RUNNING to COMPLETED
2015-04-01 17:20:49,930 INFO org.apache.hadoop.yarn.server.resourcemanager.scheduler.common.fica.FiCaSchedulerApp: Completed container: container_1427899242644_0007_01_000002 in state: COMPLETED event:FINISHED
2015-04-01 17:20:49,930 INFO org.apache.hadoop.yarn.server.resourcemanager.RMAuditLogger: USER=echallier	OPERATION=AM Released Container	TARGET=SchedulerApp	RESULT=SUCCESS	APPID=application_1427899242644_0007	CONTAINERID=container_1427899242644_0007_01_000002
2015-04-01 17:20:49,930 INFO org.apache.hadoop.yarn.server.resourcemanager.scheduler.SchedulerNode: Released container container_1427899242644_0007_01_000002 of capacity <memory:1024, vCores:1> on host a11p2.fil.univ-lille1.fr.:55305, which currently has 1 containers, <memory:2048, vCores:1> used and <memory:6144, vCores:7> available, release resources=true
2015-04-01 17:20:49,931 INFO org.apache.hadoop.yarn.server.resourcemanager.scheduler.capacity.LeafQueue: default used=<memory:2048, vCores:1> numContainers=1 user=echallier user-resources=<memory:2048, vCores:1>
2015-04-01 17:20:49,932 INFO org.apache.hadoop.yarn.server.resourcemanager.scheduler.capacity.LeafQueue: completedContainer container=Container: [ContainerId: container_1427899242644_0007_01_000002, NodeId: a11p2.fil.univ-lille1.fr.:55305, NodeHttpAddress: a11p2.fil.univ-lille1.fr.:8042, Resource: <memory:1024, vCores:1>, Priority: 20, Token: Token { kind: ContainerToken, service: 127.0.1.1:55305 }, ] queue=default: capacity=1.0, absoluteCapacity=1.0, usedResources=<memory:2048, vCores:1>, usedCapacity=0.25, absoluteUsedCapacity=0.25, numApps=1, numContainers=1 cluster=<memory:8192, vCores:8>
2015-04-01 17:20:49,932 INFO org.apache.hadoop.yarn.server.resourcemanager.scheduler.capacity.ParentQueue: completedContainer queue=root usedCapacity=0.25 absoluteUsedCapacity=0.25 used=<memory:2048, vCores:1> cluster=<memory:8192, vCores:8>
2015-04-01 17:20:49,932 INFO org.apache.hadoop.yarn.server.resourcemanager.scheduler.capacity.ParentQueue: Re-sorting completed queue: root.default stats: default: capacity=1.0, absoluteCapacity=1.0, usedResources=<memory:2048, vCores:1>, usedCapacity=0.25, absoluteUsedCapacity=0.25, numApps=1, numContainers=1
2015-04-01 17:20:49,932 INFO org.apache.hadoop.yarn.server.resourcemanager.scheduler.capacity.CapacityScheduler: Application attempt appattempt_1427899242644_0007_000001 released container container_1427899242644_0007_01_000002 on node: host: a11p2.fil.univ-lille1.fr.:55305 #containers=1 available=6144 used=2048 with event: FINISHED
2015-04-01 17:20:50,932 INFO org.apache.hadoop.yarn.server.resourcemanager.rmcontainer.RMContainerImpl: container_1427899242644_0007_01_000003 Container Transitioned from NEW to ALLOCATED
2015-04-01 17:20:50,932 INFO org.apache.hadoop.yarn.server.resourcemanager.RMAuditLogger: USER=echallier	OPERATION=AM Allocated Container	TARGET=SchedulerApp	RESULT=SUCCESS	APPID=application_1427899242644_0007	CONTAINERID=container_1427899242644_0007_01_000003
2015-04-01 17:20:50,932 INFO org.apache.hadoop.yarn.server.resourcemanager.scheduler.SchedulerNode: Assigned container container_1427899242644_0007_01_000003 of capacity <memory:1024, vCores:1> on host a11p2.fil.univ-lille1.fr.:55305, which has 2 containers, <memory:3072, vCores:2> used and <memory:5120, vCores:6> available after allocation
2015-04-01 17:20:50,932 INFO org.apache.hadoop.yarn.server.resourcemanager.scheduler.capacity.LeafQueue: assignedContainer application attempt=appattempt_1427899242644_0007_000001 container=Container: [ContainerId: container_1427899242644_0007_01_000003, NodeId: a11p2.fil.univ-lille1.fr.:55305, NodeHttpAddress: a11p2.fil.univ-lille1.fr.:8042, Resource: <memory:1024, vCores:1>, Priority: 10, Token: null, ] queue=default: capacity=1.0, absoluteCapacity=1.0, usedResources=<memory:2048, vCores:1>, usedCapacity=0.25, absoluteUsedCapacity=0.25, numApps=1, numContainers=1 clusterResource=<memory:8192, vCores:8>
2015-04-01 17:20:50,933 INFO org.apache.hadoop.yarn.server.resourcemanager.scheduler.capacity.ParentQueue: Re-sorting assigned queue: root.default stats: default: capacity=1.0, absoluteCapacity=1.0, usedResources=<memory:3072, vCores:2>, usedCapacity=0.375, absoluteUsedCapacity=0.375, numApps=1, numContainers=2
2015-04-01 17:20:50,933 INFO org.apache.hadoop.yarn.server.resourcemanager.scheduler.capacity.ParentQueue: assignedContainer queue=root usedCapacity=0.375 absoluteUsedCapacity=0.375 used=<memory:3072, vCores:2> cluster=<memory:8192, vCores:8>
2015-04-01 17:20:51,275 INFO org.apache.hadoop.yarn.server.resourcemanager.rmcontainer.RMContainerImpl: container_1427899242644_0007_01_000003 Container Transitioned from ALLOCATED to ACQUIRED
2015-04-01 17:20:51,933 INFO org.apache.hadoop.yarn.server.resourcemanager.rmcontainer.RMContainerImpl: container_1427899242644_0007_01_000003 Container Transitioned from ACQUIRED to RUNNING
2015-04-01 17:20:52,279 INFO org.apache.hadoop.yarn.server.resourcemanager.scheduler.AppSchedulingInfo: checking for deactivate... 
2015-04-01 17:20:54,092 INFO org.apache.hadoop.yarn.server.resourcemanager.rmapp.attempt.RMAppAttemptImpl: Updating application attempt appattempt_1427899242644_0007_000001 with final state: FINISHING, and exit status: -1000
2015-04-01 17:20:54,092 INFO org.apache.hadoop.yarn.server.resourcemanager.rmapp.attempt.RMAppAttemptImpl: appattempt_1427899242644_0007_000001 State change from RUNNING to FINAL_SAVING
2015-04-01 17:20:54,092 INFO org.apache.hadoop.yarn.server.resourcemanager.rmapp.RMAppImpl: Updating application application_1427899242644_0007 with final state: FINISHING
2015-04-01 17:20:54,092 INFO org.apache.hadoop.yarn.server.resourcemanager.rmapp.RMAppImpl: application_1427899242644_0007 State change from RUNNING to FINAL_SAVING
2015-04-01 17:20:54,092 INFO org.apache.hadoop.yarn.server.resourcemanager.recovery.RMStateStore: Updating info for app: application_1427899242644_0007
2015-04-01 17:20:54,092 INFO org.apache.hadoop.yarn.server.resourcemanager.rmapp.attempt.RMAppAttemptImpl: appattempt_1427899242644_0007_000001 State change from FINAL_SAVING to FINISHING
2015-04-01 17:20:54,092 INFO org.apache.hadoop.yarn.server.resourcemanager.rmapp.RMAppImpl: application_1427899242644_0007 State change from FINAL_SAVING to FINISHING
2015-04-01 17:20:54,740 INFO org.apache.hadoop.yarn.server.resourcemanager.rmcontainer.RMContainerImpl: container_1427899242644_0007_01_000003 Container Transitioned from RUNNING to COMPLETED
2015-04-01 17:20:54,740 INFO org.apache.hadoop.yarn.server.resourcemanager.scheduler.common.fica.FiCaSchedulerApp: Completed container: container_1427899242644_0007_01_000003 in state: COMPLETED event:FINISHED
2015-04-01 17:20:54,740 INFO org.apache.hadoop.yarn.server.resourcemanager.RMAuditLogger: USER=echallier	OPERATION=AM Released Container	TARGET=SchedulerApp	RESULT=SUCCESS	APPID=application_1427899242644_0007	CONTAINERID=container_1427899242644_0007_01_000003
2015-04-01 17:20:54,740 INFO org.apache.hadoop.yarn.server.resourcemanager.scheduler.SchedulerNode: Released container container_1427899242644_0007_01_000003 of capacity <memory:1024, vCores:1> on host a11p2.fil.univ-lille1.fr.:55305, which currently has 1 containers, <memory:2048, vCores:1> used and <memory:6144, vCores:7> available, release resources=true
2015-04-01 17:20:54,740 INFO org.apache.hadoop.yarn.server.resourcemanager.scheduler.capacity.LeafQueue: default used=<memory:2048, vCores:1> numContainers=1 user=echallier user-resources=<memory:2048, vCores:1>
2015-04-01 17:20:54,740 INFO org.apache.hadoop.yarn.server.resourcemanager.scheduler.capacity.LeafQueue: completedContainer container=Container: [ContainerId: container_1427899242644_0007_01_000003, NodeId: a11p2.fil.univ-lille1.fr.:55305, NodeHttpAddress: a11p2.fil.univ-lille1.fr.:8042, Resource: <memory:1024, vCores:1>, Priority: 10, Token: Token { kind: ContainerToken, service: 127.0.1.1:55305 }, ] queue=default: capacity=1.0, absoluteCapacity=1.0, usedResources=<memory:2048, vCores:1>, usedCapacity=0.25, absoluteUsedCapacity=0.25, numApps=1, numContainers=1 cluster=<memory:8192, vCores:8>
2015-04-01 17:20:54,741 INFO org.apache.hadoop.yarn.server.resourcemanager.scheduler.capacity.ParentQueue: completedContainer queue=root usedCapacity=0.25 absoluteUsedCapacity=0.25 used=<memory:2048, vCores:1> cluster=<memory:8192, vCores:8>
2015-04-01 17:20:54,741 INFO org.apache.hadoop.yarn.server.resourcemanager.scheduler.capacity.ParentQueue: Re-sorting completed queue: root.default stats: default: capacity=1.0, absoluteCapacity=1.0, usedResources=<memory:2048, vCores:1>, usedCapacity=0.25, absoluteUsedCapacity=0.25, numApps=1, numContainers=1
2015-04-01 17:20:54,741 INFO org.apache.hadoop.yarn.server.resourcemanager.scheduler.capacity.CapacityScheduler: Application attempt appattempt_1427899242644_0007_000001 released container container_1427899242644_0007_01_000003 on node: host: a11p2.fil.univ-lille1.fr.:55305 #containers=1 available=6144 used=2048 with event: FINISHED
2015-04-01 17:21:00,749 INFO org.apache.hadoop.yarn.server.resourcemanager.rmcontainer.RMContainerImpl: container_1427899242644_0007_01_000001 Container Transitioned from RUNNING to COMPLETED
2015-04-01 17:21:00,749 INFO org.apache.hadoop.yarn.server.resourcemanager.ApplicationMasterService: Unregistering app attempt : appattempt_1427899242644_0007_000001
2015-04-01 17:21:00,750 INFO org.apache.hadoop.yarn.server.resourcemanager.scheduler.common.fica.FiCaSchedulerApp: Completed container: container_1427899242644_0007_01_000001 in state: COMPLETED event:FINISHED
2015-04-01 17:21:00,750 INFO org.apache.hadoop.yarn.server.resourcemanager.rmapp.attempt.RMAppAttemptImpl: appattempt_1427899242644_0007_000001 State change from FINISHING to FINISHED
2015-04-01 17:21:00,750 INFO org.apache.hadoop.yarn.server.resourcemanager.RMAuditLogger: USER=echallier	OPERATION=AM Released Container	TARGET=SchedulerApp	RESULT=SUCCESS	APPID=application_1427899242644_0007	CONTAINERID=container_1427899242644_0007_01_000001
2015-04-01 17:21:00,750 INFO org.apache.hadoop.yarn.server.resourcemanager.rmapp.RMAppImpl: application_1427899242644_0007 State change from FINISHING to FINISHED
2015-04-01 17:21:00,750 INFO org.apache.hadoop.yarn.server.resourcemanager.scheduler.SchedulerNode: Released container container_1427899242644_0007_01_000001 of capacity <memory:2048, vCores:1> on host a11p2.fil.univ-lille1.fr.:55305, which currently has 0 containers, <memory:0, vCores:0> used and <memory:8192, vCores:8> available, release resources=true
2015-04-01 17:21:00,750 INFO org.apache.hadoop.yarn.server.resourcemanager.scheduler.capacity.LeafQueue: default used=<memory:0, vCores:0> numContainers=0 user=echallier user-resources=<memory:0, vCores:0>
2015-04-01 17:21:00,751 INFO org.apache.hadoop.yarn.server.resourcemanager.RMAuditLogger: USER=echallier	OPERATION=Application Finished - Succeeded	TARGET=RMAppManager	RESULT=SUCCESS	APPID=application_1427899242644_0007
2015-04-01 17:21:00,751 INFO org.apache.hadoop.yarn.server.resourcemanager.amlauncher.AMLauncher: Cleaning master appattempt_1427899242644_0007_000001
2015-04-01 17:21:00,751 INFO org.apache.hadoop.yarn.server.resourcemanager.scheduler.capacity.LeafQueue: completedContainer container=Container: [ContainerId: container_1427899242644_0007_01_000001, NodeId: a11p2.fil.univ-lille1.fr.:55305, NodeHttpAddress: a11p2.fil.univ-lille1.fr.:8042, Resource: <memory:2048, vCores:1>, Priority: 0, Token: Token { kind: ContainerToken, service: 127.0.1.1:55305 }, ] queue=default: capacity=1.0, absoluteCapacity=1.0, usedResources=<memory:0, vCores:0>, usedCapacity=0.0, absoluteUsedCapacity=0.0, numApps=1, numContainers=0 cluster=<memory:8192, vCores:8>
2015-04-01 17:21:00,751 INFO org.apache.hadoop.yarn.server.resourcemanager.scheduler.capacity.ParentQueue: completedContainer queue=root usedCapacity=0.0 absoluteUsedCapacity=0.0 used=<memory:0, vCores:0> cluster=<memory:8192, vCores:8>
2015-04-01 17:21:00,751 INFO org.apache.hadoop.yarn.server.resourcemanager.scheduler.capacity.ParentQueue: Re-sorting completed queue: root.default stats: default: capacity=1.0, absoluteCapacity=1.0, usedResources=<memory:0, vCores:0>, usedCapacity=0.0, absoluteUsedCapacity=0.0, numApps=1, numContainers=0
2015-04-01 17:21:00,751 INFO org.apache.hadoop.yarn.server.resourcemanager.scheduler.capacity.CapacityScheduler: Application attempt appattempt_1427899242644_0007_000001 released container container_1427899242644_0007_01_000001 on node: host: a11p2.fil.univ-lille1.fr.:55305 #containers=0 available=8192 used=0 with event: FINISHED
2015-04-01 17:21:00,751 INFO org.apache.hadoop.yarn.server.resourcemanager.RMAppManager$ApplicationSummary: appId=application_1427899242644_0007,name=GPS,user=echallier,queue=default,state=FINISHED,trackingUrl=http://a11p2.fil.univ-lille1.fr.:8088/proxy/application_1427899242644_0007/jobhistory/job/job_1427899242644_0007,appMasterHost=a11p2,startTime=1427901640832,finishTime=1427901654092,finalStatus=SUCCEEDED
2015-04-01 17:21:00,751 INFO org.apache.hadoop.yarn.server.resourcemanager.scheduler.capacity.CapacityScheduler: Application Attempt appattempt_1427899242644_0007_000001 is done. finalState=FINISHED
2015-04-01 17:21:00,751 INFO org.apache.hadoop.yarn.server.resourcemanager.scheduler.AppSchedulingInfo: Application application_1427899242644_0007 requests cleared
2015-04-01 17:21:00,752 INFO org.apache.hadoop.yarn.server.resourcemanager.scheduler.capacity.LeafQueue: Application removed - appId: application_1427899242644_0007 user: echallier queue: default #user-pending-applications: 0 #user-active-applications: 0 #queue-pending-applications: 0 #queue-active-applications: 0
2015-04-01 17:21:00,752 INFO org.apache.hadoop.yarn.server.resourcemanager.scheduler.capacity.ParentQueue: Application removed - appId: application_1427899242644_0007 user: echallier leaf-queue of parent: root #applications: 0
2015-04-01 17:28:54,651 INFO org.apache.hadoop.yarn.server.resourcemanager.ClientRMService: Allocated new applicationId: 8
2015-04-01 17:28:55,489 INFO org.apache.hadoop.yarn.server.resourcemanager.ClientRMService: Application with id 8 submitted by user echallier
2015-04-01 17:28:55,489 INFO org.apache.hadoop.yarn.server.resourcemanager.rmapp.RMAppImpl: Storing application with id application_1427899242644_0008
2015-04-01 17:28:55,489 INFO org.apache.hadoop.yarn.server.resourcemanager.rmapp.RMAppImpl: application_1427899242644_0008 State change from NEW to NEW_SAVING
2015-04-01 17:28:55,489 INFO org.apache.hadoop.yarn.server.resourcemanager.RMAuditLogger: USER=echallier	IP=127.0.0.1	OPERATION=Submit Application Request	TARGET=ClientRMService	RESULT=SUCCESS	APPID=application_1427899242644_0008
2015-04-01 17:28:55,489 INFO org.apache.hadoop.yarn.server.resourcemanager.recovery.RMStateStore: Storing info for app: application_1427899242644_0008
2015-04-01 17:28:55,489 INFO org.apache.hadoop.yarn.server.resourcemanager.rmapp.RMAppImpl: application_1427899242644_0008 State change from NEW_SAVING to SUBMITTED
2015-04-01 17:28:55,489 INFO org.apache.hadoop.yarn.server.resourcemanager.scheduler.capacity.ParentQueue: Application added - appId: application_1427899242644_0008 user: echallier leaf-queue of parent: root #applications: 1
2015-04-01 17:28:55,490 INFO org.apache.hadoop.yarn.server.resourcemanager.scheduler.capacity.CapacityScheduler: Accepted application application_1427899242644_0008 from user: echallier, in queue: default
2015-04-01 17:28:55,490 INFO org.apache.hadoop.yarn.server.resourcemanager.rmapp.RMAppImpl: application_1427899242644_0008 State change from SUBMITTED to ACCEPTED
2015-04-01 17:28:55,490 INFO org.apache.hadoop.yarn.server.resourcemanager.ApplicationMasterService: Registering app attempt : appattempt_1427899242644_0008_000001
2015-04-01 17:28:55,490 INFO org.apache.hadoop.yarn.server.resourcemanager.rmapp.attempt.RMAppAttemptImpl: appattempt_1427899242644_0008_000001 State change from NEW to SUBMITTED
2015-04-01 17:28:55,490 INFO org.apache.hadoop.yarn.server.resourcemanager.scheduler.capacity.LeafQueue: Application application_1427899242644_0008 from user: echallier activated in queue: default
2015-04-01 17:28:55,490 INFO org.apache.hadoop.yarn.server.resourcemanager.scheduler.capacity.LeafQueue: Application added - appId: application_1427899242644_0008 user: org.apache.hadoop.yarn.server.resourcemanager.scheduler.capacity.LeafQueue$User@c8b8ac, leaf-queue: default #user-pending-applications: 0 #user-active-applications: 1 #queue-pending-applications: 0 #queue-active-applications: 1
2015-04-01 17:28:55,490 INFO org.apache.hadoop.yarn.server.resourcemanager.scheduler.capacity.CapacityScheduler: Added Application Attempt appattempt_1427899242644_0008_000001 to scheduler from user echallier in queue default
2015-04-01 17:28:55,490 INFO org.apache.hadoop.yarn.server.resourcemanager.rmapp.attempt.RMAppAttemptImpl: appattempt_1427899242644_0008_000001 State change from SUBMITTED to SCHEDULED
2015-04-01 17:28:56,435 INFO org.apache.hadoop.yarn.server.resourcemanager.rmcontainer.RMContainerImpl: container_1427899242644_0008_01_000001 Container Transitioned from NEW to ALLOCATED
2015-04-01 17:28:56,435 INFO org.apache.hadoop.yarn.server.resourcemanager.RMAuditLogger: USER=echallier	OPERATION=AM Allocated Container	TARGET=SchedulerApp	RESULT=SUCCESS	APPID=application_1427899242644_0008	CONTAINERID=container_1427899242644_0008_01_000001
2015-04-01 17:28:56,435 INFO org.apache.hadoop.yarn.server.resourcemanager.scheduler.SchedulerNode: Assigned container container_1427899242644_0008_01_000001 of capacity <memory:2048, vCores:1> on host a11p2.fil.univ-lille1.fr.:55305, which has 1 containers, <memory:2048, vCores:1> used and <memory:6144, vCores:7> available after allocation
2015-04-01 17:28:56,435 INFO org.apache.hadoop.yarn.server.resourcemanager.scheduler.capacity.LeafQueue: assignedContainer application attempt=appattempt_1427899242644_0008_000001 container=Container: [ContainerId: container_1427899242644_0008_01_000001, NodeId: a11p2.fil.univ-lille1.fr.:55305, NodeHttpAddress: a11p2.fil.univ-lille1.fr.:8042, Resource: <memory:2048, vCores:1>, Priority: 0, Token: null, ] queue=default: capacity=1.0, absoluteCapacity=1.0, usedResources=<memory:0, vCores:0>, usedCapacity=0.0, absoluteUsedCapacity=0.0, numApps=1, numContainers=0 clusterResource=<memory:8192, vCores:8>
2015-04-01 17:28:56,435 INFO org.apache.hadoop.yarn.server.resourcemanager.scheduler.capacity.ParentQueue: Re-sorting assigned queue: root.default stats: default: capacity=1.0, absoluteCapacity=1.0, usedResources=<memory:2048, vCores:1>, usedCapacity=0.25, absoluteUsedCapacity=0.25, numApps=1, numContainers=1
2015-04-01 17:28:56,436 INFO org.apache.hadoop.yarn.server.resourcemanager.scheduler.capacity.ParentQueue: assignedContainer queue=root usedCapacity=0.25 absoluteUsedCapacity=0.25 used=<memory:2048, vCores:1> cluster=<memory:8192, vCores:8>
2015-04-01 17:28:56,436 INFO org.apache.hadoop.yarn.server.resourcemanager.security.NMTokenSecretManagerInRM: Sending NMToken for nodeId : a11p2.fil.univ-lille1.fr.:55305 for container : container_1427899242644_0008_01_000001
2015-04-01 17:28:56,436 INFO org.apache.hadoop.yarn.server.resourcemanager.rmcontainer.RMContainerImpl: container_1427899242644_0008_01_000001 Container Transitioned from ALLOCATED to ACQUIRED
2015-04-01 17:28:56,437 INFO org.apache.hadoop.yarn.server.resourcemanager.security.NMTokenSecretManagerInRM: Clear node set for appattempt_1427899242644_0008_000001
2015-04-01 17:28:56,437 INFO org.apache.hadoop.yarn.server.resourcemanager.rmapp.attempt.RMAppAttemptImpl: Storing attempt: AppId: application_1427899242644_0008 AttemptId: appattempt_1427899242644_0008_000001 MasterContainer: Container: [ContainerId: container_1427899242644_0008_01_000001, NodeId: a11p2.fil.univ-lille1.fr.:55305, NodeHttpAddress: a11p2.fil.univ-lille1.fr.:8042, Resource: <memory:2048, vCores:1>, Priority: 0, Token: Token { kind: ContainerToken, service: 127.0.1.1:55305 }, ]
2015-04-01 17:28:56,437 INFO org.apache.hadoop.yarn.server.resourcemanager.rmapp.attempt.RMAppAttemptImpl: appattempt_1427899242644_0008_000001 State change from SCHEDULED to ALLOCATED_SAVING
2015-04-01 17:28:56,437 INFO org.apache.hadoop.yarn.server.resourcemanager.rmapp.attempt.RMAppAttemptImpl: appattempt_1427899242644_0008_000001 State change from ALLOCATED_SAVING to ALLOCATED
2015-04-01 17:28:56,437 INFO org.apache.hadoop.yarn.server.resourcemanager.amlauncher.AMLauncher: Launching masterappattempt_1427899242644_0008_000001
2015-04-01 17:28:56,438 INFO org.apache.hadoop.yarn.server.resourcemanager.amlauncher.AMLauncher: Setting up container Container: [ContainerId: container_1427899242644_0008_01_000001, NodeId: a11p2.fil.univ-lille1.fr.:55305, NodeHttpAddress: a11p2.fil.univ-lille1.fr.:8042, Resource: <memory:2048, vCores:1>, Priority: 0, Token: Token { kind: ContainerToken, service: 127.0.1.1:55305 }, ] for AM appattempt_1427899242644_0008_000001
2015-04-01 17:28:56,439 INFO org.apache.hadoop.yarn.server.resourcemanager.amlauncher.AMLauncher: Command to launch container container_1427899242644_0008_01_000001 : $JAVA_HOME/bin/java -Dlog4j.configuration=container-log4j.properties -Dyarn.app.container.log.dir=<LOG_DIR> -Dyarn.app.container.log.filesize=0 -Dhadoop.root.logger=INFO,CLA  -Xmx1024m org.apache.hadoop.mapreduce.v2.app.MRAppMaster 1><LOG_DIR>/stdout 2><LOG_DIR>/stderr 
2015-04-01 17:28:56,450 INFO org.apache.hadoop.yarn.server.resourcemanager.amlauncher.AMLauncher: Done launching container Container: [ContainerId: container_1427899242644_0008_01_000001, NodeId: a11p2.fil.univ-lille1.fr.:55305, NodeHttpAddress: a11p2.fil.univ-lille1.fr.:8042, Resource: <memory:2048, vCores:1>, Priority: 0, Token: Token { kind: ContainerToken, service: 127.0.1.1:55305 }, ] for AM appattempt_1427899242644_0008_000001
2015-04-01 17:28:56,451 INFO org.apache.hadoop.yarn.server.resourcemanager.rmapp.attempt.RMAppAttemptImpl: appattempt_1427899242644_0008_000001 State change from ALLOCATED to LAUNCHED
2015-04-01 17:28:57,436 INFO org.apache.hadoop.yarn.server.resourcemanager.rmcontainer.RMContainerImpl: container_1427899242644_0008_01_000001 Container Transitioned from ACQUIRED to RUNNING
2015-04-01 17:28:59,295 INFO SecurityLogger.org.apache.hadoop.ipc.Server: Auth successful for appattempt_1427899242644_0008_000001 (auth:SIMPLE)
2015-04-01 17:28:59,297 INFO org.apache.hadoop.yarn.server.resourcemanager.ApplicationMasterService: AM registration appattempt_1427899242644_0008_000001
2015-04-01 17:28:59,297 INFO org.apache.hadoop.yarn.server.resourcemanager.RMAuditLogger: USER=echallier	IP=127.0.0.1	OPERATION=Register App Master	TARGET=ApplicationMasterService	RESULT=SUCCESS	APPID=application_1427899242644_0008	APPATTEMPTID=appattempt_1427899242644_0008_000001
2015-04-01 17:28:59,297 INFO org.apache.hadoop.yarn.server.resourcemanager.rmapp.attempt.RMAppAttemptImpl: appattempt_1427899242644_0008_000001 State change from LAUNCHED to RUNNING
2015-04-01 17:28:59,297 INFO org.apache.hadoop.yarn.server.resourcemanager.rmapp.RMAppImpl: application_1427899242644_0008 State change from ACCEPTED to RUNNING
2015-04-01 17:29:00,440 INFO org.apache.hadoop.yarn.server.resourcemanager.rmcontainer.RMContainerImpl: container_1427899242644_0008_01_000002 Container Transitioned from NEW to ALLOCATED
2015-04-01 17:29:00,440 INFO org.apache.hadoop.yarn.server.resourcemanager.RMAuditLogger: USER=echallier	OPERATION=AM Allocated Container	TARGET=SchedulerApp	RESULT=SUCCESS	APPID=application_1427899242644_0008	CONTAINERID=container_1427899242644_0008_01_000002
2015-04-01 17:29:00,440 INFO org.apache.hadoop.yarn.server.resourcemanager.scheduler.SchedulerNode: Assigned container container_1427899242644_0008_01_000002 of capacity <memory:1024, vCores:1> on host a11p2.fil.univ-lille1.fr.:55305, which has 2 containers, <memory:3072, vCores:2> used and <memory:5120, vCores:6> available after allocation
2015-04-01 17:29:00,440 INFO org.apache.hadoop.yarn.server.resourcemanager.scheduler.capacity.LeafQueue: assignedContainer application attempt=appattempt_1427899242644_0008_000001 container=Container: [ContainerId: container_1427899242644_0008_01_000002, NodeId: a11p2.fil.univ-lille1.fr.:55305, NodeHttpAddress: a11p2.fil.univ-lille1.fr.:8042, Resource: <memory:1024, vCores:1>, Priority: 20, Token: null, ] queue=default: capacity=1.0, absoluteCapacity=1.0, usedResources=<memory:2048, vCores:1>, usedCapacity=0.25, absoluteUsedCapacity=0.25, numApps=1, numContainers=1 clusterResource=<memory:8192, vCores:8>
2015-04-01 17:29:00,440 INFO org.apache.hadoop.yarn.server.resourcemanager.scheduler.capacity.ParentQueue: Re-sorting assigned queue: root.default stats: default: capacity=1.0, absoluteCapacity=1.0, usedResources=<memory:3072, vCores:2>, usedCapacity=0.375, absoluteUsedCapacity=0.375, numApps=1, numContainers=2
2015-04-01 17:29:00,440 INFO org.apache.hadoop.yarn.server.resourcemanager.scheduler.capacity.ParentQueue: assignedContainer queue=root usedCapacity=0.375 absoluteUsedCapacity=0.375 used=<memory:3072, vCores:2> cluster=<memory:8192, vCores:8>
2015-04-01 17:29:01,350 INFO org.apache.hadoop.yarn.server.resourcemanager.security.NMTokenSecretManagerInRM: Sending NMToken for nodeId : a11p2.fil.univ-lille1.fr.:55305 for container : container_1427899242644_0008_01_000002
2015-04-01 17:29:01,350 INFO org.apache.hadoop.yarn.server.resourcemanager.rmcontainer.RMContainerImpl: container_1427899242644_0008_01_000002 Container Transitioned from ALLOCATED to ACQUIRED
2015-04-01 17:29:02,359 INFO org.apache.hadoop.yarn.server.resourcemanager.scheduler.AppSchedulingInfo: checking for deactivate... 
2015-04-01 17:29:02,442 INFO org.apache.hadoop.yarn.server.resourcemanager.rmcontainer.RMContainerImpl: container_1427899242644_0008_01_000002 Container Transitioned from ACQUIRED to RUNNING
2015-04-01 17:29:04,766 INFO org.apache.hadoop.yarn.server.resourcemanager.rmcontainer.RMContainerImpl: container_1427899242644_0008_01_000002 Container Transitioned from RUNNING to COMPLETED
2015-04-01 17:29:04,766 INFO org.apache.hadoop.yarn.server.resourcemanager.scheduler.common.fica.FiCaSchedulerApp: Completed container: container_1427899242644_0008_01_000002 in state: COMPLETED event:FINISHED
2015-04-01 17:29:04,766 INFO org.apache.hadoop.yarn.server.resourcemanager.RMAuditLogger: USER=echallier	OPERATION=AM Released Container	TARGET=SchedulerApp	RESULT=SUCCESS	APPID=application_1427899242644_0008	CONTAINERID=container_1427899242644_0008_01_000002
2015-04-01 17:29:04,766 INFO org.apache.hadoop.yarn.server.resourcemanager.scheduler.SchedulerNode: Released container container_1427899242644_0008_01_000002 of capacity <memory:1024, vCores:1> on host a11p2.fil.univ-lille1.fr.:55305, which currently has 1 containers, <memory:2048, vCores:1> used and <memory:6144, vCores:7> available, release resources=true
2015-04-01 17:29:04,766 INFO org.apache.hadoop.yarn.server.resourcemanager.scheduler.capacity.LeafQueue: default used=<memory:2048, vCores:1> numContainers=1 user=echallier user-resources=<memory:2048, vCores:1>
2015-04-01 17:29:04,767 INFO org.apache.hadoop.yarn.server.resourcemanager.scheduler.capacity.LeafQueue: completedContainer container=Container: [ContainerId: container_1427899242644_0008_01_000002, NodeId: a11p2.fil.univ-lille1.fr.:55305, NodeHttpAddress: a11p2.fil.univ-lille1.fr.:8042, Resource: <memory:1024, vCores:1>, Priority: 20, Token: Token { kind: ContainerToken, service: 127.0.1.1:55305 }, ] queue=default: capacity=1.0, absoluteCapacity=1.0, usedResources=<memory:2048, vCores:1>, usedCapacity=0.25, absoluteUsedCapacity=0.25, numApps=1, numContainers=1 cluster=<memory:8192, vCores:8>
2015-04-01 17:29:04,767 INFO org.apache.hadoop.yarn.server.resourcemanager.scheduler.capacity.ParentQueue: completedContainer queue=root usedCapacity=0.25 absoluteUsedCapacity=0.25 used=<memory:2048, vCores:1> cluster=<memory:8192, vCores:8>
2015-04-01 17:29:04,767 INFO org.apache.hadoop.yarn.server.resourcemanager.scheduler.capacity.ParentQueue: Re-sorting completed queue: root.default stats: default: capacity=1.0, absoluteCapacity=1.0, usedResources=<memory:2048, vCores:1>, usedCapacity=0.25, absoluteUsedCapacity=0.25, numApps=1, numContainers=1
2015-04-01 17:29:04,767 INFO org.apache.hadoop.yarn.server.resourcemanager.scheduler.capacity.CapacityScheduler: Application attempt appattempt_1427899242644_0008_000001 released container container_1427899242644_0008_01_000002 on node: host: a11p2.fil.univ-lille1.fr.:55305 #containers=1 available=6144 used=2048 with event: FINISHED
2015-04-01 17:29:05,768 INFO org.apache.hadoop.yarn.server.resourcemanager.rmcontainer.RMContainerImpl: container_1427899242644_0008_01_000003 Container Transitioned from NEW to ALLOCATED
2015-04-01 17:29:05,768 INFO org.apache.hadoop.yarn.server.resourcemanager.RMAuditLogger: USER=echallier	OPERATION=AM Allocated Container	TARGET=SchedulerApp	RESULT=SUCCESS	APPID=application_1427899242644_0008	CONTAINERID=container_1427899242644_0008_01_000003
2015-04-01 17:29:05,768 INFO org.apache.hadoop.yarn.server.resourcemanager.scheduler.SchedulerNode: Assigned container container_1427899242644_0008_01_000003 of capacity <memory:1024, vCores:1> on host a11p2.fil.univ-lille1.fr.:55305, which has 2 containers, <memory:3072, vCores:2> used and <memory:5120, vCores:6> available after allocation
2015-04-01 17:29:05,768 INFO org.apache.hadoop.yarn.server.resourcemanager.scheduler.capacity.LeafQueue: assignedContainer application attempt=appattempt_1427899242644_0008_000001 container=Container: [ContainerId: container_1427899242644_0008_01_000003, NodeId: a11p2.fil.univ-lille1.fr.:55305, NodeHttpAddress: a11p2.fil.univ-lille1.fr.:8042, Resource: <memory:1024, vCores:1>, Priority: 10, Token: null, ] queue=default: capacity=1.0, absoluteCapacity=1.0, usedResources=<memory:2048, vCores:1>, usedCapacity=0.25, absoluteUsedCapacity=0.25, numApps=1, numContainers=1 clusterResource=<memory:8192, vCores:8>
2015-04-01 17:29:05,768 INFO org.apache.hadoop.yarn.server.resourcemanager.scheduler.capacity.ParentQueue: Re-sorting assigned queue: root.default stats: default: capacity=1.0, absoluteCapacity=1.0, usedResources=<memory:3072, vCores:2>, usedCapacity=0.375, absoluteUsedCapacity=0.375, numApps=1, numContainers=2
2015-04-01 17:29:05,768 INFO org.apache.hadoop.yarn.server.resourcemanager.scheduler.capacity.ParentQueue: assignedContainer queue=root usedCapacity=0.375 absoluteUsedCapacity=0.375 used=<memory:3072, vCores:2> cluster=<memory:8192, vCores:8>
2015-04-01 17:29:06,375 INFO org.apache.hadoop.yarn.server.resourcemanager.rmcontainer.RMContainerImpl: container_1427899242644_0008_01_000003 Container Transitioned from ALLOCATED to ACQUIRED
2015-04-01 17:29:06,769 INFO org.apache.hadoop.yarn.server.resourcemanager.rmcontainer.RMContainerImpl: container_1427899242644_0008_01_000003 Container Transitioned from ACQUIRED to RUNNING
2015-04-01 17:29:07,379 INFO org.apache.hadoop.yarn.server.resourcemanager.scheduler.AppSchedulingInfo: checking for deactivate... 
2015-04-01 17:29:09,160 INFO org.apache.hadoop.yarn.server.resourcemanager.rmapp.attempt.RMAppAttemptImpl: Updating application attempt appattempt_1427899242644_0008_000001 with final state: FINISHING, and exit status: -1000
2015-04-01 17:29:09,160 INFO org.apache.hadoop.yarn.server.resourcemanager.rmapp.attempt.RMAppAttemptImpl: appattempt_1427899242644_0008_000001 State change from RUNNING to FINAL_SAVING
2015-04-01 17:29:09,160 INFO org.apache.hadoop.yarn.server.resourcemanager.rmapp.RMAppImpl: Updating application application_1427899242644_0008 with final state: FINISHING
2015-04-01 17:29:09,160 INFO org.apache.hadoop.yarn.server.resourcemanager.rmapp.RMAppImpl: application_1427899242644_0008 State change from RUNNING to FINAL_SAVING
2015-04-01 17:29:09,161 INFO org.apache.hadoop.yarn.server.resourcemanager.recovery.RMStateStore: Updating info for app: application_1427899242644_0008
2015-04-01 17:29:09,161 INFO org.apache.hadoop.yarn.server.resourcemanager.rmapp.attempt.RMAppAttemptImpl: appattempt_1427899242644_0008_000001 State change from FINAL_SAVING to FINISHING
2015-04-01 17:29:09,161 INFO org.apache.hadoop.yarn.server.resourcemanager.rmapp.RMAppImpl: application_1427899242644_0008 State change from FINAL_SAVING to FINISHING
2015-04-01 17:29:09,737 INFO org.apache.hadoop.yarn.server.resourcemanager.rmcontainer.RMContainerImpl: container_1427899242644_0008_01_000003 Container Transitioned from RUNNING to COMPLETED
2015-04-01 17:29:09,737 INFO org.apache.hadoop.yarn.server.resourcemanager.scheduler.common.fica.FiCaSchedulerApp: Completed container: container_1427899242644_0008_01_000003 in state: COMPLETED event:FINISHED
2015-04-01 17:29:09,737 INFO org.apache.hadoop.yarn.server.resourcemanager.RMAuditLogger: USER=echallier	OPERATION=AM Released Container	TARGET=SchedulerApp	RESULT=SUCCESS	APPID=application_1427899242644_0008	CONTAINERID=container_1427899242644_0008_01_000003
2015-04-01 17:29:09,738 INFO org.apache.hadoop.yarn.server.resourcemanager.scheduler.SchedulerNode: Released container container_1427899242644_0008_01_000003 of capacity <memory:1024, vCores:1> on host a11p2.fil.univ-lille1.fr.:55305, which currently has 1 containers, <memory:2048, vCores:1> used and <memory:6144, vCores:7> available, release resources=true
2015-04-01 17:29:09,738 INFO org.apache.hadoop.yarn.server.resourcemanager.scheduler.capacity.LeafQueue: default used=<memory:2048, vCores:1> numContainers=1 user=echallier user-resources=<memory:2048, vCores:1>
2015-04-01 17:29:09,738 INFO org.apache.hadoop.yarn.server.resourcemanager.scheduler.capacity.LeafQueue: completedContainer container=Container: [ContainerId: container_1427899242644_0008_01_000003, NodeId: a11p2.fil.univ-lille1.fr.:55305, NodeHttpAddress: a11p2.fil.univ-lille1.fr.:8042, Resource: <memory:1024, vCores:1>, Priority: 10, Token: Token { kind: ContainerToken, service: 127.0.1.1:55305 }, ] queue=default: capacity=1.0, absoluteCapacity=1.0, usedResources=<memory:2048, vCores:1>, usedCapacity=0.25, absoluteUsedCapacity=0.25, numApps=1, numContainers=1 cluster=<memory:8192, vCores:8>
2015-04-01 17:29:09,738 INFO org.apache.hadoop.yarn.server.resourcemanager.scheduler.capacity.ParentQueue: completedContainer queue=root usedCapacity=0.25 absoluteUsedCapacity=0.25 used=<memory:2048, vCores:1> cluster=<memory:8192, vCores:8>
2015-04-01 17:29:09,738 INFO org.apache.hadoop.yarn.server.resourcemanager.scheduler.capacity.ParentQueue: Re-sorting completed queue: root.default stats: default: capacity=1.0, absoluteCapacity=1.0, usedResources=<memory:2048, vCores:1>, usedCapacity=0.25, absoluteUsedCapacity=0.25, numApps=1, numContainers=1
2015-04-01 17:29:09,738 INFO org.apache.hadoop.yarn.server.resourcemanager.scheduler.capacity.CapacityScheduler: Application attempt appattempt_1427899242644_0008_000001 released container container_1427899242644_0008_01_000003 on node: host: a11p2.fil.univ-lille1.fr.:55305 #containers=1 available=6144 used=2048 with event: FINISHED
2015-04-01 17:29:15,746 INFO org.apache.hadoop.yarn.server.resourcemanager.rmcontainer.RMContainerImpl: container_1427899242644_0008_01_000001 Container Transitioned from RUNNING to COMPLETED
2015-04-01 17:29:15,746 INFO org.apache.hadoop.yarn.server.resourcemanager.ApplicationMasterService: Unregistering app attempt : appattempt_1427899242644_0008_000001
2015-04-01 17:29:15,746 INFO org.apache.hadoop.yarn.server.resourcemanager.scheduler.common.fica.FiCaSchedulerApp: Completed container: container_1427899242644_0008_01_000001 in state: COMPLETED event:FINISHED
2015-04-01 17:29:15,747 INFO org.apache.hadoop.yarn.server.resourcemanager.rmapp.attempt.RMAppAttemptImpl: appattempt_1427899242644_0008_000001 State change from FINISHING to FINISHED
2015-04-01 17:29:15,747 INFO org.apache.hadoop.yarn.server.resourcemanager.RMAuditLogger: USER=echallier	OPERATION=AM Released Container	TARGET=SchedulerApp	RESULT=SUCCESS	APPID=application_1427899242644_0008	CONTAINERID=container_1427899242644_0008_01_000001
2015-04-01 17:29:15,747 INFO org.apache.hadoop.yarn.server.resourcemanager.scheduler.SchedulerNode: Released container container_1427899242644_0008_01_000001 of capacity <memory:2048, vCores:1> on host a11p2.fil.univ-lille1.fr.:55305, which currently has 0 containers, <memory:0, vCores:0> used and <memory:8192, vCores:8> available, release resources=true
2015-04-01 17:29:15,747 INFO org.apache.hadoop.yarn.server.resourcemanager.rmapp.RMAppImpl: application_1427899242644_0008 State change from FINISHING to FINISHED
2015-04-01 17:29:15,747 INFO org.apache.hadoop.yarn.server.resourcemanager.scheduler.capacity.LeafQueue: default used=<memory:0, vCores:0> numContainers=0 user=echallier user-resources=<memory:0, vCores:0>
2015-04-01 17:29:15,747 INFO org.apache.hadoop.yarn.server.resourcemanager.RMAuditLogger: USER=echallier	OPERATION=Application Finished - Succeeded	TARGET=RMAppManager	RESULT=SUCCESS	APPID=application_1427899242644_0008
2015-04-01 17:29:15,747 INFO org.apache.hadoop.yarn.server.resourcemanager.scheduler.capacity.LeafQueue: completedContainer container=Container: [ContainerId: container_1427899242644_0008_01_000001, NodeId: a11p2.fil.univ-lille1.fr.:55305, NodeHttpAddress: a11p2.fil.univ-lille1.fr.:8042, Resource: <memory:2048, vCores:1>, Priority: 0, Token: Token { kind: ContainerToken, service: 127.0.1.1:55305 }, ] queue=default: capacity=1.0, absoluteCapacity=1.0, usedResources=<memory:0, vCores:0>, usedCapacity=0.0, absoluteUsedCapacity=0.0, numApps=1, numContainers=0 cluster=<memory:8192, vCores:8>
2015-04-01 17:29:15,747 INFO org.apache.hadoop.yarn.server.resourcemanager.amlauncher.AMLauncher: Cleaning master appattempt_1427899242644_0008_000001
2015-04-01 17:29:15,747 INFO org.apache.hadoop.yarn.server.resourcemanager.scheduler.capacity.ParentQueue: completedContainer queue=root usedCapacity=0.0 absoluteUsedCapacity=0.0 used=<memory:0, vCores:0> cluster=<memory:8192, vCores:8>
2015-04-01 17:29:15,747 INFO org.apache.hadoop.yarn.server.resourcemanager.RMAppManager$ApplicationSummary: appId=application_1427899242644_0008,name=GPS,user=echallier,queue=default,state=FINISHED,trackingUrl=http://a11p2.fil.univ-lille1.fr.:8088/proxy/application_1427899242644_0008/jobhistory/job/job_1427899242644_0008,appMasterHost=a11p2,startTime=1427902135489,finishTime=1427902149160,finalStatus=SUCCEEDED
2015-04-01 17:29:15,749 INFO org.apache.hadoop.yarn.server.resourcemanager.scheduler.capacity.ParentQueue: Re-sorting completed queue: root.default stats: default: capacity=1.0, absoluteCapacity=1.0, usedResources=<memory:0, vCores:0>, usedCapacity=0.0, absoluteUsedCapacity=0.0, numApps=1, numContainers=0
2015-04-01 17:29:15,750 INFO org.apache.hadoop.yarn.server.resourcemanager.scheduler.capacity.CapacityScheduler: Application attempt appattempt_1427899242644_0008_000001 released container container_1427899242644_0008_01_000001 on node: host: a11p2.fil.univ-lille1.fr.:55305 #containers=0 available=8192 used=0 with event: FINISHED
2015-04-01 17:29:15,750 INFO org.apache.hadoop.yarn.server.resourcemanager.scheduler.capacity.CapacityScheduler: Application Attempt appattempt_1427899242644_0008_000001 is done. finalState=FINISHED
2015-04-01 17:29:15,750 INFO org.apache.hadoop.yarn.server.resourcemanager.scheduler.AppSchedulingInfo: Application application_1427899242644_0008 requests cleared
2015-04-01 17:29:15,750 INFO org.apache.hadoop.yarn.server.resourcemanager.scheduler.capacity.LeafQueue: Application removed - appId: application_1427899242644_0008 user: echallier queue: default #user-pending-applications: 0 #user-active-applications: 0 #queue-pending-applications: 0 #queue-active-applications: 0
2015-04-01 17:29:15,750 INFO org.apache.hadoop.yarn.server.resourcemanager.scheduler.capacity.ParentQueue: Application removed - appId: application_1427899242644_0008 user: echallier leaf-queue of parent: root #applications: 0
2015-04-01 17:30:44,685 INFO org.apache.hadoop.yarn.server.resourcemanager.ClientRMService: Allocated new applicationId: 9
2015-04-01 17:30:45,525 INFO org.apache.hadoop.yarn.server.resourcemanager.ClientRMService: Application with id 9 submitted by user echallier
2015-04-01 17:30:45,525 INFO org.apache.hadoop.yarn.server.resourcemanager.rmapp.RMAppImpl: Storing application with id application_1427899242644_0009
2015-04-01 17:30:45,525 INFO org.apache.hadoop.yarn.server.resourcemanager.RMAuditLogger: USER=echallier	IP=127.0.0.1	OPERATION=Submit Application Request	TARGET=ClientRMService	RESULT=SUCCESS	APPID=application_1427899242644_0009
2015-04-01 17:30:45,525 INFO org.apache.hadoop.yarn.server.resourcemanager.rmapp.RMAppImpl: application_1427899242644_0009 State change from NEW to NEW_SAVING
2015-04-01 17:30:45,525 INFO org.apache.hadoop.yarn.server.resourcemanager.recovery.RMStateStore: Storing info for app: application_1427899242644_0009
2015-04-01 17:30:45,526 INFO org.apache.hadoop.yarn.server.resourcemanager.rmapp.RMAppImpl: application_1427899242644_0009 State change from NEW_SAVING to SUBMITTED
2015-04-01 17:30:45,526 INFO org.apache.hadoop.yarn.server.resourcemanager.scheduler.capacity.ParentQueue: Application added - appId: application_1427899242644_0009 user: echallier leaf-queue of parent: root #applications: 1
2015-04-01 17:30:45,526 INFO org.apache.hadoop.yarn.server.resourcemanager.scheduler.capacity.CapacityScheduler: Accepted application application_1427899242644_0009 from user: echallier, in queue: default
2015-04-01 17:30:45,526 INFO org.apache.hadoop.yarn.server.resourcemanager.rmapp.RMAppImpl: application_1427899242644_0009 State change from SUBMITTED to ACCEPTED
2015-04-01 17:30:45,526 INFO org.apache.hadoop.yarn.server.resourcemanager.ApplicationMasterService: Registering app attempt : appattempt_1427899242644_0009_000001
2015-04-01 17:30:45,526 INFO org.apache.hadoop.yarn.server.resourcemanager.rmapp.attempt.RMAppAttemptImpl: appattempt_1427899242644_0009_000001 State change from NEW to SUBMITTED
2015-04-01 17:30:45,527 INFO org.apache.hadoop.yarn.server.resourcemanager.scheduler.capacity.LeafQueue: Application application_1427899242644_0009 from user: echallier activated in queue: default
2015-04-01 17:30:45,527 INFO org.apache.hadoop.yarn.server.resourcemanager.scheduler.capacity.LeafQueue: Application added - appId: application_1427899242644_0009 user: org.apache.hadoop.yarn.server.resourcemanager.scheduler.capacity.LeafQueue$User@7f3c5b, leaf-queue: default #user-pending-applications: 0 #user-active-applications: 1 #queue-pending-applications: 0 #queue-active-applications: 1
2015-04-01 17:30:45,527 INFO org.apache.hadoop.yarn.server.resourcemanager.scheduler.capacity.CapacityScheduler: Added Application Attempt appattempt_1427899242644_0009_000001 to scheduler from user echallier in queue default
2015-04-01 17:30:45,527 INFO org.apache.hadoop.yarn.server.resourcemanager.rmapp.attempt.RMAppAttemptImpl: appattempt_1427899242644_0009_000001 State change from SUBMITTED to SCHEDULED
2015-04-01 17:30:45,874 INFO org.apache.hadoop.yarn.server.resourcemanager.rmcontainer.RMContainerImpl: container_1427899242644_0009_01_000001 Container Transitioned from NEW to ALLOCATED
2015-04-01 17:30:45,874 INFO org.apache.hadoop.yarn.server.resourcemanager.RMAuditLogger: USER=echallier	OPERATION=AM Allocated Container	TARGET=SchedulerApp	RESULT=SUCCESS	APPID=application_1427899242644_0009	CONTAINERID=container_1427899242644_0009_01_000001
2015-04-01 17:30:45,874 INFO org.apache.hadoop.yarn.server.resourcemanager.scheduler.SchedulerNode: Assigned container container_1427899242644_0009_01_000001 of capacity <memory:2048, vCores:1> on host a11p2.fil.univ-lille1.fr.:55305, which has 1 containers, <memory:2048, vCores:1> used and <memory:6144, vCores:7> available after allocation
2015-04-01 17:30:45,874 INFO org.apache.hadoop.yarn.server.resourcemanager.scheduler.capacity.LeafQueue: assignedContainer application attempt=appattempt_1427899242644_0009_000001 container=Container: [ContainerId: container_1427899242644_0009_01_000001, NodeId: a11p2.fil.univ-lille1.fr.:55305, NodeHttpAddress: a11p2.fil.univ-lille1.fr.:8042, Resource: <memory:2048, vCores:1>, Priority: 0, Token: null, ] queue=default: capacity=1.0, absoluteCapacity=1.0, usedResources=<memory:0, vCores:0>, usedCapacity=0.0, absoluteUsedCapacity=0.0, numApps=1, numContainers=0 clusterResource=<memory:8192, vCores:8>
2015-04-01 17:30:45,874 INFO org.apache.hadoop.yarn.server.resourcemanager.scheduler.capacity.ParentQueue: Re-sorting assigned queue: root.default stats: default: capacity=1.0, absoluteCapacity=1.0, usedResources=<memory:2048, vCores:1>, usedCapacity=0.25, absoluteUsedCapacity=0.25, numApps=1, numContainers=1
2015-04-01 17:30:45,874 INFO org.apache.hadoop.yarn.server.resourcemanager.scheduler.capacity.ParentQueue: assignedContainer queue=root usedCapacity=0.25 absoluteUsedCapacity=0.25 used=<memory:2048, vCores:1> cluster=<memory:8192, vCores:8>
2015-04-01 17:30:45,875 INFO org.apache.hadoop.yarn.server.resourcemanager.security.NMTokenSecretManagerInRM: Sending NMToken for nodeId : a11p2.fil.univ-lille1.fr.:55305 for container : container_1427899242644_0009_01_000001
2015-04-01 17:30:45,875 INFO org.apache.hadoop.yarn.server.resourcemanager.rmcontainer.RMContainerImpl: container_1427899242644_0009_01_000001 Container Transitioned from ALLOCATED to ACQUIRED
2015-04-01 17:30:45,875 INFO org.apache.hadoop.yarn.server.resourcemanager.security.NMTokenSecretManagerInRM: Clear node set for appattempt_1427899242644_0009_000001
2015-04-01 17:30:45,876 INFO org.apache.hadoop.yarn.server.resourcemanager.rmapp.attempt.RMAppAttemptImpl: Storing attempt: AppId: application_1427899242644_0009 AttemptId: appattempt_1427899242644_0009_000001 MasterContainer: Container: [ContainerId: container_1427899242644_0009_01_000001, NodeId: a11p2.fil.univ-lille1.fr.:55305, NodeHttpAddress: a11p2.fil.univ-lille1.fr.:8042, Resource: <memory:2048, vCores:1>, Priority: 0, Token: Token { kind: ContainerToken, service: 127.0.1.1:55305 }, ]
2015-04-01 17:30:45,876 INFO org.apache.hadoop.yarn.server.resourcemanager.rmapp.attempt.RMAppAttemptImpl: appattempt_1427899242644_0009_000001 State change from SCHEDULED to ALLOCATED_SAVING
2015-04-01 17:30:45,876 INFO org.apache.hadoop.yarn.server.resourcemanager.rmapp.attempt.RMAppAttemptImpl: appattempt_1427899242644_0009_000001 State change from ALLOCATED_SAVING to ALLOCATED
2015-04-01 17:30:45,876 INFO org.apache.hadoop.yarn.server.resourcemanager.amlauncher.AMLauncher: Launching masterappattempt_1427899242644_0009_000001
2015-04-01 17:30:45,877 INFO org.apache.hadoop.yarn.server.resourcemanager.amlauncher.AMLauncher: Setting up container Container: [ContainerId: container_1427899242644_0009_01_000001, NodeId: a11p2.fil.univ-lille1.fr.:55305, NodeHttpAddress: a11p2.fil.univ-lille1.fr.:8042, Resource: <memory:2048, vCores:1>, Priority: 0, Token: Token { kind: ContainerToken, service: 127.0.1.1:55305 }, ] for AM appattempt_1427899242644_0009_000001
2015-04-01 17:30:45,878 INFO org.apache.hadoop.yarn.server.resourcemanager.amlauncher.AMLauncher: Command to launch container container_1427899242644_0009_01_000001 : $JAVA_HOME/bin/java -Dlog4j.configuration=container-log4j.properties -Dyarn.app.container.log.dir=<LOG_DIR> -Dyarn.app.container.log.filesize=0 -Dhadoop.root.logger=INFO,CLA  -Xmx1024m org.apache.hadoop.mapreduce.v2.app.MRAppMaster 1><LOG_DIR>/stdout 2><LOG_DIR>/stderr 
2015-04-01 17:30:45,888 INFO org.apache.hadoop.yarn.server.resourcemanager.amlauncher.AMLauncher: Done launching container Container: [ContainerId: container_1427899242644_0009_01_000001, NodeId: a11p2.fil.univ-lille1.fr.:55305, NodeHttpAddress: a11p2.fil.univ-lille1.fr.:8042, Resource: <memory:2048, vCores:1>, Priority: 0, Token: Token { kind: ContainerToken, service: 127.0.1.1:55305 }, ] for AM appattempt_1427899242644_0009_000001
2015-04-01 17:30:45,889 INFO org.apache.hadoop.yarn.server.resourcemanager.rmapp.attempt.RMAppAttemptImpl: appattempt_1427899242644_0009_000001 State change from ALLOCATED to LAUNCHED
2015-04-01 17:30:46,874 INFO org.apache.hadoop.yarn.server.resourcemanager.rmcontainer.RMContainerImpl: container_1427899242644_0009_01_000001 Container Transitioned from ACQUIRED to RUNNING
2015-04-01 17:30:48,861 INFO SecurityLogger.org.apache.hadoop.ipc.Server: Auth successful for appattempt_1427899242644_0009_000001 (auth:SIMPLE)
2015-04-01 17:30:48,863 INFO org.apache.hadoop.yarn.server.resourcemanager.ApplicationMasterService: AM registration appattempt_1427899242644_0009_000001
2015-04-01 17:30:48,863 INFO org.apache.hadoop.yarn.server.resourcemanager.RMAuditLogger: USER=echallier	IP=127.0.0.1	OPERATION=Register App Master	TARGET=ApplicationMasterService	RESULT=SUCCESS	APPID=application_1427899242644_0009	APPATTEMPTID=appattempt_1427899242644_0009_000001
2015-04-01 17:30:48,863 INFO org.apache.hadoop.yarn.server.resourcemanager.rmapp.attempt.RMAppAttemptImpl: appattempt_1427899242644_0009_000001 State change from LAUNCHED to RUNNING
2015-04-01 17:30:48,863 INFO org.apache.hadoop.yarn.server.resourcemanager.rmapp.RMAppImpl: application_1427899242644_0009 State change from ACCEPTED to RUNNING
2015-04-01 17:30:50,880 INFO org.apache.hadoop.yarn.server.resourcemanager.rmcontainer.RMContainerImpl: container_1427899242644_0009_01_000002 Container Transitioned from NEW to ALLOCATED
2015-04-01 17:30:50,881 INFO org.apache.hadoop.yarn.server.resourcemanager.RMAuditLogger: USER=echallier	OPERATION=AM Allocated Container	TARGET=SchedulerApp	RESULT=SUCCESS	APPID=application_1427899242644_0009	CONTAINERID=container_1427899242644_0009_01_000002
2015-04-01 17:30:50,881 INFO org.apache.hadoop.yarn.server.resourcemanager.scheduler.SchedulerNode: Assigned container container_1427899242644_0009_01_000002 of capacity <memory:1024, vCores:1> on host a11p2.fil.univ-lille1.fr.:55305, which has 2 containers, <memory:3072, vCores:2> used and <memory:5120, vCores:6> available after allocation
2015-04-01 17:30:50,881 INFO org.apache.hadoop.yarn.server.resourcemanager.scheduler.capacity.LeafQueue: assignedContainer application attempt=appattempt_1427899242644_0009_000001 container=Container: [ContainerId: container_1427899242644_0009_01_000002, NodeId: a11p2.fil.univ-lille1.fr.:55305, NodeHttpAddress: a11p2.fil.univ-lille1.fr.:8042, Resource: <memory:1024, vCores:1>, Priority: 20, Token: null, ] queue=default: capacity=1.0, absoluteCapacity=1.0, usedResources=<memory:2048, vCores:1>, usedCapacity=0.25, absoluteUsedCapacity=0.25, numApps=1, numContainers=1 clusterResource=<memory:8192, vCores:8>
2015-04-01 17:30:50,881 INFO org.apache.hadoop.yarn.server.resourcemanager.scheduler.capacity.ParentQueue: Re-sorting assigned queue: root.default stats: default: capacity=1.0, absoluteCapacity=1.0, usedResources=<memory:3072, vCores:2>, usedCapacity=0.375, absoluteUsedCapacity=0.375, numApps=1, numContainers=2
2015-04-01 17:30:50,881 INFO org.apache.hadoop.yarn.server.resourcemanager.scheduler.capacity.ParentQueue: assignedContainer queue=root usedCapacity=0.375 absoluteUsedCapacity=0.375 used=<memory:3072, vCores:2> cluster=<memory:8192, vCores:8>
2015-04-01 17:30:50,900 INFO org.apache.hadoop.yarn.server.resourcemanager.security.NMTokenSecretManagerInRM: Sending NMToken for nodeId : a11p2.fil.univ-lille1.fr.:55305 for container : container_1427899242644_0009_01_000002
2015-04-01 17:30:50,901 INFO org.apache.hadoop.yarn.server.resourcemanager.rmcontainer.RMContainerImpl: container_1427899242644_0009_01_000002 Container Transitioned from ALLOCATED to ACQUIRED
2015-04-01 17:30:51,881 INFO org.apache.hadoop.yarn.server.resourcemanager.rmcontainer.RMContainerImpl: container_1427899242644_0009_01_000002 Container Transitioned from ACQUIRED to RUNNING
2015-04-01 17:30:51,916 INFO org.apache.hadoop.yarn.server.resourcemanager.scheduler.AppSchedulingInfo: checking for deactivate... 
2015-04-01 17:30:54,305 INFO org.apache.hadoop.yarn.server.resourcemanager.rmcontainer.RMContainerImpl: container_1427899242644_0009_01_000002 Container Transitioned from RUNNING to COMPLETED
2015-04-01 17:30:54,305 INFO org.apache.hadoop.yarn.server.resourcemanager.scheduler.common.fica.FiCaSchedulerApp: Completed container: container_1427899242644_0009_01_000002 in state: COMPLETED event:FINISHED
2015-04-01 17:30:54,305 INFO org.apache.hadoop.yarn.server.resourcemanager.RMAuditLogger: USER=echallier	OPERATION=AM Released Container	TARGET=SchedulerApp	RESULT=SUCCESS	APPID=application_1427899242644_0009	CONTAINERID=container_1427899242644_0009_01_000002
2015-04-01 17:30:54,306 INFO org.apache.hadoop.yarn.server.resourcemanager.scheduler.SchedulerNode: Released container container_1427899242644_0009_01_000002 of capacity <memory:1024, vCores:1> on host a11p2.fil.univ-lille1.fr.:55305, which currently has 1 containers, <memory:2048, vCores:1> used and <memory:6144, vCores:7> available, release resources=true
2015-04-01 17:30:54,306 INFO org.apache.hadoop.yarn.server.resourcemanager.scheduler.capacity.LeafQueue: default used=<memory:2048, vCores:1> numContainers=1 user=echallier user-resources=<memory:2048, vCores:1>
2015-04-01 17:30:54,306 INFO org.apache.hadoop.yarn.server.resourcemanager.scheduler.capacity.LeafQueue: completedContainer container=Container: [ContainerId: container_1427899242644_0009_01_000002, NodeId: a11p2.fil.univ-lille1.fr.:55305, NodeHttpAddress: a11p2.fil.univ-lille1.fr.:8042, Resource: <memory:1024, vCores:1>, Priority: 20, Token: Token { kind: ContainerToken, service: 127.0.1.1:55305 }, ] queue=default: capacity=1.0, absoluteCapacity=1.0, usedResources=<memory:2048, vCores:1>, usedCapacity=0.25, absoluteUsedCapacity=0.25, numApps=1, numContainers=1 cluster=<memory:8192, vCores:8>
2015-04-01 17:30:54,306 INFO org.apache.hadoop.yarn.server.resourcemanager.scheduler.capacity.ParentQueue: completedContainer queue=root usedCapacity=0.25 absoluteUsedCapacity=0.25 used=<memory:2048, vCores:1> cluster=<memory:8192, vCores:8>
2015-04-01 17:30:54,306 INFO org.apache.hadoop.yarn.server.resourcemanager.scheduler.capacity.ParentQueue: Re-sorting completed queue: root.default stats: default: capacity=1.0, absoluteCapacity=1.0, usedResources=<memory:2048, vCores:1>, usedCapacity=0.25, absoluteUsedCapacity=0.25, numApps=1, numContainers=1
2015-04-01 17:30:54,306 INFO org.apache.hadoop.yarn.server.resourcemanager.scheduler.capacity.CapacityScheduler: Application attempt appattempt_1427899242644_0009_000001 released container container_1427899242644_0009_01_000002 on node: host: a11p2.fil.univ-lille1.fr.:55305 #containers=1 available=6144 used=2048 with event: FINISHED
2015-04-01 17:30:55,307 INFO org.apache.hadoop.yarn.server.resourcemanager.rmcontainer.RMContainerImpl: container_1427899242644_0009_01_000003 Container Transitioned from NEW to ALLOCATED
2015-04-01 17:30:55,307 INFO org.apache.hadoop.yarn.server.resourcemanager.RMAuditLogger: USER=echallier	OPERATION=AM Allocated Container	TARGET=SchedulerApp	RESULT=SUCCESS	APPID=application_1427899242644_0009	CONTAINERID=container_1427899242644_0009_01_000003
2015-04-01 17:30:55,307 INFO org.apache.hadoop.yarn.server.resourcemanager.scheduler.SchedulerNode: Assigned container container_1427899242644_0009_01_000003 of capacity <memory:1024, vCores:1> on host a11p2.fil.univ-lille1.fr.:55305, which has 2 containers, <memory:3072, vCores:2> used and <memory:5120, vCores:6> available after allocation
2015-04-01 17:30:55,307 INFO org.apache.hadoop.yarn.server.resourcemanager.scheduler.capacity.LeafQueue: assignedContainer application attempt=appattempt_1427899242644_0009_000001 container=Container: [ContainerId: container_1427899242644_0009_01_000003, NodeId: a11p2.fil.univ-lille1.fr.:55305, NodeHttpAddress: a11p2.fil.univ-lille1.fr.:8042, Resource: <memory:1024, vCores:1>, Priority: 10, Token: null, ] queue=default: capacity=1.0, absoluteCapacity=1.0, usedResources=<memory:2048, vCores:1>, usedCapacity=0.25, absoluteUsedCapacity=0.25, numApps=1, numContainers=1 clusterResource=<memory:8192, vCores:8>
2015-04-01 17:30:55,308 INFO org.apache.hadoop.yarn.server.resourcemanager.scheduler.capacity.ParentQueue: Re-sorting assigned queue: root.default stats: default: capacity=1.0, absoluteCapacity=1.0, usedResources=<memory:3072, vCores:2>, usedCapacity=0.375, absoluteUsedCapacity=0.375, numApps=1, numContainers=2
2015-04-01 17:30:55,308 INFO org.apache.hadoop.yarn.server.resourcemanager.scheduler.capacity.ParentQueue: assignedContainer queue=root usedCapacity=0.375 absoluteUsedCapacity=0.375 used=<memory:3072, vCores:2> cluster=<memory:8192, vCores:8>
2015-04-01 17:30:55,935 INFO org.apache.hadoop.yarn.server.resourcemanager.rmcontainer.RMContainerImpl: container_1427899242644_0009_01_000003 Container Transitioned from ALLOCATED to ACQUIRED
2015-04-01 17:30:56,308 INFO org.apache.hadoop.yarn.server.resourcemanager.rmcontainer.RMContainerImpl: container_1427899242644_0009_01_000003 Container Transitioned from ACQUIRED to RUNNING
2015-04-01 17:30:56,938 INFO org.apache.hadoop.yarn.server.resourcemanager.scheduler.AppSchedulingInfo: checking for deactivate... 
2015-04-01 17:30:58,692 INFO org.apache.hadoop.yarn.server.resourcemanager.rmapp.attempt.RMAppAttemptImpl: Updating application attempt appattempt_1427899242644_0009_000001 with final state: FINISHING, and exit status: -1000
2015-04-01 17:30:58,692 INFO org.apache.hadoop.yarn.server.resourcemanager.rmapp.attempt.RMAppAttemptImpl: appattempt_1427899242644_0009_000001 State change from RUNNING to FINAL_SAVING
2015-04-01 17:30:58,693 INFO org.apache.hadoop.yarn.server.resourcemanager.rmapp.RMAppImpl: Updating application application_1427899242644_0009 with final state: FINISHING
2015-04-01 17:30:58,693 INFO org.apache.hadoop.yarn.server.resourcemanager.rmapp.RMAppImpl: application_1427899242644_0009 State change from RUNNING to FINAL_SAVING
2015-04-01 17:30:58,693 INFO org.apache.hadoop.yarn.server.resourcemanager.recovery.RMStateStore: Updating info for app: application_1427899242644_0009
2015-04-01 17:30:58,693 INFO org.apache.hadoop.yarn.server.resourcemanager.rmapp.attempt.RMAppAttemptImpl: appattempt_1427899242644_0009_000001 State change from FINAL_SAVING to FINISHING
2015-04-01 17:30:58,693 INFO org.apache.hadoop.yarn.server.resourcemanager.rmapp.RMAppImpl: application_1427899242644_0009 State change from FINAL_SAVING to FINISHING
2015-04-01 17:30:59,283 INFO org.apache.hadoop.yarn.server.resourcemanager.rmcontainer.RMContainerImpl: container_1427899242644_0009_01_000003 Container Transitioned from RUNNING to COMPLETED
2015-04-01 17:30:59,283 INFO org.apache.hadoop.yarn.server.resourcemanager.scheduler.common.fica.FiCaSchedulerApp: Completed container: container_1427899242644_0009_01_000003 in state: COMPLETED event:FINISHED
2015-04-01 17:30:59,283 INFO org.apache.hadoop.yarn.server.resourcemanager.RMAuditLogger: USER=echallier	OPERATION=AM Released Container	TARGET=SchedulerApp	RESULT=SUCCESS	APPID=application_1427899242644_0009	CONTAINERID=container_1427899242644_0009_01_000003
2015-04-01 17:30:59,283 INFO org.apache.hadoop.yarn.server.resourcemanager.scheduler.SchedulerNode: Released container container_1427899242644_0009_01_000003 of capacity <memory:1024, vCores:1> on host a11p2.fil.univ-lille1.fr.:55305, which currently has 1 containers, <memory:2048, vCores:1> used and <memory:6144, vCores:7> available, release resources=true
2015-04-01 17:30:59,283 INFO org.apache.hadoop.yarn.server.resourcemanager.scheduler.capacity.LeafQueue: default used=<memory:2048, vCores:1> numContainers=1 user=echallier user-resources=<memory:2048, vCores:1>
2015-04-01 17:30:59,284 INFO org.apache.hadoop.yarn.server.resourcemanager.scheduler.capacity.LeafQueue: completedContainer container=Container: [ContainerId: container_1427899242644_0009_01_000003, NodeId: a11p2.fil.univ-lille1.fr.:55305, NodeHttpAddress: a11p2.fil.univ-lille1.fr.:8042, Resource: <memory:1024, vCores:1>, Priority: 10, Token: Token { kind: ContainerToken, service: 127.0.1.1:55305 }, ] queue=default: capacity=1.0, absoluteCapacity=1.0, usedResources=<memory:2048, vCores:1>, usedCapacity=0.25, absoluteUsedCapacity=0.25, numApps=1, numContainers=1 cluster=<memory:8192, vCores:8>
2015-04-01 17:30:59,284 INFO org.apache.hadoop.yarn.server.resourcemanager.scheduler.capacity.ParentQueue: completedContainer queue=root usedCapacity=0.25 absoluteUsedCapacity=0.25 used=<memory:2048, vCores:1> cluster=<memory:8192, vCores:8>
2015-04-01 17:30:59,284 INFO org.apache.hadoop.yarn.server.resourcemanager.scheduler.capacity.ParentQueue: Re-sorting completed queue: root.default stats: default: capacity=1.0, absoluteCapacity=1.0, usedResources=<memory:2048, vCores:1>, usedCapacity=0.25, absoluteUsedCapacity=0.25, numApps=1, numContainers=1
2015-04-01 17:30:59,284 INFO org.apache.hadoop.yarn.server.resourcemanager.scheduler.capacity.CapacityScheduler: Application attempt appattempt_1427899242644_0009_000001 released container container_1427899242644_0009_01_000003 on node: host: a11p2.fil.univ-lille1.fr.:55305 #containers=1 available=6144 used=2048 with event: FINISHED
2015-04-01 17:31:05,292 INFO org.apache.hadoop.yarn.server.resourcemanager.rmcontainer.RMContainerImpl: container_1427899242644_0009_01_000001 Container Transitioned from RUNNING to COMPLETED
2015-04-01 17:31:05,292 INFO org.apache.hadoop.yarn.server.resourcemanager.ApplicationMasterService: Unregistering app attempt : appattempt_1427899242644_0009_000001
2015-04-01 17:31:05,293 INFO org.apache.hadoop.yarn.server.resourcemanager.scheduler.common.fica.FiCaSchedulerApp: Completed container: container_1427899242644_0009_01_000001 in state: COMPLETED event:FINISHED
2015-04-01 17:31:05,293 INFO org.apache.hadoop.yarn.server.resourcemanager.rmapp.attempt.RMAppAttemptImpl: appattempt_1427899242644_0009_000001 State change from FINISHING to FINISHED
2015-04-01 17:31:05,294 INFO org.apache.hadoop.yarn.server.resourcemanager.RMAuditLogger: USER=echallier	OPERATION=AM Released Container	TARGET=SchedulerApp	RESULT=SUCCESS	APPID=application_1427899242644_0009	CONTAINERID=container_1427899242644_0009_01_000001
2015-04-01 17:31:05,294 INFO org.apache.hadoop.yarn.server.resourcemanager.rmapp.RMAppImpl: application_1427899242644_0009 State change from FINISHING to FINISHED
2015-04-01 17:31:05,294 INFO org.apache.hadoop.yarn.server.resourcemanager.scheduler.SchedulerNode: Released container container_1427899242644_0009_01_000001 of capacity <memory:2048, vCores:1> on host a11p2.fil.univ-lille1.fr.:55305, which currently has 0 containers, <memory:0, vCores:0> used and <memory:8192, vCores:8> available, release resources=true
2015-04-01 17:31:05,294 INFO org.apache.hadoop.yarn.server.resourcemanager.scheduler.capacity.LeafQueue: default used=<memory:0, vCores:0> numContainers=0 user=echallier user-resources=<memory:0, vCores:0>
2015-04-01 17:31:05,294 INFO org.apache.hadoop.yarn.server.resourcemanager.RMAuditLogger: USER=echallier	OPERATION=Application Finished - Succeeded	TARGET=RMAppManager	RESULT=SUCCESS	APPID=application_1427899242644_0009
2015-04-01 17:31:05,294 INFO org.apache.hadoop.yarn.server.resourcemanager.amlauncher.AMLauncher: Cleaning master appattempt_1427899242644_0009_000001
2015-04-01 17:31:05,294 INFO org.apache.hadoop.yarn.server.resourcemanager.scheduler.capacity.LeafQueue: completedContainer container=Container: [ContainerId: container_1427899242644_0009_01_000001, NodeId: a11p2.fil.univ-lille1.fr.:55305, NodeHttpAddress: a11p2.fil.univ-lille1.fr.:8042, Resource: <memory:2048, vCores:1>, Priority: 0, Token: Token { kind: ContainerToken, service: 127.0.1.1:55305 }, ] queue=default: capacity=1.0, absoluteCapacity=1.0, usedResources=<memory:0, vCores:0>, usedCapacity=0.0, absoluteUsedCapacity=0.0, numApps=1, numContainers=0 cluster=<memory:8192, vCores:8>
2015-04-01 17:31:05,294 INFO org.apache.hadoop.yarn.server.resourcemanager.scheduler.capacity.ParentQueue: completedContainer queue=root usedCapacity=0.0 absoluteUsedCapacity=0.0 used=<memory:0, vCores:0> cluster=<memory:8192, vCores:8>
2015-04-01 17:31:05,294 INFO org.apache.hadoop.yarn.server.resourcemanager.scheduler.capacity.ParentQueue: Re-sorting completed queue: root.default stats: default: capacity=1.0, absoluteCapacity=1.0, usedResources=<memory:0, vCores:0>, usedCapacity=0.0, absoluteUsedCapacity=0.0, numApps=1, numContainers=0
2015-04-01 17:31:05,294 INFO org.apache.hadoop.yarn.server.resourcemanager.scheduler.capacity.CapacityScheduler: Application attempt appattempt_1427899242644_0009_000001 released container container_1427899242644_0009_01_000001 on node: host: a11p2.fil.univ-lille1.fr.:55305 #containers=0 available=8192 used=0 with event: FINISHED
2015-04-01 17:31:05,294 INFO org.apache.hadoop.yarn.server.resourcemanager.RMAppManager$ApplicationSummary: appId=application_1427899242644_0009,name=GPS,user=echallier,queue=default,state=FINISHED,trackingUrl=http://a11p2.fil.univ-lille1.fr.:8088/proxy/application_1427899242644_0009/jobhistory/job/job_1427899242644_0009,appMasterHost=a11p2,startTime=1427902245525,finishTime=1427902258693,finalStatus=SUCCEEDED
2015-04-01 17:31:05,294 INFO org.apache.hadoop.yarn.server.resourcemanager.scheduler.capacity.CapacityScheduler: Application Attempt appattempt_1427899242644_0009_000001 is done. finalState=FINISHED
2015-04-01 17:31:05,295 INFO org.apache.hadoop.yarn.server.resourcemanager.scheduler.AppSchedulingInfo: Application application_1427899242644_0009 requests cleared
2015-04-01 17:31:05,295 INFO org.apache.hadoop.yarn.server.resourcemanager.scheduler.capacity.LeafQueue: Application removed - appId: application_1427899242644_0009 user: echallier queue: default #user-pending-applications: 0 #user-active-applications: 0 #queue-pending-applications: 0 #queue-active-applications: 0
2015-04-01 17:31:05,295 INFO org.apache.hadoop.yarn.server.resourcemanager.scheduler.capacity.ParentQueue: Application removed - appId: application_1427899242644_0009 user: echallier leaf-queue of parent: root #applications: 0
2015-04-01 17:38:29,558 INFO org.apache.hadoop.yarn.server.resourcemanager.ClientRMService: Allocated new applicationId: 10
2015-04-01 17:38:30,383 INFO org.apache.hadoop.yarn.server.resourcemanager.ClientRMService: Application with id 10 submitted by user echallier
2015-04-01 17:38:30,383 INFO org.apache.hadoop.yarn.server.resourcemanager.rmapp.RMAppImpl: Storing application with id application_1427899242644_0010
2015-04-01 17:38:30,383 INFO org.apache.hadoop.yarn.server.resourcemanager.RMAuditLogger: USER=echallier	IP=127.0.0.1	OPERATION=Submit Application Request	TARGET=ClientRMService	RESULT=SUCCESS	APPID=application_1427899242644_0010
2015-04-01 17:38:30,383 INFO org.apache.hadoop.yarn.server.resourcemanager.rmapp.RMAppImpl: application_1427899242644_0010 State change from NEW to NEW_SAVING
2015-04-01 17:38:30,383 INFO org.apache.hadoop.yarn.server.resourcemanager.recovery.RMStateStore: Storing info for app: application_1427899242644_0010
2015-04-01 17:38:30,383 INFO org.apache.hadoop.yarn.server.resourcemanager.rmapp.RMAppImpl: application_1427899242644_0010 State change from NEW_SAVING to SUBMITTED
2015-04-01 17:38:30,384 INFO org.apache.hadoop.yarn.server.resourcemanager.scheduler.capacity.ParentQueue: Application added - appId: application_1427899242644_0010 user: echallier leaf-queue of parent: root #applications: 1
2015-04-01 17:38:30,384 INFO org.apache.hadoop.yarn.server.resourcemanager.scheduler.capacity.CapacityScheduler: Accepted application application_1427899242644_0010 from user: echallier, in queue: default
2015-04-01 17:38:30,384 INFO org.apache.hadoop.yarn.server.resourcemanager.rmapp.RMAppImpl: application_1427899242644_0010 State change from SUBMITTED to ACCEPTED
2015-04-01 17:38:30,384 INFO org.apache.hadoop.yarn.server.resourcemanager.ApplicationMasterService: Registering app attempt : appattempt_1427899242644_0010_000001
2015-04-01 17:38:30,384 INFO org.apache.hadoop.yarn.server.resourcemanager.rmapp.attempt.RMAppAttemptImpl: appattempt_1427899242644_0010_000001 State change from NEW to SUBMITTED
2015-04-01 17:38:30,384 INFO org.apache.hadoop.yarn.server.resourcemanager.scheduler.capacity.LeafQueue: Application application_1427899242644_0010 from user: echallier activated in queue: default
2015-04-01 17:38:30,384 INFO org.apache.hadoop.yarn.server.resourcemanager.scheduler.capacity.LeafQueue: Application added - appId: application_1427899242644_0010 user: org.apache.hadoop.yarn.server.resourcemanager.scheduler.capacity.LeafQueue$User@6b2ec8, leaf-queue: default #user-pending-applications: 0 #user-active-applications: 1 #queue-pending-applications: 0 #queue-active-applications: 1
2015-04-01 17:38:30,384 INFO org.apache.hadoop.yarn.server.resourcemanager.scheduler.capacity.CapacityScheduler: Added Application Attempt appattempt_1427899242644_0010_000001 to scheduler from user echallier in queue default
2015-04-01 17:38:30,385 INFO org.apache.hadoop.yarn.server.resourcemanager.rmapp.attempt.RMAppAttemptImpl: appattempt_1427899242644_0010_000001 State change from SUBMITTED to SCHEDULED
2015-04-01 17:38:30,919 INFO org.apache.hadoop.yarn.server.resourcemanager.rmcontainer.RMContainerImpl: container_1427899242644_0010_01_000001 Container Transitioned from NEW to ALLOCATED
2015-04-01 17:38:30,919 INFO org.apache.hadoop.yarn.server.resourcemanager.RMAuditLogger: USER=echallier	OPERATION=AM Allocated Container	TARGET=SchedulerApp	RESULT=SUCCESS	APPID=application_1427899242644_0010	CONTAINERID=container_1427899242644_0010_01_000001
2015-04-01 17:38:30,919 INFO org.apache.hadoop.yarn.server.resourcemanager.scheduler.SchedulerNode: Assigned container container_1427899242644_0010_01_000001 of capacity <memory:2048, vCores:1> on host a11p2.fil.univ-lille1.fr.:55305, which has 1 containers, <memory:2048, vCores:1> used and <memory:6144, vCores:7> available after allocation
2015-04-01 17:38:30,919 INFO org.apache.hadoop.yarn.server.resourcemanager.scheduler.capacity.LeafQueue: assignedContainer application attempt=appattempt_1427899242644_0010_000001 container=Container: [ContainerId: container_1427899242644_0010_01_000001, NodeId: a11p2.fil.univ-lille1.fr.:55305, NodeHttpAddress: a11p2.fil.univ-lille1.fr.:8042, Resource: <memory:2048, vCores:1>, Priority: 0, Token: null, ] queue=default: capacity=1.0, absoluteCapacity=1.0, usedResources=<memory:0, vCores:0>, usedCapacity=0.0, absoluteUsedCapacity=0.0, numApps=1, numContainers=0 clusterResource=<memory:8192, vCores:8>
2015-04-01 17:38:30,919 INFO org.apache.hadoop.yarn.server.resourcemanager.scheduler.capacity.ParentQueue: Re-sorting assigned queue: root.default stats: default: capacity=1.0, absoluteCapacity=1.0, usedResources=<memory:2048, vCores:1>, usedCapacity=0.25, absoluteUsedCapacity=0.25, numApps=1, numContainers=1
2015-04-01 17:38:30,919 INFO org.apache.hadoop.yarn.server.resourcemanager.scheduler.capacity.ParentQueue: assignedContainer queue=root usedCapacity=0.25 absoluteUsedCapacity=0.25 used=<memory:2048, vCores:1> cluster=<memory:8192, vCores:8>
2015-04-01 17:38:30,919 INFO org.apache.hadoop.yarn.server.resourcemanager.security.NMTokenSecretManagerInRM: Sending NMToken for nodeId : a11p2.fil.univ-lille1.fr.:55305 for container : container_1427899242644_0010_01_000001
2015-04-01 17:38:30,920 INFO org.apache.hadoop.yarn.server.resourcemanager.rmcontainer.RMContainerImpl: container_1427899242644_0010_01_000001 Container Transitioned from ALLOCATED to ACQUIRED
2015-04-01 17:38:30,920 INFO org.apache.hadoop.yarn.server.resourcemanager.security.NMTokenSecretManagerInRM: Clear node set for appattempt_1427899242644_0010_000001
2015-04-01 17:38:30,920 INFO org.apache.hadoop.yarn.server.resourcemanager.rmapp.attempt.RMAppAttemptImpl: Storing attempt: AppId: application_1427899242644_0010 AttemptId: appattempt_1427899242644_0010_000001 MasterContainer: Container: [ContainerId: container_1427899242644_0010_01_000001, NodeId: a11p2.fil.univ-lille1.fr.:55305, NodeHttpAddress: a11p2.fil.univ-lille1.fr.:8042, Resource: <memory:2048, vCores:1>, Priority: 0, Token: Token { kind: ContainerToken, service: 127.0.1.1:55305 }, ]
2015-04-01 17:38:30,920 INFO org.apache.hadoop.yarn.server.resourcemanager.rmapp.attempt.RMAppAttemptImpl: appattempt_1427899242644_0010_000001 State change from SCHEDULED to ALLOCATED_SAVING
2015-04-01 17:38:30,921 INFO org.apache.hadoop.yarn.server.resourcemanager.rmapp.attempt.RMAppAttemptImpl: appattempt_1427899242644_0010_000001 State change from ALLOCATED_SAVING to ALLOCATED
2015-04-01 17:38:30,921 INFO org.apache.hadoop.yarn.server.resourcemanager.amlauncher.AMLauncher: Launching masterappattempt_1427899242644_0010_000001
2015-04-01 17:38:30,922 INFO org.apache.hadoop.yarn.server.resourcemanager.amlauncher.AMLauncher: Setting up container Container: [ContainerId: container_1427899242644_0010_01_000001, NodeId: a11p2.fil.univ-lille1.fr.:55305, NodeHttpAddress: a11p2.fil.univ-lille1.fr.:8042, Resource: <memory:2048, vCores:1>, Priority: 0, Token: Token { kind: ContainerToken, service: 127.0.1.1:55305 }, ] for AM appattempt_1427899242644_0010_000001
2015-04-01 17:38:30,922 INFO org.apache.hadoop.yarn.server.resourcemanager.amlauncher.AMLauncher: Command to launch container container_1427899242644_0010_01_000001 : $JAVA_HOME/bin/java -Dlog4j.configuration=container-log4j.properties -Dyarn.app.container.log.dir=<LOG_DIR> -Dyarn.app.container.log.filesize=0 -Dhadoop.root.logger=INFO,CLA  -Xmx1024m org.apache.hadoop.mapreduce.v2.app.MRAppMaster 1><LOG_DIR>/stdout 2><LOG_DIR>/stderr 
2015-04-01 17:38:30,934 INFO org.apache.hadoop.yarn.server.resourcemanager.amlauncher.AMLauncher: Done launching container Container: [ContainerId: container_1427899242644_0010_01_000001, NodeId: a11p2.fil.univ-lille1.fr.:55305, NodeHttpAddress: a11p2.fil.univ-lille1.fr.:8042, Resource: <memory:2048, vCores:1>, Priority: 0, Token: Token { kind: ContainerToken, service: 127.0.1.1:55305 }, ] for AM appattempt_1427899242644_0010_000001
2015-04-01 17:38:30,934 INFO org.apache.hadoop.yarn.server.resourcemanager.rmapp.attempt.RMAppAttemptImpl: appattempt_1427899242644_0010_000001 State change from ALLOCATED to LAUNCHED
2015-04-01 17:38:31,919 INFO org.apache.hadoop.yarn.server.resourcemanager.rmcontainer.RMContainerImpl: container_1427899242644_0010_01_000001 Container Transitioned from ACQUIRED to RUNNING
2015-04-01 17:38:34,010 INFO SecurityLogger.org.apache.hadoop.ipc.Server: Auth successful for appattempt_1427899242644_0010_000001 (auth:SIMPLE)
2015-04-01 17:38:34,012 INFO org.apache.hadoop.yarn.server.resourcemanager.ApplicationMasterService: AM registration appattempt_1427899242644_0010_000001
2015-04-01 17:38:34,012 INFO org.apache.hadoop.yarn.server.resourcemanager.RMAuditLogger: USER=echallier	IP=127.0.0.1	OPERATION=Register App Master	TARGET=ApplicationMasterService	RESULT=SUCCESS	APPID=application_1427899242644_0010	APPATTEMPTID=appattempt_1427899242644_0010_000001
2015-04-01 17:38:34,012 INFO org.apache.hadoop.yarn.server.resourcemanager.rmapp.attempt.RMAppAttemptImpl: appattempt_1427899242644_0010_000001 State change from LAUNCHED to RUNNING
2015-04-01 17:38:34,012 INFO org.apache.hadoop.yarn.server.resourcemanager.rmapp.RMAppImpl: application_1427899242644_0010 State change from ACCEPTED to RUNNING
2015-04-01 17:38:35,929 INFO org.apache.hadoop.yarn.server.resourcemanager.rmcontainer.RMContainerImpl: container_1427899242644_0010_01_000002 Container Transitioned from NEW to ALLOCATED
2015-04-01 17:38:35,930 INFO org.apache.hadoop.yarn.server.resourcemanager.RMAuditLogger: USER=echallier	OPERATION=AM Allocated Container	TARGET=SchedulerApp	RESULT=SUCCESS	APPID=application_1427899242644_0010	CONTAINERID=container_1427899242644_0010_01_000002
2015-04-01 17:38:35,930 INFO org.apache.hadoop.yarn.server.resourcemanager.scheduler.SchedulerNode: Assigned container container_1427899242644_0010_01_000002 of capacity <memory:1024, vCores:1> on host a11p2.fil.univ-lille1.fr.:55305, which has 2 containers, <memory:3072, vCores:2> used and <memory:5120, vCores:6> available after allocation
2015-04-01 17:38:35,930 INFO org.apache.hadoop.yarn.server.resourcemanager.scheduler.capacity.LeafQueue: assignedContainer application attempt=appattempt_1427899242644_0010_000001 container=Container: [ContainerId: container_1427899242644_0010_01_000002, NodeId: a11p2.fil.univ-lille1.fr.:55305, NodeHttpAddress: a11p2.fil.univ-lille1.fr.:8042, Resource: <memory:1024, vCores:1>, Priority: 20, Token: null, ] queue=default: capacity=1.0, absoluteCapacity=1.0, usedResources=<memory:2048, vCores:1>, usedCapacity=0.25, absoluteUsedCapacity=0.25, numApps=1, numContainers=1 clusterResource=<memory:8192, vCores:8>
2015-04-01 17:38:35,930 INFO org.apache.hadoop.yarn.server.resourcemanager.scheduler.capacity.ParentQueue: Re-sorting assigned queue: root.default stats: default: capacity=1.0, absoluteCapacity=1.0, usedResources=<memory:3072, vCores:2>, usedCapacity=0.375, absoluteUsedCapacity=0.375, numApps=1, numContainers=2
2015-04-01 17:38:35,930 INFO org.apache.hadoop.yarn.server.resourcemanager.scheduler.capacity.ParentQueue: assignedContainer queue=root usedCapacity=0.375 absoluteUsedCapacity=0.375 used=<memory:3072, vCores:2> cluster=<memory:8192, vCores:8>
2015-04-01 17:38:36,067 INFO org.apache.hadoop.yarn.server.resourcemanager.security.NMTokenSecretManagerInRM: Sending NMToken for nodeId : a11p2.fil.univ-lille1.fr.:55305 for container : container_1427899242644_0010_01_000002
2015-04-01 17:38:36,068 INFO org.apache.hadoop.yarn.server.resourcemanager.rmcontainer.RMContainerImpl: container_1427899242644_0010_01_000002 Container Transitioned from ALLOCATED to ACQUIRED
2015-04-01 17:38:36,930 INFO org.apache.hadoop.yarn.server.resourcemanager.rmcontainer.RMContainerImpl: container_1427899242644_0010_01_000002 Container Transitioned from ACQUIRED to RUNNING
2015-04-01 17:38:37,084 INFO org.apache.hadoop.yarn.server.resourcemanager.scheduler.AppSchedulingInfo: checking for deactivate... 
2015-04-01 17:38:39,611 INFO org.apache.hadoop.yarn.server.resourcemanager.rmcontainer.RMContainerImpl: container_1427899242644_0010_01_000002 Container Transitioned from RUNNING to COMPLETED
2015-04-01 17:38:39,611 INFO org.apache.hadoop.yarn.server.resourcemanager.scheduler.common.fica.FiCaSchedulerApp: Completed container: container_1427899242644_0010_01_000002 in state: COMPLETED event:FINISHED
2015-04-01 17:38:39,611 INFO org.apache.hadoop.yarn.server.resourcemanager.RMAuditLogger: USER=echallier	OPERATION=AM Released Container	TARGET=SchedulerApp	RESULT=SUCCESS	APPID=application_1427899242644_0010	CONTAINERID=container_1427899242644_0010_01_000002
2015-04-01 17:38:39,611 INFO org.apache.hadoop.yarn.server.resourcemanager.scheduler.SchedulerNode: Released container container_1427899242644_0010_01_000002 of capacity <memory:1024, vCores:1> on host a11p2.fil.univ-lille1.fr.:55305, which currently has 1 containers, <memory:2048, vCores:1> used and <memory:6144, vCores:7> available, release resources=true
2015-04-01 17:38:39,611 INFO org.apache.hadoop.yarn.server.resourcemanager.scheduler.capacity.LeafQueue: default used=<memory:2048, vCores:1> numContainers=1 user=echallier user-resources=<memory:2048, vCores:1>
2015-04-01 17:38:39,612 INFO org.apache.hadoop.yarn.server.resourcemanager.scheduler.capacity.LeafQueue: completedContainer container=Container: [ContainerId: container_1427899242644_0010_01_000002, NodeId: a11p2.fil.univ-lille1.fr.:55305, NodeHttpAddress: a11p2.fil.univ-lille1.fr.:8042, Resource: <memory:1024, vCores:1>, Priority: 20, Token: Token { kind: ContainerToken, service: 127.0.1.1:55305 }, ] queue=default: capacity=1.0, absoluteCapacity=1.0, usedResources=<memory:2048, vCores:1>, usedCapacity=0.25, absoluteUsedCapacity=0.25, numApps=1, numContainers=1 cluster=<memory:8192, vCores:8>
2015-04-01 17:38:39,612 INFO org.apache.hadoop.yarn.server.resourcemanager.scheduler.capacity.ParentQueue: completedContainer queue=root usedCapacity=0.25 absoluteUsedCapacity=0.25 used=<memory:2048, vCores:1> cluster=<memory:8192, vCores:8>
2015-04-01 17:38:39,612 INFO org.apache.hadoop.yarn.server.resourcemanager.scheduler.capacity.ParentQueue: Re-sorting completed queue: root.default stats: default: capacity=1.0, absoluteCapacity=1.0, usedResources=<memory:2048, vCores:1>, usedCapacity=0.25, absoluteUsedCapacity=0.25, numApps=1, numContainers=1
2015-04-01 17:38:39,612 INFO org.apache.hadoop.yarn.server.resourcemanager.scheduler.capacity.CapacityScheduler: Application attempt appattempt_1427899242644_0010_000001 released container container_1427899242644_0010_01_000002 on node: host: a11p2.fil.univ-lille1.fr.:55305 #containers=1 available=6144 used=2048 with event: FINISHED
2015-04-01 17:38:40,613 INFO org.apache.hadoop.yarn.server.resourcemanager.rmcontainer.RMContainerImpl: container_1427899242644_0010_01_000003 Container Transitioned from NEW to ALLOCATED
2015-04-01 17:38:40,613 INFO org.apache.hadoop.yarn.server.resourcemanager.RMAuditLogger: USER=echallier	OPERATION=AM Allocated Container	TARGET=SchedulerApp	RESULT=SUCCESS	APPID=application_1427899242644_0010	CONTAINERID=container_1427899242644_0010_01_000003
2015-04-01 17:38:40,613 INFO org.apache.hadoop.yarn.server.resourcemanager.scheduler.SchedulerNode: Assigned container container_1427899242644_0010_01_000003 of capacity <memory:1024, vCores:1> on host a11p2.fil.univ-lille1.fr.:55305, which has 2 containers, <memory:3072, vCores:2> used and <memory:5120, vCores:6> available after allocation
2015-04-01 17:38:40,613 INFO org.apache.hadoop.yarn.server.resourcemanager.scheduler.capacity.LeafQueue: assignedContainer application attempt=appattempt_1427899242644_0010_000001 container=Container: [ContainerId: container_1427899242644_0010_01_000003, NodeId: a11p2.fil.univ-lille1.fr.:55305, NodeHttpAddress: a11p2.fil.univ-lille1.fr.:8042, Resource: <memory:1024, vCores:1>, Priority: 10, Token: null, ] queue=default: capacity=1.0, absoluteCapacity=1.0, usedResources=<memory:2048, vCores:1>, usedCapacity=0.25, absoluteUsedCapacity=0.25, numApps=1, numContainers=1 clusterResource=<memory:8192, vCores:8>
2015-04-01 17:38:40,613 INFO org.apache.hadoop.yarn.server.resourcemanager.scheduler.capacity.ParentQueue: Re-sorting assigned queue: root.default stats: default: capacity=1.0, absoluteCapacity=1.0, usedResources=<memory:3072, vCores:2>, usedCapacity=0.375, absoluteUsedCapacity=0.375, numApps=1, numContainers=2
2015-04-01 17:38:40,613 INFO org.apache.hadoop.yarn.server.resourcemanager.scheduler.capacity.ParentQueue: assignedContainer queue=root usedCapacity=0.375 absoluteUsedCapacity=0.375 used=<memory:3072, vCores:2> cluster=<memory:8192, vCores:8>
2015-04-01 17:38:41,100 INFO org.apache.hadoop.yarn.server.resourcemanager.rmcontainer.RMContainerImpl: container_1427899242644_0010_01_000003 Container Transitioned from ALLOCATED to ACQUIRED
2015-04-01 17:38:41,614 INFO org.apache.hadoop.yarn.server.resourcemanager.rmcontainer.RMContainerImpl: container_1427899242644_0010_01_000003 Container Transitioned from ACQUIRED to RUNNING
2015-04-01 17:38:42,103 INFO org.apache.hadoop.yarn.server.resourcemanager.scheduler.AppSchedulingInfo: checking for deactivate... 
2015-04-01 17:38:43,928 INFO org.apache.hadoop.yarn.server.resourcemanager.rmapp.attempt.RMAppAttemptImpl: Updating application attempt appattempt_1427899242644_0010_000001 with final state: FINISHING, and exit status: -1000
2015-04-01 17:38:43,928 INFO org.apache.hadoop.yarn.server.resourcemanager.rmapp.attempt.RMAppAttemptImpl: appattempt_1427899242644_0010_000001 State change from RUNNING to FINAL_SAVING
2015-04-01 17:38:43,928 INFO org.apache.hadoop.yarn.server.resourcemanager.rmapp.RMAppImpl: Updating application application_1427899242644_0010 with final state: FINISHING
2015-04-01 17:38:43,928 INFO org.apache.hadoop.yarn.server.resourcemanager.rmapp.RMAppImpl: application_1427899242644_0010 State change from RUNNING to FINAL_SAVING
2015-04-01 17:38:43,928 INFO org.apache.hadoop.yarn.server.resourcemanager.recovery.RMStateStore: Updating info for app: application_1427899242644_0010
2015-04-01 17:38:43,929 INFO org.apache.hadoop.yarn.server.resourcemanager.rmapp.attempt.RMAppAttemptImpl: appattempt_1427899242644_0010_000001 State change from FINAL_SAVING to FINISHING
2015-04-01 17:38:43,929 INFO org.apache.hadoop.yarn.server.resourcemanager.rmapp.RMAppImpl: application_1427899242644_0010 State change from FINAL_SAVING to FINISHING
2015-04-01 17:38:44,574 INFO org.apache.hadoop.yarn.server.resourcemanager.rmcontainer.RMContainerImpl: container_1427899242644_0010_01_000003 Container Transitioned from RUNNING to COMPLETED
2015-04-01 17:38:44,575 INFO org.apache.hadoop.yarn.server.resourcemanager.scheduler.common.fica.FiCaSchedulerApp: Completed container: container_1427899242644_0010_01_000003 in state: COMPLETED event:FINISHED
2015-04-01 17:38:44,575 INFO org.apache.hadoop.yarn.server.resourcemanager.RMAuditLogger: USER=echallier	OPERATION=AM Released Container	TARGET=SchedulerApp	RESULT=SUCCESS	APPID=application_1427899242644_0010	CONTAINERID=container_1427899242644_0010_01_000003
2015-04-01 17:38:44,575 INFO org.apache.hadoop.yarn.server.resourcemanager.scheduler.SchedulerNode: Released container container_1427899242644_0010_01_000003 of capacity <memory:1024, vCores:1> on host a11p2.fil.univ-lille1.fr.:55305, which currently has 1 containers, <memory:2048, vCores:1> used and <memory:6144, vCores:7> available, release resources=true
2015-04-01 17:38:44,575 INFO org.apache.hadoop.yarn.server.resourcemanager.scheduler.capacity.LeafQueue: default used=<memory:2048, vCores:1> numContainers=1 user=echallier user-resources=<memory:2048, vCores:1>
2015-04-01 17:38:44,575 INFO org.apache.hadoop.yarn.server.resourcemanager.scheduler.capacity.LeafQueue: completedContainer container=Container: [ContainerId: container_1427899242644_0010_01_000003, NodeId: a11p2.fil.univ-lille1.fr.:55305, NodeHttpAddress: a11p2.fil.univ-lille1.fr.:8042, Resource: <memory:1024, vCores:1>, Priority: 10, Token: Token { kind: ContainerToken, service: 127.0.1.1:55305 }, ] queue=default: capacity=1.0, absoluteCapacity=1.0, usedResources=<memory:2048, vCores:1>, usedCapacity=0.25, absoluteUsedCapacity=0.25, numApps=1, numContainers=1 cluster=<memory:8192, vCores:8>
2015-04-01 17:38:44,575 INFO org.apache.hadoop.yarn.server.resourcemanager.scheduler.capacity.ParentQueue: completedContainer queue=root usedCapacity=0.25 absoluteUsedCapacity=0.25 used=<memory:2048, vCores:1> cluster=<memory:8192, vCores:8>
2015-04-01 17:38:44,575 INFO org.apache.hadoop.yarn.server.resourcemanager.scheduler.capacity.ParentQueue: Re-sorting completed queue: root.default stats: default: capacity=1.0, absoluteCapacity=1.0, usedResources=<memory:2048, vCores:1>, usedCapacity=0.25, absoluteUsedCapacity=0.25, numApps=1, numContainers=1
2015-04-01 17:38:44,576 INFO org.apache.hadoop.yarn.server.resourcemanager.scheduler.capacity.CapacityScheduler: Application attempt appattempt_1427899242644_0010_000001 released container container_1427899242644_0010_01_000003 on node: host: a11p2.fil.univ-lille1.fr.:55305 #containers=1 available=6144 used=2048 with event: FINISHED
2015-04-01 17:38:50,584 INFO org.apache.hadoop.yarn.server.resourcemanager.rmcontainer.RMContainerImpl: container_1427899242644_0010_01_000001 Container Transitioned from RUNNING to COMPLETED
2015-04-01 17:38:50,584 INFO org.apache.hadoop.yarn.server.resourcemanager.ApplicationMasterService: Unregistering app attempt : appattempt_1427899242644_0010_000001
2015-04-01 17:38:50,584 INFO org.apache.hadoop.yarn.server.resourcemanager.scheduler.common.fica.FiCaSchedulerApp: Completed container: container_1427899242644_0010_01_000001 in state: COMPLETED event:FINISHED
2015-04-01 17:38:50,584 INFO org.apache.hadoop.yarn.server.resourcemanager.rmapp.attempt.RMAppAttemptImpl: appattempt_1427899242644_0010_000001 State change from FINISHING to FINISHED
2015-04-01 17:38:50,584 INFO org.apache.hadoop.yarn.server.resourcemanager.RMAuditLogger: USER=echallier	OPERATION=AM Released Container	TARGET=SchedulerApp	RESULT=SUCCESS	APPID=application_1427899242644_0010	CONTAINERID=container_1427899242644_0010_01_000001
2015-04-01 17:38:50,585 INFO org.apache.hadoop.yarn.server.resourcemanager.rmapp.RMAppImpl: application_1427899242644_0010 State change from FINISHING to FINISHED
2015-04-01 17:38:50,585 INFO org.apache.hadoop.yarn.server.resourcemanager.scheduler.SchedulerNode: Released container container_1427899242644_0010_01_000001 of capacity <memory:2048, vCores:1> on host a11p2.fil.univ-lille1.fr.:55305, which currently has 0 containers, <memory:0, vCores:0> used and <memory:8192, vCores:8> available, release resources=true
2015-04-01 17:38:50,585 INFO org.apache.hadoop.yarn.server.resourcemanager.scheduler.capacity.LeafQueue: default used=<memory:0, vCores:0> numContainers=0 user=echallier user-resources=<memory:0, vCores:0>
2015-04-01 17:38:50,585 INFO org.apache.hadoop.yarn.server.resourcemanager.RMAuditLogger: USER=echallier	OPERATION=Application Finished - Succeeded	TARGET=RMAppManager	RESULT=SUCCESS	APPID=application_1427899242644_0010
2015-04-01 17:38:50,585 INFO org.apache.hadoop.yarn.server.resourcemanager.amlauncher.AMLauncher: Cleaning master appattempt_1427899242644_0010_000001
2015-04-01 17:38:50,585 INFO org.apache.hadoop.yarn.server.resourcemanager.scheduler.capacity.LeafQueue: completedContainer container=Container: [ContainerId: container_1427899242644_0010_01_000001, NodeId: a11p2.fil.univ-lille1.fr.:55305, NodeHttpAddress: a11p2.fil.univ-lille1.fr.:8042, Resource: <memory:2048, vCores:1>, Priority: 0, Token: Token { kind: ContainerToken, service: 127.0.1.1:55305 }, ] queue=default: capacity=1.0, absoluteCapacity=1.0, usedResources=<memory:0, vCores:0>, usedCapacity=0.0, absoluteUsedCapacity=0.0, numApps=1, numContainers=0 cluster=<memory:8192, vCores:8>
2015-04-01 17:38:50,585 INFO org.apache.hadoop.yarn.server.resourcemanager.scheduler.capacity.ParentQueue: completedContainer queue=root usedCapacity=0.0 absoluteUsedCapacity=0.0 used=<memory:0, vCores:0> cluster=<memory:8192, vCores:8>
2015-04-01 17:38:50,585 INFO org.apache.hadoop.yarn.server.resourcemanager.scheduler.capacity.ParentQueue: Re-sorting completed queue: root.default stats: default: capacity=1.0, absoluteCapacity=1.0, usedResources=<memory:0, vCores:0>, usedCapacity=0.0, absoluteUsedCapacity=0.0, numApps=1, numContainers=0
2015-04-01 17:38:50,585 INFO org.apache.hadoop.yarn.server.resourcemanager.scheduler.capacity.CapacityScheduler: Application attempt appattempt_1427899242644_0010_000001 released container container_1427899242644_0010_01_000001 on node: host: a11p2.fil.univ-lille1.fr.:55305 #containers=0 available=8192 used=0 with event: FINISHED
2015-04-01 17:38:50,585 INFO org.apache.hadoop.yarn.server.resourcemanager.RMAppManager$ApplicationSummary: appId=application_1427899242644_0010,name=GPS,user=echallier,queue=default,state=FINISHED,trackingUrl=http://a11p2.fil.univ-lille1.fr.:8088/proxy/application_1427899242644_0010/jobhistory/job/job_1427899242644_0010,appMasterHost=a11p2,startTime=1427902710383,finishTime=1427902723928,finalStatus=SUCCEEDED
2015-04-01 17:38:50,585 INFO org.apache.hadoop.yarn.server.resourcemanager.scheduler.capacity.CapacityScheduler: Application Attempt appattempt_1427899242644_0010_000001 is done. finalState=FINISHED
2015-04-01 17:38:50,586 INFO org.apache.hadoop.yarn.server.resourcemanager.scheduler.AppSchedulingInfo: Application application_1427899242644_0010 requests cleared
2015-04-01 17:38:50,586 INFO org.apache.hadoop.yarn.server.resourcemanager.scheduler.capacity.LeafQueue: Application removed - appId: application_1427899242644_0010 user: echallier queue: default #user-pending-applications: 0 #user-active-applications: 0 #queue-pending-applications: 0 #queue-active-applications: 0
2015-04-01 17:38:50,586 INFO org.apache.hadoop.yarn.server.resourcemanager.scheduler.capacity.ParentQueue: Application removed - appId: application_1427899242644_0010 user: echallier leaf-queue of parent: root #applications: 0
2015-04-01 17:40:17,154 INFO org.apache.hadoop.yarn.server.resourcemanager.ClientRMService: Allocated new applicationId: 11
2015-04-01 17:40:17,925 INFO org.apache.hadoop.yarn.server.resourcemanager.ClientRMService: Application with id 11 submitted by user echallier
2015-04-01 17:40:17,925 INFO org.apache.hadoop.yarn.server.resourcemanager.RMAuditLogger: USER=echallier	IP=127.0.0.1	OPERATION=Submit Application Request	TARGET=ClientRMService	RESULT=SUCCESS	APPID=application_1427899242644_0011
2015-04-01 17:40:17,925 INFO org.apache.hadoop.yarn.server.resourcemanager.rmapp.RMAppImpl: Storing application with id application_1427899242644_0011
2015-04-01 17:40:17,926 INFO org.apache.hadoop.yarn.server.resourcemanager.recovery.RMStateStore: Storing info for app: application_1427899242644_0011
2015-04-01 17:40:17,926 INFO org.apache.hadoop.yarn.server.resourcemanager.rmapp.RMAppImpl: application_1427899242644_0011 State change from NEW to NEW_SAVING
2015-04-01 17:40:17,926 INFO org.apache.hadoop.yarn.server.resourcemanager.rmapp.RMAppImpl: application_1427899242644_0011 State change from NEW_SAVING to SUBMITTED
2015-04-01 17:40:17,926 INFO org.apache.hadoop.yarn.server.resourcemanager.scheduler.capacity.ParentQueue: Application added - appId: application_1427899242644_0011 user: echallier leaf-queue of parent: root #applications: 1
2015-04-01 17:40:17,926 INFO org.apache.hadoop.yarn.server.resourcemanager.scheduler.capacity.CapacityScheduler: Accepted application application_1427899242644_0011 from user: echallier, in queue: default
2015-04-01 17:40:17,926 INFO org.apache.hadoop.yarn.server.resourcemanager.rmapp.RMAppImpl: application_1427899242644_0011 State change from SUBMITTED to ACCEPTED
2015-04-01 17:40:17,926 INFO org.apache.hadoop.yarn.server.resourcemanager.ApplicationMasterService: Registering app attempt : appattempt_1427899242644_0011_000001
2015-04-01 17:40:17,927 INFO org.apache.hadoop.yarn.server.resourcemanager.rmapp.attempt.RMAppAttemptImpl: appattempt_1427899242644_0011_000001 State change from NEW to SUBMITTED
2015-04-01 17:40:17,927 INFO org.apache.hadoop.yarn.server.resourcemanager.scheduler.capacity.LeafQueue: Application application_1427899242644_0011 from user: echallier activated in queue: default
2015-04-01 17:40:17,927 INFO org.apache.hadoop.yarn.server.resourcemanager.scheduler.capacity.LeafQueue: Application added - appId: application_1427899242644_0011 user: org.apache.hadoop.yarn.server.resourcemanager.scheduler.capacity.LeafQueue$User@a089d4, leaf-queue: default #user-pending-applications: 0 #user-active-applications: 1 #queue-pending-applications: 0 #queue-active-applications: 1
2015-04-01 17:40:17,927 INFO org.apache.hadoop.yarn.server.resourcemanager.scheduler.capacity.CapacityScheduler: Added Application Attempt appattempt_1427899242644_0011_000001 to scheduler from user echallier in queue default
2015-04-01 17:40:17,927 INFO org.apache.hadoop.yarn.server.resourcemanager.rmapp.attempt.RMAppAttemptImpl: appattempt_1427899242644_0011_000001 State change from SUBMITTED to SCHEDULED
2015-04-01 17:40:18,705 INFO org.apache.hadoop.yarn.server.resourcemanager.rmcontainer.RMContainerImpl: container_1427899242644_0011_01_000001 Container Transitioned from NEW to ALLOCATED
2015-04-01 17:40:18,705 INFO org.apache.hadoop.yarn.server.resourcemanager.RMAuditLogger: USER=echallier	OPERATION=AM Allocated Container	TARGET=SchedulerApp	RESULT=SUCCESS	APPID=application_1427899242644_0011	CONTAINERID=container_1427899242644_0011_01_000001
2015-04-01 17:40:18,705 INFO org.apache.hadoop.yarn.server.resourcemanager.scheduler.SchedulerNode: Assigned container container_1427899242644_0011_01_000001 of capacity <memory:2048, vCores:1> on host a11p2.fil.univ-lille1.fr.:55305, which has 1 containers, <memory:2048, vCores:1> used and <memory:6144, vCores:7> available after allocation
2015-04-01 17:40:18,705 INFO org.apache.hadoop.yarn.server.resourcemanager.scheduler.capacity.LeafQueue: assignedContainer application attempt=appattempt_1427899242644_0011_000001 container=Container: [ContainerId: container_1427899242644_0011_01_000001, NodeId: a11p2.fil.univ-lille1.fr.:55305, NodeHttpAddress: a11p2.fil.univ-lille1.fr.:8042, Resource: <memory:2048, vCores:1>, Priority: 0, Token: null, ] queue=default: capacity=1.0, absoluteCapacity=1.0, usedResources=<memory:0, vCores:0>, usedCapacity=0.0, absoluteUsedCapacity=0.0, numApps=1, numContainers=0 clusterResource=<memory:8192, vCores:8>
2015-04-01 17:40:18,705 INFO org.apache.hadoop.yarn.server.resourcemanager.scheduler.capacity.ParentQueue: Re-sorting assigned queue: root.default stats: default: capacity=1.0, absoluteCapacity=1.0, usedResources=<memory:2048, vCores:1>, usedCapacity=0.25, absoluteUsedCapacity=0.25, numApps=1, numContainers=1
2015-04-01 17:40:18,705 INFO org.apache.hadoop.yarn.server.resourcemanager.scheduler.capacity.ParentQueue: assignedContainer queue=root usedCapacity=0.25 absoluteUsedCapacity=0.25 used=<memory:2048, vCores:1> cluster=<memory:8192, vCores:8>
2015-04-01 17:40:18,706 INFO org.apache.hadoop.yarn.server.resourcemanager.security.NMTokenSecretManagerInRM: Sending NMToken for nodeId : a11p2.fil.univ-lille1.fr.:55305 for container : container_1427899242644_0011_01_000001
2015-04-01 17:40:18,706 INFO org.apache.hadoop.yarn.server.resourcemanager.rmcontainer.RMContainerImpl: container_1427899242644_0011_01_000001 Container Transitioned from ALLOCATED to ACQUIRED
2015-04-01 17:40:18,706 INFO org.apache.hadoop.yarn.server.resourcemanager.security.NMTokenSecretManagerInRM: Clear node set for appattempt_1427899242644_0011_000001
2015-04-01 17:40:18,707 INFO org.apache.hadoop.yarn.server.resourcemanager.rmapp.attempt.RMAppAttemptImpl: Storing attempt: AppId: application_1427899242644_0011 AttemptId: appattempt_1427899242644_0011_000001 MasterContainer: Container: [ContainerId: container_1427899242644_0011_01_000001, NodeId: a11p2.fil.univ-lille1.fr.:55305, NodeHttpAddress: a11p2.fil.univ-lille1.fr.:8042, Resource: <memory:2048, vCores:1>, Priority: 0, Token: Token { kind: ContainerToken, service: 127.0.1.1:55305 }, ]
2015-04-01 17:40:18,707 INFO org.apache.hadoop.yarn.server.resourcemanager.rmapp.attempt.RMAppAttemptImpl: appattempt_1427899242644_0011_000001 State change from SCHEDULED to ALLOCATED_SAVING
2015-04-01 17:40:18,707 INFO org.apache.hadoop.yarn.server.resourcemanager.rmapp.attempt.RMAppAttemptImpl: appattempt_1427899242644_0011_000001 State change from ALLOCATED_SAVING to ALLOCATED
2015-04-01 17:40:18,707 INFO org.apache.hadoop.yarn.server.resourcemanager.amlauncher.AMLauncher: Launching masterappattempt_1427899242644_0011_000001
2015-04-01 17:40:18,708 INFO org.apache.hadoop.yarn.server.resourcemanager.amlauncher.AMLauncher: Setting up container Container: [ContainerId: container_1427899242644_0011_01_000001, NodeId: a11p2.fil.univ-lille1.fr.:55305, NodeHttpAddress: a11p2.fil.univ-lille1.fr.:8042, Resource: <memory:2048, vCores:1>, Priority: 0, Token: Token { kind: ContainerToken, service: 127.0.1.1:55305 }, ] for AM appattempt_1427899242644_0011_000001
2015-04-01 17:40:18,708 INFO org.apache.hadoop.yarn.server.resourcemanager.amlauncher.AMLauncher: Command to launch container container_1427899242644_0011_01_000001 : $JAVA_HOME/bin/java -Dlog4j.configuration=container-log4j.properties -Dyarn.app.container.log.dir=<LOG_DIR> -Dyarn.app.container.log.filesize=0 -Dhadoop.root.logger=INFO,CLA  -Xmx1024m org.apache.hadoop.mapreduce.v2.app.MRAppMaster 1><LOG_DIR>/stdout 2><LOG_DIR>/stderr 
2015-04-01 17:40:18,718 INFO org.apache.hadoop.yarn.server.resourcemanager.amlauncher.AMLauncher: Done launching container Container: [ContainerId: container_1427899242644_0011_01_000001, NodeId: a11p2.fil.univ-lille1.fr.:55305, NodeHttpAddress: a11p2.fil.univ-lille1.fr.:8042, Resource: <memory:2048, vCores:1>, Priority: 0, Token: Token { kind: ContainerToken, service: 127.0.1.1:55305 }, ] for AM appattempt_1427899242644_0011_000001
2015-04-01 17:40:18,718 INFO org.apache.hadoop.yarn.server.resourcemanager.rmapp.attempt.RMAppAttemptImpl: appattempt_1427899242644_0011_000001 State change from ALLOCATED to LAUNCHED
2015-04-01 17:40:19,705 INFO org.apache.hadoop.yarn.server.resourcemanager.rmcontainer.RMContainerImpl: container_1427899242644_0011_01_000001 Container Transitioned from ACQUIRED to RUNNING
2015-04-01 17:40:21,559 INFO SecurityLogger.org.apache.hadoop.ipc.Server: Auth successful for appattempt_1427899242644_0011_000001 (auth:SIMPLE)
2015-04-01 17:40:21,561 INFO org.apache.hadoop.yarn.server.resourcemanager.ApplicationMasterService: AM registration appattempt_1427899242644_0011_000001
2015-04-01 17:40:21,561 INFO org.apache.hadoop.yarn.server.resourcemanager.RMAuditLogger: USER=echallier	IP=127.0.0.1	OPERATION=Register App Master	TARGET=ApplicationMasterService	RESULT=SUCCESS	APPID=application_1427899242644_0011	APPATTEMPTID=appattempt_1427899242644_0011_000001
2015-04-01 17:40:21,562 INFO org.apache.hadoop.yarn.server.resourcemanager.rmapp.attempt.RMAppAttemptImpl: appattempt_1427899242644_0011_000001 State change from LAUNCHED to RUNNING
2015-04-01 17:40:21,562 INFO org.apache.hadoop.yarn.server.resourcemanager.rmapp.RMAppImpl: application_1427899242644_0011 State change from ACCEPTED to RUNNING
2015-04-01 17:40:22,709 INFO org.apache.hadoop.yarn.server.resourcemanager.rmcontainer.RMContainerImpl: container_1427899242644_0011_01_000002 Container Transitioned from NEW to ALLOCATED
2015-04-01 17:40:22,709 INFO org.apache.hadoop.yarn.server.resourcemanager.RMAuditLogger: USER=echallier	OPERATION=AM Allocated Container	TARGET=SchedulerApp	RESULT=SUCCESS	APPID=application_1427899242644_0011	CONTAINERID=container_1427899242644_0011_01_000002
2015-04-01 17:40:22,709 INFO org.apache.hadoop.yarn.server.resourcemanager.scheduler.SchedulerNode: Assigned container container_1427899242644_0011_01_000002 of capacity <memory:1024, vCores:1> on host a11p2.fil.univ-lille1.fr.:55305, which has 2 containers, <memory:3072, vCores:2> used and <memory:5120, vCores:6> available after allocation
2015-04-01 17:40:22,710 INFO org.apache.hadoop.yarn.server.resourcemanager.scheduler.capacity.LeafQueue: assignedContainer application attempt=appattempt_1427899242644_0011_000001 container=Container: [ContainerId: container_1427899242644_0011_01_000002, NodeId: a11p2.fil.univ-lille1.fr.:55305, NodeHttpAddress: a11p2.fil.univ-lille1.fr.:8042, Resource: <memory:1024, vCores:1>, Priority: 20, Token: null, ] queue=default: capacity=1.0, absoluteCapacity=1.0, usedResources=<memory:2048, vCores:1>, usedCapacity=0.25, absoluteUsedCapacity=0.25, numApps=1, numContainers=1 clusterResource=<memory:8192, vCores:8>
2015-04-01 17:40:22,710 INFO org.apache.hadoop.yarn.server.resourcemanager.scheduler.capacity.ParentQueue: Re-sorting assigned queue: root.default stats: default: capacity=1.0, absoluteCapacity=1.0, usedResources=<memory:3072, vCores:2>, usedCapacity=0.375, absoluteUsedCapacity=0.375, numApps=1, numContainers=2
2015-04-01 17:40:22,710 INFO org.apache.hadoop.yarn.server.resourcemanager.scheduler.capacity.ParentQueue: assignedContainer queue=root usedCapacity=0.375 absoluteUsedCapacity=0.375 used=<memory:3072, vCores:2> cluster=<memory:8192, vCores:8>
2015-04-01 17:40:23,618 INFO org.apache.hadoop.yarn.server.resourcemanager.security.NMTokenSecretManagerInRM: Sending NMToken for nodeId : a11p2.fil.univ-lille1.fr.:55305 for container : container_1427899242644_0011_01_000002
2015-04-01 17:40:23,620 INFO org.apache.hadoop.yarn.server.resourcemanager.rmcontainer.RMContainerImpl: container_1427899242644_0011_01_000002 Container Transitioned from ALLOCATED to ACQUIRED
2015-04-01 17:40:24,632 INFO org.apache.hadoop.yarn.server.resourcemanager.scheduler.AppSchedulingInfo: checking for deactivate... 
2015-04-01 17:40:24,712 INFO org.apache.hadoop.yarn.server.resourcemanager.rmcontainer.RMContainerImpl: container_1427899242644_0011_01_000002 Container Transitioned from ACQUIRED to RUNNING
2015-04-01 17:40:27,154 INFO org.apache.hadoop.yarn.server.resourcemanager.rmcontainer.RMContainerImpl: container_1427899242644_0011_01_000002 Container Transitioned from RUNNING to COMPLETED
2015-04-01 17:40:27,154 INFO org.apache.hadoop.yarn.server.resourcemanager.scheduler.common.fica.FiCaSchedulerApp: Completed container: container_1427899242644_0011_01_000002 in state: COMPLETED event:FINISHED
2015-04-01 17:40:27,155 INFO org.apache.hadoop.yarn.server.resourcemanager.RMAuditLogger: USER=echallier	OPERATION=AM Released Container	TARGET=SchedulerApp	RESULT=SUCCESS	APPID=application_1427899242644_0011	CONTAINERID=container_1427899242644_0011_01_000002
2015-04-01 17:40:27,155 INFO org.apache.hadoop.yarn.server.resourcemanager.scheduler.SchedulerNode: Released container container_1427899242644_0011_01_000002 of capacity <memory:1024, vCores:1> on host a11p2.fil.univ-lille1.fr.:55305, which currently has 1 containers, <memory:2048, vCores:1> used and <memory:6144, vCores:7> available, release resources=true
2015-04-01 17:40:27,155 INFO org.apache.hadoop.yarn.server.resourcemanager.scheduler.capacity.LeafQueue: default used=<memory:2048, vCores:1> numContainers=1 user=echallier user-resources=<memory:2048, vCores:1>
2015-04-01 17:40:27,155 INFO org.apache.hadoop.yarn.server.resourcemanager.scheduler.capacity.LeafQueue: completedContainer container=Container: [ContainerId: container_1427899242644_0011_01_000002, NodeId: a11p2.fil.univ-lille1.fr.:55305, NodeHttpAddress: a11p2.fil.univ-lille1.fr.:8042, Resource: <memory:1024, vCores:1>, Priority: 20, Token: Token { kind: ContainerToken, service: 127.0.1.1:55305 }, ] queue=default: capacity=1.0, absoluteCapacity=1.0, usedResources=<memory:2048, vCores:1>, usedCapacity=0.25, absoluteUsedCapacity=0.25, numApps=1, numContainers=1 cluster=<memory:8192, vCores:8>
2015-04-01 17:40:27,155 INFO org.apache.hadoop.yarn.server.resourcemanager.scheduler.capacity.ParentQueue: completedContainer queue=root usedCapacity=0.25 absoluteUsedCapacity=0.25 used=<memory:2048, vCores:1> cluster=<memory:8192, vCores:8>
2015-04-01 17:40:27,155 INFO org.apache.hadoop.yarn.server.resourcemanager.scheduler.capacity.ParentQueue: Re-sorting completed queue: root.default stats: default: capacity=1.0, absoluteCapacity=1.0, usedResources=<memory:2048, vCores:1>, usedCapacity=0.25, absoluteUsedCapacity=0.25, numApps=1, numContainers=1
2015-04-01 17:40:27,155 INFO org.apache.hadoop.yarn.server.resourcemanager.scheduler.capacity.CapacityScheduler: Application attempt appattempt_1427899242644_0011_000001 released container container_1427899242644_0011_01_000002 on node: host: a11p2.fil.univ-lille1.fr.:55305 #containers=1 available=6144 used=2048 with event: FINISHED
2015-04-01 17:40:27,156 INFO org.apache.hadoop.yarn.server.resourcemanager.rmcontainer.RMContainerImpl: container_1427899242644_0011_01_000003 Container Transitioned from NEW to ALLOCATED
2015-04-01 17:40:27,156 INFO org.apache.hadoop.yarn.server.resourcemanager.RMAuditLogger: USER=echallier	OPERATION=AM Allocated Container	TARGET=SchedulerApp	RESULT=SUCCESS	APPID=application_1427899242644_0011	CONTAINERID=container_1427899242644_0011_01_000003
2015-04-01 17:40:27,156 INFO org.apache.hadoop.yarn.server.resourcemanager.scheduler.SchedulerNode: Assigned container container_1427899242644_0011_01_000003 of capacity <memory:1024, vCores:1> on host a11p2.fil.univ-lille1.fr.:55305, which has 2 containers, <memory:3072, vCores:2> used and <memory:5120, vCores:6> available after allocation
2015-04-01 17:40:27,156 INFO org.apache.hadoop.yarn.server.resourcemanager.scheduler.capacity.LeafQueue: assignedContainer application attempt=appattempt_1427899242644_0011_000001 container=Container: [ContainerId: container_1427899242644_0011_01_000003, NodeId: a11p2.fil.univ-lille1.fr.:55305, NodeHttpAddress: a11p2.fil.univ-lille1.fr.:8042, Resource: <memory:1024, vCores:1>, Priority: 5, Token: null, ] queue=default: capacity=1.0, absoluteCapacity=1.0, usedResources=<memory:2048, vCores:1>, usedCapacity=0.25, absoluteUsedCapacity=0.25, numApps=1, numContainers=1 clusterResource=<memory:8192, vCores:8>
2015-04-01 17:40:27,156 INFO org.apache.hadoop.yarn.server.resourcemanager.scheduler.capacity.ParentQueue: Re-sorting assigned queue: root.default stats: default: capacity=1.0, absoluteCapacity=1.0, usedResources=<memory:3072, vCores:2>, usedCapacity=0.375, absoluteUsedCapacity=0.375, numApps=1, numContainers=2
2015-04-01 17:40:27,156 INFO org.apache.hadoop.yarn.server.resourcemanager.scheduler.capacity.ParentQueue: assignedContainer queue=root usedCapacity=0.375 absoluteUsedCapacity=0.375 used=<memory:3072, vCores:2> cluster=<memory:8192, vCores:8>
2015-04-01 17:40:27,639 INFO org.apache.hadoop.yarn.server.resourcemanager.rmcontainer.RMContainerImpl: container_1427899242644_0011_01_000003 Container Transitioned from ALLOCATED to ACQUIRED
2015-04-01 17:40:28,156 INFO org.apache.hadoop.yarn.server.resourcemanager.rmcontainer.RMContainerImpl: container_1427899242644_0011_01_000003 Container Transitioned from ACQUIRED to RUNNING
2015-04-01 17:40:28,648 INFO org.apache.hadoop.yarn.server.resourcemanager.scheduler.AppSchedulingInfo: checking for deactivate... 
2015-04-01 17:40:30,763 INFO org.apache.hadoop.yarn.server.resourcemanager.rmcontainer.RMContainerImpl: container_1427899242644_0011_01_000003 Container Transitioned from RUNNING to COMPLETED
2015-04-01 17:40:30,763 INFO org.apache.hadoop.yarn.server.resourcemanager.scheduler.common.fica.FiCaSchedulerApp: Completed container: container_1427899242644_0011_01_000003 in state: COMPLETED event:FINISHED
2015-04-01 17:40:30,763 INFO org.apache.hadoop.yarn.server.resourcemanager.RMAuditLogger: USER=echallier	OPERATION=AM Released Container	TARGET=SchedulerApp	RESULT=SUCCESS	APPID=application_1427899242644_0011	CONTAINERID=container_1427899242644_0011_01_000003
2015-04-01 17:40:30,763 INFO org.apache.hadoop.yarn.server.resourcemanager.scheduler.SchedulerNode: Released container container_1427899242644_0011_01_000003 of capacity <memory:1024, vCores:1> on host a11p2.fil.univ-lille1.fr.:55305, which currently has 1 containers, <memory:2048, vCores:1> used and <memory:6144, vCores:7> available, release resources=true
2015-04-01 17:40:30,763 INFO org.apache.hadoop.yarn.server.resourcemanager.scheduler.capacity.LeafQueue: default used=<memory:2048, vCores:1> numContainers=1 user=echallier user-resources=<memory:2048, vCores:1>
2015-04-01 17:40:30,763 INFO org.apache.hadoop.yarn.server.resourcemanager.scheduler.capacity.LeafQueue: completedContainer container=Container: [ContainerId: container_1427899242644_0011_01_000003, NodeId: a11p2.fil.univ-lille1.fr.:55305, NodeHttpAddress: a11p2.fil.univ-lille1.fr.:8042, Resource: <memory:1024, vCores:1>, Priority: 5, Token: Token { kind: ContainerToken, service: 127.0.1.1:55305 }, ] queue=default: capacity=1.0, absoluteCapacity=1.0, usedResources=<memory:2048, vCores:1>, usedCapacity=0.25, absoluteUsedCapacity=0.25, numApps=1, numContainers=1 cluster=<memory:8192, vCores:8>
2015-04-01 17:40:30,764 INFO org.apache.hadoop.yarn.server.resourcemanager.scheduler.capacity.ParentQueue: completedContainer queue=root usedCapacity=0.25 absoluteUsedCapacity=0.25 used=<memory:2048, vCores:1> cluster=<memory:8192, vCores:8>
2015-04-01 17:40:30,764 INFO org.apache.hadoop.yarn.server.resourcemanager.scheduler.capacity.ParentQueue: Re-sorting completed queue: root.default stats: default: capacity=1.0, absoluteCapacity=1.0, usedResources=<memory:2048, vCores:1>, usedCapacity=0.25, absoluteUsedCapacity=0.25, numApps=1, numContainers=1
2015-04-01 17:40:30,764 INFO org.apache.hadoop.yarn.server.resourcemanager.scheduler.capacity.CapacityScheduler: Application attempt appattempt_1427899242644_0011_000001 released container container_1427899242644_0011_01_000003 on node: host: a11p2.fil.univ-lille1.fr.:55305 #containers=1 available=6144 used=2048 with event: FINISHED
2015-04-01 17:40:30,764 INFO org.apache.hadoop.yarn.server.resourcemanager.rmcontainer.RMContainerImpl: container_1427899242644_0011_01_000004 Container Transitioned from NEW to ALLOCATED
2015-04-01 17:40:30,764 INFO org.apache.hadoop.yarn.server.resourcemanager.RMAuditLogger: USER=echallier	OPERATION=AM Allocated Container	TARGET=SchedulerApp	RESULT=SUCCESS	APPID=application_1427899242644_0011	CONTAINERID=container_1427899242644_0011_01_000004
2015-04-01 17:40:30,764 INFO org.apache.hadoop.yarn.server.resourcemanager.scheduler.SchedulerNode: Assigned container container_1427899242644_0011_01_000004 of capacity <memory:1024, vCores:1> on host a11p2.fil.univ-lille1.fr.:55305, which has 2 containers, <memory:3072, vCores:2> used and <memory:5120, vCores:6> available after allocation
2015-04-01 17:40:30,764 INFO org.apache.hadoop.yarn.server.resourcemanager.scheduler.capacity.LeafQueue: assignedContainer application attempt=appattempt_1427899242644_0011_000001 container=Container: [ContainerId: container_1427899242644_0011_01_000004, NodeId: a11p2.fil.univ-lille1.fr.:55305, NodeHttpAddress: a11p2.fil.univ-lille1.fr.:8042, Resource: <memory:1024, vCores:1>, Priority: 5, Token: null, ] queue=default: capacity=1.0, absoluteCapacity=1.0, usedResources=<memory:2048, vCores:1>, usedCapacity=0.25, absoluteUsedCapacity=0.25, numApps=1, numContainers=1 clusterResource=<memory:8192, vCores:8>
2015-04-01 17:40:30,764 INFO org.apache.hadoop.yarn.server.resourcemanager.scheduler.capacity.ParentQueue: Re-sorting assigned queue: root.default stats: default: capacity=1.0, absoluteCapacity=1.0, usedResources=<memory:3072, vCores:2>, usedCapacity=0.375, absoluteUsedCapacity=0.375, numApps=1, numContainers=2
2015-04-01 17:40:30,764 INFO org.apache.hadoop.yarn.server.resourcemanager.scheduler.capacity.ParentQueue: assignedContainer queue=root usedCapacity=0.375 absoluteUsedCapacity=0.375 used=<memory:3072, vCores:2> cluster=<memory:8192, vCores:8>
2015-04-01 17:40:31,654 INFO org.apache.hadoop.yarn.server.resourcemanager.rmcontainer.RMContainerImpl: container_1427899242644_0011_01_000004 Container Transitioned from ALLOCATED to ACQUIRED
2015-04-01 17:40:31,765 INFO org.apache.hadoop.yarn.server.resourcemanager.rmcontainer.RMContainerImpl: container_1427899242644_0011_01_000004 Container Transitioned from ACQUIRED to RUNNING
2015-04-01 17:40:32,658 INFO org.apache.hadoop.yarn.server.resourcemanager.scheduler.AppSchedulingInfo: checking for deactivate... 
2015-04-01 17:40:34,662 INFO org.apache.hadoop.yarn.server.resourcemanager.ApplicationMasterService: blacklist are updated in Scheduler.blacklistAdditions: [a11p2.fil.univ-lille1.fr.], blacklistRemovals: []
2015-04-01 17:40:34,666 INFO org.apache.hadoop.yarn.server.resourcemanager.rmcontainer.RMContainerImpl: container_1427899242644_0011_01_000004 Container Transitioned from RUNNING to COMPLETED
2015-04-01 17:40:34,666 INFO org.apache.hadoop.yarn.server.resourcemanager.scheduler.common.fica.FiCaSchedulerApp: Completed container: container_1427899242644_0011_01_000004 in state: COMPLETED event:FINISHED
2015-04-01 17:40:34,666 INFO org.apache.hadoop.yarn.server.resourcemanager.RMAuditLogger: USER=echallier	OPERATION=AM Released Container	TARGET=SchedulerApp	RESULT=SUCCESS	APPID=application_1427899242644_0011	CONTAINERID=container_1427899242644_0011_01_000004
2015-04-01 17:40:34,666 INFO org.apache.hadoop.yarn.server.resourcemanager.scheduler.SchedulerNode: Released container container_1427899242644_0011_01_000004 of capacity <memory:1024, vCores:1> on host a11p2.fil.univ-lille1.fr.:55305, which currently has 1 containers, <memory:2048, vCores:1> used and <memory:6144, vCores:7> available, release resources=true
2015-04-01 17:40:34,666 INFO org.apache.hadoop.yarn.server.resourcemanager.scheduler.capacity.LeafQueue: default used=<memory:2048, vCores:1> numContainers=1 user=echallier user-resources=<memory:2048, vCores:1>
2015-04-01 17:40:34,667 INFO org.apache.hadoop.yarn.server.resourcemanager.scheduler.capacity.LeafQueue: completedContainer container=Container: [ContainerId: container_1427899242644_0011_01_000004, NodeId: a11p2.fil.univ-lille1.fr.:55305, NodeHttpAddress: a11p2.fil.univ-lille1.fr.:8042, Resource: <memory:1024, vCores:1>, Priority: 5, Token: Token { kind: ContainerToken, service: 127.0.1.1:55305 }, ] queue=default: capacity=1.0, absoluteCapacity=1.0, usedResources=<memory:2048, vCores:1>, usedCapacity=0.25, absoluteUsedCapacity=0.25, numApps=1, numContainers=1 cluster=<memory:8192, vCores:8>
2015-04-01 17:40:34,667 INFO org.apache.hadoop.yarn.server.resourcemanager.scheduler.capacity.ParentQueue: completedContainer queue=root usedCapacity=0.25 absoluteUsedCapacity=0.25 used=<memory:2048, vCores:1> cluster=<memory:8192, vCores:8>
2015-04-01 17:40:34,667 INFO org.apache.hadoop.yarn.server.resourcemanager.scheduler.capacity.ParentQueue: Re-sorting completed queue: root.default stats: default: capacity=1.0, absoluteCapacity=1.0, usedResources=<memory:2048, vCores:1>, usedCapacity=0.25, absoluteUsedCapacity=0.25, numApps=1, numContainers=1
2015-04-01 17:40:34,667 INFO org.apache.hadoop.yarn.server.resourcemanager.scheduler.capacity.CapacityScheduler: Application attempt appattempt_1427899242644_0011_000001 released container container_1427899242644_0011_01_000004 on node: host: a11p2.fil.univ-lille1.fr.:55305 #containers=1 available=6144 used=2048 with event: FINISHED
2015-04-01 17:40:35,665 INFO org.apache.hadoop.yarn.server.resourcemanager.ApplicationMasterService: blacklist are updated in Scheduler.blacklistAdditions: [], blacklistRemovals: [a11p2.fil.univ-lille1.fr.]
2015-04-01 17:40:35,668 INFO org.apache.hadoop.yarn.server.resourcemanager.rmcontainer.RMContainerImpl: container_1427899242644_0011_01_000005 Container Transitioned from NEW to ALLOCATED
2015-04-01 17:40:35,668 INFO org.apache.hadoop.yarn.server.resourcemanager.RMAuditLogger: USER=echallier	OPERATION=AM Allocated Container	TARGET=SchedulerApp	RESULT=SUCCESS	APPID=application_1427899242644_0011	CONTAINERID=container_1427899242644_0011_01_000005
2015-04-01 17:40:35,668 INFO org.apache.hadoop.yarn.server.resourcemanager.scheduler.SchedulerNode: Assigned container container_1427899242644_0011_01_000005 of capacity <memory:1024, vCores:1> on host a11p2.fil.univ-lille1.fr.:55305, which has 2 containers, <memory:3072, vCores:2> used and <memory:5120, vCores:6> available after allocation
2015-04-01 17:40:35,668 INFO org.apache.hadoop.yarn.server.resourcemanager.scheduler.capacity.LeafQueue: assignedContainer application attempt=appattempt_1427899242644_0011_000001 container=Container: [ContainerId: container_1427899242644_0011_01_000005, NodeId: a11p2.fil.univ-lille1.fr.:55305, NodeHttpAddress: a11p2.fil.univ-lille1.fr.:8042, Resource: <memory:1024, vCores:1>, Priority: 5, Token: null, ] queue=default: capacity=1.0, absoluteCapacity=1.0, usedResources=<memory:2048, vCores:1>, usedCapacity=0.25, absoluteUsedCapacity=0.25, numApps=1, numContainers=1 clusterResource=<memory:8192, vCores:8>
2015-04-01 17:40:35,668 INFO org.apache.hadoop.yarn.server.resourcemanager.scheduler.capacity.ParentQueue: Re-sorting assigned queue: root.default stats: default: capacity=1.0, absoluteCapacity=1.0, usedResources=<memory:3072, vCores:2>, usedCapacity=0.375, absoluteUsedCapacity=0.375, numApps=1, numContainers=2
2015-04-01 17:40:35,668 INFO org.apache.hadoop.yarn.server.resourcemanager.scheduler.capacity.ParentQueue: assignedContainer queue=root usedCapacity=0.375 absoluteUsedCapacity=0.375 used=<memory:3072, vCores:2> cluster=<memory:8192, vCores:8>
2015-04-01 17:40:36,669 INFO org.apache.hadoop.yarn.server.resourcemanager.rmcontainer.RMContainerImpl: container_1427899242644_0011_01_000005 Container Transitioned from ALLOCATED to ACQUIRED
2015-04-01 17:40:37,670 INFO org.apache.hadoop.yarn.server.resourcemanager.rmcontainer.RMContainerImpl: container_1427899242644_0011_01_000005 Container Transitioned from ACQUIRED to RUNNING
2015-04-01 17:40:37,682 INFO org.apache.hadoop.yarn.server.resourcemanager.scheduler.AppSchedulingInfo: checking for deactivate... 
2015-04-01 17:40:39,056 INFO org.apache.hadoop.yarn.server.resourcemanager.rmapp.attempt.RMAppAttemptImpl: Updating application attempt appattempt_1427899242644_0011_000001 with final state: FINISHING, and exit status: -1000
2015-04-01 17:40:39,056 INFO org.apache.hadoop.yarn.server.resourcemanager.rmapp.attempt.RMAppAttemptImpl: appattempt_1427899242644_0011_000001 State change from RUNNING to FINAL_SAVING
2015-04-01 17:40:39,056 INFO org.apache.hadoop.yarn.server.resourcemanager.rmapp.RMAppImpl: Updating application application_1427899242644_0011 with final state: FINISHING
2015-04-01 17:40:39,056 INFO org.apache.hadoop.yarn.server.resourcemanager.rmapp.RMAppImpl: application_1427899242644_0011 State change from RUNNING to FINAL_SAVING
2015-04-01 17:40:39,056 INFO org.apache.hadoop.yarn.server.resourcemanager.recovery.RMStateStore: Updating info for app: application_1427899242644_0011
2015-04-01 17:40:39,056 INFO org.apache.hadoop.yarn.server.resourcemanager.rmapp.attempt.RMAppAttemptImpl: appattempt_1427899242644_0011_000001 State change from FINAL_SAVING to FINISHING
2015-04-01 17:40:39,056 INFO org.apache.hadoop.yarn.server.resourcemanager.rmapp.RMAppImpl: application_1427899242644_0011 State change from FINAL_SAVING to FINISHING
2015-04-01 17:40:39,766 INFO org.apache.hadoop.yarn.server.resourcemanager.rmcontainer.RMContainerImpl: container_1427899242644_0011_01_000005 Container Transitioned from RUNNING to COMPLETED
2015-04-01 17:40:39,766 INFO org.apache.hadoop.yarn.server.resourcemanager.scheduler.common.fica.FiCaSchedulerApp: Completed container: container_1427899242644_0011_01_000005 in state: COMPLETED event:FINISHED
2015-04-01 17:40:39,766 INFO org.apache.hadoop.yarn.server.resourcemanager.RMAuditLogger: USER=echallier	OPERATION=AM Released Container	TARGET=SchedulerApp	RESULT=SUCCESS	APPID=application_1427899242644_0011	CONTAINERID=container_1427899242644_0011_01_000005
2015-04-01 17:40:39,766 INFO org.apache.hadoop.yarn.server.resourcemanager.scheduler.SchedulerNode: Released container container_1427899242644_0011_01_000005 of capacity <memory:1024, vCores:1> on host a11p2.fil.univ-lille1.fr.:55305, which currently has 1 containers, <memory:2048, vCores:1> used and <memory:6144, vCores:7> available, release resources=true
2015-04-01 17:40:39,766 INFO org.apache.hadoop.yarn.server.resourcemanager.scheduler.capacity.LeafQueue: default used=<memory:2048, vCores:1> numContainers=1 user=echallier user-resources=<memory:2048, vCores:1>
2015-04-01 17:40:39,767 INFO org.apache.hadoop.yarn.server.resourcemanager.scheduler.capacity.LeafQueue: completedContainer container=Container: [ContainerId: container_1427899242644_0011_01_000005, NodeId: a11p2.fil.univ-lille1.fr.:55305, NodeHttpAddress: a11p2.fil.univ-lille1.fr.:8042, Resource: <memory:1024, vCores:1>, Priority: 5, Token: Token { kind: ContainerToken, service: 127.0.1.1:55305 }, ] queue=default: capacity=1.0, absoluteCapacity=1.0, usedResources=<memory:2048, vCores:1>, usedCapacity=0.25, absoluteUsedCapacity=0.25, numApps=1, numContainers=1 cluster=<memory:8192, vCores:8>
2015-04-01 17:40:39,767 INFO org.apache.hadoop.yarn.server.resourcemanager.scheduler.capacity.ParentQueue: completedContainer queue=root usedCapacity=0.25 absoluteUsedCapacity=0.25 used=<memory:2048, vCores:1> cluster=<memory:8192, vCores:8>
2015-04-01 17:40:39,767 INFO org.apache.hadoop.yarn.server.resourcemanager.scheduler.capacity.ParentQueue: Re-sorting completed queue: root.default stats: default: capacity=1.0, absoluteCapacity=1.0, usedResources=<memory:2048, vCores:1>, usedCapacity=0.25, absoluteUsedCapacity=0.25, numApps=1, numContainers=1
2015-04-01 17:40:39,767 INFO org.apache.hadoop.yarn.server.resourcemanager.scheduler.capacity.CapacityScheduler: Application attempt appattempt_1427899242644_0011_000001 released container container_1427899242644_0011_01_000005 on node: host: a11p2.fil.univ-lille1.fr.:55305 #containers=1 available=6144 used=2048 with event: FINISHED
2015-04-01 17:40:45,775 INFO org.apache.hadoop.yarn.server.resourcemanager.rmcontainer.RMContainerImpl: container_1427899242644_0011_01_000001 Container Transitioned from RUNNING to COMPLETED
2015-04-01 17:40:45,775 INFO org.apache.hadoop.yarn.server.resourcemanager.ApplicationMasterService: Unregistering app attempt : appattempt_1427899242644_0011_000001
2015-04-01 17:40:45,775 INFO org.apache.hadoop.yarn.server.resourcemanager.scheduler.common.fica.FiCaSchedulerApp: Completed container: container_1427899242644_0011_01_000001 in state: COMPLETED event:FINISHED
2015-04-01 17:40:45,776 INFO org.apache.hadoop.yarn.server.resourcemanager.rmapp.attempt.RMAppAttemptImpl: appattempt_1427899242644_0011_000001 State change from FINISHING to FINISHED
2015-04-01 17:40:45,776 INFO org.apache.hadoop.yarn.server.resourcemanager.RMAuditLogger: USER=echallier	OPERATION=AM Released Container	TARGET=SchedulerApp	RESULT=SUCCESS	APPID=application_1427899242644_0011	CONTAINERID=container_1427899242644_0011_01_000001
2015-04-01 17:40:45,776 INFO org.apache.hadoop.yarn.server.resourcemanager.rmapp.RMAppImpl: application_1427899242644_0011 State change from FINISHING to FINISHED
2015-04-01 17:40:45,776 INFO org.apache.hadoop.yarn.server.resourcemanager.scheduler.SchedulerNode: Released container container_1427899242644_0011_01_000001 of capacity <memory:2048, vCores:1> on host a11p2.fil.univ-lille1.fr.:55305, which currently has 0 containers, <memory:0, vCores:0> used and <memory:8192, vCores:8> available, release resources=true
2015-04-01 17:40:45,776 INFO org.apache.hadoop.yarn.server.resourcemanager.RMAuditLogger: USER=echallier	OPERATION=Application Finished - Succeeded	TARGET=RMAppManager	RESULT=SUCCESS	APPID=application_1427899242644_0011
2015-04-01 17:40:45,776 INFO org.apache.hadoop.yarn.server.resourcemanager.scheduler.capacity.LeafQueue: default used=<memory:0, vCores:0> numContainers=0 user=echallier user-resources=<memory:0, vCores:0>
2015-04-01 17:40:45,776 INFO org.apache.hadoop.yarn.server.resourcemanager.amlauncher.AMLauncher: Cleaning master appattempt_1427899242644_0011_000001
2015-04-01 17:40:45,776 INFO org.apache.hadoop.yarn.server.resourcemanager.scheduler.capacity.LeafQueue: completedContainer container=Container: [ContainerId: container_1427899242644_0011_01_000001, NodeId: a11p2.fil.univ-lille1.fr.:55305, NodeHttpAddress: a11p2.fil.univ-lille1.fr.:8042, Resource: <memory:2048, vCores:1>, Priority: 0, Token: Token { kind: ContainerToken, service: 127.0.1.1:55305 }, ] queue=default: capacity=1.0, absoluteCapacity=1.0, usedResources=<memory:0, vCores:0>, usedCapacity=0.0, absoluteUsedCapacity=0.0, numApps=1, numContainers=0 cluster=<memory:8192, vCores:8>
2015-04-01 17:40:45,776 INFO org.apache.hadoop.yarn.server.resourcemanager.scheduler.capacity.ParentQueue: completedContainer queue=root usedCapacity=0.0 absoluteUsedCapacity=0.0 used=<memory:0, vCores:0> cluster=<memory:8192, vCores:8>
2015-04-01 17:40:45,776 INFO org.apache.hadoop.yarn.server.resourcemanager.scheduler.capacity.ParentQueue: Re-sorting completed queue: root.default stats: default: capacity=1.0, absoluteCapacity=1.0, usedResources=<memory:0, vCores:0>, usedCapacity=0.0, absoluteUsedCapacity=0.0, numApps=1, numContainers=0
2015-04-01 17:40:45,777 INFO org.apache.hadoop.yarn.server.resourcemanager.RMAppManager$ApplicationSummary: appId=application_1427899242644_0011,name=GPS,user=echallier,queue=default,state=FINISHED,trackingUrl=http://a11p2.fil.univ-lille1.fr.:8088/proxy/application_1427899242644_0011/jobhistory/job/job_1427899242644_0011,appMasterHost=a11p2,startTime=1427902817925,finishTime=1427902839056,finalStatus=FAILED
2015-04-01 17:40:45,777 INFO org.apache.hadoop.yarn.server.resourcemanager.scheduler.capacity.CapacityScheduler: Application attempt appattempt_1427899242644_0011_000001 released container container_1427899242644_0011_01_000001 on node: host: a11p2.fil.univ-lille1.fr.:55305 #containers=0 available=8192 used=0 with event: FINISHED
2015-04-01 17:40:45,777 INFO org.apache.hadoop.yarn.server.resourcemanager.scheduler.capacity.CapacityScheduler: Application Attempt appattempt_1427899242644_0011_000001 is done. finalState=FINISHED
2015-04-01 17:40:45,777 INFO org.apache.hadoop.yarn.server.resourcemanager.scheduler.AppSchedulingInfo: Application application_1427899242644_0011 requests cleared
2015-04-01 17:40:45,777 INFO org.apache.hadoop.yarn.server.resourcemanager.scheduler.capacity.LeafQueue: Application removed - appId: application_1427899242644_0011 user: echallier queue: default #user-pending-applications: 0 #user-active-applications: 0 #queue-pending-applications: 0 #queue-active-applications: 0
2015-04-01 17:40:45,777 INFO org.apache.hadoop.yarn.server.resourcemanager.scheduler.capacity.ParentQueue: Application removed - appId: application_1427899242644_0011 user: echallier leaf-queue of parent: root #applications: 0
2015-04-01 17:41:06,509 INFO org.apache.hadoop.yarn.server.resourcemanager.ClientRMService: Allocated new applicationId: 12
2015-04-01 17:41:07,315 INFO org.apache.hadoop.yarn.server.resourcemanager.ClientRMService: Application with id 12 submitted by user echallier
2015-04-01 17:41:07,315 INFO org.apache.hadoop.yarn.server.resourcemanager.rmapp.RMAppImpl: Storing application with id application_1427899242644_0012
2015-04-01 17:41:07,315 INFO org.apache.hadoop.yarn.server.resourcemanager.RMAuditLogger: USER=echallier	IP=127.0.0.1	OPERATION=Submit Application Request	TARGET=ClientRMService	RESULT=SUCCESS	APPID=application_1427899242644_0012
2015-04-01 17:41:07,315 INFO org.apache.hadoop.yarn.server.resourcemanager.rmapp.RMAppImpl: application_1427899242644_0012 State change from NEW to NEW_SAVING
2015-04-01 17:41:07,315 INFO org.apache.hadoop.yarn.server.resourcemanager.recovery.RMStateStore: Storing info for app: application_1427899242644_0012
2015-04-01 17:41:07,315 INFO org.apache.hadoop.yarn.server.resourcemanager.rmapp.RMAppImpl: application_1427899242644_0012 State change from NEW_SAVING to SUBMITTED
2015-04-01 17:41:07,315 INFO org.apache.hadoop.yarn.server.resourcemanager.scheduler.capacity.ParentQueue: Application added - appId: application_1427899242644_0012 user: echallier leaf-queue of parent: root #applications: 1
2015-04-01 17:41:07,315 INFO org.apache.hadoop.yarn.server.resourcemanager.scheduler.capacity.CapacityScheduler: Accepted application application_1427899242644_0012 from user: echallier, in queue: default
2015-04-01 17:41:07,316 INFO org.apache.hadoop.yarn.server.resourcemanager.rmapp.RMAppImpl: application_1427899242644_0012 State change from SUBMITTED to ACCEPTED
2015-04-01 17:41:07,316 INFO org.apache.hadoop.yarn.server.resourcemanager.ApplicationMasterService: Registering app attempt : appattempt_1427899242644_0012_000001
2015-04-01 17:41:07,316 INFO org.apache.hadoop.yarn.server.resourcemanager.rmapp.attempt.RMAppAttemptImpl: appattempt_1427899242644_0012_000001 State change from NEW to SUBMITTED
2015-04-01 17:41:07,316 INFO org.apache.hadoop.yarn.server.resourcemanager.scheduler.capacity.LeafQueue: Application application_1427899242644_0012 from user: echallier activated in queue: default
2015-04-01 17:41:07,316 INFO org.apache.hadoop.yarn.server.resourcemanager.scheduler.capacity.LeafQueue: Application added - appId: application_1427899242644_0012 user: org.apache.hadoop.yarn.server.resourcemanager.scheduler.capacity.LeafQueue$User@1a5cd40, leaf-queue: default #user-pending-applications: 0 #user-active-applications: 1 #queue-pending-applications: 0 #queue-active-applications: 1
2015-04-01 17:41:07,316 INFO org.apache.hadoop.yarn.server.resourcemanager.scheduler.capacity.CapacityScheduler: Added Application Attempt appattempt_1427899242644_0012_000001 to scheduler from user echallier in queue default
2015-04-01 17:41:07,316 INFO org.apache.hadoop.yarn.server.resourcemanager.rmapp.attempt.RMAppAttemptImpl: appattempt_1427899242644_0012_000001 State change from SUBMITTED to SCHEDULED
2015-04-01 17:41:07,805 INFO org.apache.hadoop.yarn.server.resourcemanager.rmcontainer.RMContainerImpl: container_1427899242644_0012_01_000001 Container Transitioned from NEW to ALLOCATED
2015-04-01 17:41:07,805 INFO org.apache.hadoop.yarn.server.resourcemanager.RMAuditLogger: USER=echallier	OPERATION=AM Allocated Container	TARGET=SchedulerApp	RESULT=SUCCESS	APPID=application_1427899242644_0012	CONTAINERID=container_1427899242644_0012_01_000001
2015-04-01 17:41:07,805 INFO org.apache.hadoop.yarn.server.resourcemanager.scheduler.SchedulerNode: Assigned container container_1427899242644_0012_01_000001 of capacity <memory:2048, vCores:1> on host a11p2.fil.univ-lille1.fr.:55305, which has 1 containers, <memory:2048, vCores:1> used and <memory:6144, vCores:7> available after allocation
2015-04-01 17:41:07,805 INFO org.apache.hadoop.yarn.server.resourcemanager.scheduler.capacity.LeafQueue: assignedContainer application attempt=appattempt_1427899242644_0012_000001 container=Container: [ContainerId: container_1427899242644_0012_01_000001, NodeId: a11p2.fil.univ-lille1.fr.:55305, NodeHttpAddress: a11p2.fil.univ-lille1.fr.:8042, Resource: <memory:2048, vCores:1>, Priority: 0, Token: null, ] queue=default: capacity=1.0, absoluteCapacity=1.0, usedResources=<memory:0, vCores:0>, usedCapacity=0.0, absoluteUsedCapacity=0.0, numApps=1, numContainers=0 clusterResource=<memory:8192, vCores:8>
2015-04-01 17:41:07,805 INFO org.apache.hadoop.yarn.server.resourcemanager.scheduler.capacity.ParentQueue: Re-sorting assigned queue: root.default stats: default: capacity=1.0, absoluteCapacity=1.0, usedResources=<memory:2048, vCores:1>, usedCapacity=0.25, absoluteUsedCapacity=0.25, numApps=1, numContainers=1
2015-04-01 17:41:07,805 INFO org.apache.hadoop.yarn.server.resourcemanager.scheduler.capacity.ParentQueue: assignedContainer queue=root usedCapacity=0.25 absoluteUsedCapacity=0.25 used=<memory:2048, vCores:1> cluster=<memory:8192, vCores:8>
2015-04-01 17:41:07,805 INFO org.apache.hadoop.yarn.server.resourcemanager.security.NMTokenSecretManagerInRM: Sending NMToken for nodeId : a11p2.fil.univ-lille1.fr.:55305 for container : container_1427899242644_0012_01_000001
2015-04-01 17:41:07,807 INFO org.apache.hadoop.yarn.server.resourcemanager.rmcontainer.RMContainerImpl: container_1427899242644_0012_01_000001 Container Transitioned from ALLOCATED to ACQUIRED
2015-04-01 17:41:07,807 INFO org.apache.hadoop.yarn.server.resourcemanager.security.NMTokenSecretManagerInRM: Clear node set for appattempt_1427899242644_0012_000001
2015-04-01 17:41:07,807 INFO org.apache.hadoop.yarn.server.resourcemanager.rmapp.attempt.RMAppAttemptImpl: Storing attempt: AppId: application_1427899242644_0012 AttemptId: appattempt_1427899242644_0012_000001 MasterContainer: Container: [ContainerId: container_1427899242644_0012_01_000001, NodeId: a11p2.fil.univ-lille1.fr.:55305, NodeHttpAddress: a11p2.fil.univ-lille1.fr.:8042, Resource: <memory:2048, vCores:1>, Priority: 0, Token: Token { kind: ContainerToken, service: 127.0.1.1:55305 }, ]
2015-04-01 17:41:07,807 INFO org.apache.hadoop.yarn.server.resourcemanager.rmapp.attempt.RMAppAttemptImpl: appattempt_1427899242644_0012_000001 State change from SCHEDULED to ALLOCATED_SAVING
2015-04-01 17:41:07,807 INFO org.apache.hadoop.yarn.server.resourcemanager.rmapp.attempt.RMAppAttemptImpl: appattempt_1427899242644_0012_000001 State change from ALLOCATED_SAVING to ALLOCATED
2015-04-01 17:41:07,807 INFO org.apache.hadoop.yarn.server.resourcemanager.amlauncher.AMLauncher: Launching masterappattempt_1427899242644_0012_000001
2015-04-01 17:41:07,809 INFO org.apache.hadoop.yarn.server.resourcemanager.amlauncher.AMLauncher: Setting up container Container: [ContainerId: container_1427899242644_0012_01_000001, NodeId: a11p2.fil.univ-lille1.fr.:55305, NodeHttpAddress: a11p2.fil.univ-lille1.fr.:8042, Resource: <memory:2048, vCores:1>, Priority: 0, Token: Token { kind: ContainerToken, service: 127.0.1.1:55305 }, ] for AM appattempt_1427899242644_0012_000001
2015-04-01 17:41:07,809 INFO org.apache.hadoop.yarn.server.resourcemanager.amlauncher.AMLauncher: Command to launch container container_1427899242644_0012_01_000001 : $JAVA_HOME/bin/java -Dlog4j.configuration=container-log4j.properties -Dyarn.app.container.log.dir=<LOG_DIR> -Dyarn.app.container.log.filesize=0 -Dhadoop.root.logger=INFO,CLA  -Xmx1024m org.apache.hadoop.mapreduce.v2.app.MRAppMaster 1><LOG_DIR>/stdout 2><LOG_DIR>/stderr 
2015-04-01 17:41:07,820 INFO org.apache.hadoop.yarn.server.resourcemanager.amlauncher.AMLauncher: Done launching container Container: [ContainerId: container_1427899242644_0012_01_000001, NodeId: a11p2.fil.univ-lille1.fr.:55305, NodeHttpAddress: a11p2.fil.univ-lille1.fr.:8042, Resource: <memory:2048, vCores:1>, Priority: 0, Token: Token { kind: ContainerToken, service: 127.0.1.1:55305 }, ] for AM appattempt_1427899242644_0012_000001
2015-04-01 17:41:07,820 INFO org.apache.hadoop.yarn.server.resourcemanager.rmapp.attempt.RMAppAttemptImpl: appattempt_1427899242644_0012_000001 State change from ALLOCATED to LAUNCHED
2015-04-01 17:41:08,805 INFO org.apache.hadoop.yarn.server.resourcemanager.rmcontainer.RMContainerImpl: container_1427899242644_0012_01_000001 Container Transitioned from ACQUIRED to RUNNING
2015-04-01 17:41:10,834 INFO SecurityLogger.org.apache.hadoop.ipc.Server: Auth successful for appattempt_1427899242644_0012_000001 (auth:SIMPLE)
2015-04-01 17:41:10,836 INFO org.apache.hadoop.yarn.server.resourcemanager.ApplicationMasterService: AM registration appattempt_1427899242644_0012_000001
2015-04-01 17:41:10,836 INFO org.apache.hadoop.yarn.server.resourcemanager.RMAuditLogger: USER=echallier	IP=127.0.0.1	OPERATION=Register App Master	TARGET=ApplicationMasterService	RESULT=SUCCESS	APPID=application_1427899242644_0012	APPATTEMPTID=appattempt_1427899242644_0012_000001
2015-04-01 17:41:10,836 INFO org.apache.hadoop.yarn.server.resourcemanager.rmapp.attempt.RMAppAttemptImpl: appattempt_1427899242644_0012_000001 State change from LAUNCHED to RUNNING
2015-04-01 17:41:10,836 INFO org.apache.hadoop.yarn.server.resourcemanager.rmapp.RMAppImpl: application_1427899242644_0012 State change from ACCEPTED to RUNNING
2015-04-01 17:41:12,813 INFO org.apache.hadoop.yarn.server.resourcemanager.rmcontainer.RMContainerImpl: container_1427899242644_0012_01_000002 Container Transitioned from NEW to ALLOCATED
2015-04-01 17:41:12,813 INFO org.apache.hadoop.yarn.server.resourcemanager.RMAuditLogger: USER=echallier	OPERATION=AM Allocated Container	TARGET=SchedulerApp	RESULT=SUCCESS	APPID=application_1427899242644_0012	CONTAINERID=container_1427899242644_0012_01_000002
2015-04-01 17:41:12,813 INFO org.apache.hadoop.yarn.server.resourcemanager.scheduler.SchedulerNode: Assigned container container_1427899242644_0012_01_000002 of capacity <memory:1024, vCores:1> on host a11p2.fil.univ-lille1.fr.:55305, which has 2 containers, <memory:3072, vCores:2> used and <memory:5120, vCores:6> available after allocation
2015-04-01 17:41:12,814 INFO org.apache.hadoop.yarn.server.resourcemanager.scheduler.capacity.LeafQueue: assignedContainer application attempt=appattempt_1427899242644_0012_000001 container=Container: [ContainerId: container_1427899242644_0012_01_000002, NodeId: a11p2.fil.univ-lille1.fr.:55305, NodeHttpAddress: a11p2.fil.univ-lille1.fr.:8042, Resource: <memory:1024, vCores:1>, Priority: 20, Token: null, ] queue=default: capacity=1.0, absoluteCapacity=1.0, usedResources=<memory:2048, vCores:1>, usedCapacity=0.25, absoluteUsedCapacity=0.25, numApps=1, numContainers=1 clusterResource=<memory:8192, vCores:8>
2015-04-01 17:41:12,814 INFO org.apache.hadoop.yarn.server.resourcemanager.scheduler.capacity.ParentQueue: Re-sorting assigned queue: root.default stats: default: capacity=1.0, absoluteCapacity=1.0, usedResources=<memory:3072, vCores:2>, usedCapacity=0.375, absoluteUsedCapacity=0.375, numApps=1, numContainers=2
2015-04-01 17:41:12,814 INFO org.apache.hadoop.yarn.server.resourcemanager.scheduler.capacity.ParentQueue: assignedContainer queue=root usedCapacity=0.375 absoluteUsedCapacity=0.375 used=<memory:3072, vCores:2> cluster=<memory:8192, vCores:8>
2015-04-01 17:41:12,893 INFO org.apache.hadoop.yarn.server.resourcemanager.security.NMTokenSecretManagerInRM: Sending NMToken for nodeId : a11p2.fil.univ-lille1.fr.:55305 for container : container_1427899242644_0012_01_000002
2015-04-01 17:41:12,895 INFO org.apache.hadoop.yarn.server.resourcemanager.rmcontainer.RMContainerImpl: container_1427899242644_0012_01_000002 Container Transitioned from ALLOCATED to ACQUIRED
2015-04-01 17:41:13,814 INFO org.apache.hadoop.yarn.server.resourcemanager.rmcontainer.RMContainerImpl: container_1427899242644_0012_01_000002 Container Transitioned from ACQUIRED to RUNNING
2015-04-01 17:41:13,909 INFO org.apache.hadoop.yarn.server.resourcemanager.scheduler.AppSchedulingInfo: checking for deactivate... 
2015-04-01 17:41:16,234 INFO org.apache.hadoop.yarn.server.resourcemanager.rmcontainer.RMContainerImpl: container_1427899242644_0012_01_000002 Container Transitioned from RUNNING to COMPLETED
2015-04-01 17:41:16,235 INFO org.apache.hadoop.yarn.server.resourcemanager.scheduler.common.fica.FiCaSchedulerApp: Completed container: container_1427899242644_0012_01_000002 in state: COMPLETED event:FINISHED
2015-04-01 17:41:16,235 INFO org.apache.hadoop.yarn.server.resourcemanager.RMAuditLogger: USER=echallier	OPERATION=AM Released Container	TARGET=SchedulerApp	RESULT=SUCCESS	APPID=application_1427899242644_0012	CONTAINERID=container_1427899242644_0012_01_000002
2015-04-01 17:41:16,235 INFO org.apache.hadoop.yarn.server.resourcemanager.scheduler.SchedulerNode: Released container container_1427899242644_0012_01_000002 of capacity <memory:1024, vCores:1> on host a11p2.fil.univ-lille1.fr.:55305, which currently has 1 containers, <memory:2048, vCores:1> used and <memory:6144, vCores:7> available, release resources=true
2015-04-01 17:41:16,235 INFO org.apache.hadoop.yarn.server.resourcemanager.scheduler.capacity.LeafQueue: default used=<memory:2048, vCores:1> numContainers=1 user=echallier user-resources=<memory:2048, vCores:1>
2015-04-01 17:41:16,235 INFO org.apache.hadoop.yarn.server.resourcemanager.scheduler.capacity.LeafQueue: completedContainer container=Container: [ContainerId: container_1427899242644_0012_01_000002, NodeId: a11p2.fil.univ-lille1.fr.:55305, NodeHttpAddress: a11p2.fil.univ-lille1.fr.:8042, Resource: <memory:1024, vCores:1>, Priority: 20, Token: Token { kind: ContainerToken, service: 127.0.1.1:55305 }, ] queue=default: capacity=1.0, absoluteCapacity=1.0, usedResources=<memory:2048, vCores:1>, usedCapacity=0.25, absoluteUsedCapacity=0.25, numApps=1, numContainers=1 cluster=<memory:8192, vCores:8>
2015-04-01 17:41:16,235 INFO org.apache.hadoop.yarn.server.resourcemanager.scheduler.capacity.ParentQueue: completedContainer queue=root usedCapacity=0.25 absoluteUsedCapacity=0.25 used=<memory:2048, vCores:1> cluster=<memory:8192, vCores:8>
2015-04-01 17:41:16,235 INFO org.apache.hadoop.yarn.server.resourcemanager.scheduler.capacity.ParentQueue: Re-sorting completed queue: root.default stats: default: capacity=1.0, absoluteCapacity=1.0, usedResources=<memory:2048, vCores:1>, usedCapacity=0.25, absoluteUsedCapacity=0.25, numApps=1, numContainers=1
2015-04-01 17:41:16,235 INFO org.apache.hadoop.yarn.server.resourcemanager.scheduler.capacity.CapacityScheduler: Application attempt appattempt_1427899242644_0012_000001 released container container_1427899242644_0012_01_000002 on node: host: a11p2.fil.univ-lille1.fr.:55305 #containers=1 available=6144 used=2048 with event: FINISHED
2015-04-01 17:41:17,236 INFO org.apache.hadoop.yarn.server.resourcemanager.rmcontainer.RMContainerImpl: container_1427899242644_0012_01_000003 Container Transitioned from NEW to ALLOCATED
2015-04-01 17:41:17,236 INFO org.apache.hadoop.yarn.server.resourcemanager.RMAuditLogger: USER=echallier	OPERATION=AM Allocated Container	TARGET=SchedulerApp	RESULT=SUCCESS	APPID=application_1427899242644_0012	CONTAINERID=container_1427899242644_0012_01_000003
2015-04-01 17:41:17,236 INFO org.apache.hadoop.yarn.server.resourcemanager.scheduler.SchedulerNode: Assigned container container_1427899242644_0012_01_000003 of capacity <memory:1024, vCores:1> on host a11p2.fil.univ-lille1.fr.:55305, which has 2 containers, <memory:3072, vCores:2> used and <memory:5120, vCores:6> available after allocation
2015-04-01 17:41:17,237 INFO org.apache.hadoop.yarn.server.resourcemanager.scheduler.capacity.LeafQueue: assignedContainer application attempt=appattempt_1427899242644_0012_000001 container=Container: [ContainerId: container_1427899242644_0012_01_000003, NodeId: a11p2.fil.univ-lille1.fr.:55305, NodeHttpAddress: a11p2.fil.univ-lille1.fr.:8042, Resource: <memory:1024, vCores:1>, Priority: 10, Token: null, ] queue=default: capacity=1.0, absoluteCapacity=1.0, usedResources=<memory:2048, vCores:1>, usedCapacity=0.25, absoluteUsedCapacity=0.25, numApps=1, numContainers=1 clusterResource=<memory:8192, vCores:8>
2015-04-01 17:41:17,237 INFO org.apache.hadoop.yarn.server.resourcemanager.scheduler.capacity.ParentQueue: Re-sorting assigned queue: root.default stats: default: capacity=1.0, absoluteCapacity=1.0, usedResources=<memory:3072, vCores:2>, usedCapacity=0.375, absoluteUsedCapacity=0.375, numApps=1, numContainers=2
2015-04-01 17:41:17,237 INFO org.apache.hadoop.yarn.server.resourcemanager.scheduler.capacity.ParentQueue: assignedContainer queue=root usedCapacity=0.375 absoluteUsedCapacity=0.375 used=<memory:3072, vCores:2> cluster=<memory:8192, vCores:8>
2015-04-01 17:41:17,925 INFO org.apache.hadoop.yarn.server.resourcemanager.rmcontainer.RMContainerImpl: container_1427899242644_0012_01_000003 Container Transitioned from ALLOCATED to ACQUIRED
2015-04-01 17:41:18,237 INFO org.apache.hadoop.yarn.server.resourcemanager.rmcontainer.RMContainerImpl: container_1427899242644_0012_01_000003 Container Transitioned from ACQUIRED to RUNNING
2015-04-01 17:41:18,929 INFO org.apache.hadoop.yarn.server.resourcemanager.scheduler.AppSchedulingInfo: checking for deactivate... 
2015-04-01 17:41:20,585 INFO org.apache.hadoop.yarn.server.resourcemanager.rmapp.attempt.RMAppAttemptImpl: Updating application attempt appattempt_1427899242644_0012_000001 with final state: FINISHING, and exit status: -1000
2015-04-01 17:41:20,585 INFO org.apache.hadoop.yarn.server.resourcemanager.rmapp.attempt.RMAppAttemptImpl: appattempt_1427899242644_0012_000001 State change from RUNNING to FINAL_SAVING
2015-04-01 17:41:20,585 INFO org.apache.hadoop.yarn.server.resourcemanager.rmapp.RMAppImpl: Updating application application_1427899242644_0012 with final state: FINISHING
2015-04-01 17:41:20,585 INFO org.apache.hadoop.yarn.server.resourcemanager.rmapp.RMAppImpl: application_1427899242644_0012 State change from RUNNING to FINAL_SAVING
2015-04-01 17:41:20,585 INFO org.apache.hadoop.yarn.server.resourcemanager.recovery.RMStateStore: Updating info for app: application_1427899242644_0012
2015-04-01 17:41:20,586 INFO org.apache.hadoop.yarn.server.resourcemanager.rmapp.attempt.RMAppAttemptImpl: appattempt_1427899242644_0012_000001 State change from FINAL_SAVING to FINISHING
2015-04-01 17:41:20,586 INFO org.apache.hadoop.yarn.server.resourcemanager.rmapp.RMAppImpl: application_1427899242644_0012 State change from FINAL_SAVING to FINISHING
2015-04-01 17:41:21,230 INFO org.apache.hadoop.yarn.server.resourcemanager.rmcontainer.RMContainerImpl: container_1427899242644_0012_01_000003 Container Transitioned from RUNNING to COMPLETED
2015-04-01 17:41:21,231 INFO org.apache.hadoop.yarn.server.resourcemanager.scheduler.common.fica.FiCaSchedulerApp: Completed container: container_1427899242644_0012_01_000003 in state: COMPLETED event:FINISHED
2015-04-01 17:41:21,231 INFO org.apache.hadoop.yarn.server.resourcemanager.RMAuditLogger: USER=echallier	OPERATION=AM Released Container	TARGET=SchedulerApp	RESULT=SUCCESS	APPID=application_1427899242644_0012	CONTAINERID=container_1427899242644_0012_01_000003
2015-04-01 17:41:21,231 INFO org.apache.hadoop.yarn.server.resourcemanager.scheduler.SchedulerNode: Released container container_1427899242644_0012_01_000003 of capacity <memory:1024, vCores:1> on host a11p2.fil.univ-lille1.fr.:55305, which currently has 1 containers, <memory:2048, vCores:1> used and <memory:6144, vCores:7> available, release resources=true
2015-04-01 17:41:21,231 INFO org.apache.hadoop.yarn.server.resourcemanager.scheduler.capacity.LeafQueue: default used=<memory:2048, vCores:1> numContainers=1 user=echallier user-resources=<memory:2048, vCores:1>
2015-04-01 17:41:21,231 INFO org.apache.hadoop.yarn.server.resourcemanager.scheduler.capacity.LeafQueue: completedContainer container=Container: [ContainerId: container_1427899242644_0012_01_000003, NodeId: a11p2.fil.univ-lille1.fr.:55305, NodeHttpAddress: a11p2.fil.univ-lille1.fr.:8042, Resource: <memory:1024, vCores:1>, Priority: 10, Token: Token { kind: ContainerToken, service: 127.0.1.1:55305 }, ] queue=default: capacity=1.0, absoluteCapacity=1.0, usedResources=<memory:2048, vCores:1>, usedCapacity=0.25, absoluteUsedCapacity=0.25, numApps=1, numContainers=1 cluster=<memory:8192, vCores:8>
2015-04-01 17:41:21,231 INFO org.apache.hadoop.yarn.server.resourcemanager.scheduler.capacity.ParentQueue: completedContainer queue=root usedCapacity=0.25 absoluteUsedCapacity=0.25 used=<memory:2048, vCores:1> cluster=<memory:8192, vCores:8>
2015-04-01 17:41:21,231 INFO org.apache.hadoop.yarn.server.resourcemanager.scheduler.capacity.ParentQueue: Re-sorting completed queue: root.default stats: default: capacity=1.0, absoluteCapacity=1.0, usedResources=<memory:2048, vCores:1>, usedCapacity=0.25, absoluteUsedCapacity=0.25, numApps=1, numContainers=1
2015-04-01 17:41:21,232 INFO org.apache.hadoop.yarn.server.resourcemanager.scheduler.capacity.CapacityScheduler: Application attempt appattempt_1427899242644_0012_000001 released container container_1427899242644_0012_01_000003 on node: host: a11p2.fil.univ-lille1.fr.:55305 #containers=1 available=6144 used=2048 with event: FINISHED
2015-04-01 17:41:27,240 INFO org.apache.hadoop.yarn.server.resourcemanager.rmcontainer.RMContainerImpl: container_1427899242644_0012_01_000001 Container Transitioned from RUNNING to COMPLETED
2015-04-01 17:41:27,241 INFO org.apache.hadoop.yarn.server.resourcemanager.scheduler.common.fica.FiCaSchedulerApp: Completed container: container_1427899242644_0012_01_000001 in state: COMPLETED event:FINISHED
2015-04-01 17:41:27,241 INFO org.apache.hadoop.yarn.server.resourcemanager.RMAuditLogger: USER=echallier	OPERATION=AM Released Container	TARGET=SchedulerApp	RESULT=SUCCESS	APPID=application_1427899242644_0012	CONTAINERID=container_1427899242644_0012_01_000001
2015-04-01 17:41:27,241 INFO org.apache.hadoop.yarn.server.resourcemanager.scheduler.SchedulerNode: Released container container_1427899242644_0012_01_000001 of capacity <memory:2048, vCores:1> on host a11p2.fil.univ-lille1.fr.:55305, which currently has 0 containers, <memory:0, vCores:0> used and <memory:8192, vCores:8> available, release resources=true
2015-04-01 17:41:27,241 INFO org.apache.hadoop.yarn.server.resourcemanager.scheduler.capacity.LeafQueue: default used=<memory:0, vCores:0> numContainers=0 user=echallier user-resources=<memory:0, vCores:0>
2015-04-01 17:41:27,241 INFO org.apache.hadoop.yarn.server.resourcemanager.scheduler.capacity.LeafQueue: completedContainer container=Container: [ContainerId: container_1427899242644_0012_01_000001, NodeId: a11p2.fil.univ-lille1.fr.:55305, NodeHttpAddress: a11p2.fil.univ-lille1.fr.:8042, Resource: <memory:2048, vCores:1>, Priority: 0, Token: Token { kind: ContainerToken, service: 127.0.1.1:55305 }, ] queue=default: capacity=1.0, absoluteCapacity=1.0, usedResources=<memory:0, vCores:0>, usedCapacity=0.0, absoluteUsedCapacity=0.0, numApps=1, numContainers=0 cluster=<memory:8192, vCores:8>
2015-04-01 17:41:27,241 INFO org.apache.hadoop.yarn.server.resourcemanager.scheduler.capacity.ParentQueue: completedContainer queue=root usedCapacity=0.0 absoluteUsedCapacity=0.0 used=<memory:0, vCores:0> cluster=<memory:8192, vCores:8>
2015-04-01 17:41:27,241 INFO org.apache.hadoop.yarn.server.resourcemanager.scheduler.capacity.ParentQueue: Re-sorting completed queue: root.default stats: default: capacity=1.0, absoluteCapacity=1.0, usedResources=<memory:0, vCores:0>, usedCapacity=0.0, absoluteUsedCapacity=0.0, numApps=1, numContainers=0
2015-04-01 17:41:27,241 INFO org.apache.hadoop.yarn.server.resourcemanager.scheduler.capacity.CapacityScheduler: Application attempt appattempt_1427899242644_0012_000001 released container container_1427899242644_0012_01_000001 on node: host: a11p2.fil.univ-lille1.fr.:55305 #containers=0 available=8192 used=0 with event: FINISHED
2015-04-01 17:41:27,240 INFO org.apache.hadoop.yarn.server.resourcemanager.ApplicationMasterService: Unregistering app attempt : appattempt_1427899242644_0012_000001
2015-04-01 17:41:27,241 INFO org.apache.hadoop.yarn.server.resourcemanager.rmapp.attempt.RMAppAttemptImpl: appattempt_1427899242644_0012_000001 State change from FINISHING to FINISHED
2015-04-01 17:41:27,241 INFO org.apache.hadoop.yarn.server.resourcemanager.rmapp.RMAppImpl: application_1427899242644_0012 State change from FINISHING to FINISHED
2015-04-01 17:41:27,241 INFO org.apache.hadoop.yarn.server.resourcemanager.RMAuditLogger: USER=echallier	OPERATION=Application Finished - Succeeded	TARGET=RMAppManager	RESULT=SUCCESS	APPID=application_1427899242644_0012
2015-04-01 17:41:27,241 INFO org.apache.hadoop.yarn.server.resourcemanager.amlauncher.AMLauncher: Cleaning master appattempt_1427899242644_0012_000001
2015-04-01 17:41:27,242 INFO org.apache.hadoop.yarn.server.resourcemanager.RMAppManager$ApplicationSummary: appId=application_1427899242644_0012,name=GPS,user=echallier,queue=default,state=FINISHED,trackingUrl=http://a11p2.fil.univ-lille1.fr.:8088/proxy/application_1427899242644_0012/jobhistory/job/job_1427899242644_0012,appMasterHost=a11p2,startTime=1427902867315,finishTime=1427902880585,finalStatus=SUCCEEDED
2015-04-01 17:41:27,242 INFO org.apache.hadoop.yarn.server.resourcemanager.scheduler.capacity.CapacityScheduler: Application Attempt appattempt_1427899242644_0012_000001 is done. finalState=FINISHED
2015-04-01 17:41:27,242 INFO org.apache.hadoop.yarn.server.resourcemanager.scheduler.AppSchedulingInfo: Application application_1427899242644_0012 requests cleared
2015-04-01 17:41:27,242 INFO org.apache.hadoop.yarn.server.resourcemanager.scheduler.capacity.LeafQueue: Application removed - appId: application_1427899242644_0012 user: echallier queue: default #user-pending-applications: 0 #user-active-applications: 0 #queue-pending-applications: 0 #queue-active-applications: 0
2015-04-01 17:41:27,242 INFO org.apache.hadoop.yarn.server.resourcemanager.scheduler.capacity.ParentQueue: Application removed - appId: application_1427899242644_0012 user: echallier leaf-queue of parent: root #applications: 0
2015-04-01 17:44:31,459 INFO org.apache.hadoop.yarn.server.resourcemanager.ClientRMService: Allocated new applicationId: 13
2015-04-01 17:44:32,271 INFO org.apache.hadoop.yarn.server.resourcemanager.ClientRMService: Application with id 13 submitted by user echallier
2015-04-01 17:44:32,271 INFO org.apache.hadoop.yarn.server.resourcemanager.rmapp.RMAppImpl: Storing application with id application_1427899242644_0013
2015-04-01 17:44:32,271 INFO org.apache.hadoop.yarn.server.resourcemanager.RMAuditLogger: USER=echallier	IP=127.0.0.1	OPERATION=Submit Application Request	TARGET=ClientRMService	RESULT=SUCCESS	APPID=application_1427899242644_0013
2015-04-01 17:44:32,271 INFO org.apache.hadoop.yarn.server.resourcemanager.rmapp.RMAppImpl: application_1427899242644_0013 State change from NEW to NEW_SAVING
2015-04-01 17:44:32,271 INFO org.apache.hadoop.yarn.server.resourcemanager.recovery.RMStateStore: Storing info for app: application_1427899242644_0013
2015-04-01 17:44:32,271 INFO org.apache.hadoop.yarn.server.resourcemanager.rmapp.RMAppImpl: application_1427899242644_0013 State change from NEW_SAVING to SUBMITTED
2015-04-01 17:44:32,271 INFO org.apache.hadoop.yarn.server.resourcemanager.scheduler.capacity.ParentQueue: Application added - appId: application_1427899242644_0013 user: echallier leaf-queue of parent: root #applications: 1
2015-04-01 17:44:32,271 INFO org.apache.hadoop.yarn.server.resourcemanager.scheduler.capacity.CapacityScheduler: Accepted application application_1427899242644_0013 from user: echallier, in queue: default
2015-04-01 17:44:32,272 INFO org.apache.hadoop.yarn.server.resourcemanager.rmapp.RMAppImpl: application_1427899242644_0013 State change from SUBMITTED to ACCEPTED
2015-04-01 17:44:32,272 INFO org.apache.hadoop.yarn.server.resourcemanager.ApplicationMasterService: Registering app attempt : appattempt_1427899242644_0013_000001
2015-04-01 17:44:32,272 INFO org.apache.hadoop.yarn.server.resourcemanager.rmapp.attempt.RMAppAttemptImpl: appattempt_1427899242644_0013_000001 State change from NEW to SUBMITTED
2015-04-01 17:44:32,272 INFO org.apache.hadoop.yarn.server.resourcemanager.scheduler.capacity.LeafQueue: Application application_1427899242644_0013 from user: echallier activated in queue: default
2015-04-01 17:44:32,272 INFO org.apache.hadoop.yarn.server.resourcemanager.scheduler.capacity.LeafQueue: Application added - appId: application_1427899242644_0013 user: org.apache.hadoop.yarn.server.resourcemanager.scheduler.capacity.LeafQueue$User@e51242, leaf-queue: default #user-pending-applications: 0 #user-active-applications: 1 #queue-pending-applications: 0 #queue-active-applications: 1
2015-04-01 17:44:32,272 INFO org.apache.hadoop.yarn.server.resourcemanager.scheduler.capacity.CapacityScheduler: Added Application Attempt appattempt_1427899242644_0013_000001 to scheduler from user echallier in queue default
2015-04-01 17:44:32,272 INFO org.apache.hadoop.yarn.server.resourcemanager.rmapp.attempt.RMAppAttemptImpl: appattempt_1427899242644_0013_000001 State change from SUBMITTED to SCHEDULED
2015-04-01 17:44:32,495 INFO org.apache.hadoop.yarn.server.resourcemanager.rmcontainer.RMContainerImpl: container_1427899242644_0013_01_000001 Container Transitioned from NEW to ALLOCATED
2015-04-01 17:44:32,495 INFO org.apache.hadoop.yarn.server.resourcemanager.RMAuditLogger: USER=echallier	OPERATION=AM Allocated Container	TARGET=SchedulerApp	RESULT=SUCCESS	APPID=application_1427899242644_0013	CONTAINERID=container_1427899242644_0013_01_000001
2015-04-01 17:44:32,495 INFO org.apache.hadoop.yarn.server.resourcemanager.scheduler.SchedulerNode: Assigned container container_1427899242644_0013_01_000001 of capacity <memory:2048, vCores:1> on host a11p2.fil.univ-lille1.fr.:55305, which has 1 containers, <memory:2048, vCores:1> used and <memory:6144, vCores:7> available after allocation
2015-04-01 17:44:32,495 INFO org.apache.hadoop.yarn.server.resourcemanager.scheduler.capacity.LeafQueue: assignedContainer application attempt=appattempt_1427899242644_0013_000001 container=Container: [ContainerId: container_1427899242644_0013_01_000001, NodeId: a11p2.fil.univ-lille1.fr.:55305, NodeHttpAddress: a11p2.fil.univ-lille1.fr.:8042, Resource: <memory:2048, vCores:1>, Priority: 0, Token: null, ] queue=default: capacity=1.0, absoluteCapacity=1.0, usedResources=<memory:0, vCores:0>, usedCapacity=0.0, absoluteUsedCapacity=0.0, numApps=1, numContainers=0 clusterResource=<memory:8192, vCores:8>
2015-04-01 17:44:32,495 INFO org.apache.hadoop.yarn.server.resourcemanager.scheduler.capacity.ParentQueue: Re-sorting assigned queue: root.default stats: default: capacity=1.0, absoluteCapacity=1.0, usedResources=<memory:2048, vCores:1>, usedCapacity=0.25, absoluteUsedCapacity=0.25, numApps=1, numContainers=1
2015-04-01 17:44:32,495 INFO org.apache.hadoop.yarn.server.resourcemanager.scheduler.capacity.ParentQueue: assignedContainer queue=root usedCapacity=0.25 absoluteUsedCapacity=0.25 used=<memory:2048, vCores:1> cluster=<memory:8192, vCores:8>
2015-04-01 17:44:32,495 INFO org.apache.hadoop.yarn.server.resourcemanager.security.NMTokenSecretManagerInRM: Sending NMToken for nodeId : a11p2.fil.univ-lille1.fr.:55305 for container : container_1427899242644_0013_01_000001
2015-04-01 17:44:32,496 INFO org.apache.hadoop.yarn.server.resourcemanager.rmcontainer.RMContainerImpl: container_1427899242644_0013_01_000001 Container Transitioned from ALLOCATED to ACQUIRED
2015-04-01 17:44:32,496 INFO org.apache.hadoop.yarn.server.resourcemanager.security.NMTokenSecretManagerInRM: Clear node set for appattempt_1427899242644_0013_000001
2015-04-01 17:44:32,496 INFO org.apache.hadoop.yarn.server.resourcemanager.rmapp.attempt.RMAppAttemptImpl: Storing attempt: AppId: application_1427899242644_0013 AttemptId: appattempt_1427899242644_0013_000001 MasterContainer: Container: [ContainerId: container_1427899242644_0013_01_000001, NodeId: a11p2.fil.univ-lille1.fr.:55305, NodeHttpAddress: a11p2.fil.univ-lille1.fr.:8042, Resource: <memory:2048, vCores:1>, Priority: 0, Token: Token { kind: ContainerToken, service: 127.0.1.1:55305 }, ]
2015-04-01 17:44:32,496 INFO org.apache.hadoop.yarn.server.resourcemanager.rmapp.attempt.RMAppAttemptImpl: appattempt_1427899242644_0013_000001 State change from SCHEDULED to ALLOCATED_SAVING
2015-04-01 17:44:32,497 INFO org.apache.hadoop.yarn.server.resourcemanager.rmapp.attempt.RMAppAttemptImpl: appattempt_1427899242644_0013_000001 State change from ALLOCATED_SAVING to ALLOCATED
2015-04-01 17:44:32,497 INFO org.apache.hadoop.yarn.server.resourcemanager.amlauncher.AMLauncher: Launching masterappattempt_1427899242644_0013_000001
2015-04-01 17:44:32,498 INFO org.apache.hadoop.yarn.server.resourcemanager.amlauncher.AMLauncher: Setting up container Container: [ContainerId: container_1427899242644_0013_01_000001, NodeId: a11p2.fil.univ-lille1.fr.:55305, NodeHttpAddress: a11p2.fil.univ-lille1.fr.:8042, Resource: <memory:2048, vCores:1>, Priority: 0, Token: Token { kind: ContainerToken, service: 127.0.1.1:55305 }, ] for AM appattempt_1427899242644_0013_000001
2015-04-01 17:44:32,498 INFO org.apache.hadoop.yarn.server.resourcemanager.amlauncher.AMLauncher: Command to launch container container_1427899242644_0013_01_000001 : $JAVA_HOME/bin/java -Dlog4j.configuration=container-log4j.properties -Dyarn.app.container.log.dir=<LOG_DIR> -Dyarn.app.container.log.filesize=0 -Dhadoop.root.logger=INFO,CLA  -Xmx1024m org.apache.hadoop.mapreduce.v2.app.MRAppMaster 1><LOG_DIR>/stdout 2><LOG_DIR>/stderr 
2015-04-01 17:44:32,509 INFO org.apache.hadoop.yarn.server.resourcemanager.amlauncher.AMLauncher: Done launching container Container: [ContainerId: container_1427899242644_0013_01_000001, NodeId: a11p2.fil.univ-lille1.fr.:55305, NodeHttpAddress: a11p2.fil.univ-lille1.fr.:8042, Resource: <memory:2048, vCores:1>, Priority: 0, Token: Token { kind: ContainerToken, service: 127.0.1.1:55305 }, ] for AM appattempt_1427899242644_0013_000001
2015-04-01 17:44:32,509 INFO org.apache.hadoop.yarn.server.resourcemanager.rmapp.attempt.RMAppAttemptImpl: appattempt_1427899242644_0013_000001 State change from ALLOCATED to LAUNCHED
2015-04-01 17:44:33,495 INFO org.apache.hadoop.yarn.server.resourcemanager.rmcontainer.RMContainerImpl: container_1427899242644_0013_01_000001 Container Transitioned from ACQUIRED to RUNNING
2015-04-01 17:44:35,390 INFO SecurityLogger.org.apache.hadoop.ipc.Server: Auth successful for appattempt_1427899242644_0013_000001 (auth:SIMPLE)
2015-04-01 17:44:35,392 INFO org.apache.hadoop.yarn.server.resourcemanager.ApplicationMasterService: AM registration appattempt_1427899242644_0013_000001
2015-04-01 17:44:35,392 INFO org.apache.hadoop.yarn.server.resourcemanager.RMAuditLogger: USER=echallier	IP=127.0.0.1	OPERATION=Register App Master	TARGET=ApplicationMasterService	RESULT=SUCCESS	APPID=application_1427899242644_0013	APPATTEMPTID=appattempt_1427899242644_0013_000001
2015-04-01 17:44:35,393 INFO org.apache.hadoop.yarn.server.resourcemanager.rmapp.attempt.RMAppAttemptImpl: appattempt_1427899242644_0013_000001 State change from LAUNCHED to RUNNING
2015-04-01 17:44:35,393 INFO org.apache.hadoop.yarn.server.resourcemanager.rmapp.RMAppImpl: application_1427899242644_0013 State change from ACCEPTED to RUNNING
2015-04-01 17:44:36,499 INFO org.apache.hadoop.yarn.server.resourcemanager.rmcontainer.RMContainerImpl: container_1427899242644_0013_01_000002 Container Transitioned from NEW to ALLOCATED
2015-04-01 17:44:36,499 INFO org.apache.hadoop.yarn.server.resourcemanager.RMAuditLogger: USER=echallier	OPERATION=AM Allocated Container	TARGET=SchedulerApp	RESULT=SUCCESS	APPID=application_1427899242644_0013	CONTAINERID=container_1427899242644_0013_01_000002
2015-04-01 17:44:36,499 INFO org.apache.hadoop.yarn.server.resourcemanager.scheduler.SchedulerNode: Assigned container container_1427899242644_0013_01_000002 of capacity <memory:1024, vCores:1> on host a11p2.fil.univ-lille1.fr.:55305, which has 2 containers, <memory:3072, vCores:2> used and <memory:5120, vCores:6> available after allocation
2015-04-01 17:44:36,500 INFO org.apache.hadoop.yarn.server.resourcemanager.scheduler.capacity.LeafQueue: assignedContainer application attempt=appattempt_1427899242644_0013_000001 container=Container: [ContainerId: container_1427899242644_0013_01_000002, NodeId: a11p2.fil.univ-lille1.fr.:55305, NodeHttpAddress: a11p2.fil.univ-lille1.fr.:8042, Resource: <memory:1024, vCores:1>, Priority: 20, Token: null, ] queue=default: capacity=1.0, absoluteCapacity=1.0, usedResources=<memory:2048, vCores:1>, usedCapacity=0.25, absoluteUsedCapacity=0.25, numApps=1, numContainers=1 clusterResource=<memory:8192, vCores:8>
2015-04-01 17:44:36,500 INFO org.apache.hadoop.yarn.server.resourcemanager.scheduler.capacity.ParentQueue: Re-sorting assigned queue: root.default stats: default: capacity=1.0, absoluteCapacity=1.0, usedResources=<memory:3072, vCores:2>, usedCapacity=0.375, absoluteUsedCapacity=0.375, numApps=1, numContainers=2
2015-04-01 17:44:36,500 INFO org.apache.hadoop.yarn.server.resourcemanager.scheduler.capacity.ParentQueue: assignedContainer queue=root usedCapacity=0.375 absoluteUsedCapacity=0.375 used=<memory:3072, vCores:2> cluster=<memory:8192, vCores:8>
2015-04-01 17:44:37,436 INFO org.apache.hadoop.yarn.server.resourcemanager.security.NMTokenSecretManagerInRM: Sending NMToken for nodeId : a11p2.fil.univ-lille1.fr.:55305 for container : container_1427899242644_0013_01_000002
2015-04-01 17:44:37,437 INFO org.apache.hadoop.yarn.server.resourcemanager.rmcontainer.RMContainerImpl: container_1427899242644_0013_01_000002 Container Transitioned from ALLOCATED to ACQUIRED
2015-04-01 17:44:38,452 INFO org.apache.hadoop.yarn.server.resourcemanager.scheduler.AppSchedulingInfo: checking for deactivate... 
2015-04-01 17:44:38,501 INFO org.apache.hadoop.yarn.server.resourcemanager.rmcontainer.RMContainerImpl: container_1427899242644_0013_01_000002 Container Transitioned from ACQUIRED to RUNNING
2015-04-01 17:44:40,837 INFO org.apache.hadoop.yarn.server.resourcemanager.rmcontainer.RMContainerImpl: container_1427899242644_0013_01_000002 Container Transitioned from RUNNING to COMPLETED
2015-04-01 17:44:40,837 INFO org.apache.hadoop.yarn.server.resourcemanager.scheduler.common.fica.FiCaSchedulerApp: Completed container: container_1427899242644_0013_01_000002 in state: COMPLETED event:FINISHED
2015-04-01 17:44:40,837 INFO org.apache.hadoop.yarn.server.resourcemanager.RMAuditLogger: USER=echallier	OPERATION=AM Released Container	TARGET=SchedulerApp	RESULT=SUCCESS	APPID=application_1427899242644_0013	CONTAINERID=container_1427899242644_0013_01_000002
2015-04-01 17:44:40,837 INFO org.apache.hadoop.yarn.server.resourcemanager.scheduler.SchedulerNode: Released container container_1427899242644_0013_01_000002 of capacity <memory:1024, vCores:1> on host a11p2.fil.univ-lille1.fr.:55305, which currently has 1 containers, <memory:2048, vCores:1> used and <memory:6144, vCores:7> available, release resources=true
2015-04-01 17:44:40,837 INFO org.apache.hadoop.yarn.server.resourcemanager.scheduler.capacity.LeafQueue: default used=<memory:2048, vCores:1> numContainers=1 user=echallier user-resources=<memory:2048, vCores:1>
2015-04-01 17:44:40,837 INFO org.apache.hadoop.yarn.server.resourcemanager.scheduler.capacity.LeafQueue: completedContainer container=Container: [ContainerId: container_1427899242644_0013_01_000002, NodeId: a11p2.fil.univ-lille1.fr.:55305, NodeHttpAddress: a11p2.fil.univ-lille1.fr.:8042, Resource: <memory:1024, vCores:1>, Priority: 20, Token: Token { kind: ContainerToken, service: 127.0.1.1:55305 }, ] queue=default: capacity=1.0, absoluteCapacity=1.0, usedResources=<memory:2048, vCores:1>, usedCapacity=0.25, absoluteUsedCapacity=0.25, numApps=1, numContainers=1 cluster=<memory:8192, vCores:8>
2015-04-01 17:44:40,837 INFO org.apache.hadoop.yarn.server.resourcemanager.scheduler.capacity.ParentQueue: completedContainer queue=root usedCapacity=0.25 absoluteUsedCapacity=0.25 used=<memory:2048, vCores:1> cluster=<memory:8192, vCores:8>
2015-04-01 17:44:40,837 INFO org.apache.hadoop.yarn.server.resourcemanager.scheduler.capacity.ParentQueue: Re-sorting completed queue: root.default stats: default: capacity=1.0, absoluteCapacity=1.0, usedResources=<memory:2048, vCores:1>, usedCapacity=0.25, absoluteUsedCapacity=0.25, numApps=1, numContainers=1
2015-04-01 17:44:40,838 INFO org.apache.hadoop.yarn.server.resourcemanager.scheduler.capacity.CapacityScheduler: Application attempt appattempt_1427899242644_0013_000001 released container container_1427899242644_0013_01_000002 on node: host: a11p2.fil.univ-lille1.fr.:55305 #containers=1 available=6144 used=2048 with event: FINISHED
2015-04-01 17:44:41,838 INFO org.apache.hadoop.yarn.server.resourcemanager.rmcontainer.RMContainerImpl: container_1427899242644_0013_01_000003 Container Transitioned from NEW to ALLOCATED
2015-04-01 17:44:41,839 INFO org.apache.hadoop.yarn.server.resourcemanager.RMAuditLogger: USER=echallier	OPERATION=AM Allocated Container	TARGET=SchedulerApp	RESULT=SUCCESS	APPID=application_1427899242644_0013	CONTAINERID=container_1427899242644_0013_01_000003
2015-04-01 17:44:41,839 INFO org.apache.hadoop.yarn.server.resourcemanager.scheduler.SchedulerNode: Assigned container container_1427899242644_0013_01_000003 of capacity <memory:1024, vCores:1> on host a11p2.fil.univ-lille1.fr.:55305, which has 2 containers, <memory:3072, vCores:2> used and <memory:5120, vCores:6> available after allocation
2015-04-01 17:44:41,839 INFO org.apache.hadoop.yarn.server.resourcemanager.scheduler.capacity.LeafQueue: assignedContainer application attempt=appattempt_1427899242644_0013_000001 container=Container: [ContainerId: container_1427899242644_0013_01_000003, NodeId: a11p2.fil.univ-lille1.fr.:55305, NodeHttpAddress: a11p2.fil.univ-lille1.fr.:8042, Resource: <memory:1024, vCores:1>, Priority: 10, Token: null, ] queue=default: capacity=1.0, absoluteCapacity=1.0, usedResources=<memory:2048, vCores:1>, usedCapacity=0.25, absoluteUsedCapacity=0.25, numApps=1, numContainers=1 clusterResource=<memory:8192, vCores:8>
2015-04-01 17:44:41,840 INFO org.apache.hadoop.yarn.server.resourcemanager.scheduler.capacity.ParentQueue: Re-sorting assigned queue: root.default stats: default: capacity=1.0, absoluteCapacity=1.0, usedResources=<memory:3072, vCores:2>, usedCapacity=0.375, absoluteUsedCapacity=0.375, numApps=1, numContainers=2
2015-04-01 17:44:41,840 INFO org.apache.hadoop.yarn.server.resourcemanager.scheduler.capacity.ParentQueue: assignedContainer queue=root usedCapacity=0.375 absoluteUsedCapacity=0.375 used=<memory:3072, vCores:2> cluster=<memory:8192, vCores:8>
2015-04-01 17:44:42,467 INFO org.apache.hadoop.yarn.server.resourcemanager.rmcontainer.RMContainerImpl: container_1427899242644_0013_01_000003 Container Transitioned from ALLOCATED to ACQUIRED
2015-04-01 17:44:42,839 INFO org.apache.hadoop.yarn.server.resourcemanager.rmcontainer.RMContainerImpl: container_1427899242644_0013_01_000003 Container Transitioned from ACQUIRED to RUNNING
2015-04-01 17:44:43,471 INFO org.apache.hadoop.yarn.server.resourcemanager.scheduler.AppSchedulingInfo: checking for deactivate... 
2015-04-01 17:44:45,196 INFO org.apache.hadoop.yarn.server.resourcemanager.rmapp.attempt.RMAppAttemptImpl: Updating application attempt appattempt_1427899242644_0013_000001 with final state: FINISHING, and exit status: -1000
2015-04-01 17:44:45,197 INFO org.apache.hadoop.yarn.server.resourcemanager.rmapp.attempt.RMAppAttemptImpl: appattempt_1427899242644_0013_000001 State change from RUNNING to FINAL_SAVING
2015-04-01 17:44:45,197 INFO org.apache.hadoop.yarn.server.resourcemanager.rmapp.RMAppImpl: Updating application application_1427899242644_0013 with final state: FINISHING
2015-04-01 17:44:45,197 INFO org.apache.hadoop.yarn.server.resourcemanager.rmapp.RMAppImpl: application_1427899242644_0013 State change from RUNNING to FINAL_SAVING
2015-04-01 17:44:45,197 INFO org.apache.hadoop.yarn.server.resourcemanager.recovery.RMStateStore: Updating info for app: application_1427899242644_0013
2015-04-01 17:44:45,197 INFO org.apache.hadoop.yarn.server.resourcemanager.rmapp.attempt.RMAppAttemptImpl: appattempt_1427899242644_0013_000001 State change from FINAL_SAVING to FINISHING
2015-04-01 17:44:45,197 INFO org.apache.hadoop.yarn.server.resourcemanager.rmapp.RMAppImpl: application_1427899242644_0013 State change from FINAL_SAVING to FINISHING
2015-04-01 17:44:45,847 INFO org.apache.hadoop.yarn.server.resourcemanager.rmcontainer.RMContainerImpl: container_1427899242644_0013_01_000003 Container Transitioned from RUNNING to COMPLETED
2015-04-01 17:44:45,848 INFO org.apache.hadoop.yarn.server.resourcemanager.scheduler.common.fica.FiCaSchedulerApp: Completed container: container_1427899242644_0013_01_000003 in state: COMPLETED event:FINISHED
2015-04-01 17:44:45,848 INFO org.apache.hadoop.yarn.server.resourcemanager.RMAuditLogger: USER=echallier	OPERATION=AM Released Container	TARGET=SchedulerApp	RESULT=SUCCESS	APPID=application_1427899242644_0013	CONTAINERID=container_1427899242644_0013_01_000003
2015-04-01 17:44:45,848 INFO org.apache.hadoop.yarn.server.resourcemanager.scheduler.SchedulerNode: Released container container_1427899242644_0013_01_000003 of capacity <memory:1024, vCores:1> on host a11p2.fil.univ-lille1.fr.:55305, which currently has 1 containers, <memory:2048, vCores:1> used and <memory:6144, vCores:7> available, release resources=true
2015-04-01 17:44:45,848 INFO org.apache.hadoop.yarn.server.resourcemanager.scheduler.capacity.LeafQueue: default used=<memory:2048, vCores:1> numContainers=1 user=echallier user-resources=<memory:2048, vCores:1>
2015-04-01 17:44:45,849 INFO org.apache.hadoop.yarn.server.resourcemanager.scheduler.capacity.LeafQueue: completedContainer container=Container: [ContainerId: container_1427899242644_0013_01_000003, NodeId: a11p2.fil.univ-lille1.fr.:55305, NodeHttpAddress: a11p2.fil.univ-lille1.fr.:8042, Resource: <memory:1024, vCores:1>, Priority: 10, Token: Token { kind: ContainerToken, service: 127.0.1.1:55305 }, ] queue=default: capacity=1.0, absoluteCapacity=1.0, usedResources=<memory:2048, vCores:1>, usedCapacity=0.25, absoluteUsedCapacity=0.25, numApps=1, numContainers=1 cluster=<memory:8192, vCores:8>
2015-04-01 17:44:45,849 INFO org.apache.hadoop.yarn.server.resourcemanager.scheduler.capacity.ParentQueue: completedContainer queue=root usedCapacity=0.25 absoluteUsedCapacity=0.25 used=<memory:2048, vCores:1> cluster=<memory:8192, vCores:8>
2015-04-01 17:44:45,849 INFO org.apache.hadoop.yarn.server.resourcemanager.scheduler.capacity.ParentQueue: Re-sorting completed queue: root.default stats: default: capacity=1.0, absoluteCapacity=1.0, usedResources=<memory:2048, vCores:1>, usedCapacity=0.25, absoluteUsedCapacity=0.25, numApps=1, numContainers=1
2015-04-01 17:44:45,849 INFO org.apache.hadoop.yarn.server.resourcemanager.scheduler.capacity.CapacityScheduler: Application attempt appattempt_1427899242644_0013_000001 released container container_1427899242644_0013_01_000003 on node: host: a11p2.fil.univ-lille1.fr.:55305 #containers=1 available=6144 used=2048 with event: FINISHED
2015-04-01 17:44:51,856 INFO org.apache.hadoop.yarn.server.resourcemanager.rmcontainer.RMContainerImpl: container_1427899242644_0013_01_000001 Container Transitioned from RUNNING to COMPLETED
2015-04-01 17:44:51,856 INFO org.apache.hadoop.yarn.server.resourcemanager.ApplicationMasterService: Unregistering app attempt : appattempt_1427899242644_0013_000001
2015-04-01 17:44:51,856 INFO org.apache.hadoop.yarn.server.resourcemanager.scheduler.common.fica.FiCaSchedulerApp: Completed container: container_1427899242644_0013_01_000001 in state: COMPLETED event:FINISHED
2015-04-01 17:44:51,857 INFO org.apache.hadoop.yarn.server.resourcemanager.rmapp.attempt.RMAppAttemptImpl: appattempt_1427899242644_0013_000001 State change from FINISHING to FINISHED
2015-04-01 17:44:51,857 INFO org.apache.hadoop.yarn.server.resourcemanager.RMAuditLogger: USER=echallier	OPERATION=AM Released Container	TARGET=SchedulerApp	RESULT=SUCCESS	APPID=application_1427899242644_0013	CONTAINERID=container_1427899242644_0013_01_000001
2015-04-01 17:44:51,857 INFO org.apache.hadoop.yarn.server.resourcemanager.rmapp.RMAppImpl: application_1427899242644_0013 State change from FINISHING to FINISHED
2015-04-01 17:44:51,857 INFO org.apache.hadoop.yarn.server.resourcemanager.scheduler.SchedulerNode: Released container container_1427899242644_0013_01_000001 of capacity <memory:2048, vCores:1> on host a11p2.fil.univ-lille1.fr.:55305, which currently has 0 containers, <memory:0, vCores:0> used and <memory:8192, vCores:8> available, release resources=true
2015-04-01 17:44:51,857 INFO org.apache.hadoop.yarn.server.resourcemanager.scheduler.capacity.LeafQueue: default used=<memory:0, vCores:0> numContainers=0 user=echallier user-resources=<memory:0, vCores:0>
2015-04-01 17:44:51,857 INFO org.apache.hadoop.yarn.server.resourcemanager.RMAuditLogger: USER=echallier	OPERATION=Application Finished - Succeeded	TARGET=RMAppManager	RESULT=SUCCESS	APPID=application_1427899242644_0013
2015-04-01 17:44:51,857 INFO org.apache.hadoop.yarn.server.resourcemanager.amlauncher.AMLauncher: Cleaning master appattempt_1427899242644_0013_000001
2015-04-01 17:44:51,857 INFO org.apache.hadoop.yarn.server.resourcemanager.scheduler.capacity.LeafQueue: completedContainer container=Container: [ContainerId: container_1427899242644_0013_01_000001, NodeId: a11p2.fil.univ-lille1.fr.:55305, NodeHttpAddress: a11p2.fil.univ-lille1.fr.:8042, Resource: <memory:2048, vCores:1>, Priority: 0, Token: Token { kind: ContainerToken, service: 127.0.1.1:55305 }, ] queue=default: capacity=1.0, absoluteCapacity=1.0, usedResources=<memory:0, vCores:0>, usedCapacity=0.0, absoluteUsedCapacity=0.0, numApps=1, numContainers=0 cluster=<memory:8192, vCores:8>
2015-04-01 17:44:51,857 INFO org.apache.hadoop.yarn.server.resourcemanager.scheduler.capacity.ParentQueue: completedContainer queue=root usedCapacity=0.0 absoluteUsedCapacity=0.0 used=<memory:0, vCores:0> cluster=<memory:8192, vCores:8>
2015-04-01 17:44:51,857 INFO org.apache.hadoop.yarn.server.resourcemanager.scheduler.capacity.ParentQueue: Re-sorting completed queue: root.default stats: default: capacity=1.0, absoluteCapacity=1.0, usedResources=<memory:0, vCores:0>, usedCapacity=0.0, absoluteUsedCapacity=0.0, numApps=1, numContainers=0
2015-04-01 17:44:51,857 INFO org.apache.hadoop.yarn.server.resourcemanager.scheduler.capacity.CapacityScheduler: Application attempt appattempt_1427899242644_0013_000001 released container container_1427899242644_0013_01_000001 on node: host: a11p2.fil.univ-lille1.fr.:55305 #containers=0 available=8192 used=0 with event: FINISHED
2015-04-01 17:44:51,858 INFO org.apache.hadoop.yarn.server.resourcemanager.RMAppManager$ApplicationSummary: appId=application_1427899242644_0013,name=GPS,user=echallier,queue=default,state=FINISHED,trackingUrl=http://a11p2.fil.univ-lille1.fr.:8088/proxy/application_1427899242644_0013/jobhistory/job/job_1427899242644_0013,appMasterHost=a11p2,startTime=1427903072270,finishTime=1427903085197,finalStatus=SUCCEEDED
2015-04-01 17:44:51,858 INFO org.apache.hadoop.yarn.server.resourcemanager.scheduler.capacity.CapacityScheduler: Application Attempt appattempt_1427899242644_0013_000001 is done. finalState=FINISHED
2015-04-01 17:44:51,858 INFO org.apache.hadoop.yarn.server.resourcemanager.scheduler.AppSchedulingInfo: Application application_1427899242644_0013 requests cleared
2015-04-01 17:44:51,858 INFO org.apache.hadoop.yarn.server.resourcemanager.scheduler.capacity.LeafQueue: Application removed - appId: application_1427899242644_0013 user: echallier queue: default #user-pending-applications: 0 #user-active-applications: 0 #queue-pending-applications: 0 #queue-active-applications: 0
2015-04-01 17:44:51,858 INFO org.apache.hadoop.yarn.server.resourcemanager.scheduler.capacity.ParentQueue: Application removed - appId: application_1427899242644_0013 user: echallier leaf-queue of parent: root #applications: 0
2015-04-01 17:47:49,788 INFO org.apache.hadoop.yarn.server.resourcemanager.ClientRMService: Allocated new applicationId: 14
2015-04-01 17:47:50,617 INFO org.apache.hadoop.yarn.server.resourcemanager.ClientRMService: Application with id 14 submitted by user echallier
2015-04-01 17:47:50,617 INFO org.apache.hadoop.yarn.server.resourcemanager.rmapp.RMAppImpl: Storing application with id application_1427899242644_0014
2015-04-01 17:47:50,617 INFO org.apache.hadoop.yarn.server.resourcemanager.RMAuditLogger: USER=echallier	IP=127.0.0.1	OPERATION=Submit Application Request	TARGET=ClientRMService	RESULT=SUCCESS	APPID=application_1427899242644_0014
2015-04-01 17:47:50,617 INFO org.apache.hadoop.yarn.server.resourcemanager.rmapp.RMAppImpl: application_1427899242644_0014 State change from NEW to NEW_SAVING
2015-04-01 17:47:50,617 INFO org.apache.hadoop.yarn.server.resourcemanager.recovery.RMStateStore: Storing info for app: application_1427899242644_0014
2015-04-01 17:47:50,618 INFO org.apache.hadoop.yarn.server.resourcemanager.rmapp.RMAppImpl: application_1427899242644_0014 State change from NEW_SAVING to SUBMITTED
2015-04-01 17:47:50,618 INFO org.apache.hadoop.yarn.server.resourcemanager.scheduler.capacity.ParentQueue: Application added - appId: application_1427899242644_0014 user: echallier leaf-queue of parent: root #applications: 1
2015-04-01 17:47:50,618 INFO org.apache.hadoop.yarn.server.resourcemanager.scheduler.capacity.CapacityScheduler: Accepted application application_1427899242644_0014 from user: echallier, in queue: default
2015-04-01 17:47:50,618 INFO org.apache.hadoop.yarn.server.resourcemanager.rmapp.RMAppImpl: application_1427899242644_0014 State change from SUBMITTED to ACCEPTED
2015-04-01 17:47:50,618 INFO org.apache.hadoop.yarn.server.resourcemanager.ApplicationMasterService: Registering app attempt : appattempt_1427899242644_0014_000001
2015-04-01 17:47:50,619 INFO org.apache.hadoop.yarn.server.resourcemanager.rmapp.attempt.RMAppAttemptImpl: appattempt_1427899242644_0014_000001 State change from NEW to SUBMITTED
2015-04-01 17:47:50,619 INFO org.apache.hadoop.yarn.server.resourcemanager.scheduler.capacity.LeafQueue: Application application_1427899242644_0014 from user: echallier activated in queue: default
2015-04-01 17:47:50,619 INFO org.apache.hadoop.yarn.server.resourcemanager.scheduler.capacity.LeafQueue: Application added - appId: application_1427899242644_0014 user: org.apache.hadoop.yarn.server.resourcemanager.scheduler.capacity.LeafQueue$User@ee2ed1, leaf-queue: default #user-pending-applications: 0 #user-active-applications: 1 #queue-pending-applications: 0 #queue-active-applications: 1
2015-04-01 17:47:50,619 INFO org.apache.hadoop.yarn.server.resourcemanager.scheduler.capacity.CapacityScheduler: Added Application Attempt appattempt_1427899242644_0014_000001 to scheduler from user echallier in queue default
2015-04-01 17:47:50,619 INFO org.apache.hadoop.yarn.server.resourcemanager.rmapp.attempt.RMAppAttemptImpl: appattempt_1427899242644_0014_000001 State change from SUBMITTED to SCHEDULED
2015-04-01 17:47:51,104 INFO org.apache.hadoop.yarn.server.resourcemanager.rmcontainer.RMContainerImpl: container_1427899242644_0014_01_000001 Container Transitioned from NEW to ALLOCATED
2015-04-01 17:47:51,104 INFO org.apache.hadoop.yarn.server.resourcemanager.RMAuditLogger: USER=echallier	OPERATION=AM Allocated Container	TARGET=SchedulerApp	RESULT=SUCCESS	APPID=application_1427899242644_0014	CONTAINERID=container_1427899242644_0014_01_000001
2015-04-01 17:47:51,104 INFO org.apache.hadoop.yarn.server.resourcemanager.scheduler.SchedulerNode: Assigned container container_1427899242644_0014_01_000001 of capacity <memory:2048, vCores:1> on host a11p2.fil.univ-lille1.fr.:55305, which has 1 containers, <memory:2048, vCores:1> used and <memory:6144, vCores:7> available after allocation
2015-04-01 17:47:51,105 INFO org.apache.hadoop.yarn.server.resourcemanager.scheduler.capacity.LeafQueue: assignedContainer application attempt=appattempt_1427899242644_0014_000001 container=Container: [ContainerId: container_1427899242644_0014_01_000001, NodeId: a11p2.fil.univ-lille1.fr.:55305, NodeHttpAddress: a11p2.fil.univ-lille1.fr.:8042, Resource: <memory:2048, vCores:1>, Priority: 0, Token: null, ] queue=default: capacity=1.0, absoluteCapacity=1.0, usedResources=<memory:0, vCores:0>, usedCapacity=0.0, absoluteUsedCapacity=0.0, numApps=1, numContainers=0 clusterResource=<memory:8192, vCores:8>
2015-04-01 17:47:51,105 INFO org.apache.hadoop.yarn.server.resourcemanager.scheduler.capacity.ParentQueue: Re-sorting assigned queue: root.default stats: default: capacity=1.0, absoluteCapacity=1.0, usedResources=<memory:2048, vCores:1>, usedCapacity=0.25, absoluteUsedCapacity=0.25, numApps=1, numContainers=1
2015-04-01 17:47:51,105 INFO org.apache.hadoop.yarn.server.resourcemanager.scheduler.capacity.ParentQueue: assignedContainer queue=root usedCapacity=0.25 absoluteUsedCapacity=0.25 used=<memory:2048, vCores:1> cluster=<memory:8192, vCores:8>
2015-04-01 17:47:51,105 INFO org.apache.hadoop.yarn.server.resourcemanager.security.NMTokenSecretManagerInRM: Sending NMToken for nodeId : a11p2.fil.univ-lille1.fr.:55305 for container : container_1427899242644_0014_01_000001
2015-04-01 17:47:51,106 INFO org.apache.hadoop.yarn.server.resourcemanager.rmcontainer.RMContainerImpl: container_1427899242644_0014_01_000001 Container Transitioned from ALLOCATED to ACQUIRED
2015-04-01 17:47:51,106 INFO org.apache.hadoop.yarn.server.resourcemanager.security.NMTokenSecretManagerInRM: Clear node set for appattempt_1427899242644_0014_000001
2015-04-01 17:47:51,106 INFO org.apache.hadoop.yarn.server.resourcemanager.rmapp.attempt.RMAppAttemptImpl: Storing attempt: AppId: application_1427899242644_0014 AttemptId: appattempt_1427899242644_0014_000001 MasterContainer: Container: [ContainerId: container_1427899242644_0014_01_000001, NodeId: a11p2.fil.univ-lille1.fr.:55305, NodeHttpAddress: a11p2.fil.univ-lille1.fr.:8042, Resource: <memory:2048, vCores:1>, Priority: 0, Token: Token { kind: ContainerToken, service: 127.0.1.1:55305 }, ]
2015-04-01 17:47:51,106 INFO org.apache.hadoop.yarn.server.resourcemanager.rmapp.attempt.RMAppAttemptImpl: appattempt_1427899242644_0014_000001 State change from SCHEDULED to ALLOCATED_SAVING
2015-04-01 17:47:51,106 INFO org.apache.hadoop.yarn.server.resourcemanager.rmapp.attempt.RMAppAttemptImpl: appattempt_1427899242644_0014_000001 State change from ALLOCATED_SAVING to ALLOCATED
2015-04-01 17:47:51,106 INFO org.apache.hadoop.yarn.server.resourcemanager.amlauncher.AMLauncher: Launching masterappattempt_1427899242644_0014_000001
2015-04-01 17:47:51,107 INFO org.apache.hadoop.yarn.server.resourcemanager.amlauncher.AMLauncher: Setting up container Container: [ContainerId: container_1427899242644_0014_01_000001, NodeId: a11p2.fil.univ-lille1.fr.:55305, NodeHttpAddress: a11p2.fil.univ-lille1.fr.:8042, Resource: <memory:2048, vCores:1>, Priority: 0, Token: Token { kind: ContainerToken, service: 127.0.1.1:55305 }, ] for AM appattempt_1427899242644_0014_000001
2015-04-01 17:47:51,107 INFO org.apache.hadoop.yarn.server.resourcemanager.amlauncher.AMLauncher: Command to launch container container_1427899242644_0014_01_000001 : $JAVA_HOME/bin/java -Dlog4j.configuration=container-log4j.properties -Dyarn.app.container.log.dir=<LOG_DIR> -Dyarn.app.container.log.filesize=0 -Dhadoop.root.logger=INFO,CLA  -Xmx1024m org.apache.hadoop.mapreduce.v2.app.MRAppMaster 1><LOG_DIR>/stdout 2><LOG_DIR>/stderr 
2015-04-01 17:47:51,116 INFO org.apache.hadoop.yarn.server.resourcemanager.amlauncher.AMLauncher: Done launching container Container: [ContainerId: container_1427899242644_0014_01_000001, NodeId: a11p2.fil.univ-lille1.fr.:55305, NodeHttpAddress: a11p2.fil.univ-lille1.fr.:8042, Resource: <memory:2048, vCores:1>, Priority: 0, Token: Token { kind: ContainerToken, service: 127.0.1.1:55305 }, ] for AM appattempt_1427899242644_0014_000001
2015-04-01 17:47:51,116 INFO org.apache.hadoop.yarn.server.resourcemanager.rmapp.attempt.RMAppAttemptImpl: appattempt_1427899242644_0014_000001 State change from ALLOCATED to LAUNCHED
2015-04-01 17:47:52,105 INFO org.apache.hadoop.yarn.server.resourcemanager.rmcontainer.RMContainerImpl: container_1427899242644_0014_01_000001 Container Transitioned from ACQUIRED to RUNNING
2015-04-01 17:47:54,020 INFO SecurityLogger.org.apache.hadoop.ipc.Server: Auth successful for appattempt_1427899242644_0014_000001 (auth:SIMPLE)
2015-04-01 17:47:54,022 INFO org.apache.hadoop.yarn.server.resourcemanager.ApplicationMasterService: AM registration appattempt_1427899242644_0014_000001
2015-04-01 17:47:54,022 INFO org.apache.hadoop.yarn.server.resourcemanager.RMAuditLogger: USER=echallier	IP=127.0.0.1	OPERATION=Register App Master	TARGET=ApplicationMasterService	RESULT=SUCCESS	APPID=application_1427899242644_0014	APPATTEMPTID=appattempt_1427899242644_0014_000001
2015-04-01 17:47:54,022 INFO org.apache.hadoop.yarn.server.resourcemanager.rmapp.attempt.RMAppAttemptImpl: appattempt_1427899242644_0014_000001 State change from LAUNCHED to RUNNING
2015-04-01 17:47:54,022 INFO org.apache.hadoop.yarn.server.resourcemanager.rmapp.RMAppImpl: application_1427899242644_0014 State change from ACCEPTED to RUNNING
2015-04-01 17:47:55,109 INFO org.apache.hadoop.yarn.server.resourcemanager.rmcontainer.RMContainerImpl: container_1427899242644_0014_01_000002 Container Transitioned from NEW to ALLOCATED
2015-04-01 17:47:55,109 INFO org.apache.hadoop.yarn.server.resourcemanager.RMAuditLogger: USER=echallier	OPERATION=AM Allocated Container	TARGET=SchedulerApp	RESULT=SUCCESS	APPID=application_1427899242644_0014	CONTAINERID=container_1427899242644_0014_01_000002
2015-04-01 17:47:55,109 INFO org.apache.hadoop.yarn.server.resourcemanager.scheduler.SchedulerNode: Assigned container container_1427899242644_0014_01_000002 of capacity <memory:1024, vCores:1> on host a11p2.fil.univ-lille1.fr.:55305, which has 2 containers, <memory:3072, vCores:2> used and <memory:5120, vCores:6> available after allocation
2015-04-01 17:47:55,110 INFO org.apache.hadoop.yarn.server.resourcemanager.scheduler.capacity.LeafQueue: assignedContainer application attempt=appattempt_1427899242644_0014_000001 container=Container: [ContainerId: container_1427899242644_0014_01_000002, NodeId: a11p2.fil.univ-lille1.fr.:55305, NodeHttpAddress: a11p2.fil.univ-lille1.fr.:8042, Resource: <memory:1024, vCores:1>, Priority: 20, Token: null, ] queue=default: capacity=1.0, absoluteCapacity=1.0, usedResources=<memory:2048, vCores:1>, usedCapacity=0.25, absoluteUsedCapacity=0.25, numApps=1, numContainers=1 clusterResource=<memory:8192, vCores:8>
2015-04-01 17:47:55,110 INFO org.apache.hadoop.yarn.server.resourcemanager.scheduler.capacity.ParentQueue: Re-sorting assigned queue: root.default stats: default: capacity=1.0, absoluteCapacity=1.0, usedResources=<memory:3072, vCores:2>, usedCapacity=0.375, absoluteUsedCapacity=0.375, numApps=1, numContainers=2
2015-04-01 17:47:55,110 INFO org.apache.hadoop.yarn.server.resourcemanager.scheduler.capacity.ParentQueue: assignedContainer queue=root usedCapacity=0.375 absoluteUsedCapacity=0.375 used=<memory:3072, vCores:2> cluster=<memory:8192, vCores:8>
2015-04-01 17:47:56,078 INFO org.apache.hadoop.yarn.server.resourcemanager.security.NMTokenSecretManagerInRM: Sending NMToken for nodeId : a11p2.fil.univ-lille1.fr.:55305 for container : container_1427899242644_0014_01_000002
2015-04-01 17:47:56,080 INFO org.apache.hadoop.yarn.server.resourcemanager.rmcontainer.RMContainerImpl: container_1427899242644_0014_01_000002 Container Transitioned from ALLOCATED to ACQUIRED
2015-04-01 17:47:57,095 INFO org.apache.hadoop.yarn.server.resourcemanager.scheduler.AppSchedulingInfo: checking for deactivate... 
2015-04-01 17:47:57,112 INFO org.apache.hadoop.yarn.server.resourcemanager.rmcontainer.RMContainerImpl: container_1427899242644_0014_01_000002 Container Transitioned from ACQUIRED to RUNNING
2015-04-01 17:47:59,510 INFO org.apache.hadoop.yarn.server.resourcemanager.rmcontainer.RMContainerImpl: container_1427899242644_0014_01_000002 Container Transitioned from RUNNING to COMPLETED
2015-04-01 17:47:59,511 INFO org.apache.hadoop.yarn.server.resourcemanager.scheduler.common.fica.FiCaSchedulerApp: Completed container: container_1427899242644_0014_01_000002 in state: COMPLETED event:FINISHED
2015-04-01 17:47:59,511 INFO org.apache.hadoop.yarn.server.resourcemanager.RMAuditLogger: USER=echallier	OPERATION=AM Released Container	TARGET=SchedulerApp	RESULT=SUCCESS	APPID=application_1427899242644_0014	CONTAINERID=container_1427899242644_0014_01_000002
2015-04-01 17:47:59,511 INFO org.apache.hadoop.yarn.server.resourcemanager.scheduler.SchedulerNode: Released container container_1427899242644_0014_01_000002 of capacity <memory:1024, vCores:1> on host a11p2.fil.univ-lille1.fr.:55305, which currently has 1 containers, <memory:2048, vCores:1> used and <memory:6144, vCores:7> available, release resources=true
2015-04-01 17:47:59,511 INFO org.apache.hadoop.yarn.server.resourcemanager.scheduler.capacity.LeafQueue: default used=<memory:2048, vCores:1> numContainers=1 user=echallier user-resources=<memory:2048, vCores:1>
2015-04-01 17:47:59,511 INFO org.apache.hadoop.yarn.server.resourcemanager.scheduler.capacity.LeafQueue: completedContainer container=Container: [ContainerId: container_1427899242644_0014_01_000002, NodeId: a11p2.fil.univ-lille1.fr.:55305, NodeHttpAddress: a11p2.fil.univ-lille1.fr.:8042, Resource: <memory:1024, vCores:1>, Priority: 20, Token: Token { kind: ContainerToken, service: 127.0.1.1:55305 }, ] queue=default: capacity=1.0, absoluteCapacity=1.0, usedResources=<memory:2048, vCores:1>, usedCapacity=0.25, absoluteUsedCapacity=0.25, numApps=1, numContainers=1 cluster=<memory:8192, vCores:8>
2015-04-01 17:47:59,511 INFO org.apache.hadoop.yarn.server.resourcemanager.scheduler.capacity.ParentQueue: completedContainer queue=root usedCapacity=0.25 absoluteUsedCapacity=0.25 used=<memory:2048, vCores:1> cluster=<memory:8192, vCores:8>
2015-04-01 17:47:59,511 INFO org.apache.hadoop.yarn.server.resourcemanager.scheduler.capacity.ParentQueue: Re-sorting completed queue: root.default stats: default: capacity=1.0, absoluteCapacity=1.0, usedResources=<memory:2048, vCores:1>, usedCapacity=0.25, absoluteUsedCapacity=0.25, numApps=1, numContainers=1
2015-04-01 17:47:59,511 INFO org.apache.hadoop.yarn.server.resourcemanager.scheduler.capacity.CapacityScheduler: Application attempt appattempt_1427899242644_0014_000001 released container container_1427899242644_0014_01_000002 on node: host: a11p2.fil.univ-lille1.fr.:55305 #containers=1 available=6144 used=2048 with event: FINISHED
2015-04-01 17:48:00,512 INFO org.apache.hadoop.yarn.server.resourcemanager.rmcontainer.RMContainerImpl: container_1427899242644_0014_01_000003 Container Transitioned from NEW to ALLOCATED
2015-04-01 17:48:00,512 INFO org.apache.hadoop.yarn.server.resourcemanager.RMAuditLogger: USER=echallier	OPERATION=AM Allocated Container	TARGET=SchedulerApp	RESULT=SUCCESS	APPID=application_1427899242644_0014	CONTAINERID=container_1427899242644_0014_01_000003
2015-04-01 17:48:00,512 INFO org.apache.hadoop.yarn.server.resourcemanager.scheduler.SchedulerNode: Assigned container container_1427899242644_0014_01_000003 of capacity <memory:1024, vCores:1> on host a11p2.fil.univ-lille1.fr.:55305, which has 2 containers, <memory:3072, vCores:2> used and <memory:5120, vCores:6> available after allocation
2015-04-01 17:48:00,513 INFO org.apache.hadoop.yarn.server.resourcemanager.scheduler.capacity.LeafQueue: assignedContainer application attempt=appattempt_1427899242644_0014_000001 container=Container: [ContainerId: container_1427899242644_0014_01_000003, NodeId: a11p2.fil.univ-lille1.fr.:55305, NodeHttpAddress: a11p2.fil.univ-lille1.fr.:8042, Resource: <memory:1024, vCores:1>, Priority: 10, Token: null, ] queue=default: capacity=1.0, absoluteCapacity=1.0, usedResources=<memory:2048, vCores:1>, usedCapacity=0.25, absoluteUsedCapacity=0.25, numApps=1, numContainers=1 clusterResource=<memory:8192, vCores:8>
2015-04-01 17:48:00,513 INFO org.apache.hadoop.yarn.server.resourcemanager.scheduler.capacity.ParentQueue: Re-sorting assigned queue: root.default stats: default: capacity=1.0, absoluteCapacity=1.0, usedResources=<memory:3072, vCores:2>, usedCapacity=0.375, absoluteUsedCapacity=0.375, numApps=1, numContainers=2
2015-04-01 17:48:00,513 INFO org.apache.hadoop.yarn.server.resourcemanager.scheduler.capacity.ParentQueue: assignedContainer queue=root usedCapacity=0.375 absoluteUsedCapacity=0.375 used=<memory:3072, vCores:2> cluster=<memory:8192, vCores:8>
2015-04-01 17:48:01,111 INFO org.apache.hadoop.yarn.server.resourcemanager.rmcontainer.RMContainerImpl: container_1427899242644_0014_01_000003 Container Transitioned from ALLOCATED to ACQUIRED
2015-04-01 17:48:01,513 INFO org.apache.hadoop.yarn.server.resourcemanager.rmcontainer.RMContainerImpl: container_1427899242644_0014_01_000003 Container Transitioned from ACQUIRED to RUNNING
2015-04-01 17:48:02,115 INFO org.apache.hadoop.yarn.server.resourcemanager.scheduler.AppSchedulingInfo: checking for deactivate... 
2015-04-01 17:48:04,028 INFO org.apache.hadoop.yarn.server.resourcemanager.rmapp.attempt.RMAppAttemptImpl: Updating application attempt appattempt_1427899242644_0014_000001 with final state: FINISHING, and exit status: -1000
2015-04-01 17:48:04,028 INFO org.apache.hadoop.yarn.server.resourcemanager.rmapp.attempt.RMAppAttemptImpl: appattempt_1427899242644_0014_000001 State change from RUNNING to FINAL_SAVING
2015-04-01 17:48:04,028 INFO org.apache.hadoop.yarn.server.resourcemanager.rmapp.RMAppImpl: Updating application application_1427899242644_0014 with final state: FINISHING
2015-04-01 17:48:04,028 INFO org.apache.hadoop.yarn.server.resourcemanager.rmapp.RMAppImpl: application_1427899242644_0014 State change from RUNNING to FINAL_SAVING
2015-04-01 17:48:04,028 INFO org.apache.hadoop.yarn.server.resourcemanager.recovery.RMStateStore: Updating info for app: application_1427899242644_0014
2015-04-01 17:48:04,029 INFO org.apache.hadoop.yarn.server.resourcemanager.rmapp.attempt.RMAppAttemptImpl: appattempt_1427899242644_0014_000001 State change from FINAL_SAVING to FINISHING
2015-04-01 17:48:04,029 INFO org.apache.hadoop.yarn.server.resourcemanager.rmapp.RMAppImpl: application_1427899242644_0014 State change from FINAL_SAVING to FINISHING
2015-04-01 17:48:04,615 INFO org.apache.hadoop.yarn.server.resourcemanager.rmcontainer.RMContainerImpl: container_1427899242644_0014_01_000003 Container Transitioned from RUNNING to COMPLETED
2015-04-01 17:48:04,615 INFO org.apache.hadoop.yarn.server.resourcemanager.scheduler.common.fica.FiCaSchedulerApp: Completed container: container_1427899242644_0014_01_000003 in state: COMPLETED event:FINISHED
2015-04-01 17:48:04,615 INFO org.apache.hadoop.yarn.server.resourcemanager.RMAuditLogger: USER=echallier	OPERATION=AM Released Container	TARGET=SchedulerApp	RESULT=SUCCESS	APPID=application_1427899242644_0014	CONTAINERID=container_1427899242644_0014_01_000003
2015-04-01 17:48:04,615 INFO org.apache.hadoop.yarn.server.resourcemanager.scheduler.SchedulerNode: Released container container_1427899242644_0014_01_000003 of capacity <memory:1024, vCores:1> on host a11p2.fil.univ-lille1.fr.:55305, which currently has 1 containers, <memory:2048, vCores:1> used and <memory:6144, vCores:7> available, release resources=true
2015-04-01 17:48:04,615 INFO org.apache.hadoop.yarn.server.resourcemanager.scheduler.capacity.LeafQueue: default used=<memory:2048, vCores:1> numContainers=1 user=echallier user-resources=<memory:2048, vCores:1>
2015-04-01 17:48:04,616 INFO org.apache.hadoop.yarn.server.resourcemanager.scheduler.capacity.LeafQueue: completedContainer container=Container: [ContainerId: container_1427899242644_0014_01_000003, NodeId: a11p2.fil.univ-lille1.fr.:55305, NodeHttpAddress: a11p2.fil.univ-lille1.fr.:8042, Resource: <memory:1024, vCores:1>, Priority: 10, Token: Token { kind: ContainerToken, service: 127.0.1.1:55305 }, ] queue=default: capacity=1.0, absoluteCapacity=1.0, usedResources=<memory:2048, vCores:1>, usedCapacity=0.25, absoluteUsedCapacity=0.25, numApps=1, numContainers=1 cluster=<memory:8192, vCores:8>
2015-04-01 17:48:04,616 INFO org.apache.hadoop.yarn.server.resourcemanager.scheduler.capacity.ParentQueue: completedContainer queue=root usedCapacity=0.25 absoluteUsedCapacity=0.25 used=<memory:2048, vCores:1> cluster=<memory:8192, vCores:8>
2015-04-01 17:48:04,616 INFO org.apache.hadoop.yarn.server.resourcemanager.scheduler.capacity.ParentQueue: Re-sorting completed queue: root.default stats: default: capacity=1.0, absoluteCapacity=1.0, usedResources=<memory:2048, vCores:1>, usedCapacity=0.25, absoluteUsedCapacity=0.25, numApps=1, numContainers=1
2015-04-01 17:48:04,616 INFO org.apache.hadoop.yarn.server.resourcemanager.scheduler.capacity.CapacityScheduler: Application attempt appattempt_1427899242644_0014_000001 released container container_1427899242644_0014_01_000003 on node: host: a11p2.fil.univ-lille1.fr.:55305 #containers=1 available=6144 used=2048 with event: FINISHED
2015-04-01 17:48:10,624 INFO org.apache.hadoop.yarn.server.resourcemanager.rmcontainer.RMContainerImpl: container_1427899242644_0014_01_000001 Container Transitioned from RUNNING to COMPLETED
2015-04-01 17:48:10,624 INFO org.apache.hadoop.yarn.server.resourcemanager.ApplicationMasterService: Unregistering app attempt : appattempt_1427899242644_0014_000001
2015-04-01 17:48:10,625 INFO org.apache.hadoop.yarn.server.resourcemanager.scheduler.common.fica.FiCaSchedulerApp: Completed container: container_1427899242644_0014_01_000001 in state: COMPLETED event:FINISHED
2015-04-01 17:48:10,625 INFO org.apache.hadoop.yarn.server.resourcemanager.rmapp.attempt.RMAppAttemptImpl: appattempt_1427899242644_0014_000001 State change from FINISHING to FINISHED
2015-04-01 17:48:10,625 INFO org.apache.hadoop.yarn.server.resourcemanager.RMAuditLogger: USER=echallier	OPERATION=AM Released Container	TARGET=SchedulerApp	RESULT=SUCCESS	APPID=application_1427899242644_0014	CONTAINERID=container_1427899242644_0014_01_000001
2015-04-01 17:48:10,625 INFO org.apache.hadoop.yarn.server.resourcemanager.rmapp.RMAppImpl: application_1427899242644_0014 State change from FINISHING to FINISHED
2015-04-01 17:48:10,625 INFO org.apache.hadoop.yarn.server.resourcemanager.scheduler.SchedulerNode: Released container container_1427899242644_0014_01_000001 of capacity <memory:2048, vCores:1> on host a11p2.fil.univ-lille1.fr.:55305, which currently has 0 containers, <memory:0, vCores:0> used and <memory:8192, vCores:8> available, release resources=true
2015-04-01 17:48:10,625 INFO org.apache.hadoop.yarn.server.resourcemanager.scheduler.capacity.LeafQueue: default used=<memory:0, vCores:0> numContainers=0 user=echallier user-resources=<memory:0, vCores:0>
2015-04-01 17:48:10,625 INFO org.apache.hadoop.yarn.server.resourcemanager.RMAuditLogger: USER=echallier	OPERATION=Application Finished - Succeeded	TARGET=RMAppManager	RESULT=SUCCESS	APPID=application_1427899242644_0014
2015-04-01 17:48:10,625 INFO org.apache.hadoop.yarn.server.resourcemanager.amlauncher.AMLauncher: Cleaning master appattempt_1427899242644_0014_000001
2015-04-01 17:48:10,625 INFO org.apache.hadoop.yarn.server.resourcemanager.scheduler.capacity.LeafQueue: completedContainer container=Container: [ContainerId: container_1427899242644_0014_01_000001, NodeId: a11p2.fil.univ-lille1.fr.:55305, NodeHttpAddress: a11p2.fil.univ-lille1.fr.:8042, Resource: <memory:2048, vCores:1>, Priority: 0, Token: Token { kind: ContainerToken, service: 127.0.1.1:55305 }, ] queue=default: capacity=1.0, absoluteCapacity=1.0, usedResources=<memory:0, vCores:0>, usedCapacity=0.0, absoluteUsedCapacity=0.0, numApps=1, numContainers=0 cluster=<memory:8192, vCores:8>
2015-04-01 17:48:10,626 INFO org.apache.hadoop.yarn.server.resourcemanager.scheduler.capacity.ParentQueue: completedContainer queue=root usedCapacity=0.0 absoluteUsedCapacity=0.0 used=<memory:0, vCores:0> cluster=<memory:8192, vCores:8>
2015-04-01 17:48:10,626 INFO org.apache.hadoop.yarn.server.resourcemanager.scheduler.capacity.ParentQueue: Re-sorting completed queue: root.default stats: default: capacity=1.0, absoluteCapacity=1.0, usedResources=<memory:0, vCores:0>, usedCapacity=0.0, absoluteUsedCapacity=0.0, numApps=1, numContainers=0
2015-04-01 17:48:10,626 INFO org.apache.hadoop.yarn.server.resourcemanager.scheduler.capacity.CapacityScheduler: Application attempt appattempt_1427899242644_0014_000001 released container container_1427899242644_0014_01_000001 on node: host: a11p2.fil.univ-lille1.fr.:55305 #containers=0 available=8192 used=0 with event: FINISHED
2015-04-01 17:48:10,626 INFO org.apache.hadoop.yarn.server.resourcemanager.RMAppManager$ApplicationSummary: appId=application_1427899242644_0014,name=GPS,user=echallier,queue=default,state=FINISHED,trackingUrl=http://a11p2.fil.univ-lille1.fr.:8088/proxy/application_1427899242644_0014/jobhistory/job/job_1427899242644_0014,appMasterHost=a11p2,startTime=1427903270617,finishTime=1427903284028,finalStatus=SUCCEEDED
2015-04-01 17:48:10,626 INFO org.apache.hadoop.yarn.server.resourcemanager.scheduler.capacity.CapacityScheduler: Application Attempt appattempt_1427899242644_0014_000001 is done. finalState=FINISHED
2015-04-01 17:48:10,626 INFO org.apache.hadoop.yarn.server.resourcemanager.scheduler.AppSchedulingInfo: Application application_1427899242644_0014 requests cleared
2015-04-01 17:48:10,626 INFO org.apache.hadoop.yarn.server.resourcemanager.scheduler.capacity.LeafQueue: Application removed - appId: application_1427899242644_0014 user: echallier queue: default #user-pending-applications: 0 #user-active-applications: 0 #queue-pending-applications: 0 #queue-active-applications: 0
2015-04-01 17:48:10,626 INFO org.apache.hadoop.yarn.server.resourcemanager.scheduler.capacity.ParentQueue: Application removed - appId: application_1427899242644_0014 user: echallier leaf-queue of parent: root #applications: 0
2015-04-01 17:49:33,192 ERROR org.apache.hadoop.yarn.server.resourcemanager.ResourceManager: RECEIVED SIGNAL 15: SIGTERM
2015-04-01 17:49:33,203 INFO org.mortbay.log: Stopped HttpServer2$SelectChannelConnectorWithSafeStartup@0.0.0.0:8088
2015-04-01 17:49:33,303 INFO org.apache.hadoop.ipc.Server: Stopping server on 8032
2015-04-01 17:49:33,304 INFO org.apache.hadoop.ipc.Server: Stopping IPC Server listener on 8032
2015-04-01 17:49:33,304 INFO org.apache.hadoop.ipc.Server: Stopping server on 8033
2015-04-01 17:49:33,304 INFO org.apache.hadoop.ipc.Server: Stopping IPC Server Responder
2015-04-01 17:49:33,304 INFO org.apache.hadoop.ipc.Server: Stopping IPC Server Responder
2015-04-01 17:49:33,304 INFO org.apache.hadoop.ipc.Server: Stopping IPC Server listener on 8033
2015-04-01 17:49:33,305 INFO org.apache.hadoop.yarn.server.resourcemanager.ResourceManager: Transitioning to standby state
2015-04-01 17:49:33,305 INFO org.apache.hadoop.metrics2.impl.MetricsSystemImpl: Stopping ResourceManager metrics system...
2015-04-01 17:49:33,306 INFO org.apache.hadoop.metrics2.impl.MetricsSystemImpl: ResourceManager metrics system stopped.
2015-04-01 17:49:33,306 INFO org.apache.hadoop.metrics2.impl.MetricsSystemImpl: ResourceManager metrics system shutdown complete.
2015-04-01 17:49:33,306 INFO org.apache.hadoop.yarn.event.AsyncDispatcher: AsyncDispatcher is draining to stop, igonring any new events.
2015-04-01 17:49:33,307 WARN org.apache.hadoop.yarn.server.resourcemanager.amlauncher.ApplicationMasterLauncher: org.apache.hadoop.yarn.server.resourcemanager.amlauncher.ApplicationMasterLauncher$LauncherThread interrupted. Returning.
2015-04-01 17:49:33,307 INFO org.apache.hadoop.ipc.Server: Stopping server on 8030
2015-04-01 17:49:33,308 INFO org.apache.hadoop.ipc.Server: Stopping server on 8031
2015-04-01 17:49:33,308 INFO org.apache.hadoop.ipc.Server: Stopping IPC Server listener on 8030
2015-04-01 17:49:33,308 INFO org.apache.hadoop.ipc.Server: Stopping IPC Server Responder
2015-04-01 17:49:33,314 INFO org.apache.hadoop.yarn.util.AbstractLivelinessMonitor: NMLivelinessMonitor thread interrupted
2015-04-01 17:49:33,314 INFO org.apache.hadoop.ipc.Server: Stopping IPC Server listener on 8031
2015-04-01 17:49:33,315 INFO org.apache.hadoop.ipc.Server: Stopping IPC Server Responder
2015-04-01 17:49:33,315 ERROR org.apache.hadoop.yarn.server.resourcemanager.ResourceManager: Returning, interrupted : java.lang.InterruptedException
2015-04-01 17:49:33,315 INFO org.apache.hadoop.yarn.event.AsyncDispatcher: AsyncDispatcher is draining to stop, igonring any new events.
2015-04-01 17:49:33,316 INFO org.apache.hadoop.yarn.event.AsyncDispatcher: AsyncDispatcher is draining to stop, igonring any new events.
2015-04-01 17:49:33,317 INFO org.apache.hadoop.yarn.event.AsyncDispatcher: AsyncDispatcher is draining to stop, igonring any new events.
2015-04-01 17:49:33,317 INFO org.apache.hadoop.yarn.event.AsyncDispatcher: AsyncDispatcher is draining to stop, igonring any new events.
2015-04-01 17:49:33,326 INFO org.apache.hadoop.yarn.event.AsyncDispatcher: AsyncDispatcher is draining to stop, igonring any new events.
2015-04-01 17:49:33,326 INFO org.apache.hadoop.yarn.event.AsyncDispatcher: AsyncDispatcher is draining to stop, igonring any new events.
2015-04-01 17:49:33,327 INFO org.apache.hadoop.yarn.event.AsyncDispatcher: AsyncDispatcher is draining to stop, igonring any new events.
2015-04-01 17:49:33,327 INFO org.apache.hadoop.yarn.event.AsyncDispatcher: AsyncDispatcher is draining to stop, igonring any new events.
2015-04-01 17:49:33,327 INFO org.apache.hadoop.yarn.event.AsyncDispatcher: AsyncDispatcher is draining to stop, igonring any new events.
2015-04-01 17:49:33,328 INFO org.apache.hadoop.yarn.event.AsyncDispatcher: AsyncDispatcher is draining to stop, igonring any new events.
2015-04-01 17:49:33,328 INFO org.apache.hadoop.yarn.util.AbstractLivelinessMonitor: AMLivelinessMonitor thread interrupted
2015-04-01 17:49:33,328 INFO org.apache.hadoop.yarn.util.AbstractLivelinessMonitor: org.apache.hadoop.yarn.server.resourcemanager.rmcontainer.ContainerAllocationExpirer thread interrupted
2015-04-01 17:49:33,328 ERROR org.apache.hadoop.security.token.delegation.AbstractDelegationTokenSecretManager: ExpiredTokenRemover received java.lang.InterruptedException: sleep interrupted
2015-04-01 17:49:33,328 INFO org.apache.hadoop.yarn.server.resourcemanager.ResourceManager: Transitioned to standby state
2015-04-01 17:49:33,328 INFO org.apache.hadoop.yarn.server.resourcemanager.ResourceManager: SHUTDOWN_MSG: 
/************************************************************
SHUTDOWN_MSG: Shutting down ResourceManager at a11p2/127.0.1.1
************************************************************/
2015-04-01 17:49:33,329 INFO org.apache.hadoop.yarn.util.AbstractLivelinessMonitor: AMLivelinessMonitor thread interrupted
